Workbook

Sheet About
A1: GaHEbIC Government and Household Expenditures by ISIC Code
A3: Source: | B3: Most Industries
B4: OECD
B5: 2018
B6: Input-Output Tables 2018 Edition (ISIC Rev. 4)
B7: https://stats.oecd.org/Index.aspx?DataSetCode=IOTS#
B8: Variable: TTL
B10: ISIC Code Splits
B11: see variable io-model/DLIM
A13: Notes
A14: To split certain ISIC codes grouped by the OECD,
A15: we use data from DLIM on government and household expenditures to apportion the
A16: OECD's total values in ISIC 20T21 into the split ISIC codes.
A18: If you are updating this variable for a new region, update io-model/DLIM first, then
A19: update this variable. Data from DLIM is in the tab beginning with "DLIM".
A21: We convert 2015 USD to 2012 USD with the following conversion factor:
A22: 0.96868157 | B22: 2012 USD per 2015 USD

Sheet OECD TTL
A1: =DotStatQuery(B1) -> #NAME? | B1: Sorry, the query is too large to fit into the Excel cell. You will not be able to update your table with the .Stat Populator.
A2: Dataset: Input-Output Tables 2018 edition
A3: Variable | C3: TTL: Total
A4: Country | C4: BRA: Brazil
A5: Time | C5: 2015
A6: Unit | C6: US Dollar, Millions
A7: To: (sector in column) | C7: D01T03: Agriculture, forestry and fishing | D7: D05T06: Mining and extraction of energy producing products | E7: D07T08: Mining and quarrying of non-energy producing products | F7: D09: Mining support service activities | G7: D10T12: Food products, beverages and tobacco | H7: D13T15: Textiles, wearing apparel, leather and related products | I7: D16: Wood and products of wood and cork | J7: D17T18: Paper products and printing | K7: D19: Coke and refined petroleum products | L7: D20T21: Chemicals and pharmaceutical products | M7: D22: Rubber and plastic products | N7: D23: Other non-metallic mineral products | O7: D24: Basic metals | P7: D25: Fabricated metal products | Q7: D26: Computer, electronic and optical products | R7: D27: Electrical equipment | S7: D28: Machinery and equipment, nec | T7: D29: Motor vehicles, trailers and semi-trailers | U7: D30: Other transport equipment | V7: D31T33: Other manufacturing; repair and installation of machinery and equipment | W7: D35T39: Electricity, gas, water supply, sewerage, waste and remediation services | X7: D41T43: Construction | Y7: D45T47: Wholesale and retail trade; repair of motor vehicles | Z7: D49T53: Transportation and storage | AA7: D55T56: Accomodation and food services | AB7: D58T60: Publishing, audiovisual and broadcasting activities | AC7: D61: Telecommunications | AD7: D62T63: IT and other information services | AE7: D64T66: Financial and insurance activities | AF7: D68: Real estate activities | AG7: D69T82: Other business sector services | AH7: D84: Public admin. and defence; compulsory social security | AI7: D85: Education | AJ7: D86T88: Human health and social work | AK7: D90T96: Arts, entertainment, recreation and other service activities | AL7: D97T98: Private households with employed persons | AM7: HFCE: Final consumption expenditure of households | AN7: NPISH: Final consumption expenditure of non-profit institutions serving households | AO7: GGFC: Final consumption expenditure of general government | AP7: GFCF: Gross Fixed Capital Formation | AQ7: INVNT: Changes in inventories | AR7: CONS_ABR: Direct purchases abroad by residents (imports) | AS7: CONS_NONRES: Direct purchases by non-residents (exports) | AT7: EXPO: Exports (cross border) | AU7: IMPO: Imports (cross border)
A8: From: (sector in row)
A9: TTL_01T03: Agriculture, forestry and fishing | C9: 6071.2 | D9: 22.9 | E9: 12.6 | F9: 5.4 | G9: 54628.4 | H9: 1070.9 | I9: 950.5 | J9: 1220.4 | K9: 3732.1 | L9: 116.1 | M9: 376.9 | N9: 55 | O9: 271.2 | P9: 7.4 | Q9: 1.9 | R9: 1.6 | S9: 2.6 | T9: 17 | U9: 4.9 | V9: 15.4 | W9: 16.5 | X9: 420 | Y9: 820.1 | Z9: 24.6 | AA9: 1503.9 | AB9: 3.6 | AC9: 19.5 | AD9: 5.6 | AE9: 25.7 | AF9: 52 | AG9: 88.9 | AH9: 360.6 | AI9: 254.5 | AJ9: 170.5 | AK9: 156 | AL9: 0 | AM9: 35490.9 | AN9: 0 | AO9: 2021.7 | AP9: 5117.2 | AQ9: -280.5 | AR9: 150.2 | AS9: 17.4 | AT9: 34291.8 | AU9: -3343.4
A10: TTL_05T06: Mining and extraction of energy producing products | C10: 35.2 | D10: 3165.2 | E10: 72.9 | F10: 283.8 | G10: 439.3 | H10: 57.8 | I10: 17.3 | J10: 268.7 | K10: 32198.4 | L10: 855.8 | M10: 35.9 | N10: 233.3 | O10: 1547.6 | P10: 152.2 | Q10: 1.2 | R10: 10.2 | S10: 11.8 | T10: 112.3 | U10: 13.9 | V10: 3.6 | W10: 4544.1 | X10: 241 | Y10: 260.3 | Z10: 138.4 | AA10: 6.9 | AB10: 2.1 | AC10: 20 | AD10: 4.4 | AE10: 45.9 | AF10: 82.2 | AG10: 80.7 | AH10: 75 | AI10: 12.5 | AJ10: 199.1 | AK10: 150.6 | AL10: 0 | AM10: 161.6 | AN10: 0 | AO10: 32.7 | AP10: 4254.8 | AQ10: -228.8 | AR10: 6.4 | AS10: 0.2 | AT10: 11513.1 | AU10: -13509.9
A11: TTL_07T08: Mining and quarrying of non-energy producing products | C11: 148.4 | D11: 134.8 | E11: 774.1 | F11: 24.4 | G11: 141.5 | H11: 4.1 | I11: 0.7 | J11: 18.5 | K11: 66.9 | L11: 1065.1 | M11: 12.7 | N11: 1577.5 | O11: 6004.1 | P11: 79.9 | Q11: 5.5 | R11: 196.1 | S11: 33.4 | T11: 118.3 | U11: 22 | V11: 84.1 | W11: 34.6 | X11: 1914.2 | Y11: 60.7 | Z11: 17.1 | AA11: 3 | AB11: 0.3 | AC11: 0.7 | AD11: 0.5 | AE11: 6.2 | AF11: 30.5 | AG11: 12.9 | AH11: 80.6 | AI11: 6 | AJ11: 7.9 | AK11: 23.6 | AL11: 0 | AM11: 86.6 | AN11: 0 | AO11: 3.6 | AP11: 68.9 | AQ11: -49.2 | AR11: 1.1 | AS11: 0 | AT11: 15903.2 | AU11: -2324.1
A12: TTL_09: Mining support service activities | C12: 390.2 | D12: 1981.2 | E12: 412.9 | F12: 281.3 | G12: 96.6 | H12: 0 | I12: 2.6 | J12: 22.8 | K12: 67.6 | L12: 28.6 | M12: 29.1 | N12: 15 | O12: 6.5 | P12: 0.7 | Q12: 0 | R12: 0.1 | S12: 13.2 | T12: 0.5 | U12: 0.1 | V12: 6.9 | W12: 166.7 | X12: 439.9 | Y12: 0.8 | Z12: 14.5 | AA12: 0.1 | AB12: 0 | AC12: 0 | AD12: 0.1 | AE12: 0.2 | AF12: 0 | AG12: 9.4 | AH12: 53.2 | AI12: 17.9 | AJ12: 0.5 | AK12: 0.5 | AL12: 0 | AM12: 0.4 | AN12: 0 | AO12: 781.8 | AP12: 0.7 | AQ12: 0.5 | AR12: 0.2 | AS12: 0 | AT12: 62.1 | AU12: -73.5
A13: TTL_10T12: Food products, beverages and tobacco | C13: 4743.3 | D13: 149.8 | E13: 51.6 | F13: 7.4 | G13: 27878.5 | H13: 668.7 | I13: 34 | J13: 335.2 | K13: 1174.7 | L13: 3015 | M13: 451.2 | N13: 114.2 | O13: 97.4 | P13: 98.3 | Q13: 40.5 | R13: 87.7 | S13: 59.5 | T13: 93.1 | U13: 33.3 | V13: 122.2 | W13: 85.3 | X13: 290.9 | Y13: 1161.8 | Z13: 160.4 | AA13: 14989 | AB13: 28 | AC13: 60.4 | AD13: 33.9 | AE13: 96.7 | AF13: 34.8 | AG13: 228.4 | AH13: 991.2 | AI13: 994.4 | AJ13: 936.3 | AK13: 468.5 | AL13: 0 | AM13: 110403.4 | AN13: 0.3 | AO13: 1487.2 | AP13: 372.6 | AQ13: 109.8 | AR13: 583.8 | AS13: 53.8 | AT13: 30575.3 | AU13: -7327.9
A14: TTL_13T15: Textiles, wearing apparel, leather and related products | C14: 228.6 | D14: 38.4 | E14: 10.7 | F14: 6.9 | G14: 164 | H14: 10509.7 | I14: 3.1 | J14: 108.6 | K14: 30.3 | L14: 167.6 | M14: 151.2 | N14: 16.5 | O14: 11.2 | P14: 55.8 | Q14: 7.8 | R14: 12.7 | S14: 15.3 | T14: 374.8 | U14: 65.9 | V14: 389.3 | W14: 130.2 | X14: 216.5 | Y14: 650.2 | Z14: 75.8 | AA14: 112.6 | AB14: 23.9 | AC14: 9.3 | AD14: 5.3 | AE14: 82.5 | AF14: 7.7 | AG14: 100.3 | AH14: 238 | AI14: 75.7 | AJ14: 323.4 | AK14: 261.6 | AL14: 0 | AM14: 33181.7 | AN14: 0 | AO14: 176.4 | AP14: 151 | AQ14: 12.1 | AR14: 213.7 | AS14: 31.1 | AT14: 3595.2 | AU14: -7272.9
A15: TTL_16: Wood and of products of wood and cork (except furniture) | C15: 227.7 | D15: 2.6 | E15: 12.4 | F15: 6.4 | G15: 139.9 | H15: 10.3 | I15: 921.6 | J15: 114.9 | K15: 1.8 | L15: 24.1 | M15: 6.6 | N15: 12.4 | O15: 10.9 | P15: 66.3 | Q15: 2.4 | R15: 2.8 | S15: 79.4 | T15: 68.5 | U15: 48 | V15: 1515.3 | W15: 114.7 | X15: 1317.5 | Y15: 246.9 | Z15: 34.8 | AA15: 5.6 | AB15: 21.3 | AC15: 3.5 | AD15: 2 | AE15: 22.8 | AF15: 233.6 | AG15: 70.9 | AH15: 80.3 | AI15: 13 | AJ15: 28.2 | AK15: 112.8 | AL15: 0 | AM15: 629.3 | AN15: 0 | AO15: 24.3 | AP15: 66.1 | AQ15: 7.1 | AR15: 18.7 | AS15: 2.1 | AT15: 1946.9 | AU15: -231.7
A16: TTL_17T18: Paper products and printing | C16: 188.1 | D16: 20.7 | E16: 66.3 | F16: 5.3 | G16: 2522 | H16: 454.3 | I16: 219.3 | J16: 4083.1 | K16: 58.6 | L16: 898.6 | M16: 553.3 | N16: 536.1 | O16: 28.2 | P16: 389.4 | Q16: 372.5 | R16: 121.6 | S16: 80.4 | T16: 324.2 | U16: 32.7 | V16: 302.4 | W16: 180.4 | X16: 153.2 | Y16: 1780.9 | Z16: 253.2 | AA16: 293.1 | AB16: 882.7 | AC16: 278.2 | AD16: 274.3 | AE16: 850.9 | AF16: 81.5 | AG16: 1398.7 | AH16: 1180.6 | AI16: 452.2 | AJ16: 532.1 | AK16: 634.6 | AL16: 0 | AM16: 3926.1 | AN16: 0.1 | AO16: 89.5 | AP16: 232.6 | AQ16: -2.9 | AR16: 80.9 | AS16: 5.5 | AT16: 6840.4 | AU16: -1455.7
A17: TTL_19: Coke and refined petroleum products | C17: 5688.7 | D17: 827.5 | E17: 1510.3 | F17: 143.9 | G17: 2877.5 | H17: 364.4 | I17: 109.2 | J17: 672 | K17: 33940.1 | L17: 8081.3 | M17: 1029 | N17: 1292.1 | O17: 1540.9 | P17: 215.2 | Q17: 69.3 | R17: 320.1 | S17: 147.6 | T17: 502.1 | U17: 114.9 | V17: 269.7 | W17: 1787.7 | X17: 2515.2 | Y17: 2028.1 | Z17: 21335 | AA17: 463.2 | AB17: 29.2 | AC17: 36.4 | AD17: 38.3 | AE17: 419.7 | AF17: 148.7 | AG17: 742.5 | AH17: 1617.5 | AI17: 182.7 | AJ17: 614.9 | AK17: 473.1 | AL17: 0 | AM17: 24668 | AN17: 0 | AO17: 38.7 | AP17: 25.1 | AQ17: 44.1 | AR17: 186.4 | AS17: 15.6 | AT17: 4745.1 | AU17: -8905.2
A18: TTL_20T21: Chemicals and pharmaceutical products | C18: 19057.5 | D18: 1385.4 | E18: 418.3 | F18: 50.4 | G18: 2524.5 | H18: 2288.7 | I18: 422.4 | J18: 2499 | K18: 6057.7 | L18: 29472.8 | M18: 6115.7 | N18: 1452.5 | O18: 1014 | P18: 997.2 | Q18: 207.7 | R18: 1029.4 | S18: 215.2 | T18: 849.5 | U18: 207.3 | V18: 1179.2 | W18: 280.2 | X18: 2741.7 | Y18: 1212.3 | Z18: 740.2 | AA18: 124.3 | AB18: 99.4 | AC18: 82.1 | AD18: 31.6 | AE18: 181.1 | AF18: 180 | AG18: 565.1 | AH18: 553.1 | AI18: 329.5 | AJ18: 1797.3 | AK18: 558.7 | AL18: 0 | AM18: 33283.1 | AN18: 0.3 | AO18: 10168.3 | AP18: 1088.4 | AQ18: 27.5 | AR18: 144.2 | AS18: 10.6 | AT18: 8173.9 | AU18: -30495.7
A19: TTL_22: Rubber and plastics products | C19: 316.9 | D19: 46.8 | E19: 216.1 | F19: 31 | G19: 4089.3 | H19: 357.3 | I19: 63.5 | J19: 465.7 | K19: 59.6 | L19: 1359.2 | M19: 4231.4 | N19: 624.2 | O19: 178.3 | P19: 244.5 | Q19: 372.3 | R19: 598.8 | S19: 629 | T19: 3840 | U19: 259.5 | V19: 1055.7 | W19: 166.9 | X19: 3479.3 | Y19: 1502.1 | Z19: 2097.7 | AA19: 110.2 | AB19: 7.2 | AC19: 11.5 | AD19: 7.9 | AE19: 115 | AF19: 81.1 | AG19: 395.5 | AH19: 315.8 | AI19: 77.7 | AJ19: 335.8 | AK19: 204.9 | AL19: 0 | AM19: 4315.3 | AN19: 0 | AO19: 70.9 | AP19: 440 | AQ19: 5.2 | AR19: 6 | AS19: 1 | AT19: 2440.1 | AU19: -4614.6
A20: TTL_23: Other non-metallic mineral products | C20: 1582.3 | D20: 34.6 | E20: 110.2 | F20: 23.8 | G20: 1128.5 | H20: 32.6 | I20: 2.2 | J20: 72.6 | K20: 46.4 | L20: 469 | M20: 145.9 | N20: 2812.8 | O20: 138.4 | P20: 65 | Q20: 8.1 | R20: 103.6 | S20: 110.9 | T20: 753.8 | U20: 66.1 | V20: 230.1 | W20: 527.2 | X20: 15760.3 | Y20: 387.1 | Z20: 80.5 | AA20: 187.1 | AB20: 2.8 | AC20: 7.7 | AD20: 4.2 | AE20: 52.6 | AF20: 156.9 | AG20: 90.7 | AH20: 202.5 | AI20: 58.2 | AJ20: 153.2 | AK20: 110.2 | AL20: 0 | AM20: 1092.2 | AN20: 0 | AO20: 49.3 | AP20: 139.3 | AQ20: 16.5 | AR20: 2.6 | AS20: 0.5 | AT20: 2037.5 | AU20: -1954.8
... A49: OUTPUT: Output at basic prices | C49: 145972.1 | D49: 47609.5 | E49: 26401.3 | F49: 4831.8 | G49: 196073.8 | H49: 44770 | I49: 8044.8 | J49: 30199.9 | K49: 112965.6 | L49: 109321.4 | M49: 30611.7 | N49: 27101.2 | O49: 48034.8 | P49: 27615.6 | Q49: 25782 | R49: 21784.7 | S49: 36501.9 | T49: 65641.3 | U49: 15435.8 | V49: 40199.3 | W49: 97912.3 | X49: 191319.8 | Y49: 333062 | Z49: 152925.9 | AA49: 74861.6 | AB49: 19331.4 | AC49: 48726.2 | AD49: 37984.2 | AE49: 175880.3 | AF49: 168922.7 | AG49: 195796.7 | AH49: 217738.1 | AI49: 127026.8 | AJ49: 122794.9 | AK49: 54530.1 | AL49: 18634.7 | AM49: 0 | AN49: 0 | AO49: 0 | AP49: 0 | AQ49: 0 | AR49: 0 | AS49: 0 | AT49: 0 | AU49: 0
A50: Data extracted on 15 May 2024 14:54 UTC (GMT) from OECD.Stat

Sheet SCNtoISIC
B3: SCN67 | C3: Descrição do produto | D3: ISIC Code | E3: Meaning | G3: SCN128 | H3: Descrição do produto | I3: ISIC Code | J3: Meaning | K3: Meaning
B4: 191 | C4: Agricultura, inclusive o apoio à agricultura e a pós-colheita | D4: ISIC 01T03 | E4: 01T03: Agriculture, forestry and fishing | G4: 1911 | H4: Arroz, trigo e outros cereais | I4: ISIC 01T03 | J4: 01T03: Agriculture, forestry and fishing | K4: Agriculture, forestry and fishing
B5: 192 | C5: Pecuária, inclusive o apoio à pecuária | D5: ISIC 01T03 | G5: 1912 | H5: Milho em grão | I5: ISIC 01T03
B6: 280 | C6: Produção florestal; pesca e aquicultura | D6: ISIC 01T03 | G6: 1913 | H6: Algodão herbáceo, outras fibras da lav. temporária | I6: ISIC 01T03
B7: 580 | C7: Extração de carvão mineral e de minerais não metálicos | D7: ISIC 05 | E7: 05: Coal mining | G7: 1914 | H7: Cana-de-açúcar | I7: ISIC 01T03
B8: 680 | C8: Extração de petróleo e gás, inclusive as atividades de apoio | D8: ISIC 06 | E8: 06: Oil and gas extraction | G8: 1915 | H8: Soja em grão | I8: ISIC 01T03
B9: 791 | C9: Extração de minério de ferro, inclusive beneficiamentos e a aglomeração | D9: ISIC 07T08 | E9: 07T08: Mining and quarrying of non-energy producing products | G9: 1916 | H9: Outros produtos e serviços da lavoura temporária | I9: ISIC 01T03
B10: 792 | C10: Extração de minerais metálicos não ferrosos, inclusive beneficiamentos | D10: ISIC 09 | E10: 09: Mining support service activities | G10: 1917 | H10: Laranja | I10: ISIC 01T03
B11: 1091 | C11: Abate e produtos de carne, inclusive os produtos do laticínio e da pesca | D11: ISIC 10T12 | E11: 10T12: Food products, beverages and tobacco | G11: 1918 | H11: Café em grão | I11: ISIC 01T03
B12: 1092 | C12: Fabricação e refino de açúcar | D12: ISIC 10T12 | G12: 1919 | H12: Outros produtos da lavoura permanente | I12: ISIC 01T03
B13: 1093 | C13: Outros produtos alimentares | D13: ISIC 10T12 | G13: 1921 | H13: Bovinos e outros animais vivos, prods. animal, caça e serv. | I13: ISIC 01T03
B14: 1100 | C14: Fabricação de bebidas | D14: ISIC 10T12 | G14: 1922 | H14: Leite de vaca e de outros animais | I14: ISIC 01T03
B15: 1200 | C15: Fabricação de produtos do fumo | D15: ISIC 10T12 | G15: 1923 | H15: Suínos | I15: ISIC 01T03
B16: 1300 | C16: Fabricação de produtos têxteis | D16: ISIC 13T15 | E16: 13T15: Textiles, wearing apparel, leather and related products | G16: 1924 | H16: Aves e ovos | I16: ISIC 01T03
B17: 1400 | C17: Confecção de artefatos do vestuário e acessórios | D17: ISIC 13T15 | G17: 2801 | H17: Produtos da exploração florestal e da silvicultura | I17: ISIC 01T03
B18: 1500 | C18: Fabricação de calçados e de artefatos de couro | D18: ISIC 13T15 | G18: 2802 | H18: Pesca e aquicultura (peixe, crustáceos e moluscos) | I18: ISIC 01T03
B19: 1600 | C19: Fabricação de produtos da madeira | D19: ISIC 16 | E19: 16: Wood and of products of wood and cork (except furniture) | G19: 5801 | H19: Carvão mineral | I19: ISIC 05 | J19: 05: Coal mining | K19: Coal mining
B20: 1700 | C20: Fabricação de celulose, papel e produtos de papel | D20: ISIC 17T18 | E20: 17T18: Paper products and printing | G20: 5802 | H20: Minerais não-metálicos | I20: ISIC 05
B21: 1800 | C21: Impressão e reprodução de gravações | D21: ISIC 17T18 | G21: 6801 | H21: Petróleo, gás natural e serviços de apoio | I21: ISIC 06 | J21: 06: Oil and gas extraction | K21: Oil and gas extraction
B22: 1991 | C22: Refino de petróleo e coquerias | D22: ISIC 19 | E22: 19: Coke and refined petroleum products | G22: 7911 | H22: Minério de ferro | I22: ISIC 07T08 | J22: 07T08: Mining and quarrying of non-energy producing products | K22: Mining and quarrying of non-energy producing products
B23: 1992 | C23: Fabricação de biocombustíveis | D23: ISIC 19 | G23: 7921 | H23: Minerais metálicos não-ferrosos | I23: ISIC 09 | J23: 09: Mining support service activities | K23: Mining support service activities
B24: 2091 | C24: Fabricação de químicos orgânicos e inorgânicos, resinas e elastômeros | D24: ISIC 20 | E24: 20: Chemicals | G24: 10911 | H24: Carne de bovinos e outros prod. de carne | I24: ISIC 10T12 | J24: 10T12: Food products, beverages and tobacco | K24: Food products, beverages and tobacco
B25: 2092 | C25: Fabricação de defensivos, desinfestantes, tintas e químicos diversos | D25: ISIC 20 | G25: 10912 | H25: Carne de suíno | I25: ISIC 10T12
B26: 2093 | C26: Fabricação de produtos de limpeza, cosméticos/perfumaria e higiene pessoal | D26: ISIC 20 | G26: 10913 | H26: Carne de aves | I26: ISIC 10T12
B27: 2100 | C27: Fabricação de produtos farmoquímicos e farmacêuticos | D27: ISIC 21 | E27: 21: Pharmaceuticals | G27: 10914 | H27: Pescado industrializado | I27: ISIC 10T12
B28: 2200 | C28: Fabricação de produtos de borracha e de material plástico | D28: ISIC 22 | E28: 22: Rubber and plastics products | G28: 10915 | H28: Leite resfriado, esterilizado e pasteurizado | I28: ISIC 10T12
B29: 2300 | C29: Fabricação de produtos de minerais não metálicos | D29: x | G29: 10916 | H29: Outros produtos do laticínio | I29: ISIC 10T12
B30: 2310 | C30: Cimento / Artefatos de cimento, gesso e semelhantes | D30: ISIC 239 | E30: 239: Cement and other nometallic minerals | G30: 10921 | H30: Açúcar | I30: ISIC 10T12
B31: 2320 | C31: Vidros, cerâmicos e outros prod. de minerais não-metálicos | D31: ISIC 231 | E31: 231: Glass | G31: 10931 | H31: Conservas de frutas, legumes, outros vegetais e sucos de frutas | I31: ISIC 10T12
B32: 2491 | C32: Produção de ferro gusa/ferroligas, siderurgia e tubos de aço sem costura | D32: ISIC 241 | E32: 241: Iron and steel | G32: 10932 | H32: Óleos e gorduras vegetais e animais | I32: ISIC 10T12
B33: 2492 | C33: Metalurgia de metais não ferosos e a fundição de metais | D33: ISIC 242 | E33: 242: Other metals | G33: 10933 | H33: Café beneficiado | I33: ISIC 10T12
B34: 2500 | C34: Fabricação de produtos de metal, exceto máquinas e equipamentos | D34: ISIC 25 | E34: 25: Fabricated metal products, except machinery and equipment | G34: 10934 | H34: Arroz beneficiado e produtos derivados do arroz | I34: ISIC 10T12
B35: 2600 | C35: Fabricação de equipamentos de informática, produtos eletrônicos e ópticos | D35: ISIC 26 | E35: 26: Computer, electronic and optical products | G35: 10935 | H35: Produtos derivados do trigo, mandioca ou milho | I35: ISIC 10T12
B36: 2700 | C36: Fabricação de máquinas e equipamentos elétricos | D36: ISIC 27 | E36: 27: Electrical equipment | G36: 10936 | H36: Rações balanceadas para animais | I36: ISIC 10T12
B37: 2800 | C37: Fabricação de máquinas e equipamentos mecânicos | D37: ISIC 28 | E37: 28: Machinery and equipment n.e.c. | G37: 10937 | H37: Outros produtos alimentares | I37: ISIC 10T12
B38: 2991 | C38: Fabricação de automóveis, caminhões e ônibus, exceto peças | D38: ISIC 29 | E38: 29: Motor vehicles, trailers and semi-trailers | G38: 11001 | H38: Bebidas | I38: ISIC 10T12
B39: 2992 | C39: Fabricação de peças e acessórios para veículos automotores | D39: ISIC 29 | G39: 12001 | H39: Produtos do fumo | I39: ISIC 10T12
B40: 3000 | C40: Fabricação de outros equipamentos de transporte, exceto veículos automotores | D40: ISIC 30 | E40: 30: Other transport equipment | G40: 13001 | H40: Fios e fibras têxteis beneficiadas | I40: ISIC 13T15 | J40: 13T15: Textiles, wearing apparel, leather and related products | K40: Textiles, wearing apparel, leather and related products
B41: 3180 | C41: Fabricação de móveis e de produtos de indústrias diversas | D41: ISIC 30 | G41: 13002 | H41: Tecidos | I41: ISIC 13T15
B42: 3300 | C42: Manutenção, reparação e instalação de máquinas e equipamentos | D42: ISIC 31T33 | E42: 31T33: Other manufacturing; repair and installation of machinery and equipment | G42: 13003 | H42: Art. têxteis de uso doméstico e outros têxteis | I42: ISIC 13T15
...

Sheet DLIM IBGE Use Table
A1: Tabela 2 - Usos de bens e serviços - 2012
A3: Código do produto | D3: Descrição do produto | E3: Consumo intermediário das atividades (valores correntes em 1 000 000 R$)
E4: 0191 Agricultura, inclusive o apoio à agricultura e a pós-colheita | F4: 0192 Pecuária, inclusive o apoio à pecuária | G4: 0280 Produção florestal; pesca e aquicultura | H4: 0580 Extração de carvão mineral e de minerais não-metálicos | I4: 0680 Extração de petróleo e gás, inclusive as atividades de apoio | J4: 0791 Extração de minério de ferro, inclusive beneficiamentos e a aglomeração | K4: 0792 Extração de minerais metálicos não-ferrosos, inclusive beneficiamentos | L4: 1091 Abate e produtos de carne, inclusive os produtos do laticínio e da pesca | M4: 1092 Fabricação e refino de açúcar | N4: 1093 Outros produtos alimentares | O4: 1100 Fabricação de bebidas | P4: 1200 Fabricação de produtos do fumo | Q4: 1300 Fabricação de produtos têxteis | R4: 1400 Confecção de artefatos do vestuário e acessórios | S4: 1500 Fabricação de calçados e de artefatos de couro | T4: 1600 Fabricação de produtos da madeira | U4: 1700 Fabricação de celulose, papel e produtos de papel | V4: 1800 Impressão e reprodução de gravações | W4: 1991 Refino de petróleo e coquerias | X4: 1992 Fabricação de biocombustíveis | Y4: 2091 Fabricação de químicos orgânicos e inorgânicos, resinas e elastômeros | Z4: 2092 Fabricação de defensivos, desinfestantes, tintas e químicos diversos | AA4: 2093 Fabricação de produtos de limpeza, cosméticos/perfumaria e higiene pessoal | AB4: 2100 Fabricação de produtos farmoquímicos e farmacêuticos | AC4: 2200 Fabricação de produtos de borracha e de material plástico | AD4: 2300 Fabricação de produtos de minerais não-metálicos | AE4: 2491 Produção de ferro-gusa/ferroligas, siderurgia e tubos de aço sem costura | AF4: 2492 Metalurgia de metais não-ferrosos e a fundição de metais | AG4: 2500 Fabricação de produtos de metal, exceto máquinas e equipamentos | AH4: 2600 Fabricação de equipamentos de informática, produtos eletrônicos e ópticos | AI4: 2700 Fabricação de máquinas e equipamentos elétricos | AJ4: 2800 Fabricação de máquinas e equipamentos mecânicos | AK4: 2991 Fabricação de automóveis, caminhões e ônibus, exceto peças | AL4: 2992 Fabricação de peças e acessórios para veículos automotores | AM4: 3000 Fabricação de outros equipamentos de transporte, exceto veículos automotores | AN4: 3180 Fabricação de móveis e de produtos de indústrias diversas | AO4: 3300 Manutenção, reparação e instalação de máquinas e equipamentos | AP4: 3500 Energia elétrica, gás natural e outras utilidades | AQ4: 3680 Água, esgoto e gestão de resíduos | AR4: 4180 Construção | AS4: 4500 Comércio e reparação de veículos automotores e motocicletas | AT4: 4680 Comércio por atacado e a varejo, exceto veículos automotores | AU4: 4900 Transporte terrestre | AV4: 5000 Transporte aquaviário | AW4: 5100 Transporte aéreo | AX4: 5280 Armazenamento, atividades auxiliares dos transportes e correio | AY4: 5500 Alojamento | AZ4: 5600 Alimentação | BA4: 5800 Edição e edição integrada à impressão | BB4: 5980 Atividades de televisão, rádio, cinema e gravação/edição de som e imagem | BC4: 6100 Telecomunicações | BD4: 6280 Desenvolvimento de sistemas e outros serviços de informação | BE4: 6480 Intermediação financeira, seguros e previdência complementar | BF4: 6800 Atividades imobiliárias | BG4: 6980 Atividades jurídicas, contábeis, consultoria e sedes de empresas | BH4: 7180 Serviços de arquitetura, engenharia, testes/análises técnicas e P & D | BI4: 7380 Outras atividades profissionais, científicas e técnicas | BJ4: 7700 Aluguéis não-imobiliários e gestão de ativos de propriedade intelectual | BK4: 7880 Outras atividades administrativas e serviços complementares | BL4: 8000 Atividades de vigilância, segurança e investigação | BM4: 8400 Administração pública, defesa e seguridade social | BN4: 8591 Educação pública | BO4: 8592 Educação privada | BP4: 8691 Saúde pública | BQ4: 8692 Saúde privada | BR4: 9080 Atividades artísticas, criativas e de espetáculos | BS4: 9480 Organizações associativas e outros serviços pessoais | BT4: 9700 Serviços domésticos | BU4: Total do produto | BV4: Exportação de bens e serviços (1) | BW4: Consumo do governo | BX4: Consumo das ISFLSF | BY4: Consumo das famílias | BZ4: Formação bruta de capital fixo | CA4: Variação de estoque | CB4: Demanda final | CC4: Demanda total
E5: =VALUE(LEFT(E4,4)) -> 191 | F5: =VALUE(LEFT(F4,4)) -> 192 | G5: =VALUE(LEFT(G4,4)) -> 280 | H5: =VALUE(LEFT(H4,4)) -> 580 | I5: =VALUE(LEFT(I4,4)) -> 680 | J5: =VALUE(LEFT(J4,4)) -> 791 | K5: =VALUE(LEFT(K4,4)) -> 792 | L5: =VALUE(LEFT(L4,4)) -> 1091 | ... BT5: =VALUE(LEFT(BT4,4)) -> 9700
A6: Matching ISIC Code | D6: Matching ISIC Code | E6: =IFERROR(INDEX([1]SCNtoISIC!$D:$D,MATCH(E$5,[1]SCNtoISIC!$B:$B,0)),0) -> ISIC 01T03 | F6: =IFERROR(INDEX([1]SCNtoISIC!$D:$D,MATCH(F$5,[1]SCNtoISIC!$B:$B,0)),0) -> ISIC 01T03 | G6: =IFERROR(INDEX([1]SCNtoISIC!$D:$D,MATCH(G$5,[1]SCNtoISIC!$B:$B,0)),0) -> ISIC 01T03 | H6: =IFERROR(INDEX([1]SCNtoISIC!$D:$D,MATCH(H$5,[1]SCNtoISIC!$B:$B,0)),0) -> ISIC 05 | I6: =IFERROR(INDEX([1]SCNtoISIC!$D:$D,MATCH(I$5,[1]SCNtoISIC!$B:$B,0)),0) -> ISIC 06 | J6: =IFERROR(INDEX([1]SCNtoISIC!$D:$D,MATCH(J$5,[1]SCNtoISIC!$B:$B,0)),0) -> ISIC 07T08 | K6: =IFERROR(INDEX([1]SCNtoISIC!$D:$D,MATCH(K$5,[1]SCNtoISIC!$B:$B,0)),0) -> ISIC 09 | L6: =IFERROR(INDEX([1]SCNtoISIC!$D:$D,MATCH(L$5,[1]SCNtoISIC!$B:$B,0)),0) -> ISIC 10T12 | ... BT6: =IFERROR(INDEX([1]SCNtoISIC!$D:$D,MATCH(BT$5,[1]SCNtoISIC!$B:$B,0)),0) -> ISIC 97T98
A7: 1911 | B7: =IFERROR(INDEX(SCNtoISIC!$I:$I,MATCH($A7,SCNtoISIC!$G:$G,0)),0) -> ISIC 01T03 | C7: =IFERROR(INDEX(SCNtoISIC!$K:$K,MATCH($B7,SCNtoISIC!$I:$I,0)),0) -> Agriculture, forestry and fishing | D7: Arroz, trigo e outros cereais | E7: 219 | F7: 213 | G7: 0 | H7: 0 | I7: 0 | J7: 0 | K7: 0 | L7: 34 | M7: 0 | N7: 12200 | O7: 308 | P7: 0 | Q7: 0 | R7: 0 | S7: 0 | T7: 0 | U7: 0 | V7: 0 | W7: 0 | X7: 0 | Y7: 0 | Z7: 0 | AA7: 0 | AB7: 0 | AC7: 0 | AD7: 0 | AE7: 0 | AF7: 0 | AG7: 0 | AH7: 0 | AI7: 0 | AJ7: 0 | AK7: 0 | AL7: 0 | AM7: 0 | AN7: 0 | AO7: 0 | AP7: 0 | AQ7: 0 | AR7: 0 | AS7: 0 | AT7: 469 | AU7: 0 | AV7: 0 | AW7: 0 | AX7: 0 | AY7: 1 | AZ7: 0 | BA7: 0 | BB7: 0 | BC7: 0 | BD7: 0 | BE7: 0 | BF7: 0 | BG7: 0 | BH7: 0 | BI7: 0 | BJ7: 0 | BK7: 0 | BL7: 0 | BM7: 197 | BN7: 0 | BO7: 0 | BP7: 0 | BQ7: 0 | BR7: 0 | BS7: 0 | BT7: 0 | BU7: 13641 | BV7: 1262 | BW7: 0 | BX7: 0 | BY7: 561 | BZ7: 0 | CA7: -166 | CB7: 1657 | CC7: 15298
A8: 1912 | B8: =IFERROR(INDEX(SCNtoISIC!$I:$I,MATCH($A8,SCNtoISIC!$G:$G,0)),0) -> ISIC 01T03 | C8: =IFERROR(INDEX(SCNtoISIC!$K:$K,MATCH($B8,SCNtoISIC!$I:$I,0)),0) -> Agriculture, forestry and fishing | D8: Milho em grão | E8: 1020 | F8: 3401 | G8: 15 | H8: 0 | I8: 0 | J8: 0 | K8: 0 | L8: 606 | M8: 0 | N8: 10378 | O8: 0 | P8: 0 | Q8: 0 | R8: 0 | S8: 0 | T8: 0 | U8: 0 | V8: 0 | W8: 0 | X8: 0 | Y8: 0 | Z8: 0 | AA8: 0 | AB8: 0 | AC8: 0 | AD8: 0 | AE8: 0 | AF8: 0 | AG8: 0 | AH8: 0 | AI8: 0 | AJ8: 0 | AK8: 0 | AL8: 0 | AM8: 0 | AN8: 0 | AO8: 0 | AP8: 0 | AQ8: 0 | AR8: 0 | AS8: 0 | AT8: 471 | AU8: 0 | AV8: 0 | AW8: 0 | AX8: 0 | AY8: 0 | AZ8: 190 | BA8: 0 | BB8: 0 | BC8: 0 | BD8: 0 | BE8: 0 | BF8: 0 | BG8: 0 | BH8: 0 | BI8: 0 | BJ8: 0 | BK8: 0 | BL8: 0 | BM8: 237 | BN8: 2 | BO8: 0 | BP8: 0 | BQ8: 2 | BR8: 0 | BS8: 0 | BT8: 0 | BU8: 16322 | BV8: 10890 | BW8: 0 | BX8: 0 | BY8: 3855 | BZ8: 0 | CA8: 1600 | CB8: 16345 | CC8: 32667
A9: 1913 | B9: =IFERROR(INDEX(SCNtoISIC!$I:$I,MATCH($A9,SCNtoISIC!$G:$G,0)),0) -> ISIC 01T03 | C9: =IFERROR(INDEX(SCNtoISIC!$K:$K,MATCH($B9,SCNtoISIC!$I:$I,0)),0) -> Agriculture, forestry and fishing | D9: Algodão herbáceo, outras fibras da lav. temporária | E9: 194 | F9: 14 | G9: 0 | H9: 0 | I9: 0 | J9: 0 | K9: 0 | L9: 0 | M9: 0 | N9: 481 | O9: 0 | P9: 0 | Q9: 3569 | R9: 0 | S9: 0 | T9: 0 | U9: 0 | V9: 0 | W9: 0 | X9: 33 | Y9: 0 | Z9: 0 | AA9: 0 | AB9: 0 | AC9: 0 | AD9: 0 | AE9: 0 | AF9: 0 | AG9: 0 | AH9: 0 | AI9: 0 | AJ9: 0 | AK9: 0 | AL9: 0 | AM9: 0 | AN9: 0 | AO9: 0 | AP9: 0 | AQ9: 0 | AR9: 0 | AS9: 0 | AT9: 147 | AU9: 0 | AV9: 0 | AW9: 0 | AX9: 0 | AY9: 0 | AZ9: 0 | BA9: 0 | BB9: 0 | BC9: 0 | BD9: 0 | BE9: 0 | BF9: 0 | BG9: 0 | BH9: 0 | BI9: 0 | BJ9: 0 | BK9: 0 | BL9: 0 | BM9: 0 | BN9: 0 | BO9: 0 | BP9: 0 | BQ9: 0 | BR9: 0 | BS9: 0 | BT9: 0 | BU9: 4438 | BV9: 4183 | BW9: 0 | BX9: 0 | BY9: 5 | BZ9: 0 | CA9: 1425 | CB9: 5613 | CC9: 10051
A10: 1914 | B10: =IFERROR(INDEX(SCNtoISIC!$I:$I,MATCH($A10,SCNtoISIC!$G:$G,0)),0) -> ISIC 01T03 | C10: =IFERROR(INDEX(SCNtoISIC!$K:$K,MATCH($B10,SCNtoISIC!$I:$I,0)),0) -> Agriculture, forestry and fishing | D10: Cana-de-açúcar | E10: 729 | F10: 117 | G10: 2 | H10: 0 | I10: 0 | J10: 0 | K10: 0 | L10: 0 | M10: 30408 | N10: 0 | O10: 1631 | P10: 0 | Q10: 0 | R10: 0 | S10: 0 | T10: 0 | U10: 0 | V10: 0 | W10: 0 | X10: 9916 | Y10: 0 | Z10: 0 | AA10: 0 | AB10: 0 | AC10: 0 | AD10: 0 | AE10: 0 | AF10: 0 | AG10: 0 | AH10: 0 | AI10: 0 | AJ10: 0 | AK10: 0 | AL10: 0 | AM10: 0 | AN10: 0 | AO10: 0 | AP10: 0 | AQ10: 0 | AR10: 0 | AS10: 0 | AT10: 0 | AU10: 0 | AV10: 0 | AW10: 0 | AX10: 0 | AY10: 0 | AZ10: 967 | BA10: 0 | BB10: 0 | BC10: 0 | BD10: 0 | BE10: 0 | BF10: 0 | BG10: 0 | BH10: 0 | BI10: 0 | BJ10: 0 | BK10: 0 | BL10: 0 | BM10: 0 | BN10: 0 | BO10: 0 | BP10: 0 | BQ10: 0 | BR10: 0 | BS10: 0 | BT10: 0 | BU10: 43770 | BV10: 1 | BW10: 0 | BX10: 0 | BY10: 1194 | BZ10: 0 | CA10: 0 | CB10: 1195 | CC10: 44965
A11: 1915 | B11: =IFERROR(INDEX(SCNtoISIC!$I:$I,MATCH($A11,SCNtoISIC!$G:$G,0)),0) -> ISIC 01T03 | C11: =IFERROR(INDEX(SCNtoISIC!$K:$K,MATCH($B11,SCNtoISIC!$I:$I,0)),0) -> Agriculture, forestry and fishing | D11: Soja em grão | E11: 1696 | F11: 142 | G11: 0 | H11: 0 | I11: 0 | J11: 0 | K11: 0 | L11: 372 | M11: 0 | N11: 27346 | O11: 0 | P11: 0 | Q11: 0 | R11: 0 | S11: 0 | T11: 0 | U11: 0 | V11: 0 | W11: 0 | X11: 876 | Y11: 0 | Z11: 0 | AA11: 0 | AB11: 0 | AC11: 0 | AD11: 0 | AE11: 0 | AF11: 0 | AG11: 0 | AH11: 0 | AI11: 0 | AJ11: 0 | AK11: 0 | AL11: 0 | AM11: 0 | AN11: 0 | AO11: 0 | AP11: 0 | AQ11: 0 | AR11: 0 | AS11: 0 | AT11: 7568 | AU11: 0 | AV11: 0 | AW11: 0 | AX11: 0 | AY11: 0 | AZ11: 0 | BA11: 0 | BB11: 0 | BC11: 0 | BD11: 0 | BE11: 0 | BF11: 0 | BG11: 0 | BH11: 0 | BI11: 0 | BJ11: 0 | BK11: 0 | BL11: 0 | BM11: 0 | BN11: 0 | BO11: 0 | BP11: 0 | BQ11: 0 | BR11: 0 | BS11: 0 | BT11: 0 | BU11: 38000 | BV11: 34857 | BW11: 0 | BX11: 0 | BY11: 48 | BZ11: 0 | CA11: -4757 | CB11: 30148 | CC11: 68148
A12: 1916 | B12: =IFERROR(INDEX(SCNtoISIC!$I:$I,MATCH($A12,SCNtoISIC!$G:$G,0)),0) -> ISIC 01T03 | C12: =IFERROR(INDEX(SCNtoISIC!$K:$K,MATCH($B12,SCNtoISIC!$I:$I,0)),0) -> Agriculture, forestry and fishing | D12: Outros produtos e serviços da lavoura temporária | E12: 3406 | F12: 968 | G12: 108 | H12: 0 | I12: 0 | J12: 0 | K12: 0 | L12: 19 | M12: 0 | N12: 3031 | O12: 0 | P12: 4949 | Q12: 0 | R12: 0 | S12: 0 | T12: 0 | U12: 0 | V12: 0 | W12: 0 | X12: 119 | Y12: 0 | Z12: 0 | AA12: 0 | AB12: 0 | AC12: 0 | AD12: 0 | AE12: 0 | AF12: 0 | AG12: 0 | AH12: 0 | AI12: 0 | AJ12: 0 | AK12: 0 | AL12: 0 | AM12: 0 | AN12: 0 | AO12: 0 | AP12: 0 | AQ12: 25 | AR12: 6 | AS12: 0 | AT12: 550 | AU12: 0 | AV12: 0 | AW12: 0 | AX12: 0 | AY12: 140 | AZ12: 1911 | BA12: 0 | BB12: 0 | BC12: 0 | BD12: 0 | BE12: 0 | BF12: 0 | BG12: 3 | BH12: 0 | BI12: 0 | BJ12: 0 | BK12: 96 | BL12: 0 | BM12: 533 | BN12: 348 | BO12: 37 | BP12: 154 | BQ12: 127 | BR12: 1 | BS12: 180 | BT12: 0 | BU12: 16711 | BV12: 813 | BW12: 54 | BX12: 0 | BY12: 36618 | BZ12: 0 | CA12: -295 | CB12: 37190 | CC12: 53901
A13: 1917 | B13: =IFERROR(INDEX(SCNtoISIC!$I:$I,MATCH($A13,SCNtoISIC!$G:$G,0)),0) -> ISIC 01T03 | C13: =IFERROR(INDEX(SCNtoISIC!$K:$K,MATCH($B13,SCNtoISIC!$I:$I,0)),0) -> Agriculture, forestry and fishing | D13: Laranja | E13: 5 | F13: 4 | G13: 2 | H13: 0 | I13: 0 | J13: 0 | K13: 0 | L13: 0 | M13: 0 | N13: 5359 | O13: 0 | P13: 0 | Q13: 0 | R13: 0 | S13: 0 | T13: 0 | U13: 0 | V13: 0 | W13: 0 | X13: 0 | Y13: 0 | Z13: 0 | AA13: 0 | AB13: 0 | AC13: 0 | AD13: 0 | AE13: 0 | AF13: 0 | AG13: 0 | AH13: 0 | AI13: 0 | AJ13: 0 | AK13: 0 | AL13: 0 | AM13: 0 | AN13: 0 | AO13: 0 | AP13: 0 | AQ13: 0 | AR13: 0 | AS13: 0 | AT13: 0 | AU13: 0 | AV13: 0 | AW13: 0 | AX13: 0 | AY13: 69 | AZ13: 268 | BA13: 0 | BB13: 0 | BC13: 0 | BD13: 0 | BE13: 0 | BF13: 0 | BG13: 0 | BH13: 0 | BI13: 0 | BJ13: 0 | BK13: 0 | BL13: 0 | BM13: 9 | BN13: 6 | BO13: 0 | BP13: 2 | BQ13: 0 | BR13: 0 | BS13: 4 | BT13: 0 | BU13: 5728 | BV13: 18 | BW13: 1 | BX13: 0 | BY13: 1541 | BZ13: 161 | CA13: 0 | CB13: 1721 | CC13: 7449
A14: 1918 | B14: =IFERROR(INDEX(SCNtoISIC!$I:$I,MATCH($A14,SCNtoISIC!$G:$G,0)),0) -> ISIC 01T03 | C14: =IFERROR(INDEX(SCNtoISIC!$K:$K,MATCH($B14,SCNtoISIC!$I:$I,0)),0) -> Agriculture, forestry and fishing | D14: Café em grão | E14: 28 | F14: 97 | G14: 1 | H14: 0 | I14: 0 | J14: 0 | K14: 0 | L14: 0 | M14: 0 | N14: 4979 | O14: 0 | P14: 0 | Q14: 0 | R14: 0 | S14: 0 | T14: 0 | U14: 0 | V14: 0 | W14: 0 | X14: 0 | Y14: 0 | Z14: 0 | AA14: 0 | AB14: 0 | AC14: 0 | AD14: 0 | AE14: 0 | AF14: 0 | AG14: 0 | AH14: 0 | AI14: 0 | AJ14: 0 | AK14: 0 | AL14: 0 | AM14: 0 | AN14: 0 | AO14: 0 | AP14: 0 | AQ14: 0 | AR14: 0 | AS14: 0 | AT14: 0 | AU14: 0 | AV14: 0 | AW14: 0 | AX14: 0 | AY14: 0 | AZ14: 0 | BA14: 0 | BB14: 0 | BC14: 0 | BD14: 0 | BE14: 0 | BF14: 0 | BG14: 0 | BH14: 4 | BI14: 0 | BJ14: 0 | BK14: 0 | BL14: 0 | BM14: 68 | BN14: 0 | BO14: 0 | BP14: 0 | BQ14: 0 | BR14: 0 | BS14: 5 | BT14: 0 | BU14: 5182 | BV14: 11149 | BW14: 0 | BX14: 0 | BY14: 404 | BZ14: 376 | CA14: 311 | CB14: 12240 | CC14: 17422
A15: 1919 | B15: =IFERROR(INDEX(SCNtoISIC!$I:$I,MATCH($A15,SCNtoISIC!$G:$G,0)),0) -> ISIC 01T03 | C15: =IFERROR(INDEX(SCNtoISIC!$K:$K,MATCH($B15,SCNtoISIC!$I:$I,0)),0) -> Agriculture, forestry and fishing | D15: Outros produtos da lavoura permanente | E15: 49 | F15: 14 | G15: 1 | H15: 0 | I15: 0 | J15: 0 | K15: 0 | L15: 1 | M15: 0 | N15: 2368 | O15: 17 | P15: 0 | Q15: 0 | R15: 0 | S15: 0 | T15: 0 | U15: 0 | V15: 0 | W15: 0 | X15: 0 | Y15: 0 | Z15: 0 | AA15: 0 | AB15: 0 | AC15: 0 | AD15: 0 | AE15: 0 | AF15: 0 | AG15: 0 | AH15: 0 | AI15: 0 | AJ15: 0 | AK15: 0 | AL15: 0 | AM15: 0 | AN15: 0 | AO15: 0 | AP15: 0 | AQ15: 0 | AR15: 0 | AS15: 0 | AT15: 92 | AU15: 0 | AV15: 0 | AW15: 0 | AX15: 0 | AY15: 19 | AZ15: 489 | BA15: 0 | BB15: 0 | BC15: 0 | BD15: 0 | BE15: 0 | BF15: 0 | BG15: 0 | BH15: 2 | BI15: 0 | BJ15: 0 | BK15: 0 | BL15: 0 | BM15: 128 | BN15: 81 | BO15: 3 | BP15: 31 | BQ15: 18 | BR15: 0 | BS15: 4 | BT15: 0 | BU15: 3317 | BV15: 1028 | BW15: 20 | BX15: 0 | BY15: 19050 | BZ15: 102 | CA15: 0 | CB15: 20200 | CC15: 23517
A16: 1921 | B16: =IFERROR(INDEX(SCNtoISIC!$I:$I,MATCH($A16,SCNtoISIC!$G:$G,0)),0) -> ISIC 01T03 | C16: =IFERROR(INDEX(SCNtoISIC!$K:$K,MATCH($B16,SCNtoISIC!$I:$I,0)),0) -> Agriculture, forestry and fishing | D16: Bovinos e outros animais vivos, prods. animal, caça e serv. | E16: 295 | F16: 1535 | G16: 9 | H16: 0 | I16: 0 | J16: 0 | K16: 0 | L16: 41164 | M16: 0 | N16: 25 | O16: 0 | P16: 0 | Q16: 0 | R16: 0 | S16: 0 | T16: 0 | U16: 0 | V16: 0 | W16: 0 | X16: 0 | Y16: 0 | Z16: 0 | AA16: 0 | AB16: 0 | AC16: 0 | AD16: 0 | AE16: 0 | AF16: 0 | AG16: 0 | AH16: 0 | AI16: 0 | AJ16: 0 | AK16: 0 | AL16: 0 | AM16: 0 | AN16: 0 | AO16: 0 | AP16: 0 | AQ16: 0 | AR16: 0 | AS16: 0 | AT16: 0 | AU16: 0 | AV16: 0 | AW16: 0 | AX16: 0 | AY16: 0 | AZ16: 0 | BA16: 0 | BB16: 0 | BC16: 0 | BD16: 0 | BE16: 0 | BF16: 0 | BG16: 0 | BH16: 0 | BI16: 5 | BJ16: 0 | BK16: 0 | BL16: 0 | BM16: 95 | BN16: 50 | BO16: 5 | BP16: 0 | BQ16: 72 | BR16: 0 | BS16: 0 | BT16: 0 | BU16: 43255 | BV16: 1443 | BW16: 1 | BX16: 0 | BY16: 711 | BZ16: 10645 | CA16: 1053 | CB16: 13853 | CC16: 57108
A17: 1922 | B17: =IFERROR(INDEX(SCNtoISIC!$I:$I,MATCH($A17,SCNtoISIC!$G:$G,0)),0) -> ISIC 01T03 | C17: =IFERROR(INDEX(SCNtoISIC!$K:$K,MATCH($B17,SCNtoISIC!$I:$I,0)),0) -> Agriculture, forestry and fishing | D17: Leite de vaca e de outros animais | E17: 52 | F17: 1033 | G17: 32 | H17: 0 | I17: 0 | J17: 0 | K17: 0 | L17: 13089 | M17: 0 | N17: 0 | O17: 0 | P17: 0 | Q17: 0 | R17: 0 | S17: 0 | T17: 0 | U17: 0 | V17: 0 | W17: 0 | X17: 0 | Y17: 0 | Z17: 0 | AA17: 0 | AB17: 0 | AC17: 0 | AD17: 0 | AE17: 0 | AF17: 0 | AG17: 0 | AH17: 0 | AI17: 0 | AJ17: 0 | AK17: 0 | AL17: 0 | AM17: 0 | AN17: 0 | AO17: 0 | AP17: 0 | AQ17: 0 | AR17: 0 | AS17: 0 | AT17: 0 | AU17: 0 | AV17: 0 | AW17: 0 | AX17: 0 | AY17: 0 | AZ17: 70 | BA17: 0 | BB17: 0 | BC17: 0 | BD17: 0 | BE17: 0 | BF17: 0 | BG17: 0 | BH17: 0 | BI17: 0 | BJ17: 0 | BK17: 0 | BL17: 0 | BM17: 0 | BN17: 0 | BO17: 0 | BP17: 0 | BQ17: 0 | BR17: 0 | BS17: 11 | BT17: 0 | BU17: 14287 | BV17: 0 | BW17: 0 | BX17: 0 | BY17: 9172 | BZ17: 0 | CA17: 0 | CB17: 9172 | CC17: 23459
A18: 1923 | B18: =IFERROR(INDEX(SCNtoISIC!$I:$I,MATCH($A18,SCNtoISIC!$G:$G,0)),0) -> ISIC 01T03 | C18: =IFERROR(INDEX(SCNtoISIC!$K:$K,MATCH($B18,SCNtoISIC!$I:$I,0)),0) -> Agriculture, forestry and fishing | D18: Suínos | E18: 31 | F18: 163 | G18: 1 | H18: 0 | I18: 0 | J18: 0 | K18: 0 | L18: 6482 | M18: 0 | N18: 0 | O18: 0 | P18: 0 | Q18: 0 | R18: 0 | S18: 0 | T18: 0 | U18: 0 | V18: 0 | W18: 0 | X18: 0 | Y18: 0 | Z18: 0 | AA18: 0 | AB18: 0 | AC18: 0 | AD18: 0 | AE18: 0 | AF18: 0 | AG18: 0 | AH18: 0 | AI18: 0 | AJ18: 0 | AK18: 0 | AL18: 0 | AM18: 0 | AN18: 0 | AO18: 0 | AP18: 0 | AQ18: 0 | AR18: 0 | AS18: 0 | AT18: 0 | AU18: 0 | AV18: 0 | AW18: 0 | AX18: 0 | AY18: 0 | AZ18: 0 | BA18: 0 | BB18: 0 | BC18: 0 | BD18: 0 | BE18: 0 | BF18: 0 | BG18: 0 | BH18: 0 | BI18: 0 | BJ18: 0 | BK18: 0 | BL18: 0 | BM18: 0 | BN18: 0 | BO18: 0 | BP18: 0 | BQ18: 0 | BR18: 0 | BS18: 0 | BT18: 0 | BU18: 6677 | BV18: 4 | BW18: 0 | BX18: 0 | BY18: 186 | BZ18: 30 | CA18: 0 | CB18: 220 | CC18: 6897
... A134: 97001 | B134: =IFERROR(INDEX(SCNtoISIC!$I:$I,MATCH($A134,SCNtoISIC!$G:$G,0)),0) -> ISIC 97T98 | C134: =IFERROR(INDEX(SCNtoISIC!$K:$K,MATCH($B134,SCNtoISIC!$I:$I,0)),0) -> Private households with employed persons | D134: Serviços domésticos | E134: 0 | F134: 0 | G134: 0 | H134: 0 | I134: 0 | J134: 0 | K134: 0 | L134: 0 | M134: 0 | N134: 0 | O134: 0 | P134: 0 | Q134: 0 | R134: 0 | S134: 0 | T134: 0 | U134: 0 | V134: 0 | W134: 0 | X134: 0 | Y134: 0 | Z134: 0 | AA134: 0 | AB134: 0 | AC134: 0 | AD134: 0 | AE134: 0 | AF134: 0 | AG134: 0 | AH134: 0 | AI134: 0 | AJ134: 0 | AK134: 0 | AL134: 0 | AM134: 0 | AN134: 0 | AO134: 0 | AP134: 0 | AQ134: 0 | AR134: 0 | AS134: 0 | AT134: 0 | AU134: 0 | AV134: 0 | AW134: 0 | AX134: 0 | AY134: 0 | AZ134: 0 | BA134: 0 | BB134: 0 | BC134: 0 | BD134: 0 | BE134: 0 | BF134: 0 | BG134: 0 | BH134: 0 | BI134: 0 | BJ134: 0 | BK134: 0 | BL134: 0 | BM134: 0 | BN134: 0 | BO134: 0 | BP134: 0 | BQ134: 0 | BR134: 0 | BS134: 0 | BT134: 0 | BU134: 0 | BV134: 0 | BW134: 0 | BX134: 0 | BY134: 47365 | BZ134: 0 | CA134: 0 | CB134: 47365 | CC134: 47365
E135: 0 | F135: 0 | G135: 0 | H135: 0 | I135: 0 | J135: 0 | K135: 0 | L135: 0 | M135: 0 | N135: 0 | O135: 0 | P135: 0 | Q135: 0 | R135: 0 | S135: 0 | T135: 0 | U135: 0 | V135: 0 | W135: 0 | X135: 0 | Y135: 0 | Z135: 0 | AA135: 0 | AB135: 0 | AC135: 0 | AD135: 0 | AE135: 0 | AF135: 0 | AG135: 0 | AH135: 0 | AI135: 0 | AJ135: 0 | AK135: 0 | AL135: 0 | AM135: 0 | AN135: 0 | AO135: 0 | AP135: 0 | AQ135: 0 | AR135: 0 | AS135: 0 | AT135: 0 | AU135: 0 | AV135: 0 | AW135: 0 | AX135: 0 | AY135: 0 | AZ135: 0 | BA135: 0 | BB135: 0 | BC135: 0 | BD135: 0 | BE135: 0 | BF135: 0 | BG135: 0 | BH135: 0 | BI135: 0 | BJ135: 0 | BK135: 0 | BL135: 0 | BM135: 0 | BN135: 0 | BO135: 0 | BP135: 0 | BQ135: 0 | BR135: 0 | BS135: 0 | BT135: 0 | BU135: 0
A136: Total | E136: 97767 | F136: 50400 | G136: 7273 | H136: 9784 | I136: 64782 | J136: 22119 | K136: 7767 | L136: 152991 | M136: 45728 | N136: 170180 | O136: 40478 | P136: 9900 | Q136: 31252 | R136: 34498 | S136: 22939 | T136: 14879 | U136: 46394 | V136: 10894 | W136: 305468 | X136: 18245 | Y136: 101162 | Z136: 43795 | AA136: 23281 | AB136: 25530 | AC136: 63347 | AD136: 52022 | AE136: 72540 | AF136: 35471 | AG136: 53355 | AH136: 60706 | AI136: 48546 | AJ136: 78734 | AK136: 132782 | AL136: 57523 | AM136: 28061 | AN136: 34516 | AO136: 30229 | AP136: 115061 | AQ136: 19157 | AR136: 310543 | AS136: 53226 | AT136: 255434 | AU136: 141353 | AV136: 9319 | AW136: 24032 | AX136: 35879 | AY136: 8060 | AZ136: 90883 | BA136: 12191 | BB136: 19301 | BC136: 92065 | BD136: 29543 | BE136: 166597 | BF136: 33889 | BG136: 44774 | BH136: 24204 | BI136: 50341 | BJ136: 12362 | BK136: 52385 | BL136: 4984 | BM136: 172473 | BN136: 43102 | BO136: 24263 | BP136: 42608 | BQ136: 58657 | BR136: 12184 | BS136: 64711 | BT136: 0 | BU136: 4128919 | BV136: 563474 | BW136: 892180 | BX136: 72905 | BY136: 2883929 | BZ136: 997460 | CA136: 33728 | CB136: 5443676 | CC136: 9572595

Sheet Split ISIC Code Shares
B1: Unit | C1: Coal mining | D1: Oil and gas extraction | E1: Chemicals | F1: Pharmaceuticals | G1: Glass | H1: Cement and Other Nometallic Minerals | I1: Iron and steel | J1: Other metals | K1: Electricity generation and distribution | L1: Energy pipelines and gas processing | M1: Water and waste
C2: ISIC 05 | D2: ISIC 06 | E2: ISIC 20 | F2: ISIC 21 | G2: ISIC 231 | H2: ISIC 239 | I2: ISIC 241 | J2: ISIC 242 | K2: ISIC 351 | L2: ISIC 352T353 | M2: ISIC 36T39
A3: Government | B3: million USD | C3: {=SUMPRODUCT('DLIM IBGE Use Table'!$BM$7:$BN$134*('DLIM IBGE Use Table'!$B$7:$B$134=C$2))+SUMPRODUCT('DLIM IBGE Use Table'!$BP$7:$BP$134*('DLIM IBGE Use Table'!$B$7:$B$134=C$2))} -> 100 | D3: {=SUMPRODUCT('DLIM IBGE Use Table'!$BM$7:$BN$134*('DLIM IBGE Use Table'!$B$7:$B$134=D$2))+SUMPRODUCT('DLIM IBGE Use Table'!$BP$7:$BP$134*('DLIM IBGE Use Table'!$B$7:$B$134=D$2))} -> 0 | E3: {=SUMPRODUCT('DLIM IBGE Use Table'!$BM$7:$BN$134*('DLIM IBGE Use Table'!$B$7:$B$134=E$2))+SUMPRODUCT('DLIM IBGE Use Table'!$BP$7:$BP$134*('DLIM IBGE Use Table'!$B$7:$B$134=E$2))} -> 2542 | F3: {=SUMPRODUCT('DLIM IBGE Use Table'!$BM$7:$BN$134*('DLIM IBGE Use Table'!$B$7:$B$134=F$2))+SUMPRODUCT('DLIM IBGE Use Table'!$BP$7:$BP$134*('DLIM IBGE Use Table'!$B$7:$B$134=F$2))} -> 6213 | G3: {=SUMPRODUCT('DLIM IBGE Use Table'!$BM$7:$BN$134*('DLIM IBGE Use Table'!$B$7:$B$134=G$2))+SUMPRODUCT('DLIM IBGE Use Table'!$BP$7:$BP$134*('DLIM IBGE Use Table'!$B$7:$B$134=G$2))} -> 604 | H3: {=SUMPRODUCT('DLIM IBGE Use Table'!$BM$7:$BN$134*('DLIM IBGE Use Table'!$B$7:$B$134=H$2))+SUMPRODUCT('DLIM IBGE Use Table'!$BP$7:$BP$134*('DLIM IBGE Use Table'!$B$7:$B$134=H$2))} -> 151 | I3: {=SUMPRODUCT('DLIM IBGE Use Table'!$BM$7:$BN$134*('DLIM IBGE Use Table'!$B$7:$B$134=I$2))+SUMPRODUCT('DLIM IBGE Use Table'!$BP$7:$BP$134*('DLIM IBGE Use Table'!$B$7:$B$134=I$2))} -> 195 | J3: {=SUMPRODUCT('DLIM IBGE Use Table'!$BM$7:$BN$134*('DLIM IBGE Use Table'!$B$7:$B$134=J$2))+SUMPRODUCT('DLIM IBGE Use Table'!$BP$7:$BP$134*('DLIM IBGE Use Table'!$B$7:$B$134=J$2))} -> 19 | ... M3: {=SUMPRODUCT('DLIM IBGE Use Table'!$BM$7:$BN$134*('DLIM IBGE Use Table'!$B$7:$B$134=M$2))+SUMPRODUCT('DLIM IBGE Use Table'!$BP$7:$BP$134*('DLIM IBGE Use Table'!$B$7:$B$134=M$2))} -> 11642
A4: Households | B4: million USD | C4: {=SUMPRODUCT('DLIM IBGE Use Table'!$BY$7:$BY$134*('DLIM IBGE Use Table'!$B$7:$B$134=C$2))} -> 0 | D4: {=SUMPRODUCT('DLIM IBGE Use Table'!$BY$7:$BY$134*('DLIM IBGE Use Table'!$B$7:$B$134=D$2))} -> 0 | E4: {=SUMPRODUCT('DLIM IBGE Use Table'!$BY$7:$BY$134*('DLIM IBGE Use Table'!$B$7:$B$134=E$2))} -> 65308 | F4: {=SUMPRODUCT('DLIM IBGE Use Table'!$BY$7:$BY$134*('DLIM IBGE Use Table'!$B$7:$B$134=F$2))} -> 71202 | G4: {=SUMPRODUCT('DLIM IBGE Use Table'!$BY$7:$BY$134*('DLIM IBGE Use Table'!$B$7:$B$134=G$2))} -> 2886 | H4: {=SUMPRODUCT('DLIM IBGE Use Table'!$BY$7:$BY$134*('DLIM IBGE Use Table'!$B$7:$B$134=H$2))} -> 0 | I4: {=SUMPRODUCT('DLIM IBGE Use Table'!$BY$7:$BY$134*('DLIM IBGE Use Table'!$B$7:$B$134=I$2))} -> 239 | J4: {=SUMPRODUCT('DLIM IBGE Use Table'!$BY$7:$BY$134*('DLIM IBGE Use Table'!$B$7:$B$134=J$2))} -> 392 | ... M4: {=SUMPRODUCT('DLIM IBGE Use Table'!$BY$7:$BY$134*('DLIM IBGE Use Table'!$B$7:$B$134=M$2))} -> 21860
A6: Government | B6: percent | C6: =IFERROR(C3/SUM(C3:D3),0) -> 1 | D6: =IFERROR(D3/SUM(C3:D3),0) -> 0 | E6: =IFERROR(E3/SUM(E3:F3),0) -> 0.29034837 | F6: =IFERROR(F3/SUM(E3:F3),0) -> 0.70965163 | G6: =IFERROR(G3/SUM(G3:H3),0) -> 0.8 | H6: =IFERROR(H3/SUM(G3:H3),0) -> 0.2 | I6: =IFERROR(I3/SUM(I3:J3),0) -> 0.91121495 | J6: =IFERROR(J3/SUM(I3:J3),0) -> 0.088785047 | K6: =IFERROR(K3/SUM($K3:$M3),0) -> 0 | L6: =IFERROR(L3/SUM($K3:$M3),0) -> 0.39828406 | M6: =IFERROR(M3/SUM($K3:$M3),0) -> 0.60171594
A7: Households | B7: percent | C7: =IFERROR(C4/SUM(C4:D4),0) -> 0 | D7: =IFERROR(D4/SUM(C4:D4),0) -> 0 | E7: =IFERROR(E4/SUM(E4:F4),0) -> 0.47841184 | F7: =IFERROR(F4/SUM(E4:F4),0) -> 0.52158816 | G7: =IFERROR(G4/SUM(G4:H4),0) -> 1 | H7: =IFERROR(H4/SUM(G4:H4),0) -> 0 | I7: =IFERROR(I4/SUM(I4:J4),0) -> 0.37876387 | J7: =IFERROR(J4/SUM(I4:J4),0) -> 0.62123613 | K7: =IFERROR(K4/SUM($K4:$M4),0) -> 0 | L7: =IFERROR(L4/SUM($K4:$M4),0) -> 0.75828745 | M7: =IFERROR(M4/SUM($K4:$M4),0) -> 0.24171255

Sheet GaHEbIC-government
A1: Unit: USD | B1: ISIC 01T03 | C1: ISIC 05 | D1: ISIC 06 | E1: ISIC 07T08 | F1: ISIC 09 | G1: ISIC 10T12 | H1: ISIC 13T15 | I1: ISIC 16 | J1: ISIC 17T18 | K1: ISIC 19 | L1: ISIC 20 | M1: ISIC 21 | N1: ISIC 22 | O1: ISIC 231 | P1: ISIC 239 | Q1: ISIC 241 | R1: ISIC 242 | S1: ISIC 25 | T1: ISIC 26 | U1: ISIC 27 | V1: ISIC 28 | W1: ISIC 29 | X1: ISIC 30 | Y1: ISIC 31T33 | Z1: ISIC 351 | AA1: ISIC 352T353 | AB1: ISIC 36T39 | AC1: ISIC 41T43 | AD1: ISIC 45T47 | AE1: ISIC 49T53 | AF1: ISIC 55T56 | AG1: ISIC 58T60 | AH1: ISIC 61 | AI1: ISIC 62T63 | AJ1: ISIC 64T66 | AK1: ISIC 68 | AL1: ISIC 69T82 | AM1: ISIC 84 | AN1: ISIC 85 | AO1: ISIC 86T88 | AP1: ISIC 90T96 | AQ1: ISIC 97T98
A2: Government Expenditures | B2: ='OECD TTL'!AO9*10^6*About!$A$22 -> 1.9583835e+09 | C2: ='OECD TTL'!AO10*10^6*About!$A$22*'Split ISIC Code Shares'!C6 -> 31675887 | D2: ='OECD TTL'!AO10*10^6*About!$A$22*'Split ISIC Code Shares'!D6 -> 0 | E2: {=TRANSPOSE('OECD TTL'!AO11:AO17)*10^6*About!$A$22} -> 3487253.7 | F2: 7.5731525e+08 | G2: 1.4406232e+09 | H2: 1.7087543e+08 | I2: 23538962 | J2: 86697001 | K2: 37487977 | L2: ='OECD TTL'!$AO$18*10^6*About!$A$22*'Split ISIC Code Shares'!E6 -> 2.8598864e+09 | M2: ='OECD TTL'!$AO$18*10^6*About!$A$22*'Split ISIC Code Shares'!F6 -> 6.9899584e+09 | N2: ='OECD TTL'!AO19*10^6*About!$A$22 -> 68679523 | O2: ='OECD TTL'!$AO$20*10^6*About!$A$22*'Split ISIC Code Shares'!G6 -> 38204801 | P2: ='OECD TTL'!$AO$20*10^6*About!$A$22*'Split ISIC Code Shares'!H6 -> 9551200.3 | Q2: ='OECD TTL'!$AO$21*10^6*About!$A$22*'Split ISIC Code Shares'!I6 -> 1.3372559e+08 | R2: ='OECD TTL'!$AO$21*10^6*About!$A$22*'Split ISIC Code Shares'!J6 -> 13029672 | S2: {=TRANSPOSE('OECD TTL'!AO22:AO28)*10^6*About!$A$22} -> 57442817 | T2: 21117258 | U2: 38650395 | V2: 28285502 | W2: 61511280 | X2: 2.0826654e+09 | Y2: 77591394 | Z2: ='OECD TTL'!$AO$29*10^6*About!$A$22*'Split ISIC Code Shares'!K6 -> 0 | AA2: ='OECD TTL'!$AO$29*10^6*About!$A$22*'Split ISIC Code Shares'!L6 -> 2.3630889e+08 | AB2: ='OECD TTL'!$AO$29*10^6*About!$A$22*'Split ISIC Code Shares'!M6 -> 3.5700857e+08 | AC2: {=TRANSPOSE('OECD TTL'!AO30:AO44)*10^6*About!$A$22} -> 44559352 | AD2: 7.0648853e+09 | AE2: 5.3488659e+09 | AF2: 48724683 | AG2: 18211214 | AH2: 39522208 | AI2: 19761104 | AJ2: 3.0887381e+09 | AK2: 7.669052e+09 | AL2: 9.711614e+09 | AM2: 1.9055846e+11 | AN2: 9.0727685e+10 | AO2: 4.5262615e+09 | AP2: 7.2321766e+09 | AQ2: 0

Sheet GaHEbIC-household
A1: Unit: USD | B1: ISIC 01T03 | C1: ISIC 05 | D1: ISIC 06 | E1: ISIC 07T08 | F1: ISIC 09 | G1: ISIC 10T12 | H1: ISIC 13T15 | I1: ISIC 16 | J1: ISIC 17T18 | K1: ISIC 19 | L1: ISIC 20 | M1: ISIC 21 | N1: ISIC 22 | O1: ISIC 231 | P1: ISIC 239 | Q1: ISIC 241 | R1: ISIC 242 | S1: ISIC 25 | T1: ISIC 26 | U1: ISIC 27 | V1: ISIC 28 | W1: ISIC 29 | X1: ISIC 30 | Y1: ISIC 31T33 | Z1: ISIC 351 | AA1: ISIC 352T353 | AB1: ISIC 36T39 | AC1: ISIC 41T43 | AD1: ISIC 45T47 | AE1: ISIC 49T53 | AF1: ISIC 55T56 | AG1: ISIC 58T60 | AH1: ISIC 61 | AI1: ISIC 62T63 | AJ1: ISIC 64T66 | AK1: ISIC 68 | AL1: ISIC 69T82 | AM1: ISIC 84 | AN1: ISIC 85 | AO1: ISIC 86T88 | AP1: ISIC 90T96 | AQ1: ISIC 97T98
A2: Household Expenditures | B2: ='OECD TTL'!AM9*10^6*About!$A$22 -> 3.4379381e+10 | C2: ='OECD TTL'!AM10*10^6*About!$A$22*'Split ISIC Code Shares'!C7 -> 0 | D2: ='OECD TTL'!AM10*10^6*About!$A$22*'Split ISIC Code Shares'!D7 -> 0 | E2: {=TRANSPOSE('OECD TTL'!AM11:AM17)*10^6*About!$A$22} -> 83887824 | F2: 387472.63 | G2: 1.0694574e+11 | H2: 3.2142501e+10 | I2: 6.0959131e+08 | J2: 3.8031407e+09 | K2: 2.3895437e+10 | L2: ='OECD TTL'!$AM$18*10^6*About!$A$22*'Split ISIC Code Shares'!E7 -> 1.5424345e+10 | M2: ='OECD TTL'!$AM$18*10^6*About!$A$22*'Split ISIC Code Shares'!F7 -> 1.6816381e+10 | N2: ='OECD TTL'!AM19*10^6*About!$A$22 -> 4.1801516e+09 | O2: ='OECD TTL'!$AM$20*10^6*About!$A$22*'Split ISIC Code Shares'!G7 -> 1.057994e+09 | P2: ='OECD TTL'!$AM$20*10^6*About!$A$22*'Split ISIC Code Shares'!H7 -> 0 | Q2: ='OECD TTL'!$AM$21*10^6*About!$A$22*'Split ISIC Code Shares'!I7 -> 3.6297573e+08 | R2: ='OECD TTL'!$AM$21*10^6*About!$A$22*'Split ISIC Code Shares'!J7 -> 5.9534095e+08 | S2: {=TRANSPOSE('OECD TTL'!AM22:AM28)*10^6*About!$A$22} -> 3.7887074e+09 | T2: 1.4005392e+10 | U2: 7.3382472e+09 | V2: 2.3249326e+09 | W2: 2.69834e+10 | X2: 4.3742754e+09 | Y2: 1.2301675e+10 | Z2: {='OECD TTL'!$AM$29*10^6*About!$A$22*'Split ISIC Code Shares'!K7} -> 0 | AA2: {='OECD TTL'!$AM$29*10^6*About!$A$22*'Split ISIC Code Shares'!L7} -> 2.1588838e+10 | AB2: {='OECD TTL'!$AM$29*10^6*About!$A$22*'Split ISIC Code Shares'!M7} -> 6.8816821e+09 | AC2: {=TRANSPOSE('OECD TTL'!AM30:AM44)*10^6*About!$A$22} -> 1.5624834e+08 | AD2: 1.101204e+11 | AE2: 5.1994565e+10 | AF2: 4.6787029e+10 | AG2: 3.0373011e+09 | AH2: 2.6792473e+10 | AI2: 3.4475377e+08 | AJ2: 8.397549e+10 | AK2: 1.1661163e+11 | AL2: 7.9698276e+09 | AM2: 9.7686693e+09 | AN2: 2.554762e+10 | AO2: 9.5340353e+10 | AP2: 1.9686225e+10 | AQ2: 1.805109e+10
