Workbook

Sheet About
A1: CCaMC BAU Construction Cost per Unit Capacity
A2: CCaMC Annual Fixed O&M Cost per Unit Capacity
A3: CCaMC Variable O&M Cost per Unit Elec Output
A4: CCaMC BAU Soft Costs per Unit Capacity
A6: Sources: | B6: EPE - Empresa de Pesquisa Energética
B7: Power Generation Cost Report
B8: 2021
B9: https://www.epe.gov.br/sites-pt/publicacoes-dados-abertos/publicacoes/PublishingImages/pt/publicacoes-dados-abertos/publicacoes/caderno-de-precos-da-geracao/EPE_Power%20Generation%20Costs%20Report%202021.pdf
H13: Power Generation Costs Report 2021 Empresa de Pesquisa Energética
B14: Solar Thermal Capital and O&M Costs
B15: IRENA Renewable Power Generation Cost in 2020
B16: 2020
B17: IRENA Renewable Power Generation Cost in 2020
B18: https://www.irena.org/publications/2021/Jun/Renewable-Power-Costs-in-2020
B19: page 105
B21: Nuclear Capital and O&M Costs
B22: National Renewable Energy Lab
B23: 2020
B24: Annual Technology Baseline (ATB) Spreadsheet - 2020 Final
B25: https://atb.nrel.gov/
B26: taken from US EPS
A28: Notes: | B28: For 2020 (use 2016 USD- Check page 8 from the 2017 TDIPS report for more info)
B29: For 2023-2050 (use 2022 USD- Check page 8 from the 2024 TDIPS report for more info)
B30: Solar thermal data is taken from China as available data that is the nearest (Asia) with Indonesia is China. It is assumed that the investment cost is affected by the capacity factor linearly (inversely proportional). Currency of solar thermal data is in 2020 USD and to be converted to 2019.
B31: Data for nuclear in Indonesia is not available. Data is taken from US EPS. Currency of nuclear data is in 2018 USD and to be converted to 2019.
B32: It is chosen to not include endogenous learning since soft cost data specific for Indonesia is not available. Solar PV, onshore & offshore wind data for specifically Indonesia is available but not with the soft cost, therefore we choose to not use endogenous learning.
B33: For coal power plant, data used is for sub-bituminious CPP since most CPP in Indonesia is that type. Lignite PP is assumed to be the same with CPP (since in most cases in Indonesia, lignite and sub-bituminious coal are mixed together).
B34: Petroleum, crude oil, heavy oil are assumed to be the same PP type.
A36: Currency conversion factor
A37: 0.96 | B37: 2016 USD to 2012 USD
A38: 0.89 | B38: 2020 USD to 2012 USD
A39: 0.78 | B39: 2022 USD to 2012 USD
B40: https://www.officialdata.org/us/inflation/2022?endYear=2012&amount=1

Sheet solar thermal
A1: Solar Thermal (CSP) | B1: page 105, parabolic through collector & 10h storage, data for China
A2: Available data
A3: Investment (2020 $/kW) | B3: 5154 | D3: capacity factor increase in 10 years | F3: 0.1
A4: Fixed O&M (2020 $/kWh) | B4: 0.021 | D4: capacity factor 2020 | F4: 0.41
B6: 2020 | C6: 2030 | D6: 2040 | E6: 2050
A7: Investment ($/MW) | B7: =B3*1000 -> 5154000 | C7: =$B$7*$B$8/C8 -> 4685454.5 | D7: =$B$7*$B$8/D8 -> 4259504.1 | E7: =$B$7*$B$8/E8 -> 3872276.5
A8: Capacity factor | B8: =F4 -> 0.41 | C8: =(1+$F$3)*B8 -> 0.451 | D8: =(1+$F$3)*C8 -> 0.4961 | E8: =(1+$F$3)*D8 -> 0.54571
A10: Projection each year (2020$/MW) | B10: 2019 | C10: 2020 | D10: 2021 | E10: 2022 | F10: 2023 | G10: 2024 | H10: 2025 | I10: 2026 | J10: 2027 | K10: 2028 | L10: 2029 | M10: 2030 | N10: 2031 | O10: 2032 | P10: 2033 | Q10: 2034 | R10: 2035 | S10: 2036 | T10: 2037 | U10: 2038 | V10: 2039 | W10: 2040 | X10: 2041 | Y10: 2042 | Z10: 2043 | AA10: 2044 | AB10: 2045 | AC10: 2046 | AD10: 2047 | AE10: 2048 | AF10: 2049 | AG10: 2050 | AH10: 2051 | AI10: 2052 | AJ10: 2053 | AK10: 2054 | AL10: 2055 | AM10: 2056 | AN10: 2057 | AO10: 2058 | AP10: 2059 | AQ10: 2060 | AR10: 2061 | AS10: 2062 | AT10: 2063 | AU10: 2064 | AV10: 2065 | AW10: 2066 | AX10: 2067 | AY10: 2068 | AZ10: 2069 | BA10: 2070
A11: Investment ($/MW) | B11: =TREND($B$7:$E$7,$B$6:$E$6,B10) -> 5176188.1 | C11: =TREND($B$7:$E$7,$B$6:$E$6,C10) -> 5133476.9 | D11: =TREND($B$7:$E$7,$B$6:$E$6,D10) -> 5090765.7 | E11: =TREND($B$7:$E$7,$B$6:$E$6,E10) -> 5048054.5 | F11: =TREND($B$7:$E$7,$B$6:$E$6,F10) -> 5005343.3 | G11: =TREND($B$7:$E$7,$B$6:$E$6,G10) -> 4962632.1 | H11: =TREND($B$7:$E$7,$B$6:$E$6,H10) -> 4919920.9 | I11: =TREND($B$7:$E$7,$B$6:$E$6,I10) -> 4877209.7 | ... BA11: =TREND($B$7:$E$7,$B$6:$E$6,BA10) -> 2997916.5
A12: Investment ($/MW)-2012$-BRA | B12: =B11*About!$A$38 -> 4606807.4 | C12: =C11*About!$A$38 -> 4568794.5 | D12: =D11*About!$A$38 -> 4530781.5 | E12: =E11*About!$A$38 -> 4492768.5 | F12: =F11*About!$A$38 -> 4454755.5 | G12: =G11*About!$A$38 -> 4416742.6 | H12: =H11*About!$A$38 -> 4378729.6 | I12: =I11*About!$A$38 -> 4340716.6 | ... BA12: =BA11*About!$A$38 -> 2668145.6
A13: Investment ($/MW)-2012$-US | B13: 5770615.6 | C13: 5579703.8 | D13: 5388791.9 | E13: 5197880.1 | F13: 5006968.2 | G13: 4816056.4 | H13: 4630891.4 | I13: 4445255.7 | J13: 4259148.6 | K13: 4072569.9 | L13: 3885519 | M13: 3865472.8 | N13: 3845426.6 | O13: 3825380.4 | P13: 3805334.2 | Q13: 3785288 | R13: 3765241.8 | S13: 3745195.7 | T13: 3725149.5 | U13: 3705103.3 | V13: 3685057.1 | W13: 3665010.9 | X13: 3644964.7 | Y13: 3624918.5 | Z13: 3604872.3 | AA13: 3584826.1 | AB13: 3564779.9 | AC13: 3544733.8 | AD13: 3524687.6 | AE13: 3504641.4 | AF13: 3484595.2 | AG13: =_xlfn.FORECAST.LINEAR(AG10,$B$13:$AF$13,$B$10:$AF$10) -> 3047968.7 | AH13: =_xlfn.FORECAST.LINEAR(AH10,$B$13:$AF$13,$B$10:$AF$10) -> 2983317.4 | AI13: =_xlfn.FORECAST.LINEAR(AI10,$B$13:$AF$13,$B$10:$AF$10) -> 2918666 | AJ13: =_xlfn.FORECAST.LINEAR(AJ10,$B$13:$AF$13,$B$10:$AF$10) -> 2854014.7 | AK13: =_xlfn.FORECAST.LINEAR(AK10,$B$13:$AF$13,$B$10:$AF$10) -> 2789363.4 | AL13: =_xlfn.FORECAST.LINEAR(AL10,$B$13:$AF$13,$B$10:$AF$10) -> 2724712.1 | AM13: =_xlfn.FORECAST.LINEAR(AM10,$B$13:$AF$13,$B$10:$AF$10) -> 2660060.8 | AN13: =_xlfn.FORECAST.LINEAR(AN10,$B$13:$AF$13,$B$10:$AF$10) -> 2595409.5 | ... BA13: =_xlfn.FORECAST.LINEAR(BA10,$B$13:$AF$13,$B$10:$AF$10) -> 1754942.4
A14: Adjustement factor | B14: =B13/B12 -> 1.2526279 | C14: =C13/C12 -> 1.2212639 | D14: =D13/D12 -> 1.1893736 | E14: =E13/E12 -> 1.1569437 | F14: =F13/F12 -> 1.1239603 | G14: =G13/G12 -> 1.0904091 | H14: =H13/H12 -> 1.0575879 | I14: =I13/I12 -> 1.0240834 | ... BA14: =BA13/BA12 -> 0.65773861
A15: Fixed O&M Cost ($/MW)-US | B15: 77011.173
A16: Fixed O&M Cost ($/MW)-BRA | B16: =$B$15*B14 -> 96466.346 | C16: =$B$15*C14 -> 94050.967 | D16: =$B$15*D14 -> 91595.057 | E16: =$B$15*E14 -> 89097.589 | F16: =$B$15*F14 -> 86557.499 | G16: =$B$15*G14 -> 83973.686 | H16: =$B$15*H14 -> 81446.085 | I16: =$B$15*I14 -> 78865.862 | ... BA16: =$B$15*BA14 -> 50653.222
A17: Variable O&M Cost ($/MWh)-US | B17: 0
A18: Variable O&M Cost ($/MWh)-BRA | B18: 0 | C18: 0 | D18: 0 | E18: 0 | F18: 0 | G18: 0 | H18: 0 | I18: 0 | J18: 0 | K18: 0 | L18: 0 | M18: 0 | N18: 0 | O18: 0 | P18: 0 | Q18: 0 | R18: 0 | S18: 0 | T18: 0 | U18: 0 | V18: 0 | W18: 0 | X18: 0 | Y18: 0 | Z18: 0 | AA18: 0 | AB18: 0 | AC18: 0 | AD18: 0 | AE18: 0 | AF18: 0 | AG18: 0 | AH18: 0 | AI18: 0 | AJ18: 0 | AK18: 0 | AL18: 0 | AM18: 0 | AN18: 0 | AO18: 0 | AP18: 0 | AQ18: 0 | AR18: 0 | AS18: 0 | AT18: 0 | AU18: 0 | AV18: 0 | AW18: 0 | AX18: 0 | AY18: 0 | AZ18: 0 | BA18: 0
A22: US Data
A23: RetireYear | B23: (Multiple Items)
A25: Row Labels | B25: Sum of WeightedVOM | C25: Sum of WeightedFOM | E25: VOM Adjusted for Currency Year | F25: FOM Adjusted for Currency Year
A26: battery | B26: #N/A | C26: #N/A
A27: biopower | B27: 3.4396773 | C27: 68.332119 | E27: 6.9518422 | F27: 138.10427
A28: coal | B28: 0.75224686 | C28: 15.79831 | E28: 1.5203465 | F28: 31.929553
A29: csp-ns | B29: 0 | C29: 38.104085 | E29: 0 | F29: 77.011173
A30: DUPV | B30: 0 | C30: 16.048025 | E30: 0 | F30: 32.434244
A31: gas-CC | B31: 1.7799214 | C31: 6.2877403 | E31: 3.5973528 | F31: 12.707988
A32: gas-CT | B32: 3.609773 | C32: 2.5109612 | E32: 7.2956181 | F32: 5.0748382
A33: geothermal | B33: 0 | C33: 54.610346 | E33: 0 | F33: 110.37155
A34: hydro | B34: 0 | C34: 7.6751559 | E34: 0 | F34: 15.512058
A35: lfill-gas | B35: 3.3409405 | C35: 125.55198 | E35: 6.7522877 | F35: 253.74983
A36: nuclear | B36: 0.075359365 | C36: 77.12674 | E36: 0.15230685 | F36: 155.87885
A37: o-g-s | B37: 1.0947085 | C37: 6.9712955 | E37: 2.2124868 | F37: 14.089504
A38: pumped-hydro | B38: 0.0037120326 | C38: 8.9169439 | E38: 0.0075022923 | F38: 18.021803
... A41: wind-ons | B41: 0 | C41: 17.362462 | E41: 0 | F41: 35.090819
A42: (blank)
A43: Grand Total | B43: #N/A | C43: #N/A

Sheet nuclear
A1: NREL CAPEX ($/kW)
A2: Model Electricity Source | B2: NREL Electricity Source | C2: 2018 | D2: 2019 | E2: 2020 | F2: 2021 | G2: 2022 | H2: 2023 | I2: 2024 | J2: 2025 | K2: 2026 | L2: 2027 | M2: 2028 | N2: 2029 | O2: 2030 | P2: 2031 | Q2: 2032 | R2: 2033 | S2: 2034 | T2: 2035 | U2: 2036 | V2: 2037 | W2: 2038 | X2: 2039 | Y2: 2040 | Z2: 2041 | AA2: 2042 | AB2: 2043 | AC2: 2044 | AD2: 2045 | AE2: 2046 | AF2: 2047 | AG2: 2048 | AH2: 2049 | AI2: 2050 | AJ2: 2051 | AK2: 2052 | AL2: 2053 | AM2: 2054 | AN2: 2055 | AO2: 2056 | AP2: 2057 | AQ2: 2058 | AR2: 2059 | AS2: 2060 | AT2: 2061 | AU2: 2062 | AV2: 2063 | AW2: 2064 | AX2: 2065 | AY2: 2066 | AZ2: 2067 | BA2: 2068 | BB2: 2069 | BC2: 2070
A3: nuclear | B3: Nuclear - Moderate | C3: 7185.6551 | D3: 7148.9711 | E3: 7112.287 | F3: 7075.603 | G3: 7038.919 | H3: 7002.235 | I3: 6965.551 | J3: 6928.867 | K3: 6892.183 | L3: 6851.259 | M3: 6813.6278 | N3: 6774.154 | O3: 6727.7998 | P3: 6683.196 | Q3: 6636.3542 | R3: 6588.5183 | S3: 6547.7751 | T3: 6505.1168 | U3: 6453.4228 | V3: 6411.1693 | W3: 6366.4718 | X3: 6316.8299 | Y3: 6266.0123 | Z3: 6226.1659 | AA3: 6177.744 | AB3: 6133.5759 | AC3: 6089.1105 | AD3: 6048.0421 | AE3: 5995.9541 | AF3: 5951.8102 | AG3: 5907.4101 | AH3: 5862.8789 | AI3: 5768.0886 | AJ3: =_xlfn.FORECAST.LINEAR(AJ2,$C$3:$AI$3,$C$2:$AI$2) -> 5785.9289 | AK3: =_xlfn.FORECAST.LINEAR(AK2,$C$3:$AI$3,$C$2:$AI$2) -> 5742.2264 | AL3: =_xlfn.FORECAST.LINEAR(AL2,$C$3:$AI$3,$C$2:$AI$2) -> 5698.5239 | AM3: =_xlfn.FORECAST.LINEAR(AM2,$C$3:$AI$3,$C$2:$AI$2) -> 5654.8214 | AN3: =_xlfn.FORECAST.LINEAR(AN2,$C$3:$AI$3,$C$2:$AI$2) -> 5611.1189 | AO3: =_xlfn.FORECAST.LINEAR(AO2,$C$3:$AI$3,$C$2:$AI$2) -> 5567.4164 | AP3: =_xlfn.FORECAST.LINEAR(AP2,$C$3:$AI$3,$C$2:$AI$2) -> 5523.7139 | AQ3: =_xlfn.FORECAST.LINEAR(AQ2,$C$3:$AI$3,$C$2:$AI$2) -> 5480.0114 | ... BC3: =_xlfn.FORECAST.LINEAR(BC2,$C$3:$AI$3,$C$2:$AI$2) -> 4955.5813
A4: NREL O&M Cost
A5: Model Subscript | B5: EIA Technology Name | C5: Variable O&M ($/MWh) | D5: Fixed O&M ($/kW-yr) | E5: Currency Year | F5: Source
A6: nuclear | B6: Nuclear - Moderate | C6: 2.3182711 | D6: 118.98821 | E6: 2018 | F6: NREL ATB

Sheet capital processing
A1: Available capital cost data (2019 $/MW) | E1: M$ to $ | F1: 1000000
B2: 2020 | C2: 2030 | D2: 2050
A3: hard coal | B3: 1650000 | C3: 1600000 | D3: 1550000
A4: natural gas nonpeaker | B4: 770000 | C4: 730000 | D4: 680000
A5: hydro | B5: 2080000 | C5: 2000000 | D5: 1850000
A6: onshore wind | B6: 1500000 | C6: 1280000 | D6: 1080000
A7: solar PV | B7: 790000 | C7: 560000 | D7: 410000 | F7: Need to be revised
A8: biomass | B8: 2000000 | C8: 1820000 | D8: 1600000
A9: geothermal | B9: 4000000 | C9: 3440000 | D9: 2840000
A10: petroleum | B10: 800000 | C10: 800000 | D10: 780000
A11: natural gas peaker | B11: 690000 | C11: 660000 | D11: 610000
A12: lignite | B12: 1650000 | C12: 1600000 | D12: 1550000
A13: offshore wind | B13: 3500000 | C13: 2980000 | D13: 2520000
A14: crude oil | B14: 800000 | C14: 800000 | D14: 780000
A15: heavy or residual fuel oil | B15: 800000 | C15: 800000 | D15: 780000
A16: municipal solid waste | B16: 690000 | C16: 660000 | D16: 610000

Sheet Cal
A1: Fixed O&M Cost ($/MW) | B1: 2020 | C1: 2030 | D1: 2050
A2: hard coal | B2: 25228 | C2: =B2 -> 25228 | D2: =C2 -> 25228
A3: natural gas nonpeaker | B3: 12614 | C3: =B3 -> 12614 | D3: =C3 -> 12614
A4: Nuclear | B4: 77261 | C4: =B4 -> 77261 | D4: =C4 -> 77261
A5: hydro | B5: 14191 | C5: =B5 -> 14191 | D5: =C5 -> 14191
A6: onshore wind | B6: 14191 | C6: =B6 -> 14191 | D6: =C6 -> 14191
A7: solar PV | B7: 7884 | C7: =B7 -> 7884 | D7: =C7 -> 7884
A8: biomass | B8: 45696 | C8: =B8 -> 45696 | D8: =C8 -> 45696
A9: geothermal | B9: 14191 | C9: =B9 -> 14191 | D9: =C9 -> 14191
A10: petroleum | B10: 78838 | C10: =B10 -> 78838 | D10: =C10 -> 78838
A11: natural gas peaker | B11: 12614 | C11: =B11 -> 12614 | D11: =C11 -> 12614
A12: lignite | B12: =B2 -> 25228 | C12: =B12 -> 25228 | D12: =C12 -> 25228
A13: offshore wind | B13: 77261 | C13: =B13 -> 77261 | D13: =C13 -> 77261
A14: crude oil | B14: 78838 | C14: =B14 -> 78838 | D14: =C14 -> 78838
A15: heavy or residual fuel oil | B15: 78838 | C15: =B15 -> 78838 | D15: =C15 -> 78838
A16: municipal solid waste | B16: 233952 | C16: =B16 -> 233952 | D16: =C16 -> 233952
A20: Variable O&M Cost ($/MWh) | B20: 2020 | C20: 2030 | D20: 2050
A21: hard coal | B21: 0.12 | C21: 0.12 | D21: 0.12
A22: natural gas nonpeaker | B22: 0.1248 | C22: 0.1248 | D22: 0.1248
A23: Nuclear | B23: 1.87 | C23: 1.87 | D23: 1.87
A24: hydro | B24: 0.53 | C24: 0.53 | D24: 0.53
A25: onshore wind | B25: 0 | C25: 0 | D25: 0
A26: solar PV | B26: 0 | C26: 0 | D26: 0
A27: Solar thermal | B27: 0 | C27: 0 | D27: 0
A28: biomass | B28: 2.88 | C28: 2.88 | D28: 2.88
A29: geothermal | B29: 0.21 | C29: 0.21 | D29: 0.21
A30: petroleum | B30: 6.14 | C30: 6.14 | D30: 6.14
A31: natural gas peaker | B31: 0.1248 | C31: 0.1248 | D31: 0.1248
... A36: municipal solid waste | B36: 23.14 | C36: 23.14 | D36: 23.14
A39: Energy Sources | B39: Fixed O&M (BRL/kW) | C39: Fixed O&M (BRL/MW) | D39: Fixed O&M ($/MW)
A40: hard coal | B40: 160 | C40: 160000 | D40: 25228
A41: natural gas nonpeaker | B41: 80 | C41: 80000 | D41: 12614
A42: nuclear | B42: 490 | C42: 490000 | D42: 77261
A43: hydro | B43: 90 | C43: 90000 | D43: 14191
A44: onshore wind | B44: 90 | C44: 90000 | D44: 14191
A45: solar PV | B45: 50 | C45: 50000 | D45: 7884
A46: solar thermal
A47: biomass | B47: 90 | C47: 90000 | D47: 14191
A48: geothermal
A49: petroleum | B49: 500 | C49: 500000 | D49: 78838
...

Sheet CCaMC-AFOaMCpUC-pre-ret
A1: Fixed O&M ($/MW) - Preex.Retiring | B1: 2020 | C1: 2021 | D1: 2022 | E1: 2023 | F1: 2024 | G1: 2025 | H1: 2026 | I1: 2027 | J1: 2028 | K1: 2029 | L1: 2030 | M1: 2031 | N1: 2032 | O1: 2033 | P1: 2034 | Q1: 2035 | R1: 2036 | S1: 2037 | T1: 2038 | U1: 2039 | V1: 2040 | W1: 2041 | X1: 2042 | Y1: 2043 | Z1: 2044 | AA1: 2045 | AB1: 2046 | AC1: 2047 | AD1: 2048 | AE1: 2049 | AF1: 2050 | AG1: 2051 | AH1: 2052 | AI1: 2053 | AJ1: 2054 | AK1: 2055 | AL1: 2056 | AM1: 2057 | AN1: 2058 | AO1: 2059 | AP1: 2060 | AQ1: 2061 | AR1: 2062 | AS1: 2063 | AT1: 2064 | AU1: 2065 | AV1: 2066 | AW1: 2067 | AX1: 2068 | AY1: 2069 | AZ1: 2070
A2: hard coal | B2: =Cal!B2 -> 25228 | C2: =B2 -> 25228 | D2: =C2 -> 25228 | E2: =D2 -> 25228 | F2: =E2 -> 25228 | G2: =F2 -> 25228 | H2: =G2 -> 25228 | I2: =H2 -> 25228 | J2: =I2 -> 25228 | K2: =J2 -> 25228 | L2: =Cal!C2 -> 25228 | M2: =$L2+(($AF2-$L2)/($AF$1-$L$1))*(M$1-$L$1) -> 25228 | N2: =$L2+(($AF2-$L2)/($AF$1-$L$1))*(N$1-$L$1) -> 25228 | O2: =$L2+(($AF2-$L2)/($AF$1-$L$1))*(O$1-$L$1) -> 25228 | P2: =$L2+(($AF2-$L2)/($AF$1-$L$1))*(P$1-$L$1) -> 25228 | Q2: =$L2+(($AF2-$L2)/($AF$1-$L$1))*(Q$1-$L$1) -> 25228 | R2: =$L2+(($AF2-$L2)/($AF$1-$L$1))*(R$1-$L$1) -> 25228 | S2: =$L2+(($AF2-$L2)/($AF$1-$L$1))*(S$1-$L$1) -> 25228 | T2: =$L2+(($AF2-$L2)/($AF$1-$L$1))*(T$1-$L$1) -> 25228 | ... AE2: =$L2+(($AF2-$L2)/($AF$1-$L$1))*(AE$1-$L$1) -> 25228 | AF2: =Cal!D2 -> 25228 | AG2: =_xlfn.FORECAST.LINEAR(AG$1, $AC2:$AE2, $AC$1:$AE$1) -> 25228 | AH2: =_xlfn.FORECAST.LINEAR(AH$1, $AC2:$AE2, $AC$1:$AE$1) -> 25228 | AI2: =_xlfn.FORECAST.LINEAR(AI$1, $AC2:$AE2, $AC$1:$AE$1) -> 25228 | AJ2: =_xlfn.FORECAST.LINEAR(AJ$1, $AC2:$AE2, $AC$1:$AE$1) -> 25228 | AK2: =_xlfn.FORECAST.LINEAR(AK$1, $AC2:$AE2, $AC$1:$AE$1) -> 25228 | AL2: =_xlfn.FORECAST.LINEAR(AL$1, $AC2:$AE2, $AC$1:$AE$1) -> 25228 | AM2: =_xlfn.FORECAST.LINEAR(AM$1, $AC2:$AE2, $AC$1:$AE$1) -> 25228 | AN2: =_xlfn.FORECAST.LINEAR(AN$1, $AC2:$AE2, $AC$1:$AE$1) -> 25228 | ... AZ2: =_xlfn.FORECAST.LINEAR(AZ$1, $AC2:$AE2, $AC$1:$AE$1) -> 25228
A3: natural gas nonpeaker | B3: =Cal!B3 -> 12614 | C3: =B3 -> 12614 | D3: =C3 -> 12614 | E3: =D3 -> 12614 | F3: =E3 -> 12614 | G3: =F3 -> 12614 | H3: =G3 -> 12614 | I3: =H3 -> 12614 | J3: =I3 -> 12614 | K3: =J3 -> 12614 | L3: =Cal!C3 -> 12614 | M3: =$L3+(($AF3-$L3)/($AF$1-$L$1))*(M$1-$L$1) -> 12614 | N3: =$L3+(($AF3-$L3)/($AF$1-$L$1))*(N$1-$L$1) -> 12614 | O3: =$L3+(($AF3-$L3)/($AF$1-$L$1))*(O$1-$L$1) -> 12614 | P3: =$L3+(($AF3-$L3)/($AF$1-$L$1))*(P$1-$L$1) -> 12614 | Q3: =$L3+(($AF3-$L3)/($AF$1-$L$1))*(Q$1-$L$1) -> 12614 | R3: =$L3+(($AF3-$L3)/($AF$1-$L$1))*(R$1-$L$1) -> 12614 | S3: =$L3+(($AF3-$L3)/($AF$1-$L$1))*(S$1-$L$1) -> 12614 | T3: =$L3+(($AF3-$L3)/($AF$1-$L$1))*(T$1-$L$1) -> 12614 | ... AE3: =$L3+(($AF3-$L3)/($AF$1-$L$1))*(AE$1-$L$1) -> 12614 | AF3: =Cal!D3 -> 12614 | AG3: =_xlfn.FORECAST.LINEAR(AG$1, $AC3:$AE3, $AC$1:$AE$1) -> #NAME? | AH3: =_xlfn.FORECAST.LINEAR(AH$1, $AC3:$AE3, $AC$1:$AE$1) -> #NAME? | AI3: =_xlfn.FORECAST.LINEAR(AI$1, $AC3:$AE3, $AC$1:$AE$1) -> #NAME? | AJ3: =_xlfn.FORECAST.LINEAR(AJ$1, $AC3:$AE3, $AC$1:$AE$1) -> #NAME? | AK3: =_xlfn.FORECAST.LINEAR(AK$1, $AC3:$AE3, $AC$1:$AE$1) -> #NAME? | AL3: =_xlfn.FORECAST.LINEAR(AL$1, $AC3:$AE3, $AC$1:$AE$1) -> #NAME? | AM3: =_xlfn.FORECAST.LINEAR(AM$1, $AC3:$AE3, $AC$1:$AE$1) -> #NAME? | AN3: =_xlfn.FORECAST.LINEAR(AN$1, $AC3:$AE3, $AC$1:$AE$1) -> #NAME? | ... AZ3: =_xlfn.FORECAST.LINEAR(AZ$1, $AC3:$AE3, $AC$1:$AE$1) -> #NAME?
A4: nuclear | B4: =Cal!B4 -> 77261 | C4: =B4 -> 77261 | D4: =C4 -> 77261 | E4: =D4 -> 77261 | F4: =E4 -> 77261 | G4: =F4 -> 77261 | H4: =G4 -> 77261 | I4: =H4 -> 77261 | J4: =I4 -> 77261 | K4: =J4 -> 77261 | L4: =Cal!C4 -> 77261 | M4: =$L4+(($AF4-$L4)/($AF$1-$L$1))*(M$1-$L$1) -> 77261 | N4: =$L4+(($AF4-$L4)/($AF$1-$L$1))*(N$1-$L$1) -> 77261 | O4: =$L4+(($AF4-$L4)/($AF$1-$L$1))*(O$1-$L$1) -> 77261 | P4: =$L4+(($AF4-$L4)/($AF$1-$L$1))*(P$1-$L$1) -> 77261 | Q4: =$L4+(($AF4-$L4)/($AF$1-$L$1))*(Q$1-$L$1) -> 77261 | R4: =$L4+(($AF4-$L4)/($AF$1-$L$1))*(R$1-$L$1) -> 77261 | S4: =$L4+(($AF4-$L4)/($AF$1-$L$1))*(S$1-$L$1) -> 77261 | T4: =$L4+(($AF4-$L4)/($AF$1-$L$1))*(T$1-$L$1) -> 77261 | ... AE4: =$L4+(($AF4-$L4)/($AF$1-$L$1))*(AE$1-$L$1) -> 77261 | AF4: =Cal!D4 -> 77261 | AG4: =_xlfn.FORECAST.LINEAR(AG$1, $AC4:$AE4, $AC$1:$AE$1) -> 77261 | AH4: =_xlfn.FORECAST.LINEAR(AH$1, $AC4:$AE4, $AC$1:$AE$1) -> 77261 | AI4: =_xlfn.FORECAST.LINEAR(AI$1, $AC4:$AE4, $AC$1:$AE$1) -> 77261 | AJ4: =_xlfn.FORECAST.LINEAR(AJ$1, $AC4:$AE4, $AC$1:$AE$1) -> 77261 | AK4: =_xlfn.FORECAST.LINEAR(AK$1, $AC4:$AE4, $AC$1:$AE$1) -> 77261 | AL4: =_xlfn.FORECAST.LINEAR(AL$1, $AC4:$AE4, $AC$1:$AE$1) -> 77261 | AM4: =_xlfn.FORECAST.LINEAR(AM$1, $AC4:$AE4, $AC$1:$AE$1) -> 77261 | AN4: =_xlfn.FORECAST.LINEAR(AN$1, $AC4:$AE4, $AC$1:$AE$1) -> 77261 | ... AZ4: =_xlfn.FORECAST.LINEAR(AZ$1, $AC4:$AE4, $AC$1:$AE$1) -> 77261
A5: hydro | B5: =Cal!B5 -> 14191 | C5: =B5 -> 14191 | D5: =C5 -> 14191 | E5: =D5 -> 14191 | F5: =E5 -> 14191 | G5: =F5 -> 14191 | H5: =G5 -> 14191 | I5: =H5 -> 14191 | J5: =I5 -> 14191 | K5: =J5 -> 14191 | L5: =Cal!C5 -> 14191 | M5: =$L5+(($AF5-$L5)/($AF$1-$L$1))*(M$1-$L$1) -> 14191 | N5: =$L5+(($AF5-$L5)/($AF$1-$L$1))*(N$1-$L$1) -> 14191 | O5: =$L5+(($AF5-$L5)/($AF$1-$L$1))*(O$1-$L$1) -> 14191 | P5: =$L5+(($AF5-$L5)/($AF$1-$L$1))*(P$1-$L$1) -> 14191 | Q5: =$L5+(($AF5-$L5)/($AF$1-$L$1))*(Q$1-$L$1) -> 14191 | R5: =$L5+(($AF5-$L5)/($AF$1-$L$1))*(R$1-$L$1) -> 14191 | S5: =$L5+(($AF5-$L5)/($AF$1-$L$1))*(S$1-$L$1) -> 14191 | T5: =$L5+(($AF5-$L5)/($AF$1-$L$1))*(T$1-$L$1) -> 14191 | ... AE5: =$L5+(($AF5-$L5)/($AF$1-$L$1))*(AE$1-$L$1) -> 14191 | AF5: =Cal!D5 -> 14191 | AG5: =_xlfn.FORECAST.LINEAR(AG$1, $AC5:$AE5, $AC$1:$AE$1) -> 14191 | AH5: =_xlfn.FORECAST.LINEAR(AH$1, $AC5:$AE5, $AC$1:$AE$1) -> 14191 | AI5: =_xlfn.FORECAST.LINEAR(AI$1, $AC5:$AE5, $AC$1:$AE$1) -> 14191 | AJ5: =_xlfn.FORECAST.LINEAR(AJ$1, $AC5:$AE5, $AC$1:$AE$1) -> 14191 | AK5: =_xlfn.FORECAST.LINEAR(AK$1, $AC5:$AE5, $AC$1:$AE$1) -> 14191 | AL5: =_xlfn.FORECAST.LINEAR(AL$1, $AC5:$AE5, $AC$1:$AE$1) -> 14191 | AM5: =_xlfn.FORECAST.LINEAR(AM$1, $AC5:$AE5, $AC$1:$AE$1) -> 14191 | AN5: =_xlfn.FORECAST.LINEAR(AN$1, $AC5:$AE5, $AC$1:$AE$1) -> 14191 | ... AZ5: =_xlfn.FORECAST.LINEAR(AZ$1, $AC5:$AE5, $AC$1:$AE$1) -> 14191
A6: onshore wind | B6: =Cal!B6 -> 14191 | C6: =B6 -> 14191 | D6: =C6 -> 14191 | E6: =D6 -> 14191 | F6: =E6 -> 14191 | G6: =F6 -> 14191 | H6: =G6 -> 14191 | I6: =H6 -> 14191 | J6: =I6 -> 14191 | K6: =J6 -> 14191 | L6: =Cal!C6 -> 14191 | M6: =$L6+(($AF6-$L6)/($AF$1-$L$1))*(M$1-$L$1) -> 14191 | N6: =$L6+(($AF6-$L6)/($AF$1-$L$1))*(N$1-$L$1) -> 14191 | O6: =$L6+(($AF6-$L6)/($AF$1-$L$1))*(O$1-$L$1) -> 14191 | P6: =$L6+(($AF6-$L6)/($AF$1-$L$1))*(P$1-$L$1) -> 14191 | Q6: =$L6+(($AF6-$L6)/($AF$1-$L$1))*(Q$1-$L$1) -> 14191 | R6: =$L6+(($AF6-$L6)/($AF$1-$L$1))*(R$1-$L$1) -> 14191 | S6: =$L6+(($AF6-$L6)/($AF$1-$L$1))*(S$1-$L$1) -> 14191 | T6: =$L6+(($AF6-$L6)/($AF$1-$L$1))*(T$1-$L$1) -> 14191 | ... AE6: =$L6+(($AF6-$L6)/($AF$1-$L$1))*(AE$1-$L$1) -> 14191 | AF6: =Cal!D6 -> 14191 | AG6: =_xlfn.FORECAST.LINEAR(AG$1, $AC6:$AE6, $AC$1:$AE$1) -> 14191 | AH6: =_xlfn.FORECAST.LINEAR(AH$1, $AC6:$AE6, $AC$1:$AE$1) -> 14191 | AI6: =_xlfn.FORECAST.LINEAR(AI$1, $AC6:$AE6, $AC$1:$AE$1) -> 14191 | AJ6: =_xlfn.FORECAST.LINEAR(AJ$1, $AC6:$AE6, $AC$1:$AE$1) -> 14191 | AK6: =_xlfn.FORECAST.LINEAR(AK$1, $AC6:$AE6, $AC$1:$AE$1) -> 14191 | AL6: =_xlfn.FORECAST.LINEAR(AL$1, $AC6:$AE6, $AC$1:$AE$1) -> 14191 | AM6: =_xlfn.FORECAST.LINEAR(AM$1, $AC6:$AE6, $AC$1:$AE$1) -> 14191 | AN6: =_xlfn.FORECAST.LINEAR(AN$1, $AC6:$AE6, $AC$1:$AE$1) -> 14191 | ... AZ6: =_xlfn.FORECAST.LINEAR(AZ$1, $AC6:$AE6, $AC$1:$AE$1) -> 14191
A7: solar PV | B7: =Cal!B7 -> 7884 | C7: =B7 -> 7884 | D7: =C7 -> 7884 | E7: =D7 -> 7884 | F7: =E7 -> 7884 | G7: =F7 -> 7884 | H7: =G7 -> 7884 | I7: =H7 -> 7884 | J7: =I7 -> 7884 | ... AZ7: =AY7 -> 7884
A8: solar thermal | B8: ='solar thermal'!B16 -> 96466.346 | C8: ='solar thermal'!C16 -> 94050.967 | D8: ='solar thermal'!D16 -> 91595.057 | E8: ='solar thermal'!E16 -> 89097.589 | F8: ='solar thermal'!F16 -> 86557.499 | G8: ='solar thermal'!G16 -> 83973.686 | H8: ='solar thermal'!H16 -> 81446.085 | I8: ='solar thermal'!I16 -> 78865.862 | ... AZ8: ='solar thermal'!AZ16 -> 51781.535
A9: biomass | B9: =Cal!B8 -> 45696 | C9: =B9 -> 45696 | D9: =C9 -> 45696 | E9: =D9 -> 45696 | F9: =E9 -> 45696 | G9: =F9 -> 45696 | H9: =G9 -> 45696 | I9: =H9 -> 45696 | J9: =I9 -> 45696 | K9: =J9 -> 45696 | L9: =Cal!C8 -> 45696 | M9: =$L9+(($AF9-$L9)/($AF$1-$L$1))*(M$1-$L$1) -> 45696 | N9: =$L9+(($AF9-$L9)/($AF$1-$L$1))*(N$1-$L$1) -> 45696 | O9: =$L9+(($AF9-$L9)/($AF$1-$L$1))*(O$1-$L$1) -> 45696 | P9: =$L9+(($AF9-$L9)/($AF$1-$L$1))*(P$1-$L$1) -> 45696 | Q9: =$L9+(($AF9-$L9)/($AF$1-$L$1))*(Q$1-$L$1) -> 45696 | R9: =$L9+(($AF9-$L9)/($AF$1-$L$1))*(R$1-$L$1) -> 45696 | S9: =$L9+(($AF9-$L9)/($AF$1-$L$1))*(S$1-$L$1) -> 45696 | T9: =$L9+(($AF9-$L9)/($AF$1-$L$1))*(T$1-$L$1) -> 45696 | ... AE9: =$L9+(($AF9-$L9)/($AF$1-$L$1))*(AE$1-$L$1) -> 45696 | AF9: =Cal!D8 -> 45696 | AG9: =_xlfn.FORECAST.LINEAR(AG$1, $AC9:$AE9, $AC$1:$AE$1) -> 45696 | AH9: =_xlfn.FORECAST.LINEAR(AH$1, $AC9:$AE9, $AC$1:$AE$1) -> 45696 | AI9: =_xlfn.FORECAST.LINEAR(AI$1, $AC9:$AE9, $AC$1:$AE$1) -> 45696 | AJ9: =_xlfn.FORECAST.LINEAR(AJ$1, $AC9:$AE9, $AC$1:$AE$1) -> 45696 | AK9: =_xlfn.FORECAST.LINEAR(AK$1, $AC9:$AE9, $AC$1:$AE$1) -> 45696 | AL9: =_xlfn.FORECAST.LINEAR(AL$1, $AC9:$AE9, $AC$1:$AE$1) -> 45696 | AM9: =_xlfn.FORECAST.LINEAR(AM$1, $AC9:$AE9, $AC$1:$AE$1) -> 45696 | AN9: =_xlfn.FORECAST.LINEAR(AN$1, $AC9:$AE9, $AC$1:$AE$1) -> 45696 | ... AZ9: =_xlfn.FORECAST.LINEAR(AZ$1, $AC9:$AE9, $AC$1:$AE$1) -> 45696
A10: geothermal | B10: =Cal!B9 -> 14191 | C10: =B10 -> 14191 | D10: =C10 -> 14191 | E10: =D10 -> 14191 | F10: =E10 -> 14191 | G10: =F10 -> 14191 | H10: =G10 -> 14191 | I10: =H10 -> 14191 | J10: =I10 -> 14191 | K10: =J10 -> 14191 | L10: =Cal!C9 -> 14191 | M10: =$L10+(($AF10-$L10)/($AF$1-$L$1))*(M$1-$L$1) -> 14191 | N10: =$L10+(($AF10-$L10)/($AF$1-$L$1))*(N$1-$L$1) -> 14191 | O10: =$L10+(($AF10-$L10)/($AF$1-$L$1))*(O$1-$L$1) -> 14191 | P10: =$L10+(($AF10-$L10)/($AF$1-$L$1))*(P$1-$L$1) -> 14191 | Q10: =$L10+(($AF10-$L10)/($AF$1-$L$1))*(Q$1-$L$1) -> 14191 | R10: =$L10+(($AF10-$L10)/($AF$1-$L$1))*(R$1-$L$1) -> 14191 | S10: =$L10+(($AF10-$L10)/($AF$1-$L$1))*(S$1-$L$1) -> 14191 | T10: =$L10+(($AF10-$L10)/($AF$1-$L$1))*(T$1-$L$1) -> 14191 | ... AE10: =$L10+(($AF10-$L10)/($AF$1-$L$1))*(AE$1-$L$1) -> 14191 | AF10: =Cal!D9 -> 14191 | AG10: =_xlfn.FORECAST.LINEAR(AG$1, $AC10:$AE10, $AC$1:$AE$1) -> 14191 | AH10: =_xlfn.FORECAST.LINEAR(AH$1, $AC10:$AE10, $AC$1:$AE$1) -> 14191 | AI10: =_xlfn.FORECAST.LINEAR(AI$1, $AC10:$AE10, $AC$1:$AE$1) -> 14191 | AJ10: =_xlfn.FORECAST.LINEAR(AJ$1, $AC10:$AE10, $AC$1:$AE$1) -> 14191 | AK10: =_xlfn.FORECAST.LINEAR(AK$1, $AC10:$AE10, $AC$1:$AE$1) -> 14191 | AL10: =_xlfn.FORECAST.LINEAR(AL$1, $AC10:$AE10, $AC$1:$AE$1) -> 14191 | AM10: =_xlfn.FORECAST.LINEAR(AM$1, $AC10:$AE10, $AC$1:$AE$1) -> 14191 | AN10: =_xlfn.FORECAST.LINEAR(AN$1, $AC10:$AE10, $AC$1:$AE$1) -> 14191 | ... AZ10: =_xlfn.FORECAST.LINEAR(AZ$1, $AC10:$AE10, $AC$1:$AE$1) -> 14191
A11: petroleum | B11: =Cal!B10 -> 78838 | C11: =B11 -> 78838 | D11: =C11 -> 78838 | E11: =D11 -> 78838 | F11: =E11 -> 78838 | G11: =F11 -> 78838 | H11: =G11 -> 78838 | I11: =H11 -> 78838 | J11: =I11 -> 78838 | K11: =J11 -> 78838 | L11: =Cal!C10 -> 78838 | M11: =$L11+(($AF11-$L11)/($AF$1-$L$1))*(M$1-$L$1) -> 78838 | N11: =$L11+(($AF11-$L11)/($AF$1-$L$1))*(N$1-$L$1) -> 78838 | O11: =$L11+(($AF11-$L11)/($AF$1-$L$1))*(O$1-$L$1) -> 78838 | P11: =$L11+(($AF11-$L11)/($AF$1-$L$1))*(P$1-$L$1) -> 78838 | Q11: =$L11+(($AF11-$L11)/($AF$1-$L$1))*(Q$1-$L$1) -> 78838 | R11: =$L11+(($AF11-$L11)/($AF$1-$L$1))*(R$1-$L$1) -> 78838 | S11: =$L11+(($AF11-$L11)/($AF$1-$L$1))*(S$1-$L$1) -> 78838 | T11: =$L11+(($AF11-$L11)/($AF$1-$L$1))*(T$1-$L$1) -> 78838 | ... AE11: =$L11+(($AF11-$L11)/($AF$1-$L$1))*(AE$1-$L$1) -> 78838 | AF11: =Cal!D10 -> 78838 | AG11: =_xlfn.FORECAST.LINEAR(AG$1, $AC11:$AE11, $AC$1:$AE$1) -> 78838 | AH11: =_xlfn.FORECAST.LINEAR(AH$1, $AC11:$AE11, $AC$1:$AE$1) -> 78838 | AI11: =_xlfn.FORECAST.LINEAR(AI$1, $AC11:$AE11, $AC$1:$AE$1) -> 78838 | AJ11: =_xlfn.FORECAST.LINEAR(AJ$1, $AC11:$AE11, $AC$1:$AE$1) -> 78838 | AK11: =_xlfn.FORECAST.LINEAR(AK$1, $AC11:$AE11, $AC$1:$AE$1) -> 78838 | AL11: =_xlfn.FORECAST.LINEAR(AL$1, $AC11:$AE11, $AC$1:$AE$1) -> 78838 | AM11: =_xlfn.FORECAST.LINEAR(AM$1, $AC11:$AE11, $AC$1:$AE$1) -> 78838 | AN11: =_xlfn.FORECAST.LINEAR(AN$1, $AC11:$AE11, $AC$1:$AE$1) -> 78838 | ... AZ11: =_xlfn.FORECAST.LINEAR(AZ$1, $AC11:$AE11, $AC$1:$AE$1) -> 78838
A12: natural gas peaker | B12: =Cal!B11 -> 12614 | C12: =B12 -> 12614 | D12: =C12 -> 12614 | E12: =D12 -> 12614 | F12: =E12 -> 12614 | G12: =F12 -> 12614 | H12: =G12 -> 12614 | I12: =H12 -> 12614 | J12: =I12 -> 12614 | K12: =J12 -> 12614 | L12: =Cal!C11 -> 12614 | M12: =$L12+(($AF12-$L12)/($AF$1-$L$1))*(M$1-$L$1) -> 12614 | N12: =$L12+(($AF12-$L12)/($AF$1-$L$1))*(N$1-$L$1) -> 12614 | O12: =$L12+(($AF12-$L12)/($AF$1-$L$1))*(O$1-$L$1) -> 12614 | P12: =$L12+(($AF12-$L12)/($AF$1-$L$1))*(P$1-$L$1) -> 12614 | Q12: =$L12+(($AF12-$L12)/($AF$1-$L$1))*(Q$1-$L$1) -> 12614 | R12: =$L12+(($AF12-$L12)/($AF$1-$L$1))*(R$1-$L$1) -> 12614 | S12: =$L12+(($AF12-$L12)/($AF$1-$L$1))*(S$1-$L$1) -> 12614 | T12: =$L12+(($AF12-$L12)/($AF$1-$L$1))*(T$1-$L$1) -> 12614 | ... AE12: =$L12+(($AF12-$L12)/($AF$1-$L$1))*(AE$1-$L$1) -> 12614 | AF12: =Cal!D11 -> 12614 | AG12: =_xlfn.FORECAST.LINEAR(AG$1, $AC12:$AE12, $AC$1:$AE$1) -> 12614 | AH12: =_xlfn.FORECAST.LINEAR(AH$1, $AC12:$AE12, $AC$1:$AE$1) -> 12614 | AI12: =_xlfn.FORECAST.LINEAR(AI$1, $AC12:$AE12, $AC$1:$AE$1) -> 12614 | AJ12: =_xlfn.FORECAST.LINEAR(AJ$1, $AC12:$AE12, $AC$1:$AE$1) -> 12614 | AK12: =_xlfn.FORECAST.LINEAR(AK$1, $AC12:$AE12, $AC$1:$AE$1) -> 12614 | AL12: =_xlfn.FORECAST.LINEAR(AL$1, $AC12:$AE12, $AC$1:$AE$1) -> 12614 | AM12: =_xlfn.FORECAST.LINEAR(AM$1, $AC12:$AE12, $AC$1:$AE$1) -> 12614 | AN12: =_xlfn.FORECAST.LINEAR(AN$1, $AC12:$AE12, $AC$1:$AE$1) -> 12614 | ... AZ12: =_xlfn.FORECAST.LINEAR(AZ$1, $AC12:$AE12, $AC$1:$AE$1) -> 12614
A13: lignite | B13: =Cal!B12 -> 25228 | C13: =B13 -> 25228 | D13: =C13 -> 25228 | E13: =D13 -> 25228 | F13: =E13 -> 25228 | G13: =F13 -> 25228 | H13: =G13 -> 25228 | I13: =H13 -> 25228 | J13: =I13 -> 25228 | K13: =J13 -> 25228 | L13: =Cal!C12 -> 25228 | M13: =$L13+(($AF13-$L13)/($AF$1-$L$1))*(M$1-$L$1) -> 25228 | N13: =$L13+(($AF13-$L13)/($AF$1-$L$1))*(N$1-$L$1) -> 25228 | O13: =$L13+(($AF13-$L13)/($AF$1-$L$1))*(O$1-$L$1) -> 25228 | P13: =$L13+(($AF13-$L13)/($AF$1-$L$1))*(P$1-$L$1) -> 25228 | Q13: =$L13+(($AF13-$L13)/($AF$1-$L$1))*(Q$1-$L$1) -> 25228 | R13: =$L13+(($AF13-$L13)/($AF$1-$L$1))*(R$1-$L$1) -> 25228 | S13: =$L13+(($AF13-$L13)/($AF$1-$L$1))*(S$1-$L$1) -> 25228 | T13: =$L13+(($AF13-$L13)/($AF$1-$L$1))*(T$1-$L$1) -> 25228 | ... AE13: =$L13+(($AF13-$L13)/($AF$1-$L$1))*(AE$1-$L$1) -> 25228 | AF13: =Cal!D12 -> 25228 | AG13: =_xlfn.FORECAST.LINEAR(AG$1, $AC13:$AE13, $AC$1:$AE$1) -> 25228 | AH13: =_xlfn.FORECAST.LINEAR(AH$1, $AC13:$AE13, $AC$1:$AE$1) -> 25228 | AI13: =_xlfn.FORECAST.LINEAR(AI$1, $AC13:$AE13, $AC$1:$AE$1) -> 25228 | AJ13: =_xlfn.FORECAST.LINEAR(AJ$1, $AC13:$AE13, $AC$1:$AE$1) -> 25228 | AK13: =_xlfn.FORECAST.LINEAR(AK$1, $AC13:$AE13, $AC$1:$AE$1) -> 25228 | AL13: =_xlfn.FORECAST.LINEAR(AL$1, $AC13:$AE13, $AC$1:$AE$1) -> 25228 | AM13: =_xlfn.FORECAST.LINEAR(AM$1, $AC13:$AE13, $AC$1:$AE$1) -> 25228 | AN13: =_xlfn.FORECAST.LINEAR(AN$1, $AC13:$AE13, $AC$1:$AE$1) -> 25228 | ... AZ13: =_xlfn.FORECAST.LINEAR(AZ$1, $AC13:$AE13, $AC$1:$AE$1) -> 25228
A14: offshore wind | B14: =Cal!B13 -> 77261 | C14: =B14 -> 77261 | D14: =C14 -> 77261 | E14: =D14 -> 77261 | F14: =E14 -> 77261 | G14: =F14 -> 77261 | H14: =G14 -> 77261 | I14: =H14 -> 77261 | J14: =I14 -> 77261 | K14: =J14 -> 77261 | L14: =Cal!C13 -> 77261 | M14: =$L14+(($AF14-$L14)/($AF$1-$L$1))*(M$1-$L$1) -> 77261 | N14: =$L14+(($AF14-$L14)/($AF$1-$L$1))*(N$1-$L$1) -> 77261 | O14: =$L14+(($AF14-$L14)/($AF$1-$L$1))*(O$1-$L$1) -> 77261 | P14: =$L14+(($AF14-$L14)/($AF$1-$L$1))*(P$1-$L$1) -> 77261 | Q14: =$L14+(($AF14-$L14)/($AF$1-$L$1))*(Q$1-$L$1) -> 77261 | R14: =$L14+(($AF14-$L14)/($AF$1-$L$1))*(R$1-$L$1) -> 77261 | S14: =$L14+(($AF14-$L14)/($AF$1-$L$1))*(S$1-$L$1) -> 77261 | T14: =$L14+(($AF14-$L14)/($AF$1-$L$1))*(T$1-$L$1) -> 77261 | ... AE14: =$L14+(($AF14-$L14)/($AF$1-$L$1))*(AE$1-$L$1) -> 77261 | AF14: =Cal!D13 -> 77261 | AG14: =_xlfn.FORECAST.LINEAR(AG$1, $AC14:$AE14, $AC$1:$AE$1) -> 77261 | AH14: =_xlfn.FORECAST.LINEAR(AH$1, $AC14:$AE14, $AC$1:$AE$1) -> 77261 | AI14: =_xlfn.FORECAST.LINEAR(AI$1, $AC14:$AE14, $AC$1:$AE$1) -> 77261 | AJ14: =_xlfn.FORECAST.LINEAR(AJ$1, $AC14:$AE14, $AC$1:$AE$1) -> 77261 | AK14: =_xlfn.FORECAST.LINEAR(AK$1, $AC14:$AE14, $AC$1:$AE$1) -> 77261 | AL14: =_xlfn.FORECAST.LINEAR(AL$1, $AC14:$AE14, $AC$1:$AE$1) -> 77261 | AM14: =_xlfn.FORECAST.LINEAR(AM$1, $AC14:$AE14, $AC$1:$AE$1) -> 77261 | AN14: =_xlfn.FORECAST.LINEAR(AN$1, $AC14:$AE14, $AC$1:$AE$1) -> 77261 | ... AZ14: =_xlfn.FORECAST.LINEAR(AZ$1, $AC14:$AE14, $AC$1:$AE$1) -> 77261
A15: crude oil | B15: =Cal!B14 -> 78838 | C15: =B15 -> 78838 | D15: =C15 -> 78838 | E15: =D15 -> 78838 | F15: =E15 -> 78838 | G15: =F15 -> 78838 | H15: =G15 -> 78838 | I15: =H15 -> 78838 | J15: =I15 -> 78838 | K15: =J15 -> 78838 | L15: =Cal!C14 -> 78838 | M15: =$L15+(($AF15-$L15)/($AF$1-$L$1))*(M$1-$L$1) -> 78838 | N15: =$L15+(($AF15-$L15)/($AF$1-$L$1))*(N$1-$L$1) -> 78838 | O15: =$L15+(($AF15-$L15)/($AF$1-$L$1))*(O$1-$L$1) -> 78838 | P15: =$L15+(($AF15-$L15)/($AF$1-$L$1))*(P$1-$L$1) -> 78838 | Q15: =$L15+(($AF15-$L15)/($AF$1-$L$1))*(Q$1-$L$1) -> 78838 | R15: =$L15+(($AF15-$L15)/($AF$1-$L$1))*(R$1-$L$1) -> 78838 | S15: =$L15+(($AF15-$L15)/($AF$1-$L$1))*(S$1-$L$1) -> 78838 | T15: =$L15+(($AF15-$L15)/($AF$1-$L$1))*(T$1-$L$1) -> 78838 | ... AE15: =$L15+(($AF15-$L15)/($AF$1-$L$1))*(AE$1-$L$1) -> 78838 | AF15: =Cal!D14 -> 78838 | AG15: =_xlfn.FORECAST.LINEAR(AG$1, $AC15:$AE15, $AC$1:$AE$1) -> 78838 | AH15: =_xlfn.FORECAST.LINEAR(AH$1, $AC15:$AE15, $AC$1:$AE$1) -> 78838 | AI15: =_xlfn.FORECAST.LINEAR(AI$1, $AC15:$AE15, $AC$1:$AE$1) -> 78838 | AJ15: =_xlfn.FORECAST.LINEAR(AJ$1, $AC15:$AE15, $AC$1:$AE$1) -> 78838 | AK15: =_xlfn.FORECAST.LINEAR(AK$1, $AC15:$AE15, $AC$1:$AE$1) -> 78838 | AL15: =_xlfn.FORECAST.LINEAR(AL$1, $AC15:$AE15, $AC$1:$AE$1) -> 78838 | AM15: =_xlfn.FORECAST.LINEAR(AM$1, $AC15:$AE15, $AC$1:$AE$1) -> 78838 | AN15: =_xlfn.FORECAST.LINEAR(AN$1, $AC15:$AE15, $AC$1:$AE$1) -> 78838 | ... AZ15: =_xlfn.FORECAST.LINEAR(AZ$1, $AC15:$AE15, $AC$1:$AE$1) -> 78838
A16: heavy or residual fuel oil | B16: =Cal!B15 -> 78838 | C16: =B16 -> 78838 | D16: =C16 -> 78838 | E16: =D16 -> 78838 | F16: =E16 -> 78838 | G16: =F16 -> 78838 | H16: =G16 -> 78838 | I16: =H16 -> 78838 | J16: =I16 -> 78838 | K16: =J16 -> 78838 | L16: =Cal!C15 -> 78838 | M16: =$L16+(($AF16-$L16)/($AF$1-$L$1))*(M$1-$L$1) -> 78838 | N16: =$L16+(($AF16-$L16)/($AF$1-$L$1))*(N$1-$L$1) -> 78838 | O16: =$L16+(($AF16-$L16)/($AF$1-$L$1))*(O$1-$L$1) -> 78838 | P16: =$L16+(($AF16-$L16)/($AF$1-$L$1))*(P$1-$L$1) -> 78838 | Q16: =$L16+(($AF16-$L16)/($AF$1-$L$1))*(Q$1-$L$1) -> 78838 | R16: =$L16+(($AF16-$L16)/($AF$1-$L$1))*(R$1-$L$1) -> 78838 | S16: =$L16+(($AF16-$L16)/($AF$1-$L$1))*(S$1-$L$1) -> 78838 | T16: =$L16+(($AF16-$L16)/($AF$1-$L$1))*(T$1-$L$1) -> 78838 | ... AE16: =$L16+(($AF16-$L16)/($AF$1-$L$1))*(AE$1-$L$1) -> 78838 | AF16: =Cal!D15 -> 78838 | AG16: =_xlfn.FORECAST.LINEAR(AG$1, $AC16:$AE16, $AC$1:$AE$1) -> 78838 | AH16: =_xlfn.FORECAST.LINEAR(AH$1, $AC16:$AE16, $AC$1:$AE$1) -> 78838 | AI16: =_xlfn.FORECAST.LINEAR(AI$1, $AC16:$AE16, $AC$1:$AE$1) -> 78838 | AJ16: =_xlfn.FORECAST.LINEAR(AJ$1, $AC16:$AE16, $AC$1:$AE$1) -> 78838 | AK16: =_xlfn.FORECAST.LINEAR(AK$1, $AC16:$AE16, $AC$1:$AE$1) -> 78838 | AL16: =_xlfn.FORECAST.LINEAR(AL$1, $AC16:$AE16, $AC$1:$AE$1) -> 78838 | AM16: =_xlfn.FORECAST.LINEAR(AM$1, $AC16:$AE16, $AC$1:$AE$1) -> 78838 | AN16: =_xlfn.FORECAST.LINEAR(AN$1, $AC16:$AE16, $AC$1:$AE$1) -> 78838 | ... AZ16: =_xlfn.FORECAST.LINEAR(AZ$1, $AC16:$AE16, $AC$1:$AE$1) -> 78838
A17: municipal solid waste | B17: =Cal!B16 -> 233952 | C17: =B17 -> 233952 | D17: =C17 -> 233952 | E17: =D17 -> 233952 | F17: =E17 -> 233952 | G17: =F17 -> 233952 | H17: =G17 -> 233952 | I17: =H17 -> 233952 | J17: =I17 -> 233952 | K17: =J17 -> 233952 | L17: =Cal!C16 -> 233952 | M17: =$L17+(($AF17-$L17)/($AF$1-$L$1))*(M$1-$L$1) -> 233952 | N17: =$L17+(($AF17-$L17)/($AF$1-$L$1))*(N$1-$L$1) -> 233952 | O17: =$L17+(($AF17-$L17)/($AF$1-$L$1))*(O$1-$L$1) -> 233952 | P17: =$L17+(($AF17-$L17)/($AF$1-$L$1))*(P$1-$L$1) -> 233952 | Q17: =$L17+(($AF17-$L17)/($AF$1-$L$1))*(Q$1-$L$1) -> 233952 | R17: =$L17+(($AF17-$L17)/($AF$1-$L$1))*(R$1-$L$1) -> 233952 | S17: =$L17+(($AF17-$L17)/($AF$1-$L$1))*(S$1-$L$1) -> 233952 | T17: =$L17+(($AF17-$L17)/($AF$1-$L$1))*(T$1-$L$1) -> 233952 | ... AE17: =$L17+(($AF17-$L17)/($AF$1-$L$1))*(AE$1-$L$1) -> 233952 | AF17: =Cal!D16 -> 233952 | AG17: =_xlfn.FORECAST.LINEAR(AG$1, $AC17:$AE17, $AC$1:$AE$1) -> 233952 | AH17: =_xlfn.FORECAST.LINEAR(AH$1, $AC17:$AE17, $AC$1:$AE$1) -> 233952 | AI17: =_xlfn.FORECAST.LINEAR(AI$1, $AC17:$AE17, $AC$1:$AE$1) -> 233952 | AJ17: =_xlfn.FORECAST.LINEAR(AJ$1, $AC17:$AE17, $AC$1:$AE$1) -> 233952 | AK17: =_xlfn.FORECAST.LINEAR(AK$1, $AC17:$AE17, $AC$1:$AE$1) -> 233952 | AL17: =_xlfn.FORECAST.LINEAR(AL$1, $AC17:$AE17, $AC$1:$AE$1) -> 233952 | AM17: =_xlfn.FORECAST.LINEAR(AM$1, $AC17:$AE17, $AC$1:$AE$1) -> 233952 | AN17: =_xlfn.FORECAST.LINEAR(AN$1, $AC17:$AE17, $AC$1:$AE$1) -> 233952 | ... AZ17: =_xlfn.FORECAST.LINEAR(AZ$1, $AC17:$AE17, $AC$1:$AE$1) -> 233952

Sheet CCaMC-AFOaMCpUC-pre-nonret
A1: Fixed O&M ($/MW) - Preex.Nonretiring | B1: 2020 | C1: 2021 | D1: 2022 | E1: 2023 | F1: 2024 | G1: 2025 | H1: 2026 | I1: 2027 | J1: 2028 | K1: 2029 | L1: 2030 | M1: 2031 | N1: 2032 | O1: 2033 | P1: 2034 | Q1: 2035 | R1: 2036 | S1: 2037 | T1: 2038 | U1: 2039 | V1: 2040 | W1: 2041 | X1: 2042 | Y1: 2043 | Z1: 2044 | AA1: 2045 | AB1: 2046 | AC1: 2047 | AD1: 2048 | AE1: 2049 | AF1: 2050
A2: hard coal | B2: 0 | C2: 0 | D2: 0 | E2: 0 | F2: 0 | G2: 0 | H2: 0 | I2: 0 | J2: 0 | K2: 0 | L2: 0 | M2: 0 | N2: 0 | O2: 0 | P2: 0 | Q2: 0 | R2: 0 | S2: 0 | T2: 0 | U2: 0 | V2: 0 | W2: 0 | X2: 0 | Y2: 0 | Z2: 0 | AA2: 0 | AB2: 0 | AC2: 0 | AD2: 0 | AE2: 0 | AF2: 0
A3: natural gas nonpeaker | B3: 0 | C3: 0 | D3: 0 | E3: 0 | F3: 0 | G3: 0 | H3: 0 | I3: 0 | J3: 0 | K3: 0 | L3: 0 | M3: 0 | N3: 0 | O3: 0 | P3: 0 | Q3: 0 | R3: 0 | S3: 0 | T3: 0 | U3: 0 | V3: 0 | W3: 0 | X3: 0 | Y3: 0 | Z3: 0 | AA3: 0 | AB3: 0 | AC3: 0 | AD3: 0 | AE3: 0 | AF3: 0
A4: nuclear | B4: 0 | C4: 0 | D4: 0 | E4: 0 | F4: 0 | G4: 0 | H4: 0 | I4: 0 | J4: 0 | K4: 0 | L4: 0 | M4: 0 | N4: 0 | O4: 0 | P4: 0 | Q4: 0 | R4: 0 | S4: 0 | T4: 0 | U4: 0 | V4: 0 | W4: 0 | X4: 0 | Y4: 0 | Z4: 0 | AA4: 0 | AB4: 0 | AC4: 0 | AD4: 0 | AE4: 0 | AF4: 0
A5: hydro | B5: 0 | C5: 0 | D5: 0 | E5: 0 | F5: 0 | G5: 0 | H5: 0 | I5: 0 | J5: 0 | K5: 0 | L5: 0 | M5: 0 | N5: 0 | O5: 0 | P5: 0 | Q5: 0 | R5: 0 | S5: 0 | T5: 0 | U5: 0 | V5: 0 | W5: 0 | X5: 0 | Y5: 0 | Z5: 0 | AA5: 0 | AB5: 0 | AC5: 0 | AD5: 0 | AE5: 0 | AF5: 0
A6: onshore wind | B6: 0 | C6: 0 | D6: 0 | E6: 0 | F6: 0 | G6: 0 | H6: 0 | I6: 0 | J6: 0 | K6: 0 | L6: 0 | M6: 0 | N6: 0 | O6: 0 | P6: 0 | Q6: 0 | R6: 0 | S6: 0 | T6: 0 | U6: 0 | V6: 0 | W6: 0 | X6: 0 | Y6: 0 | Z6: 0 | AA6: 0 | AB6: 0 | AC6: 0 | AD6: 0 | AE6: 0 | AF6: 0
A7: solar PV | B7: 0 | C7: 0 | D7: 0 | E7: 0 | F7: 0 | G7: 0 | H7: 0 | I7: 0 | J7: 0 | K7: 0 | L7: 0 | M7: 0 | N7: 0 | O7: 0 | P7: 0 | Q7: 0 | R7: 0 | S7: 0 | T7: 0 | U7: 0 | V7: 0 | W7: 0 | X7: 0 | Y7: 0 | Z7: 0 | AA7: 0 | AB7: 0 | AC7: 0 | AD7: 0 | AE7: 0 | AF7: 0
A8: solar thermal | B8: 0 | C8: 0 | D8: 0 | E8: 0 | F8: 0 | G8: 0 | H8: 0 | I8: 0 | J8: 0 | K8: 0 | L8: 0 | M8: 0 | N8: 0 | O8: 0 | P8: 0 | Q8: 0 | R8: 0 | S8: 0 | T8: 0 | U8: 0 | V8: 0 | W8: 0 | X8: 0 | Y8: 0 | Z8: 0 | AA8: 0 | AB8: 0 | AC8: 0 | AD8: 0 | AE8: 0 | AF8: 0
A9: biomass | B9: 0 | C9: 0 | D9: 0 | E9: 0 | F9: 0 | G9: 0 | H9: 0 | I9: 0 | J9: 0 | K9: 0 | L9: 0 | M9: 0 | N9: 0 | O9: 0 | P9: 0 | Q9: 0 | R9: 0 | S9: 0 | T9: 0 | U9: 0 | V9: 0 | W9: 0 | X9: 0 | Y9: 0 | Z9: 0 | AA9: 0 | AB9: 0 | AC9: 0 | AD9: 0 | AE9: 0 | AF9: 0
A10: geothermal | B10: 0 | C10: 0 | D10: 0 | E10: 0 | F10: 0 | G10: 0 | H10: 0 | I10: 0 | J10: 0 | K10: 0 | L10: 0 | M10: 0 | N10: 0 | O10: 0 | P10: 0 | Q10: 0 | R10: 0 | S10: 0 | T10: 0 | U10: 0 | V10: 0 | W10: 0 | X10: 0 | Y10: 0 | Z10: 0 | AA10: 0 | AB10: 0 | AC10: 0 | AD10: 0 | AE10: 0 | AF10: 0
A11: petroleum | B11: 0 | C11: 0 | D11: 0 | E11: 0 | F11: 0 | G11: 0 | H11: 0 | I11: 0 | J11: 0 | K11: 0 | L11: 0 | M11: 0 | N11: 0 | O11: 0 | P11: 0 | Q11: 0 | R11: 0 | S11: 0 | T11: 0 | U11: 0 | V11: 0 | W11: 0 | X11: 0 | Y11: 0 | Z11: 0 | AA11: 0 | AB11: 0 | AC11: 0 | AD11: 0 | AE11: 0 | AF11: 0
A12: natural gas peaker | B12: 0 | C12: 0 | D12: 0 | E12: 0 | F12: 0 | G12: 0 | H12: 0 | I12: 0 | J12: 0 | K12: 0 | L12: 0 | M12: 0 | N12: 0 | O12: 0 | P12: 0 | Q12: 0 | R12: 0 | S12: 0 | T12: 0 | U12: 0 | V12: 0 | W12: 0 | X12: 0 | Y12: 0 | Z12: 0 | AA12: 0 | AB12: 0 | AC12: 0 | AD12: 0 | AE12: 0 | AF12: 0
... A17: municipal solid waste | B17: 0 | C17: 0 | D17: 0 | E17: 0 | F17: 0 | G17: 0 | H17: 0 | I17: 0 | J17: 0 | K17: 0 | L17: 0 | M17: 0 | N17: 0 | O17: 0 | P17: 0 | Q17: 0 | R17: 0 | S17: 0 | T17: 0 | U17: 0 | V17: 0 | W17: 0 | X17: 0 | Y17: 0 | Z17: 0 | AA17: 0 | AB17: 0 | AC17: 0 | AD17: 0 | AE17: 0 | AF17: 0

Sheet CCaMC-AFOaMCpUC-new
A1: Fixed O&M ($/MW) - Preex.Nonretiring | B1: 2020 | C1: 2021 | D1: 2022 | E1: 2023 | F1: 2024 | G1: 2025 | H1: 2026 | I1: 2027 | J1: 2028 | K1: 2029 | L1: 2030 | M1: 2031 | N1: 2032 | O1: 2033 | P1: 2034 | Q1: 2035 | R1: 2036 | S1: 2037 | T1: 2038 | U1: 2039 | V1: 2040 | W1: 2041 | X1: 2042 | Y1: 2043 | Z1: 2044 | AA1: 2045 | AB1: 2046 | AC1: 2047 | AD1: 2048 | AE1: 2049 | AF1: 2050
A2: hard coal | B2: ='CCaMC-AFOaMCpUC-pre-ret'!B2 -> 25228 | C2: ='CCaMC-AFOaMCpUC-pre-ret'!C2 -> 25228 | D2: ='CCaMC-AFOaMCpUC-pre-ret'!D2 -> 25228 | E2: ='CCaMC-AFOaMCpUC-pre-ret'!E2 -> 25228 | F2: ='CCaMC-AFOaMCpUC-pre-ret'!F2 -> 25228 | G2: ='CCaMC-AFOaMCpUC-pre-ret'!G2 -> 25228 | H2: ='CCaMC-AFOaMCpUC-pre-ret'!H2 -> 25228 | I2: ='CCaMC-AFOaMCpUC-pre-ret'!I2 -> 25228 | ... AF2: ='CCaMC-AFOaMCpUC-pre-ret'!AF2 -> 25228
A3: natural gas nonpeaker | B3: ='CCaMC-AFOaMCpUC-pre-ret'!B3 -> 12614 | C3: ='CCaMC-AFOaMCpUC-pre-ret'!C3 -> 12614 | D3: ='CCaMC-AFOaMCpUC-pre-ret'!D3 -> 12614 | E3: ='CCaMC-AFOaMCpUC-pre-ret'!E3 -> 12614 | F3: ='CCaMC-AFOaMCpUC-pre-ret'!F3 -> 12614 | G3: ='CCaMC-AFOaMCpUC-pre-ret'!G3 -> 12614 | H3: ='CCaMC-AFOaMCpUC-pre-ret'!H3 -> 12614 | I3: ='CCaMC-AFOaMCpUC-pre-ret'!I3 -> 12614 | ... AF3: ='CCaMC-AFOaMCpUC-pre-ret'!AF3 -> 12614
A4: nuclear | B4: ='CCaMC-AFOaMCpUC-pre-ret'!B4 -> 77261 | C4: ='CCaMC-AFOaMCpUC-pre-ret'!C4 -> 77261 | D4: ='CCaMC-AFOaMCpUC-pre-ret'!D4 -> 77261 | E4: ='CCaMC-AFOaMCpUC-pre-ret'!E4 -> 77261 | F4: ='CCaMC-AFOaMCpUC-pre-ret'!F4 -> 77261 | G4: ='CCaMC-AFOaMCpUC-pre-ret'!G4 -> 77261 | H4: ='CCaMC-AFOaMCpUC-pre-ret'!H4 -> 77261 | I4: ='CCaMC-AFOaMCpUC-pre-ret'!I4 -> 77261 | ... AF4: ='CCaMC-AFOaMCpUC-pre-ret'!AF4 -> 77261
A5: hydro | B5: ='CCaMC-AFOaMCpUC-pre-ret'!B5 -> 14191 | C5: ='CCaMC-AFOaMCpUC-pre-ret'!C5 -> 14191 | D5: ='CCaMC-AFOaMCpUC-pre-ret'!D5 -> 14191 | E5: ='CCaMC-AFOaMCpUC-pre-ret'!E5 -> 14191 | F5: ='CCaMC-AFOaMCpUC-pre-ret'!F5 -> 14191 | G5: ='CCaMC-AFOaMCpUC-pre-ret'!G5 -> 14191 | H5: ='CCaMC-AFOaMCpUC-pre-ret'!H5 -> 14191 | I5: ='CCaMC-AFOaMCpUC-pre-ret'!I5 -> 14191 | ... AF5: ='CCaMC-AFOaMCpUC-pre-ret'!AF5 -> 14191
A6: onshore wind | B6: ='CCaMC-AFOaMCpUC-pre-ret'!B6 -> 14191 | C6: ='CCaMC-AFOaMCpUC-pre-ret'!C6 -> 14191 | D6: ='CCaMC-AFOaMCpUC-pre-ret'!D6 -> 14191 | E6: ='CCaMC-AFOaMCpUC-pre-ret'!E6 -> 14191 | F6: ='CCaMC-AFOaMCpUC-pre-ret'!F6 -> 14191 | G6: ='CCaMC-AFOaMCpUC-pre-ret'!G6 -> 14191 | H6: ='CCaMC-AFOaMCpUC-pre-ret'!H6 -> 14191 | I6: ='CCaMC-AFOaMCpUC-pre-ret'!I6 -> 14191 | ... AF6: ='CCaMC-AFOaMCpUC-pre-ret'!AF6 -> 14191
A7: solar PV | B7: ='CCaMC-AFOaMCpUC-pre-ret'!B7 -> 7884 | C7: ='CCaMC-AFOaMCpUC-pre-ret'!C7 -> 7884 | D7: ='CCaMC-AFOaMCpUC-pre-ret'!D7 -> 7884 | E7: ='CCaMC-AFOaMCpUC-pre-ret'!E7 -> 7884 | F7: ='CCaMC-AFOaMCpUC-pre-ret'!F7 -> 7884 | G7: ='CCaMC-AFOaMCpUC-pre-ret'!G7 -> 7884 | H7: ='CCaMC-AFOaMCpUC-pre-ret'!H7 -> 7884 | I7: ='CCaMC-AFOaMCpUC-pre-ret'!I7 -> 7884 | ... AF7: ='CCaMC-AFOaMCpUC-pre-ret'!AF7 -> 7884
A8: solar thermal | B8: ='CCaMC-AFOaMCpUC-pre-ret'!B8 -> 96466.346 | C8: ='CCaMC-AFOaMCpUC-pre-ret'!C8 -> 94050.967 | D8: ='CCaMC-AFOaMCpUC-pre-ret'!D8 -> 91595.057 | E8: ='CCaMC-AFOaMCpUC-pre-ret'!E8 -> 89097.589 | F8: ='CCaMC-AFOaMCpUC-pre-ret'!F8 -> 86557.499 | G8: ='CCaMC-AFOaMCpUC-pre-ret'!G8 -> 83973.686 | H8: ='CCaMC-AFOaMCpUC-pre-ret'!H8 -> 81446.085 | I8: ='CCaMC-AFOaMCpUC-pre-ret'!I8 -> 78865.862 | ... AF8: ='CCaMC-AFOaMCpUC-pre-ret'!AF8 -> 77415.001
A9: biomass | B9: ='CCaMC-AFOaMCpUC-pre-ret'!B9 -> 45696 | C9: ='CCaMC-AFOaMCpUC-pre-ret'!C9 -> 45696 | D9: ='CCaMC-AFOaMCpUC-pre-ret'!D9 -> 45696 | E9: ='CCaMC-AFOaMCpUC-pre-ret'!E9 -> 45696 | F9: ='CCaMC-AFOaMCpUC-pre-ret'!F9 -> 45696 | G9: ='CCaMC-AFOaMCpUC-pre-ret'!G9 -> 45696 | H9: ='CCaMC-AFOaMCpUC-pre-ret'!H9 -> 45696 | I9: ='CCaMC-AFOaMCpUC-pre-ret'!I9 -> 45696 | ... AF9: ='CCaMC-AFOaMCpUC-pre-ret'!AF9 -> 45696
A10: geothermal | B10: ='CCaMC-AFOaMCpUC-pre-ret'!B10 -> 14191 | C10: ='CCaMC-AFOaMCpUC-pre-ret'!C10 -> 14191 | D10: ='CCaMC-AFOaMCpUC-pre-ret'!D10 -> 14191 | E10: ='CCaMC-AFOaMCpUC-pre-ret'!E10 -> 14191 | F10: ='CCaMC-AFOaMCpUC-pre-ret'!F10 -> 14191 | G10: ='CCaMC-AFOaMCpUC-pre-ret'!G10 -> 14191 | H10: ='CCaMC-AFOaMCpUC-pre-ret'!H10 -> 14191 | I10: ='CCaMC-AFOaMCpUC-pre-ret'!I10 -> 14191 | ... AF10: ='CCaMC-AFOaMCpUC-pre-ret'!AF10 -> 14191
A11: petroleum | B11: ='CCaMC-AFOaMCpUC-pre-ret'!B11 -> 78838 | C11: ='CCaMC-AFOaMCpUC-pre-ret'!C11 -> 78838 | D11: ='CCaMC-AFOaMCpUC-pre-ret'!D11 -> 78838 | E11: ='CCaMC-AFOaMCpUC-pre-ret'!E11 -> 78838 | F11: ='CCaMC-AFOaMCpUC-pre-ret'!F11 -> 78838 | G11: ='CCaMC-AFOaMCpUC-pre-ret'!G11 -> 78838 | H11: ='CCaMC-AFOaMCpUC-pre-ret'!H11 -> 78838 | I11: ='CCaMC-AFOaMCpUC-pre-ret'!I11 -> 78838 | ... AF11: ='CCaMC-AFOaMCpUC-pre-ret'!AF11 -> 78838
A12: natural gas peaker | B12: ='CCaMC-AFOaMCpUC-pre-ret'!B12 -> 12614 | C12: ='CCaMC-AFOaMCpUC-pre-ret'!C12 -> 12614 | D12: ='CCaMC-AFOaMCpUC-pre-ret'!D12 -> 12614 | E12: ='CCaMC-AFOaMCpUC-pre-ret'!E12 -> 12614 | F12: ='CCaMC-AFOaMCpUC-pre-ret'!F12 -> 12614 | G12: ='CCaMC-AFOaMCpUC-pre-ret'!G12 -> 12614 | H12: ='CCaMC-AFOaMCpUC-pre-ret'!H12 -> 12614 | I12: ='CCaMC-AFOaMCpUC-pre-ret'!I12 -> 12614 | ... AF12: ='CCaMC-AFOaMCpUC-pre-ret'!AF12 -> 12614
A13: lignite | B13: ='CCaMC-AFOaMCpUC-pre-ret'!B13 -> 25228 | C13: ='CCaMC-AFOaMCpUC-pre-ret'!C13 -> 25228 | D13: ='CCaMC-AFOaMCpUC-pre-ret'!D13 -> 25228 | E13: ='CCaMC-AFOaMCpUC-pre-ret'!E13 -> 25228 | F13: ='CCaMC-AFOaMCpUC-pre-ret'!F13 -> 25228 | G13: ='CCaMC-AFOaMCpUC-pre-ret'!G13 -> 25228 | H13: ='CCaMC-AFOaMCpUC-pre-ret'!H13 -> 25228 | I13: ='CCaMC-AFOaMCpUC-pre-ret'!I13 -> 25228 | ... AF13: ='CCaMC-AFOaMCpUC-pre-ret'!AF13 -> 25228
... A17: municipal solid waste | B17: ='CCaMC-AFOaMCpUC-pre-ret'!B17 -> 233952 | C17: ='CCaMC-AFOaMCpUC-pre-ret'!C17 -> 233952 | D17: ='CCaMC-AFOaMCpUC-pre-ret'!D17 -> 233952 | E17: ='CCaMC-AFOaMCpUC-pre-ret'!E17 -> 233952 | F17: ='CCaMC-AFOaMCpUC-pre-ret'!F17 -> 233952 | G17: ='CCaMC-AFOaMCpUC-pre-ret'!G17 -> 233952 | H17: ='CCaMC-AFOaMCpUC-pre-ret'!H17 -> 233952 | I17: ='CCaMC-AFOaMCpUC-pre-ret'!I17 -> 233952 | ... AF17: ='CCaMC-AFOaMCpUC-pre-ret'!AF17 -> 233952

Sheet CCaMC-VOaMCpUC-pre-ret
A1: Variable O&M ($/MWh)-Preex.Retiring | B1: 2020 | C1: 2021 | D1: 2022 | E1: 2023 | F1: 2024 | G1: 2025 | H1: 2026 | I1: 2027 | J1: 2028 | K1: 2029 | L1: 2030 | M1: 2031 | N1: 2032 | O1: 2033 | P1: 2034 | Q1: 2035 | R1: 2036 | S1: 2037 | T1: 2038 | U1: 2039 | V1: 2040 | W1: 2041 | X1: 2042 | Y1: 2043 | Z1: 2044 | AA1: 2045 | AB1: 2046 | AC1: 2047 | AD1: 2048 | AE1: 2049 | AF1: 2050 | AG1: 2051 | AH1: 2052 | AI1: 2053 | AJ1: 2054 | AK1: 2055 | AL1: 2056 | AM1: 2057 | AN1: 2058 | AO1: 2059 | AP1: 2060 | AQ1: 2061 | AR1: 2062 | AS1: 2063 | AT1: 2064 | AU1: 2065 | AV1: 2066 | AW1: 2067 | AX1: 2068 | AY1: 2069 | AZ1: 2070
A2: coal | B2: =Cal!B21 -> 0.12 | C2: =$B2 -> 0.12 | D2: =$B2 -> 0.12 | E2: =$B2 -> 0.12 | F2: =$B2 -> 0.12 | G2: =$B2 -> 0.12 | H2: =$B2 -> 0.12 | I2: =$B2 -> 0.12 | J2: =$B2 -> 0.12 | ... AZ2: =$B2 -> 0.12
A3: natural gas nonpeaker | B3: =Cal!B22 -> 0.1248 | C3: =$B3 -> 0.1248 | D3: =$B3 -> 0.1248 | E3: =$B3 -> 0.1248 | F3: =$B3 -> 0.1248 | G3: =$B3 -> 0.1248 | H3: =$B3 -> 0.1248 | I3: =$B3 -> 0.1248 | J3: =$B3 -> 0.1248 | ... AZ3: =$B3 -> 0.1248
A4: nuclear | B4: =Cal!B23 -> 1.87 | C4: =$B4 -> 1.87 | D4: =$B4 -> 1.87 | E4: =$B4 -> 1.87 | F4: =$B4 -> 1.87 | G4: =$B4 -> 1.87 | H4: =$B4 -> 1.87 | I4: =$B4 -> 1.87 | J4: =$B4 -> 1.87 | ... AZ4: =$B4 -> 1.87
A5: hydro | B5: =Cal!B24 -> 0.53 | C5: =$B5 -> 0.53 | D5: =$B5 -> 0.53 | E5: =$B5 -> 0.53 | F5: =$B5 -> 0.53 | G5: =$B5 -> 0.53 | H5: =$B5 -> 0.53 | I5: =$B5 -> 0.53 | J5: =$B5 -> 0.53 | ... AZ5: =$B5 -> 0.53
A6: onshore wind | B6: =Cal!B25 -> 0 | C6: =$B6 -> 0 | D6: =$B6 -> 0 | E6: =$B6 -> 0 | F6: =$B6 -> 0 | G6: =$B6 -> 0 | H6: =$B6 -> 0 | I6: =$B6 -> 0 | J6: =$B6 -> 0 | ... AZ6: =$B6 -> 0
A7: solar PV | B7: =Cal!B26 -> 0 | C7: =$B7 -> 0 | D7: =$B7 -> 0 | E7: =$B7 -> 0 | F7: =$B7 -> 0 | G7: =$B7 -> 0 | H7: =$B7 -> 0 | I7: =$B7 -> 0 | J7: =$B7 -> 0 | ... AZ7: =$B7 -> 0
A8: solar thermal | B8: =Cal!B27 -> 0 | C8: =$B8 -> 0 | D8: =$B8 -> 0 | E8: =$B8 -> 0 | F8: =$B8 -> 0 | G8: =$B8 -> 0 | H8: =$B8 -> 0 | I8: =$B8 -> 0 | J8: =$B8 -> 0 | ... AZ8: =$B8 -> 0
A9: biomass | B9: =Cal!B28 -> 2.88 | C9: =$B9 -> 2.88 | D9: =$B9 -> 2.88 | E9: =$B9 -> 2.88 | F9: =$B9 -> 2.88 | G9: =$B9 -> 2.88 | H9: =$B9 -> 2.88 | I9: =$B9 -> 2.88 | J9: =$B9 -> 2.88 | ... AZ9: =$B9 -> 2.88
A10: geothermal | B10: =Cal!B29 -> 0.21 | C10: =$B10 -> 0.21 | D10: =$B10 -> 0.21 | E10: =$B10 -> 0.21 | F10: =$B10 -> 0.21 | G10: =$B10 -> 0.21 | H10: =$B10 -> 0.21 | I10: =$B10 -> 0.21 | J10: =$B10 -> 0.21 | ... AZ10: =$B10 -> 0.21
A11: petroleum | B11: =Cal!B30 -> 6.14 | C11: =$B11 -> 6.14 | D11: =$B11 -> 6.14 | E11: =$B11 -> 6.14 | F11: =$B11 -> 6.14 | G11: =$B11 -> 6.14 | H11: =$B11 -> 6.14 | I11: =$B11 -> 6.14 | J11: =$B11 -> 6.14 | ... AZ11: =$B11 -> 6.14
A12: natural gas peaker | B12: =Cal!B31 -> 0.1248 | C12: =$B12 -> 0.1248 | D12: =$B12 -> 0.1248 | E12: =$B12 -> 0.1248 | F12: =$B12 -> 0.1248 | G12: =$B12 -> 0.1248 | H12: =$B12 -> 0.1248 | I12: =$B12 -> 0.1248 | J12: =$B12 -> 0.1248 | ... AZ12: =$B12 -> 0.1248
A13: lignite | B13: =Cal!B32 -> 0.12 | C13: =$B13 -> 0.12 | D13: =$B13 -> 0.12 | E13: =$B13 -> 0.12 | F13: =$B13 -> 0.12 | G13: =$B13 -> 0.12 | H13: =$B13 -> 0.12 | I13: =$B13 -> 0.12 | J13: =$B13 -> 0.12 | ... AZ13: =$B13 -> 0.12
... A17: municipal solid waste | B17: =Cal!B36 -> 23.14 | C17: =$B17 -> 23.14 | D17: =$B17 -> 23.14 | E17: =$B17 -> 23.14 | F17: =$B17 -> 23.14 | G17: =$B17 -> 23.14 | H17: =$B17 -> 23.14 | I17: =$B17 -> 23.14 | J17: =$B17 -> 23.14 | ... AZ17: =$B17 -> 23.14

Sheet CCaMC-VOaMCpUC-pre-nonret
A1: Variable O&M ($/MWh)-Preex.Retiring | B1: 2020 | C1: 2021 | D1: 2022 | E1: 2023 | F1: 2024 | G1: 2025 | H1: 2026 | I1: 2027 | J1: 2028 | K1: 2029 | L1: 2030 | M1: 2031 | N1: 2032 | O1: 2033 | P1: 2034 | Q1: 2035 | R1: 2036 | S1: 2037 | T1: 2038 | U1: 2039 | V1: 2040 | W1: 2041 | X1: 2042 | Y1: 2043 | Z1: 2044 | AA1: 2045 | AB1: 2046 | AC1: 2047 | AD1: 2048 | AE1: 2049 | AF1: 2050
A2: coal | B2: 0 | C2: =$B$2 -> 0 | D2: =$B$2 -> 0 | E2: =$B$2 -> 0 | F2: =$B$2 -> 0 | G2: =$B$2 -> 0 | H2: =$B$2 -> 0 | I2: =$B$2 -> 0 | J2: =$B$2 -> 0 | ... AF2: =$B$2 -> 0
A3: natural gas nonpeaker | B3: 0 | C3: =$B$3 -> 0 | D3: =$B$3 -> 0 | E3: =$B$3 -> 0 | F3: =$B$3 -> 0 | G3: =$B$3 -> 0 | H3: =$B$3 -> 0 | I3: =$B$3 -> 0 | J3: =$B$3 -> 0 | ... AF3: =$B$3 -> 0
A4: nuclear | B4: 0 | C4: =$B$4 -> 0 | D4: =$B$4 -> 0 | E4: =$B$4 -> 0 | F4: =$B$4 -> 0 | G4: =$B$4 -> 0 | H4: =$B$4 -> 0 | I4: =$B$4 -> 0 | J4: =$B$4 -> 0 | ... AF4: =$B$4 -> 0
A5: hydro | B5: 0 | C5: =$B$5 -> 0 | D5: =$B$5 -> 0 | E5: =$B$5 -> 0 | F5: =$B$5 -> 0 | G5: =$B$5 -> 0 | H5: =$B$5 -> 0 | I5: =$B$5 -> 0 | J5: =$B$5 -> 0 | ... AF5: =$B$5 -> 0
A6: onshore wind | B6: 0 | C6: =$B$6 -> 0 | D6: =$B$6 -> 0 | E6: =$B$6 -> 0 | F6: =$B$6 -> 0 | G6: =$B$6 -> 0 | H6: =$B$6 -> 0 | I6: =$B$6 -> 0 | J6: =$B$6 -> 0 | ... AF6: =$B$6 -> 0
A7: solar PV | B7: 0 | C7: =$B$7 -> 0 | D7: =$B$7 -> 0 | E7: =$B$7 -> 0 | F7: =$B$7 -> 0 | G7: =$B$7 -> 0 | H7: =$B$7 -> 0 | I7: =$B$7 -> 0 | J7: =$B$7 -> 0 | ... AF7: =$B$7 -> 0
A8: solar thermal | B8: 0 | C8: =$B$8 -> 0 | D8: =$B$8 -> 0 | E8: =$B$8 -> 0 | F8: =$B$8 -> 0 | G8: =$B$8 -> 0 | H8: =$B$8 -> 0 | I8: =$B$8 -> 0 | J8: =$B$8 -> 0 | ... AF8: =$B$8 -> 0
A9: biomass | B9: 0 | C9: =$B$9 -> 0 | D9: =$B$9 -> 0 | E9: =$B$9 -> 0 | F9: =$B$9 -> 0 | G9: =$B$9 -> 0 | H9: =$B$9 -> 0 | I9: =$B$9 -> 0 | J9: =$B$9 -> 0 | ... AF9: =$B$9 -> 0
A10: geothermal | B10: 0 | C10: =$B10 -> 0 | D10: =$B10 -> 0 | E10: =$B10 -> 0 | F10: =$B10 -> 0 | G10: =$B10 -> 0 | H10: =$B10 -> 0 | I10: =$B10 -> 0 | J10: =$B10 -> 0 | ... AF10: =$B10 -> 0
A11: petroleum | B11: 0 | C11: =$B11 -> 0 | D11: =$B11 -> 0 | E11: =$B11 -> 0 | F11: =$B11 -> 0 | G11: =$B11 -> 0 | H11: =$B11 -> 0 | I11: =$B11 -> 0 | J11: =$B11 -> 0 | ... AF11: =$B11 -> 0
A12: natural gas peaker | B12: 0 | C12: =$B12 -> 0 | D12: =$B12 -> 0 | E12: =$B12 -> 0 | F12: =$B12 -> 0 | G12: =$B12 -> 0 | H12: =$B12 -> 0 | I12: =$B12 -> 0 | J12: =$B12 -> 0 | ... AF12: =$B12 -> 0
A13: lignite | B13: 0 | C13: =$B13 -> 0 | D13: =$B13 -> 0 | E13: =$B13 -> 0 | F13: =$B13 -> 0 | G13: =$B13 -> 0 | H13: =$B13 -> 0 | I13: =$B13 -> 0 | J13: =$B13 -> 0 | ... AF13: =$B13 -> 0
A14: offshore wind | B14: 0 | C14: =$B14 -> 0 | D14: =$B14 -> 0 | E14: =$B14 -> 0 | F14: =$B14 -> 0 | G14: =$B14 -> 0 | H14: =$B14 -> 0 | I14: =$B14 -> 0 | J14: =$B14 -> 0 | ... AF14: =$B14 -> 0
A15: crude oil | B15: 0 | C15: =$B15 -> 0 | D15: =$B15 -> 0 | E15: =$B15 -> 0 | F15: =$B15 -> 0 | G15: =$B15 -> 0 | H15: =$B15 -> 0 | I15: =$B15 -> 0 | J15: =$B15 -> 0 | ... AF15: =$B15 -> 0
A16: heavy or residual fuel oil | B16: 0 | C16: =$B16 -> 0 | D16: =$B16 -> 0 | E16: =$B16 -> 0 | F16: =$B16 -> 0 | G16: =$B16 -> 0 | H16: =$B16 -> 0 | I16: =$B16 -> 0 | J16: =$B16 -> 0 | ... AF16: =$B16 -> 0
A17: municipal solid waste | B17: 0 | C17: =$B17 -> 0 | D17: =$B17 -> 0 | E17: =$B17 -> 0 | F17: =$B17 -> 0 | G17: =$B17 -> 0 | H17: =$B17 -> 0 | I17: =$B17 -> 0 | J17: =$B17 -> 0 | ... AF17: =$B17 -> 0

Sheet CCaMC-VOaMCpUC-new
A1: Variable O&M ($/MWh)-Newly Built | B1: 2020 | C1: 2021 | D1: 2022 | E1: 2023 | F1: 2024 | G1: 2025 | H1: 2026 | I1: 2027 | J1: 2028 | K1: 2029 | L1: 2030 | M1: 2031 | N1: 2032 | O1: 2033 | P1: 2034 | Q1: 2035 | R1: 2036 | S1: 2037 | T1: 2038 | U1: 2039 | V1: 2040 | W1: 2041 | X1: 2042 | Y1: 2043 | Z1: 2044 | AA1: 2045 | AB1: 2046 | AC1: 2047 | AD1: 2048 | AE1: 2049 | AF1: 2050
A2: coal | B2: ='CCaMC-VOaMCpUC-pre-ret'!B2 -> 0.12 | C2: ='CCaMC-VOaMCpUC-pre-ret'!C2 -> 0.12 | D2: ='CCaMC-VOaMCpUC-pre-ret'!D2 -> 0.12 | E2: ='CCaMC-VOaMCpUC-pre-ret'!E2 -> 0.12 | F2: ='CCaMC-VOaMCpUC-pre-ret'!F2 -> 0.12 | G2: ='CCaMC-VOaMCpUC-pre-ret'!G2 -> 0.12 | H2: ='CCaMC-VOaMCpUC-pre-ret'!H2 -> 0.12 | I2: ='CCaMC-VOaMCpUC-pre-ret'!I2 -> 0.12 | ... AF2: ='CCaMC-VOaMCpUC-pre-ret'!AF2 -> 0.12
A3: natural gas nonpeaker | B3: ='CCaMC-VOaMCpUC-pre-ret'!B3 -> 0.1248 | C3: ='CCaMC-VOaMCpUC-pre-ret'!C3 -> 0.1248 | D3: ='CCaMC-VOaMCpUC-pre-ret'!D3 -> 0.1248 | E3: ='CCaMC-VOaMCpUC-pre-ret'!E3 -> 0.1248 | F3: ='CCaMC-VOaMCpUC-pre-ret'!F3 -> 0.1248 | G3: ='CCaMC-VOaMCpUC-pre-ret'!G3 -> 0.1248 | H3: ='CCaMC-VOaMCpUC-pre-ret'!H3 -> 0.1248 | I3: ='CCaMC-VOaMCpUC-pre-ret'!I3 -> 0.1248 | ... AF3: ='CCaMC-VOaMCpUC-pre-ret'!AF3 -> 0.1248
A4: nuclear | B4: ='CCaMC-VOaMCpUC-pre-ret'!B4 -> 1.87 | C4: ='CCaMC-VOaMCpUC-pre-ret'!C4 -> 1.87 | D4: ='CCaMC-VOaMCpUC-pre-ret'!D4 -> 1.87 | E4: ='CCaMC-VOaMCpUC-pre-ret'!E4 -> 1.87 | F4: ='CCaMC-VOaMCpUC-pre-ret'!F4 -> 1.87 | G4: ='CCaMC-VOaMCpUC-pre-ret'!G4 -> 1.87 | H4: ='CCaMC-VOaMCpUC-pre-ret'!H4 -> 1.87 | I4: ='CCaMC-VOaMCpUC-pre-ret'!I4 -> 1.87 | ... AF4: ='CCaMC-VOaMCpUC-pre-ret'!AF4 -> 1.87
A5: hydro | B5: ='CCaMC-VOaMCpUC-pre-ret'!B5 -> 0.53 | C5: ='CCaMC-VOaMCpUC-pre-ret'!C5 -> 0.53 | D5: ='CCaMC-VOaMCpUC-pre-ret'!D5 -> 0.53 | E5: ='CCaMC-VOaMCpUC-pre-ret'!E5 -> 0.53 | F5: ='CCaMC-VOaMCpUC-pre-ret'!F5 -> 0.53 | G5: ='CCaMC-VOaMCpUC-pre-ret'!G5 -> 0.53 | H5: ='CCaMC-VOaMCpUC-pre-ret'!H5 -> 0.53 | I5: ='CCaMC-VOaMCpUC-pre-ret'!I5 -> 0.53 | ... AF5: ='CCaMC-VOaMCpUC-pre-ret'!AF5 -> 0.53
A6: onshore wind | B6: ='CCaMC-VOaMCpUC-pre-ret'!B6 -> 0 | C6: ='CCaMC-VOaMCpUC-pre-ret'!C6 -> 0 | D6: ='CCaMC-VOaMCpUC-pre-ret'!D6 -> 0 | E6: ='CCaMC-VOaMCpUC-pre-ret'!E6 -> 0 | F6: ='CCaMC-VOaMCpUC-pre-ret'!F6 -> 0 | G6: ='CCaMC-VOaMCpUC-pre-ret'!G6 -> 0 | H6: ='CCaMC-VOaMCpUC-pre-ret'!H6 -> 0 | I6: ='CCaMC-VOaMCpUC-pre-ret'!I6 -> 0 | ... AF6: ='CCaMC-VOaMCpUC-pre-ret'!AF6 -> 0
A7: solar PV | B7: ='CCaMC-VOaMCpUC-pre-ret'!B7 -> 0 | C7: ='CCaMC-VOaMCpUC-pre-ret'!C7 -> 0 | D7: ='CCaMC-VOaMCpUC-pre-ret'!D7 -> 0 | E7: ='CCaMC-VOaMCpUC-pre-ret'!E7 -> 0 | F7: ='CCaMC-VOaMCpUC-pre-ret'!F7 -> 0 | G7: ='CCaMC-VOaMCpUC-pre-ret'!G7 -> 0 | H7: ='CCaMC-VOaMCpUC-pre-ret'!H7 -> 0 | I7: ='CCaMC-VOaMCpUC-pre-ret'!I7 -> 0 | ... AF7: ='CCaMC-VOaMCpUC-pre-ret'!AF7 -> 0
A8: solar thermal | B8: ='CCaMC-VOaMCpUC-pre-ret'!B8 -> 0 | C8: ='CCaMC-VOaMCpUC-pre-ret'!C8 -> 0 | D8: ='CCaMC-VOaMCpUC-pre-ret'!D8 -> 0 | E8: ='CCaMC-VOaMCpUC-pre-ret'!E8 -> 0 | F8: ='CCaMC-VOaMCpUC-pre-ret'!F8 -> 0 | G8: ='CCaMC-VOaMCpUC-pre-ret'!G8 -> 0 | H8: ='CCaMC-VOaMCpUC-pre-ret'!H8 -> 0 | I8: ='CCaMC-VOaMCpUC-pre-ret'!I8 -> 0 | ... AF8: ='CCaMC-VOaMCpUC-pre-ret'!AF8 -> 0
A9: biomass | B9: ='CCaMC-VOaMCpUC-pre-ret'!B9 -> 2.88 | C9: ='CCaMC-VOaMCpUC-pre-ret'!C9 -> 2.88 | D9: ='CCaMC-VOaMCpUC-pre-ret'!D9 -> 2.88 | E9: ='CCaMC-VOaMCpUC-pre-ret'!E9 -> 2.88 | F9: ='CCaMC-VOaMCpUC-pre-ret'!F9 -> 2.88 | G9: ='CCaMC-VOaMCpUC-pre-ret'!G9 -> 2.88 | H9: ='CCaMC-VOaMCpUC-pre-ret'!H9 -> 2.88 | I9: ='CCaMC-VOaMCpUC-pre-ret'!I9 -> 2.88 | ... AF9: ='CCaMC-VOaMCpUC-pre-ret'!AF9 -> 2.88
A10: geothermal | B10: ='CCaMC-VOaMCpUC-pre-ret'!B10 -> 0.21 | C10: ='CCaMC-VOaMCpUC-pre-ret'!C10 -> 0.21 | D10: ='CCaMC-VOaMCpUC-pre-ret'!D10 -> 0.21 | E10: ='CCaMC-VOaMCpUC-pre-ret'!E10 -> 0.21 | F10: ='CCaMC-VOaMCpUC-pre-ret'!F10 -> 0.21 | G10: ='CCaMC-VOaMCpUC-pre-ret'!G10 -> 0.21 | H10: ='CCaMC-VOaMCpUC-pre-ret'!H10 -> 0.21 | I10: ='CCaMC-VOaMCpUC-pre-ret'!I10 -> 0.21 | ... AF10: ='CCaMC-VOaMCpUC-pre-ret'!AF10 -> 0.21
A11: petroleum | B11: ='CCaMC-VOaMCpUC-pre-ret'!B11 -> 6.14 | C11: ='CCaMC-VOaMCpUC-pre-ret'!C11 -> 6.14 | D11: ='CCaMC-VOaMCpUC-pre-ret'!D11 -> 6.14 | E11: ='CCaMC-VOaMCpUC-pre-ret'!E11 -> 6.14 | F11: ='CCaMC-VOaMCpUC-pre-ret'!F11 -> 6.14 | G11: ='CCaMC-VOaMCpUC-pre-ret'!G11 -> 6.14 | H11: ='CCaMC-VOaMCpUC-pre-ret'!H11 -> 6.14 | I11: ='CCaMC-VOaMCpUC-pre-ret'!I11 -> 6.14 | ... AF11: ='CCaMC-VOaMCpUC-pre-ret'!AF11 -> 6.14
A12: natural gas peaker | B12: ='CCaMC-VOaMCpUC-pre-ret'!B12 -> 0.1248 | C12: ='CCaMC-VOaMCpUC-pre-ret'!C12 -> 0.1248 | D12: ='CCaMC-VOaMCpUC-pre-ret'!D12 -> 0.1248 | E12: ='CCaMC-VOaMCpUC-pre-ret'!E12 -> 0.1248 | F12: ='CCaMC-VOaMCpUC-pre-ret'!F12 -> 0.1248 | G12: ='CCaMC-VOaMCpUC-pre-ret'!G12 -> 0.1248 | H12: ='CCaMC-VOaMCpUC-pre-ret'!H12 -> 0.1248 | I12: ='CCaMC-VOaMCpUC-pre-ret'!I12 -> 0.1248 | ... AF12: ='CCaMC-VOaMCpUC-pre-ret'!AF12 -> 0.1248
A13: lignite | B13: ='CCaMC-VOaMCpUC-pre-ret'!B13 -> 0.12 | C13: ='CCaMC-VOaMCpUC-pre-ret'!C13 -> 0.12 | D13: ='CCaMC-VOaMCpUC-pre-ret'!D13 -> 0.12 | E13: ='CCaMC-VOaMCpUC-pre-ret'!E13 -> 0.12 | F13: ='CCaMC-VOaMCpUC-pre-ret'!F13 -> 0.12 | G13: ='CCaMC-VOaMCpUC-pre-ret'!G13 -> 0.12 | H13: ='CCaMC-VOaMCpUC-pre-ret'!H13 -> 0.12 | I13: ='CCaMC-VOaMCpUC-pre-ret'!I13 -> 0.12 | ... AF13: ='CCaMC-VOaMCpUC-pre-ret'!AF13 -> 0.12
... A17: municipal solid waste | B17: ='CCaMC-VOaMCpUC-pre-ret'!B17 -> 23.14 | C17: ='CCaMC-VOaMCpUC-pre-ret'!C17 -> 23.14 | D17: ='CCaMC-VOaMCpUC-pre-ret'!D17 -> 23.14 | E17: ='CCaMC-VOaMCpUC-pre-ret'!E17 -> 23.14 | F17: ='CCaMC-VOaMCpUC-pre-ret'!F17 -> 23.14 | G17: ='CCaMC-VOaMCpUC-pre-ret'!G17 -> 23.14 | H17: ='CCaMC-VOaMCpUC-pre-ret'!H17 -> 23.14 | I17: ='CCaMC-VOaMCpUC-pre-ret'!I17 -> 23.14 | ... AF17: ='CCaMC-VOaMCpUC-pre-ret'!AF17 -> 23.14

Sheet CCaMC-BCCpUC
A1: Unit: $/MW | B1: 2019 | C1: 2020 | D1: 2021 | E1: 2022 | F1: 2023 | G1: 2024 | H1: 2025 | I1: 2026 | J1: 2027 | K1: 2028 | L1: 2029 | M1: 2030 | N1: 2031 | O1: 2032 | P1: 2033 | Q1: 2034 | R1: 2035 | S1: 2036 | T1: 2037 | U1: 2038 | V1: 2039 | W1: 2040 | X1: 2041 | Y1: 2042 | Z1: 2043 | AA1: 2044 | AB1: 2045 | AC1: 2046 | AD1: 2047 | AE1: 2048 | AF1: 2049 | AG1: 2050
A2: Hard Coal | B2: {=TREND('capital processing'!$B$3:$D$3,'capital processing'!$B$2:$D$2,'CCaMC-BCCpUC'!B1)} -> 1646071.4 | C2: {=TREND('capital processing'!$B$3:$D$3,'capital processing'!$B$2:$D$2,'CCaMC-BCCpUC'!C1)} -> 1642857.1 | D2: {=TREND('capital processing'!$B$3:$D$3,'capital processing'!$B$2:$D$2,'CCaMC-BCCpUC'!D1)} -> 1639642.9 | E2: {=TREND('capital processing'!$B$3:$D$3,'capital processing'!$B$2:$D$2,'CCaMC-BCCpUC'!E1)} -> 1636428.6 | F2: {=TREND('capital processing'!$B$3:$D$3,'capital processing'!$B$2:$D$2,'CCaMC-BCCpUC'!F1)} -> 1633214.3 | G2: {=TREND('capital processing'!$B$3:$D$3,'capital processing'!$B$2:$D$2,'CCaMC-BCCpUC'!G1)} -> 1630000 | H2: {=TREND('capital processing'!$B$3:$D$3,'capital processing'!$B$2:$D$2,'CCaMC-BCCpUC'!H1)} -> 1626785.7 | I2: {=TREND('capital processing'!$B$3:$D$3,'capital processing'!$B$2:$D$2,'CCaMC-BCCpUC'!I1)} -> 1623571.4 | ... AG2: {=TREND('capital processing'!$B$3:$D$3,'capital processing'!$B$2:$D$2,'CCaMC-BCCpUC'!AG1)} -> 1546428.6
