Workbook
Name gal_per_barrel: [1]About!$A$63

Sheet About
A1: BFPIaE BAU Fuel Production
A2: BFPIaE BAU Fuel Imports
A3: BFPIaE BAU Fuel Exports
A5: Source: | B5: National Energy Balance - BEN 2023
B6: Empresa de Pesquisa Energética - official Energy Research Office
B7: all fuels
B8: 2023 edition with data up to 2022
B9: https://www.epe.gov.br/pt/publicacoes-dados-abertos/publicacoes/balanco-energetico-nacional-2023
B10: Area: Brazil, Period: Annual 2023
B12: Ten-Year Energy Expansion Plan - PDE 2023-32
B13: Empresa de Pesquisa Energética - official Energy Research Office
B14: 2023 edition with projections up to 2032
B15: all fuels
B16: https://www.epe.gov.br/pt/publicacoes-dados-abertos/publicacoes/plano-decenal-de-expansao-de-energia-2032
A17: natural gas | B17: see Caderno de Previsão da Produção de Petróleo e Gás Natural
A18: biomass | B18: calculated from bagasse, its main component
A19: bagasse | B19: see Oferta de Biocombustiveis
A20: petroleum gasoline | B20: see Caderno de Abastecimento de Derivados
A21: petroleum diesel | B21: see Caderno de Abastecimento de Derivados
A22: biofuel gasoline | B22: see Oferta de Biocombustiveis
A23: biofuel diesel | B23: see Oferta de Biocombustiveis
A24: jet fuel | B24: see Caderno de Abastecimento de Derivados
A25: crude oil | B25: see Caderno de Previsão da Produção de Petróleo e Gás Natural
A26: heavy fuel oil | B26: see Caderno de Previsão da Produção de Petróleo e Gás Natural
A27: LPG propane or butane | B27: see Caderno de Abastecimento de Derivados
B29: Unit Conversions for hard coal, natural gas, petroleum fuels, LPG, liquid biofuels, lignite, biomass
B30: National Energy Balance - BEN 2023
B31: Empresa de Pesquisa Energética - official Energy Research Office
B32: Annex VIII - Tables 1 - 10
B33: https://www.epe.gov.br/pt/publicacoes-dados-abertos/publicacoes/balanco-energetico-nacional-2023
A35: Notes
A37: Collect Export, Import, and Production Data for Each Fuel
A38: The consolidated data in this variable (production, imports, exports, and domestic use of each fuel)
A39: is used in the variable fuels/CiFIaEpUDFS. Therefore, even though this variable only outputs
A40: production and exports, you should also collect data on fuel imports. (Domestic use data
A41: can be calculated from production, imports, and exports. We ignore changes in fuel stocks,
A42: which should average to zero over multi-year timeframes.)
A44: Time Series
A45: This variable contains time series data.
A46: However, only data from the first year are used in variable fuels/CiFIaEpUDFS.
...

Sheet PDE-O&G
B2: DECENAL ENERGY PLAN 2023-2032
B3: Forecast of Oil and Natural Gas Production Notes
B4: Petroleum Products Supply Notes
D5: 2021 | E5: =1+D5 -> 2022 | F5: =1+E5 -> 2023 | G5: =1+F5 -> 2024 | H5: =1+G5 -> 2025 | I5: =1+H5 -> 2026 | J5: =1+I5 -> 2027 | K5: =1+J5 -> 2028 | L5: =1+K5 -> 2029 | ... O5: =1+N5 -> 2032
B6: petroleo | C6: 1000 m3 | D6: =BEN!L53 -> 168784 | E6: =BEN!M53 -> 175531 | F6: =E6*F7/E7 -> 193084.1 | G6: =F6*G7/F7 -> 222339.27 | H6: =G6*H7/G7 -> 239892.37 | I6: =H6*I7/H7 -> 263296.5 | J6: =I6*J7/I7 -> 274998.57 | K6: =J6*K7/J7 -> 298402.7 | L6: =K6*L7/K7 -> 315955.8 | M6: =L6*M7/L7 -> 310104.77 | ... O6: =N6*O7/N7 -> 286700.63
A7: =BEN!M53 -> 175531 | C7: keep proportion | E7: =365*E9/$P$7*1000 -> 174091.11 | F7: =365*F9/$P$7*1000 -> 191500.22 | G7: =365*G9/$P$7*1000 -> 220515.41 | H7: =365*H9/$P$7*1000 -> 237924.52 | I7: =365*I9/$P$7*1000 -> 261136.66 | J7: =365*J9/$P$7*1000 -> 272742.74 | K7: =365*K9/$P$7*1000 -> 295954.89 | L7: =365*L9/$P$7*1000 -> 313364 | ... O7: =365*O9/$P$7*1000 -> 284348.81 | P7: 6.28981 | Q7: Forecast of Oil and Natural Gas Production Notes
C8: Mbbl | E8: =365*E9 -> 1095 | F8: =365*F9 -> 1204.5 | G8: =365*G9 -> 1387 | H8: =365*H9 -> 1496.5 | I8: =365*I9 -> 1642.5 | J8: =365*J9 -> 1715.5 | K8: =365*K9 -> 1861.5 | L8: =365*L9 -> 1971 | ... O8: =365*O9 -> 1788.5
B9: production | C9: Mbbl/d | E9: 3 | F9: 3.3 | G9: 3.8 | H9: 4.1 | I9: 4.5 | J9: 4.7 | K9: 5.1 | L9: 5.4 | M9: 5.3 | N9: 5.2 | O9: 4.9
B10: import | C10: 1000 m3 | E10: =BEN!M54 -> 14280 | F10: =E10*F11/E11 -> 13016.283 | G10: =F10*G11/F11 -> 11752.566 | H10: =G10*H11/G11 -> 10488.85 | I10: =H10*I11/H11 -> 10320.354 | J10: =I10*J11/I11 -> 10151.858 | K10: =J10*K11/J11 -> 9983.3628 | L10: =K10*L11/K11 -> 10109.735 | M10: =L10*M11/L11 -> 10236.106 | ... O10: =N10*O11/N11 -> 10488.85
C11: keep proportion | E11: =365*E12/$P$7 -> 13114.864 | F11: =365*F12/$P$7 -> 11954.256 | G11: =365*G12/$P$7 -> 10793.649 | H11: =365*H12/$P$7 -> 9633.0414 | I11: =365*I12/$P$7 -> 9478.2937 | J11: =365*J12/$P$7 -> 9323.5461 | K11: =365*K12/$P$7 -> 9168.7984 | L11: =365*L12/$P$7 -> 9284.8592 | ... O11: =365*O12/$P$7 -> 9633.0414
C12: Mbbl/d | E12: =145+81 -> 226 | F12: =E12+1*(H12-E12)/(H$5-E$5) -> 206 | G12: =E12+2*(H12-E12)/(H$5-E$5) -> 186 | H12: =91+75 -> 166 | I12: =H12+1*(K12-H12)/(K$5-H$5) -> 163.33333 | J12: =H12+2*(K12-H12)/(K$5-H$5) -> 160.66667 | K12: =83+75 -> 158 | L12: =K12+1*(O12-K12)/(O5-K5) -> 160 | M12: =K12+2*(O12-K12)/(O5-K5) -> 162 | N12: =K12+3*(O12-K12)/(O5-K5) -> 164 | O12: =91+75 -> 166
B13: export | C13: 1000 m3 | E13: =E14*E6 -> 71967.71 | F13: =F14*F6 -> 89462.3 | G13: =G14*G6 -> 114875.29 | H13: =H14*H6 -> 136738.65 | I13: =I14*I6 -> 154467.28 | J13: =J14*J6 -> 165915.8 | K13: =K14*K6 -> 185009.67 | L13: =L14*L6 -> 195102.71 | ... O13: =O14*O6 -> 174887.39
C14: Relação entre exportação de petróleo e produção nacional | E14: 0.41 | F14: =$E14+(F5-$E5)*($H14-$E14)/($H5-$E5) -> 0.46333333 | G14: =$E14+(G5-$E5)*($H14-$E14)/($H5-$E5) -> 0.51666667 | H14: 0.57 | I14: =$H14+(I5-$H5)*($K14-$H14)/($K5-$H5) -> 0.58666667 | J14: =$H14+(J5-$H5)*($K14-$H14)/($K5-$H5) -> 0.60333333 | K14: 0.62 | L14: =$K14+(L5-$K5)*($O14-$K14)/($O5-$K5) -> 0.6175 | M14: =$K14+(M5-$K5)*($O14-$K14)/($O5-$K5) -> 0.615 | N14: =$K14+(N5-$K5)*($O14-$K14)/($O5-$K5) -> 0.6125 | O14: 0.61
B16: nat gas | C16: 10^6 m3 | D16: =365*D17 -> 20440 | E16: =365*E17 -> 24820 | F16: =365*F17 -> 26280 | G16: =365*G17 -> 27375 | H16: =365*H17 -> 27740 | I16: =365*I17 -> 28470 | J16: =365*J17 -> 34675 | K16: =365*K17 -> 40150 | ... O16: =365*O17 -> 48910 | Q16: Forecast of Oil and Natural Gas Production Notes
B17: production | C17: Mm3/d | D17: 56 | E17: 68 | F17: 72 | G17: 75 | H17: 76 | I17: 78 | J17: 95 | K17: 110 | L17: 116 | M17: 121 | N17: 129 | O17: 134
B18: import | C18: 10^6 m3 | E18: =365*(-E17+E19) -> 17520 | F18: =365*(-F17+F19) -> 22630 | G18: =365*(-G17+G19) -> 27375 | H18: =365*(-H17+H19) -> 26645 | I18: =365*(-I17+I19) -> 26280 | J18: =365*(-J17+J19) -> 23725 | K18: =365*(-K17+K19) -> 21900 | L18: =365*(-L17+L19) -> 19710 | ... O18: =365*(-O17+O19) -> 17520
E19: 116 | F19: 134 | G19: 150 | H19: 149 | I19: 150 | J19: 160 | K19: 170 | L19: 170 | M19: 173 | N19: 178 | O19: 182
B21: pet gasoline | C21: 1000 m3 | E21: =BEN!M27+BEN!M28+BEN!M30 -> 32820 | F21: =E21*F22/E22 -> 30560.88 | G21: =F21*G22/F22 -> 28364.512 | H21: =G21*H22/G22 -> 25917.132 | I21: =H21*I22/H22 -> 23909.025 | J21: =I21*J22/I22 -> 23030.478 | K21: =J21*K22/J22 -> 23030.478 | L21: =K21*L22/K22 -> 23469.751 | M21: =L21*M22/L22 -> 25289.598 | ... O21: =N21*O22/N22 -> 29682.333
C22: keep proportion | E22: =365*E23 -> 29579.542 | F22: =365*F23 -> 27543.474 | G22: =365*G23 -> 25563.963 | H22: =365*H23 -> 23358.223 | I22: =365*I23 -> 21548.385 | J22: =365*J23 -> 20756.581 | K22: =365*K23 -> 20756.581 | L22: =365*L23 -> 21152.483 | ... O22: =365*O23 -> 26751.669 | Q22: Petroleum Products Supply Notes
B23: demand | C23: Mm3/d | E23: 81.03984 | F23: 75.461572 | G23: 70.038255 | H23: 63.995132 | I23: 59.036671 | J23: 56.867345 | K23: 56.867345 | L23: 57.952008 | M23: 62.445613 | N23: 67.868929 | O23: 73.292245
B24: production | C24: 1000 m3 | E24: =BEN!M27 -> 28674 | F24: =E24*F25/E25 -> 27860.028 | G24: =F24*G25/F25 -> 27046.057 | H24: =G24*H25/G25 -> 26232.085 | I24: =H24*I25/H25 -> 26540.408 | J24: =I24*J25/I25 -> 26848.73 | K24: =J24*K25/J25 -> 27157.053 | L24: =K24*L25/K25 -> 27009.058 | M24: =L24*M25/L25 -> 26861.063 | ... O24: =N24*O25/N25 -> 26565.074
C25: keep proportion | E25: =365*E26 -> 28287.5 | F25: =365*F26 -> 27484.5 | G25: =365*G26 -> 26681.5 | H25: =365*H26 -> 25878.5 | I25: =365*I26 -> 26182.667 | J25: =365*J26 -> 26486.833 | K25: =365*K26 -> 26791 | L25: =365*L26 -> 26645 | ... O25: =365*O26 -> 26207
C26: Mm3/d | E26: 77.5 | F26: 75.3 | G26: 73.1 | H26: 70.9 | I26: 71.733333 | J26: 72.566667 | K26: 73.4 | L26: 73 | M26: 72.6 | N26: 72.2 | O26: 71.8
B27: imp+exp | C27: 1000 m3 | E27: =E21-E24 -> 4146 | F27: =F21-F24 -> 2700.8512 | G27: =G21-G24 -> 1318.4557 | H27: =H21-H24 -> -314.95323 | I27: =I21-I24 -> -2631.3829 | J27: =J21-J24 -> -3818.2523 | K27: =K21-K24 -> -4126.5749 | L27: =L21-L24 -> -3539.3066 | ... O27: =O21-O24 -> 3117.2591
B28: imp | E28: =IF(E27<0,0,$P28*E27) -> 3190.7277 | F28: =IF(F27<0,0,$P28*F27) -> 2078.553 | G28: =IF(G27<0,0,$P28*G27) -> 1014.6727 | H28: =IF(H27<0,0,$P28*H27) -> 0 | I28: =IF(I27<0,0,$P28*I27) -> 0 | J28: =IF(J27<0,0,$P28*J27) -> 0 | K28: =IF(K27<0,0,$P28*K27) -> 0 | L28: =IF(L27<0,0,$P28*L27) -> 0 | ... O28: =IF(O27<0,0,$P28*O27) -> 2399.0172 | P28: =AVERAGE(BEN!D28:M28)/(AVERAGE(BEN!D28:M28)+AVERAGE(BEN!D29:M29)) -> 0.76959183
B29: exp | E29: =IF(E27<0,E27,$P29*E27) -> 955.27226 | F29: =IF(F27<0,F27,$P29*F27) -> 622.29817 | G29: =IF(G27<0,G27,$P29*G27) -> 303.78295 | H29: =IF(H27<0,H27,$P29*H27) -> -314.95323 | I29: =IF(I27<0,I27,$P29*I27) -> -2631.3829 | J29: =IF(J27<0,J27,$P29*J27) -> -3818.2523 | K29: =IF(K27<0,K27,$P29*K27) -> -4126.5749 | L29: =IF(L27<0,L27,$P29*L27) -> -3539.3066 | ... O29: =IF(O27<0,O27,$P29*O27) -> 718.24197 | P29: =AVERAGE(BEN!D29:M29)/(AVERAGE(BEN!D28:M28)+AVERAGE(BEN!D29:M29)) -> 0.23040817
B32: pet diesel | C32: 1000 m3 | E32: =(BEN!M31+BEN!M32+BEN!M33) -> 59900 | F32: =E32*F33/E33 -> 61135.438 | G32: =F32*G33/F33 -> 62370.875 | H32: =G32*H33/G33 -> 63606.313 | I32: =H32*I33/H33 -> 64841.75 | J32: =I32*J33/I33 -> 66077.188 | K32: =J32*K33/J33 -> 67312.625 | L32: =K32*L33/K33 -> 68548.063 | M32: =L32*M33/L33 -> 69783.5 | ... O32: =N32*O33/N33 -> 72254.375
C33: keep proportion | E33: =365*E34 -> 58400 | F33: =365*F34 -> 59604.5 | G33: =365*G34 -> 60809 | H33: =365*H34 -> 62013.5 | I33: =365*I34 -> 63218 | J33: =365*J34 -> 64422.5 | K33: =365*K34 -> 65627 | L33: =365*L34 -> 66831.5 | ... O33: =365*O34 -> 70445 | Q33: Petroleum Products Supply Notes
B34: demand | C34: Mm3/d | E34: 160 | F34: =E34+$P34 -> 163.3 | G34: =F34+$P34 -> 166.6 | H34: =G34+$P34 -> 169.9 | I34: =H34+$P34 -> 173.2 | J34: =I34+$P34 -> 176.5 | K34: =J34+$P34 -> 179.8 | L34: =K34+$P34 -> 183.1 | M34: =L34+$P34 -> 186.4 | N34: =M34+$P34 -> 189.7 | O34: 193 | P34: =(O34-E34)/(O$5-E$5) -> 3.3
B35: production | C35: 1000 m3 | E35: =365*E36 -> 45625 | F35: =365*F36 -> 45369.5 | G35: =365*G36 -> 45114 | H35: =365*H36 -> 44858.5 | I35: =365*I36 -> 46367.167 | J35: =365*J36 -> 47875.833 | K35: =365*K36 -> 49384.5 | L35: =365*L36 -> 49886.375 | ... O35: =365*O36 -> 51392
C36: Mm3/d | E36: 125 | F36: 124.3 | G36: 123.6 | H36: 122.9 | I36: 127.03333 | J36: 131.16667 | K36: 135.3 | L36: 136.675 | M36: 138.05 | N36: 139.425 | O36: 140.8
B37: imp+exp | C37: 1000 m3 | E37: =E32-E35 -> 14275 | F37: =F32-F35 -> 15765.938 | G37: =G32-G35 -> 17256.875 | H37: =H32-H35 -> 18747.813 | I37: =I32-I35 -> 18474.583 | J37: =J32-J35 -> 18201.354 | K37: =K32-K35 -> 17928.125 | L37: =L32-L35 -> 18661.688 | ... O37: =O32-O35 -> 20862.375
E38: =$P38*E37 -> 13297.156 | F38: =$P38*F37 -> 14685.963 | G38: =$P38*G37 -> 16074.771 | H38: =$P38*H37 -> 17463.579 | I38: =$P38*I37 -> 17209.066 | J38: =$P38*J37 -> 16954.553 | K38: =$P38*K37 -> 16700.04 | L38: =$P38*L37 -> 17383.353 | ... O38: =$P38*O37 -> 19433.293 | P38: =AVERAGE(BEN!D32:M32)/AVERAGE(AVERAGE(BEN!D32:M32)+AVERAGE(BEN!D$33:M$33)) -> 0.93149953
E39: =$P39*E37 -> 977.84414 | F39: =$P39*F37 -> 1079.9741 | G39: =$P39*G37 -> 1182.104 | H39: =$P39*H37 -> 1284.2339 | I39: =$P39*I37 -> 1265.5176 | J39: =$P39*J37 -> 1246.8012 | K39: =$P39*K37 -> 1228.0849 | L39: =$P39*L37 -> 1278.3343 | ... O39: =$P39*O37 -> 1429.0824 | P39: =AVERAGE(BEN!D33:M33)/AVERAGE(AVERAGE(BEN!D32:M32)+AVERAGE(BEN!D$33:M$33)) -> 0.068500465
B41: jet fuel | C41: ktoe | D41: =BEN!L43 -> 3392 | E41: =BEN!M43 -> 4032 | F41: =E41*F42/E42 -> 4258.8 | G41: =F41*G42/F42 -> 4485.6 | H41: =G41*H42/G42 -> 4712.4 | I41: =H41*I42/H42 -> 4939.2 | J41: =I41*J42/I42 -> 5166 | K41: =J41*K42/J42 -> 5392.8 | L41: =K41*L42/K42 -> 5619.6 | M41: =L41*M42/L42 -> 5846.4 | ... O41: =N41*O42/N42 -> 6300 | Q41: Petroleum Products Supply Notes
C42: keep proportion | E42: =365*$P$42*E43 -> 4800.48 | F42: =365*$P$42*F43 -> 5070.507 | G42: =365*$P$42*G43 -> 5340.534 | H42: =365*$P$42*H43 -> 5610.561 | I42: =365*$P$42*I43 -> 5880.588 | J42: =365*$P$42*J43 -> 6150.615 | K42: =365*$P$42*K43 -> 6420.642 | L42: =365*$P$42*L43 -> 6690.669 | ... O42: =365*$P$42*O43 -> 7500.75 | P42: 0.822 | Q42: km3/ktoe
B43: demand | C43: Mm3/d | E43: 16 | F43: =$E43+(F5-$E5)*($O43-$E43)/($O5-$E5) -> 16.9 | G43: =$E43+(G5-$E5)*($O43-$E43)/($O5-$E5) -> 17.8 | H43: =$E43+(H5-$E5)*($O43-$E43)/($O5-$E5) -> 18.7 | I43: =$E43+(I5-$E5)*($O43-$E43)/($O5-$E5) -> 19.6 | J43: =$E43+(J5-$E5)*($O43-$E43)/($O5-$E5) -> 20.5 | K43: =$E43+(K5-$E5)*($O43-$E43)/($O5-$E5) -> 21.4 | L43: =$E43+(L5-$E5)*($O43-$E43)/($O5-$E5) -> 22.3 | M43: =$E43+(M5-$E5)*($O43-$E43)/($O5-$E5) -> 23.2 | N43: =$E43+(N5-$E5)*($O43-$E43)/($O5-$E5) -> 24.1 | O43: 25
B44: production | C44: ktoe | D44: =BEN!L43 -> 3392 | E44: =BEN!M43 -> 4032 | F44: =E44*F45/E45 -> 4315.9437 | G44: =F44*G45/F45 -> 4599.8873 | H44: =G44*H45/G45 -> 4883.831 | I44: =H44*I45/H45 -> 5262.4225 | J44: =I44*J45/I45 -> 5451.7183 | K44: =J44*K45/J45 -> 5451.7183 | L44: =K44*L45/K45 -> 5494.3099 | M44: =L44*M45/L45 -> 5536.9014 | ... O44: =N44*O45/N45 -> 5622.0845
C45: keep proportion | E45: =365*$P$42*E46 -> 4260.426 | F45: =365*$P$42*F46 -> 4560.456 | G45: =365*$P$42*G46 -> 4860.486 | H45: =365*$P$42*H46 -> 5160.516 | I45: =365*$P$42*I46 -> 5560.556 | J45: =365*$P$42*J46 -> 5760.576 | K45: =365*$P$42*K46 -> 5760.576 | L45: =365*$P$42*L46 -> 5805.5805 | ... O45: =365*$P$42*O46 -> 5940.594
C46: Mm3/d | E46: 14.2 | F46: =$E46+(F5-$E5)*($H46-$E46)/($H5-$E5) -> 15.2 | G46: =$E46+(G5-$E5)*($H46-$E46)/($H5-$E5) -> 16.2 | H46: 17.2 | I46: =$H46+(J5-$H5)*($K46-$H46)/($K5-$H5) -> 18.533333 | J46: =$H46+(K5-$H5)*($K46-$H46)/($K5-$H5) -> 19.2 | K46: 19.2 | L46: =$K46+(L5-$K5)*($O46-$K46)/($O5-$K5) -> 19.35 | M46: =$K46+(M5-$K5)*($O46-$K46)/($O5-$K5) -> 19.5 | N46: =$K46+(N5-$K5)*($O46-$K46)/($O5-$K5) -> 19.65 | O46: 19.8
...

Sheet PDE Bio
B2: DECENAL ENERGY PLAN 2023-2032
B3: Biofuels Supply Notes
C5: 1000 m3 | D5: 2021 | E5: =1+D5 -> 2022 | F5: =1+E5 -> 2023 | G5: =1+F5 -> 2024 | H5: =1+G5 -> 2025 | I5: =1+H5 -> 2026 | J5: =1+I5 -> 2027 | K5: =1+J5 -> 2028 | L5: =1+K5 -> 2029 | ... O5: =1+N5 -> 2032
B6: Biofuel Gasoline (Ethanol) | C6: production | D6: =BEN!L35 -> 29898 | E6: =BEN!M35 -> 32485 | F6: =F$9*F10 -> 33074.141 | G6: =G$9*G10 -> 34954.928 | H6: =H$9*H10 -> 35771.333 | I6: =I$9*I10 -> 37112.683 | J6: =J$9*J10 -> 39146.632 | K6: =K$9*K10 -> 40227.565 | L6: =L$9*L10 -> 42105.155 | M6: =M$9*M10 -> 43468.681 | ... O6: =O$9*O10 -> 47147
C7: import | D7: =BEN!L36 -> 432 | E7: =BEN!M36 -> 99 | F7: 0 | G7: 0 | H7: 0 | I7: 0 | J7: 0 | K7: 0 | L7: 0 | M7: 0 | N7: 0 | O7: 0
C8: export | D8: =BEN!L37 -> 1868 | E8: =BEN!M37 -> 2358 | F8: =F6-F9 -> -742.74405 | G8: =G6-G9 -> -248.44946 | H8: =H6-H9 -> -875.383 | I8: =I6-I9 -> -1036.5486 | J8: =J6-J9 -> -566.71757 | K8: =K6-K9 -> -1114.0318 | L8: =L6-L9 -> -931.44728 | M8: =M6-M9 -> -1332.422 | ... O8: =O6-O9 -> -1403.1044
C9: total | D9: =BEN!L35 -> 29898 | E9: =BEN!M35 -> 32485 | F9: =E9*(1+$D$10) -> 33816.885 | G9: =F9*(1+$D$10) -> 35203.377 | H9: =G9*(1+$D$10) -> 36646.716 | I9: =H9*(1+$D$10) -> 38149.231 | J9: =I9*(1+$D$10) -> 39713.35 | K9: =J9*(1+$D$10) -> 41341.597 | L9: =K9*(1+$D$10) -> 43036.602 | M9: =L9*(1+$D$10) -> 44801.103 | ... O9: =N9*(1+$D$10) -> 48550.104
D10: =4.1% -> 0.041 | E10: =E6/E$9 -> 1 | F10: =$E10*(F11/$E11) -> 0.9780363 | G10: =$E10*(G11/$E11) -> 0.99294245 | H10: =$E10*(H11/$E11) -> 0.97611292 | I10: =$E10*(I11/$E11) -> 0.97282911 | J10: =$E10*(J11/$E11) -> 0.9857298 | K10: =$E10*(K11/$E11) -> 0.97305301 | L10: =$E10*(L11/$E11) -> 0.97835686 | M10: =$E10*(M11/$E11) -> 0.97025917 | ... O10: =$E10*(O11/$E11) -> 0.97109987
E11: =(E13+E14)/E$12 -> 0.99032258 | F11: =(F13+F14)/F$12 -> 0.96857143 | G11: =(G13+G14)/G$12 -> 0.98333333 | H11: =(H13+H14)/H$12 -> 0.96666667 | I11: =(I13+I14)/I$12 -> 0.96341463 | J11: =(J13+J14)/J$12 -> 0.97619048 | K11: =(K13+K14)/K$12 -> 0.96363636 | L11: =(L13+L14)/L$12 -> 0.96888889 | ... O11: =(O13+O14)/O$12 -> 0.96170213
D12: oferta | E12: 31 | F12: 35 | G12: 36 | H12: 39 | I12: 41 | J12: 42 | K12: 44 | L12: 45 | M12: 46 | N12: 46 | O12: 47
D13: cana | E13: 26.4 | F13: 29 | G13: 30 | H13: 31.2 | I13: 32.2 | J13: 33.1 | K13: 34.1 | L13: 34.9 | M13: 35.2 | N13: 35.6 | O13: 36.1
D14: milho | E14: 4.3 | F14: 4.9 | G14: 5.4 | H14: 6.5 | I14: 7.3 | J14: 7.9 | K14: 8.3 | L14: 8.7 | M14: 9 | N14: 9.1 | O14: 9.1
D15: imp | E15: =E12-(E13+E14) -> 0.3 | F15: =F12-(F13+F14) -> 1.1 | G15: =G12-(G13+G14) -> 0.6 | H15: =H12-(H13+H14) -> 1.3 | I15: =I12-(I13+I14) -> 1.5 | J15: =J12-(J13+J14) -> 1 | K15: =K12-(K13+K14) -> 1.6 | L15: =L12-(L13+L14) -> 1.4 | ... O15: =O12-(O13+O14) -> 1.8
C17: 1000 t | D17: 2021 | E17: =1+D17 -> 2022 | F17: =1+E17 -> 2023 | G17: =1+F17 -> 2024 | H17: =1+G17 -> 2025 | I17: =1+H17 -> 2026 | J17: =1+I17 -> 2027 | K17: =1+J17 -> 2028 | L17: =1+K17 -> 2029 | ... O17: =1+N17 -> 2032
B18: biomass | D18: =BEN!D19 -> 249890 | E18: =BEN!E19 -> 249326 | F18: =F19/$P$19 -> 258651.19 | G18: =G19/$P$19 -> 274209.15 | H18: =H19/$P$19 -> 289767.12 | I18: =I19/$P$19 -> 305325.09 | J18: =J19/$P$19 -> 320883.05 | K18: =K19/$P$19 -> 336441.02 | L18: =L19/$P$19 -> 351998.99 | M18: =M19/$P$19 -> 367556.95 | ... O18: =O19/$P$19 -> 398672.88
B19: bagasse | D19: =BEN!L23 -> 159922 | E19: =BEN!M23 -> 157053 | F19: =E19*F21/E21 -> 167104.39 | G19: =F19*G21/F21 -> 177155.78 | H19: =G19*H21/G21 -> 187207.18 | I19: =H19*I21/H21 -> 197258.57 | J19: =I19*J21/I21 -> 207309.96 | K19: =J19*K21/J21 -> 217361.35 | L19: =K19*L21/K21 -> 227412.74 | M19: =L19*M21/L21 -> 237464.14 | ... O19: =N19*O21/N21 -> 257566.92 | P19: =BEN!C25 -> 0.64606079
C21: 1000 t | E21: =8760*E22/$B$23 -> 153274.42 | F21: =8760*F22/$B$23 -> 163083.98 | G21: =8760*G22/$B$23 -> 172893.55 | H21: =8760*H22/$B$23 -> 182703.11 | I21: =8760*I22/$B$23 -> 192512.67 | J21: =8760*J22/$B$23 -> 202322.23 | K21: =8760*K22/$B$23 -> 212131.8 | L21: =8760*L22/$B$23 -> 221941.36 | ... O21: =8760*O22/$B$23 -> 251370.05
C22: GWmed | E22: 2.5 | F22: =$E22+(F$17-$E$17)*$P$22 -> 2.66 | G22: =$E22+(G$17-$E$17)*$P$22 -> 2.82 | H22: =$E22+(H$17-$E$17)*$P$22 -> 2.98 | I22: =$E22+(I$17-$E$17)*$P$22 -> 3.14 | J22: =$E22+(J$17-$E$17)*$P$22 -> 3.3 | K22: =$E22+(K$17-$E$17)*$P$22 -> 3.46 | L22: =$E22+(L$17-$E$17)*$P$22 -> 3.62 | M22: =$E22+(M$17-$E$17)*$P$22 -> 3.78 | N22: =$E22+(N$17-$E$17)*$P$22 -> 3.94 | O22: 4.1 | P22: =(O22-E22)/(O17-E17) -> 0.16
B23: =B24/B25/1000 -> 0.14288098 | C23: MWh/t bagaço | E23: https://www.epe.gov.br/sites-pt/publicacoes-dados-abertos/publicacoes/PublicacoesArquivos/publicacao-251/topico-311/DEA%20025-17%20-%20%20Indicadores%20de%20Eficiência%20Energética.pdf
B24: 40 | C24: kWh/t cana | E24: https://www.novacana.com/noticias/cogeracao-como-funciona-producao-energia-eletrica
B25: 0.27995328 | C25: t bagaço / t cana | E25: https://www.prp.unicamp.br/inscricao-congresso/resumos/2020P17452A35250O2884.pdf
C28: 1000 m3 | D28: 2021 | E28: =1+D28 -> 2022 | F28: =1+E28 -> 2023 | G28: =1+F28 -> 2024 | H28: =1+G28 -> 2025 | I28: =1+H28 -> 2026 | J28: =1+I28 -> 2027 | K28: =1+J28 -> 2028 | L28: =1+K28 -> 2029 | ... O28: =1+N28 -> 2032
B29: biodiesel | D29: =BEN!L39 -> 6766 | E29: =BEN!M39 -> 6766 | F29: =F30*F31 -> 7336.2525 | G29: =G30*G31 -> 8731.9225 | H29: =H30*H31 -> 9540.9469 | I29: =I30*I31 -> 10374.68 | J29: =J30*J31 -> 11233.122 | K29: =K30*K31 -> 12116.273 | L29: =L30*L31 -> 13024.132 | M29: =M30*M31 -> 13956.7 | ... O29: =O30*O31 -> 14450.875
C30: pet diesel | D30: =BEN!L31+BEN!L32+BEN!L33 -> 57880 | E30: =BEN!M31+BEN!M32+BEN!M33 -> 59900 | F30: ='PDE-O&G'!F32 -> 61135.438 | G30: ='PDE-O&G'!G32 -> 62370.875 | H30: ='PDE-O&G'!H32 -> 63606.313 | I30: ='PDE-O&G'!I32 -> 64841.75 | J30: ='PDE-O&G'!J32 -> 66077.188 | K30: ='PDE-O&G'!K32 -> 67312.625 | L30: ='PDE-O&G'!L32 -> 68548.063 | M30: ='PDE-O&G'!M32 -> 69783.5 | ... O30: ='PDE-O&G'!O32 -> 72254.375
C31: ratio | D31: =D29/D30 -> 0.11689703 | E31: =E29/E30 -> 0.11295492 | F31: 0.12 | G31: 0.14 | H31: 0.15 | I31: =$H31+(I28-$H28)*($M$31-$H$31)/($M$28-$H$28) -> 0.16 | J31: =$H31+(J28-$H28)*($M$31-$H$31)/($M$28-$H$28) -> 0.17 | K31: =$H31+(K28-$H28)*($M$31-$H$31)/($M$28-$H$28) -> 0.18 | L31: =$H31+(L28-$H28)*($M$31-$H$31)/($M$28-$H$28) -> 0.19 | M31: 0.2 | N31: =$M31 -> 0.2 | O31: =$M31 -> 0.2
E32: https://g1.globo.com/politica/noticia/2024/03/13/camara-aprova-texto-base-de-projeto-que-estabelece-mistura-de-ate-25percent-de-biodiesel-no-diesel-entenda.ghtml

Sheet BEN
A1: BRAZILIAN ENERGY BALANCE 2023 | year 2022 (BEN - BALANÇO ENERGÉTICO NACIONAL)
D3: 2013 | E3: 2014 | F3: 2015 | G3: 2016 | H3: 2017 | I3: 2018 | J3: 2019 | K3: 2020 | L3: 2021 | M3: 2022 | N3: =1+M3 -> 2023 | O3: =1+N3 -> 2024 | P3: =1+O3 -> 2025 | Q3: =1+P3 -> 2026 | R3: =1+Q3 -> 2027 | S3: =1+R3 -> 2028 | T3: =1+S3 -> 2029 | U3: =1+T3 -> 2030 | ... W3: =1+V3 -> 2032
A4: Table 2.5 Hard coal | B4: 1000 t | C4: PRODUÇÃO | D4: 0 | E4: 0 | F4: 0 | G4: 0 | H4: 0 | I4: 0 | J4: 0 | K4: 0 | L4: 0 | M4: 0 | N4: 0 | O4: 0 | P4: 0 | Q4: 0 | R4: 0 | S4: 0 | T4: 0 | U4: 0 | V4: 0 | W4: 0
A5: =29.37*1000000/1000 -> 29370 | C5: IMPORTAÇÃO | D5: 10592 | E5: 10960 | F5: 10304 | G5: 10698 | H5: 11595 | I5: 11088 | J5: 10184 | K5: 9209 | L5: 10667 | M5: 10007 | N5: =AVERAGE(D5:M5) -> 10530.4 | O5: =$N5 -> 10530.4 | P5: =$N5 -> 10530.4 | Q5: =$N5 -> 10530.4 | R5: =$N5 -> 10530.4 | S5: =$N5 -> 10530.4 | T5: =$N5 -> 10530.4 | U5: =$N5 -> 10530.4 | V5: =$N5 -> 10530.4 | W5: =$N5 -> 10530.4
A6: BTU/1000 t | C6: EXPORTAÇÃO | D6: 0 | E6: 0 | F6: 0 | G6: 0 | H6: 0 | I6: 0 | J6: 0 | K6: 0 | L6: 0 | M6: 0 | N6: 0 | O6: 0 | P6: 0 | Q6: 0 | R6: 0 | S6: 0 | T6: 0 | U6: 0 | V6: 0 | W6: 0
A8: Table 2.3 Natural Gas | B8: 10^6 m3 | C8: PRODUÇÃO | D8: =D12+D11 -> 22523 | E8: =E12+E11 -> 23911 | F8: =F12+F11 -> 24103 | G8: =G12+G11 -> 25307 | H8: =H12+H11 -> 28128 | I8: =I12+I11 -> 26454 | J8: =J12+J11 -> 26935 | K8: =K12+K11 -> 24936 | ... M8: =M12+M11 -> 24314 | N8: ='PDE-O&G'!F16 -> 26280 | O8: ='PDE-O&G'!G16 -> 27375 | P8: ='PDE-O&G'!H16 -> 27740 | Q8: ='PDE-O&G'!I16 -> 28470 | R8: ='PDE-O&G'!J16 -> 34675 | S8: ='PDE-O&G'!K16 -> 40150 | T8: ='PDE-O&G'!L16 -> 42340 | U8: ='PDE-O&G'!M16 -> 44165 | ... W8: ='PDE-O&G'!O16 -> 48910
A9: =39.4*1000000/1000000 -> 39.4 | C9: IMPORTAÇÃO | D9: 16962 | E9: 19319 | F9: 18407 | G9: 11727 | H9: 10720 | I9: 10596 | J9: 9805 | K9: 9611 | L9: 16856 | M9: 8775 | N9: ='PDE-O&G'!F18 -> 22630 | O9: ='PDE-O&G'!G18 -> 27375 | P9: ='PDE-O&G'!H18 -> 26645 | Q9: ='PDE-O&G'!I18 -> 26280 | R9: ='PDE-O&G'!J18 -> 23725 | S9: ='PDE-O&G'!K18 -> 21900 | T9: ='PDE-O&G'!L18 -> 19710 | U9: ='PDE-O&G'!M18 -> 18980 | ... W9: ='PDE-O&G'!O18 -> 17520
A10: BTU/10^6 m3 | C10: EXPORTAÇÃO | D10: 0 | E10: 0 | F10: 0 | G10: 0 | H10: 0 | I10: 0 | J10: 0 | K10: 0 | L10: 0 | M10: 0 | N10: 0 | O10: 0 | P10: 0 | Q10: 0 | R10: 0 | S10: 0 | T10: 0 | U10: 0 | V10: 0 | W10: 0
C11: PRODUÇÃO BRUTA | D11: 28174 | E11: 31894 | F11: 35128 | G11: 37887 | H11: 40103 | I11: 40858 | J11: 44724 | K11: 46639 | L11: 48819 | M11: 50338
C12: não-aproveitada e reinjeção | D12: -5651 | E12: -7983 | F12: -11025 | G12: -12580 | H12: -11975 | I12: -14404 | J12: -17789 | K12: -21703 | L12: -23440 | M12: -26024
A14: Tabel 2.10 Nuclear | B14: t | C14: PRODUÇÃO | D14: 234.2 | E14: 67.2 | F14: 50.5 | G14: 0 | H14: 0 | I14: 0 | J14: 0 | K14: 20.3 | L14: 33.8 | M14: 50.9 | N14: =M14 -> 50.9 | O14: =$N14 -> 50.9 | P14: =$N14 -> 50.9 | Q14: =$N14 -> 50.9 | R14: =$N14 -> 50.9 | S14: =$N14 -> 50.9 | T14: =$N14 -> 50.9 | U14: =$N14 -> 50.9 | V14: =$N14 -> 50.9 | W14: =$N14 -> 50.9
A15: =137985.406215726 -> 137985.41 | B15: manter 2022 | C15: IMPORTAÇÃO | D15: 59.3 | E15: 284.4 | F15: 213 | G15: 411.6 | H15: 513.5 | I15: 504.6 | J15: 303.1 | K15: 463.4 | L15: 465.8 | M15: 311.6 | N15: =M15 -> 311.6 | O15: =$N15 -> 311.6 | P15: =$N15 -> 311.6 | Q15: =$N15 -> 311.6 | R15: =$N15 -> 311.6 | S15: =$N15 -> 311.6 | T15: =$N15 -> 311.6 | U15: =$N15 -> 311.6 | V15: =$N15 -> 311.6 | W15: =$N15 -> 311.6
A16: BTU/t | C16: EXPORTAÇÃO | D16: 0 | E16: 0 | F16: 0 | G16: 0 | H16: 0 | I16: 0 | J16: 0 | K16: 0 | L16: 0 | M16: 0 | N16: 0 | O16: 0 | P16: 0 | Q16: 0 | R16: 0 | S16: 0 | T16: 0 | U16: 0 | V16: 0 | W16: 0
C17: GWh | D17: 15450 | E17: 15378 | F17: 14734 | G17: 15864 | H17: 15739 | I17: 15674 | J17: 16129 | K17: 14053 | L17: 14705 | M17: 14559
A19: biomass total | B19: 1000 t | C19: PRODUÇÃO | D19: =SUM(D22:D24) -> 249890 | E19: =SUM(E22:E24) -> 249326 | F19: =SUM(F22:F24) -> 250149 | G19: =SUM(G22:G24) -> 251168 | H19: =SUM(H22:H24) -> 252605 | I19: =SUM(I22:I24) -> 249228 | J19: =SUM(J22:J24) -> 254208 | K19: =SUM(K22:K24) -> 273754 | ... W19: =SUM(W22:W24) -> 257566.92
A20: =8.45*1000000/1000 -> 8450 | C20: IMPORTAÇÃO | D20: 0 | E20: 0 | F20: 0 | G20: 0 | H20: 0 | I20: 0 | J20: 0 | K20: 0 | L20: 0 | M20: 0 | N20: 0 | O20: 0 | P20: 0 | Q20: 0 | R20: 0 | S20: 0 | T20: 0 | U20: 0 | V20: 0 | W20: 0
A21: BTU/1000 t | C21: EXPORTAÇÃO | D21: 0 | E21: 0 | F21: 0 | G21: 0 | H21: 0 | I21: 0 | J21: 0 | K21: 0 | L21: 0 | M21: 0 | N21: 0 | O21: 0 | P21: 0 | Q21: 0 | R21: 0 | S21: 0 | T21: 0 | U21: 0 | V21: 0 | W21: 0
A22: firewood | C22: PRODUÇÃO | D22: 79960 | E22: 81364 | F22: 80887 | G22: 75813 | H22: 80205 | I22: 84676 | J22: 85197 | K22: 85344 | L22: 88409 | M22: 88011
A23: bagasse | C23: PRODUÇÃO | D23: 163142 | E23: 161174 | F23: 162474 | G23: 168567 | H23: 165612 | I23: 157764 | J23: 162223 | K23: 181622 | L23: 159922 | M23: 157053 | N23: ='PDE Bio'!F19 -> 167104.39 | O23: ='PDE Bio'!G19 -> 177155.78 | P23: ='PDE Bio'!H19 -> 187207.18 | Q23: ='PDE Bio'!I19 -> 197258.57 | R23: ='PDE Bio'!J19 -> 207309.96 | S23: ='PDE Bio'!K19 -> 217361.35 | T23: ='PDE Bio'!L19 -> 227412.74 | U23: ='PDE Bio'!M19 -> 237464.14 | ... W23: ='PDE Bio'!O19 -> 257566.92
A24: charcoal | C24: PRODUÇÃO | D24: 6788 | E24: 6788 | F24: 6788 | G24: 6788 | H24: 6788 | I24: 6788 | J24: 6788 | K24: 6788 | L24: 6788 | M24: 6788
A25: Table 2.11 Firewood + Table 2.14 Bagasse + Table 2.31 Charcoal | C25: =AVERAGE(D23/D19,E23/E19,F23/F19,G23/G19,H23/H19,I23/I19,J23/J19,K23/K19,L23/L19,M23/M19) -> 0.64606079 | D25: bagasse/biomass total
A27: Table 2.23 Pet Gasoline | B27: 1000 m3 | C27: PRODUÇÃO | D27: 28514 | E27: 30972 | F27: 27946 | G27: 28187 | H27: 28338 | I27: 26011 | J27: 25395 | K27: 23547 | L27: 28100 | M27: 28674 | N27: ='PDE-O&G'!F24 -> 27860.028 | O27: ='PDE-O&G'!G24 -> 27046.057 | P27: ='PDE-O&G'!H24 -> 26232.085 | Q27: ='PDE-O&G'!I24 -> 26540.408 | R27: ='PDE-O&G'!J24 -> 26848.73 | S27: ='PDE-O&G'!K24 -> 27157.053 | T27: ='PDE-O&G'!L24 -> 27009.058 | U27: ='PDE-O&G'!M24 -> 26861.063 | ... W27: ='PDE-O&G'!O24 -> 26565.074
A28: =30.556*1000000/1000 -> 30556 | C28: IMPORTAÇÃO | D28: 2265 | E28: 2111 | F28: 2935 | G28: 3810 | H28: 4489 | I28: 3238 | J28: 4888 | K28: 4942 | L28: 2755 | M28: 4146 | N28: ='PDE-O&G'!F28 -> 2078.553 | O28: ='PDE-O&G'!G28 -> 1014.6727 | P28: ='PDE-O&G'!H28 -> 0 | Q28: ='PDE-O&G'!I28 -> 0 | R28: ='PDE-O&G'!J28 -> 0 | S28: ='PDE-O&G'!K28 -> 0 | T28: ='PDE-O&G'!L28 -> 0 | U28: ='PDE-O&G'!M28 -> 0 | ... W28: ='PDE-O&G'!O28 -> 2399.0172
A29: BTU/1000 m3 | C29: EXPORTAÇÃO | D29: 347 | E29: 365 | F29: 616 | G29: 728 | H29: 478 | I29: 1394 | J29: 2014 | K29: 2369 | L29: 1795 | M29: 546 | N29: 0 | O29: 0 | P29: 0 | Q29: 0 | R29: 0 | S29: 0 | T29: 0 | U29: 0 | V29: 0 | W29: 0
A31: Table 2.20 Pet Diesel | B31: 1000 m3 | C31: PRODUÇÃO | D31: 49201 | E31: 49350 | F31: 49154 | G31: 44805 | H31: 39993 | I31: 41278 | J31: 40679 | K31: 41549 | L31: 42853 | M31: 44870 | N31: ='PDE-O&G'!F35 -> 45369.5 | O31: ='PDE-O&G'!G35 -> 45114 | P31: ='PDE-O&G'!H35 -> 44858.5 | Q31: ='PDE-O&G'!I35 -> 46367.167 | R31: ='PDE-O&G'!J35 -> 47875.833 | S31: ='PDE-O&G'!K35 -> 49384.5 | T31: ='PDE-O&G'!L35 -> 49886.375 | U31: ='PDE-O&G'!M35 -> 50388.25 | ... W31: ='PDE-O&G'!O35 -> 51392
A32: =33651100/1000 -> 33651.1 | C32: IMPORTAÇÃO | D32: 10024 | E32: 11275 | F32: 6940 | G32: 8469 | H32: 12955 | I32: 11650 | J32: 13008 | K32: 11995 | L32: 14437 | M32: 14385 | N32: ='PDE-O&G'!F38 -> 14685.963 | O32: ='PDE-O&G'!G38 -> 16074.771 | P32: ='PDE-O&G'!H38 -> 17463.579 | Q32: ='PDE-O&G'!I38 -> 17209.066 | R32: ='PDE-O&G'!J38 -> 16954.553 | S32: ='PDE-O&G'!K38 -> 16700.04 | T32: ='PDE-O&G'!L38 -> 17383.353 | U32: ='PDE-O&G'!M38 -> 18066.666 | ... W32: ='PDE-O&G'!O38 -> 19433.293
A33: BTU/1000 m3 | C33: EXPORTAÇÃO | D33: 1030 | E33: 936 | F33: 768 | G33: 832 | H33: 687 | I33: 1429 | J33: 600 | K33: 950 | L33: 590 | M33: 645 | N33: 0 | O33: 0 | P33: 0 | Q33: 0 | R33: 0 | S33: 0 | T33: 0 | U33: 0 | V33: 0 | W33: 0
A35: Table 3.32 Biofuel Gasoline (Ethanol) | B35: 1000 m3 | C35: PRODUÇÃO | D35: 27608 | E35: 28526 | F35: 30249 | G35: 28276 | H35: 27694 | I35: 33198 | J35: 35156 | K35: 32599 | L35: 29898 | M35: 32485 | N35: ='PDE Bio'!F6 -> 33074.141 | O35: ='PDE Bio'!G6 -> 34954.928 | P35: ='PDE Bio'!H6 -> 35771.333 | Q35: ='PDE Bio'!I6 -> 37112.683 | R35: ='PDE Bio'!J6 -> 39146.632 | S35: ='PDE Bio'!K6 -> 40227.565 | T35: ='PDE Bio'!L6 -> 42105.155 | U35: ='PDE Bio'!M6 -> 43468.681 | ... W35: ='PDE Bio'!O6 -> 47147
A36: =21552100/1000 -> 21552.1 | C36: IMPORTAÇÃO | D36: 132 | E36: 984 | F36: 828 | G36: 835 | H36: 1826 | I36: 1775 | J36: 1437 | K36: 958 | L36: 432 | M36: 99 | N36: ='PDE Bio'!F7 -> 0 | O36: ='PDE Bio'!G7 -> 0 | P36: ='PDE Bio'!H7 -> 0 | Q36: ='PDE Bio'!I7 -> 0 | R36: ='PDE Bio'!J7 -> 0 | S36: ='PDE Bio'!K7 -> 0 | T36: ='PDE Bio'!L7 -> 0 | U36: ='PDE Bio'!M7 -> 0 | ... W36: ='PDE Bio'!O7 -> 0
A37: BTU/1000 m3 | C37: EXPORTAÇÃO | D37: 2940 | E37: 1469 | F37: 2121 | G37: 1789 | H37: 1380 | I37: 1682 | J37: 1933 | K37: 2026 | L37: 1868 | M37: 2358 | N37: -33816.885 | O37: -35203.377 | P37: -36646.716 | Q37: -38149.231 | R37: -39713.35 | S37: -41341.597 | T37: -43036.602 | U37: -44801.103 | V37: -46637.948 | W37: -48550.104
A39: Table 2.21 Biodiesel | B39: 1000 m3 | C39: PRODUÇÃO | D39: 2917 | E39: 3420 | F39: 3937 | G39: 3801 | H39: 4291 | I39: 5350 | J39: 5924 | K39: 6432 | L39: 6766 | M39: 6766 | N39: ='PDE Bio'!F29 -> 7336.2525 | O39: ='PDE Bio'!G29 -> 8731.9225 | P39: ='PDE Bio'!H29 -> 9540.9469 | Q39: ='PDE Bio'!I29 -> 10374.68 | R39: ='PDE Bio'!J29 -> 11233.122 | S39: ='PDE Bio'!K29 -> 12116.273 | T39: ='PDE Bio'!L29 -> 13024.132 | U39: ='PDE Bio'!M29 -> 13956.7 | ... W39: ='PDE Bio'!O29 -> 14450.875
A40: =29252892.5581395/1000 -> 29252.893 | C40: IMPORTAÇÃO | D40: 0 | E40: 0 | F40: 0 | G40: 0 | H40: 0 | I40: 0 | J40: 0 | K40: 0 | L40: 0 | M40: 0 | N40: 0 | O40: 0 | P40: 0 | Q40: 0 | R40: 0 | S40: 0 | T40: 0 | U40: 0 | V40: 0 | W40: 0
A41: BTU/1000 m3 | C41: EXPORTAÇÃO | D41: 0 | E41: 0 | F41: 0 | G41: 0 | H41: 0 | I41: 0 | J41: 0 | K41: 0 | L41: 0 | M41: 0 | N41: 0 | O41: 0 | P41: 0 | Q41: 0 | R41: 0 | S41: 0 | T41: 0 | U41: 0 | V41: 0 | W41: 0
A43: Table 5.1 Refineries | B43: 1000 toe | C43: PRODUÇÃO | D43: =4566+71 -> 4637 | E43: =4997+72 -> 5069 | F43: =4650+55 -> 4705 | G43: =4759+41 -> 4800 | H43: =5071+46 -> 5117 | I43: =5241+35 -> 5276 | J43: =4987+0 -> 4987 | K43: =2740+2 -> 2742 | L43: =3349+43 -> 3392 | M43: =3990+42 -> 4032 | N43: ='PDE-O&G'!F44 -> 4315.9437 | O43: ='PDE-O&G'!G44 -> 4599.8873 | P43: ='PDE-O&G'!H44 -> 4883.831 | Q43: ='PDE-O&G'!I44 -> 5262.4225 | R43: ='PDE-O&G'!J44 -> 5451.7183 | S43: ='PDE-O&G'!K44 -> 5451.7183 | T43: ='PDE-O&G'!L44 -> 5494.3099 | U43: ='PDE-O&G'!M44 -> 5536.9014 | ... W43: ='PDE-O&G'!O44 -> 5622.0845
A44: Jet Fuel - calulated Imports | B44: =32.619/'PDE-O&G'!P42*1000000/1000 -> 39682.482 | C44: IMPORTAÇÃO | D44: =D46+D45-D43 -> 1424 | E44: =E46+E45-E43 -> 1159 | F44: =F46+F45-F43 -> 1398 | G44: =G46+G45-G43 -> 833 | H44: =H46+H45-H43 -> 557 | I44: =I46+I45-I43 -> 947 | J44: =J46+J45-J43 -> 790 | K44: =K46+K45-K43 -> 317 | ... M44: =M46+M45-M43 -> 841 | N44: ='PDE-O&G'!F47 -> 152.62472 | O44: ='PDE-O&G'!G47 -> 305.24945 | P44: ='PDE-O&G'!H47 -> 457.87417 | Q44: ='PDE-O&G'!I47 -> 863.29347 | R44: ='PDE-O&G'!J47 -> 763.12362 | S44: ='PDE-O&G'!K47 -> 157.36462 | T44: ='PDE-O&G'!L47 -> 125.29014 | U44: ='PDE-O&G'!M47 -> 309.49859 | ... W44: ='PDE-O&G'!O47 -> 677.91549
A45: Table 4.4 Exports | B45: MBTU/1000 toe | C45: EXPORTAÇÃO | D45: =2383+11 -> 2394 | E45: =2506+13 -> 2519 | F45: =2440+5 -> 2445 | G45: =2281+5 -> 2286 | H45: =2334+5 -> 2339 | I45: =2796+3 -> 2799 | J45: =2429+0 -> 2429 | K45: =1135+0 -> 1135 | L45: =1089+0 -> 1089 | M45: =1772+0 -> 1772 | N45: ='PDE-O&G'!F48 -> 95.481062 | O45: ='PDE-O&G'!G48 -> 190.96212 | P45: ='PDE-O&G'!H48 -> 286.44319 | Q45: ='PDE-O&G'!I48 -> 540.07093 | R45: ='PDE-O&G'!J48 -> 477.40531 | S45: ='PDE-O&G'!K48 -> 98.446312 | T45: ='PDE-O&G'!L48 -> 0 | U45: ='PDE-O&G'!M48 -> 0 | ... W45: ='PDE-O&G'!O48 -> 0
A46: Table 3.6.3.a Consumption | C46: CONSUMO | D46: 3667 | E46: 3709 | F46: 3658 | G46: 3347 | H46: 3335 | I46: 3424 | J46: 3348 | K46: 1924 | L46: 2552 | M46: 3101 | N46: ='PDE-O&G'!F42 -> 5070.507 | O46: ='PDE-O&G'!G42 -> 5340.534 | P46: ='PDE-O&G'!H42 -> 5610.561 | Q46: ='PDE-O&G'!I42 -> 5880.588 | R46: ='PDE-O&G'!J42 -> 6150.615 | S46: ='PDE-O&G'!K42 -> 6420.642 | T46: ='PDE-O&G'!L42 -> 6690.669 | U46: ='PDE-O&G'!M42 -> 6960.696 | ... W46: ='PDE-O&G'!O42 -> 7500.75
A49: Table 2.4 Lignite | B49: 1000 t | C49: PRODUÇÃO | D49: 8594 | E49: 7936 | F49: 6354 | G49: 7006 | H49: 4819 | I49: 4838 | J49: 5410 | K49: 5481 | L49: 6665 | M49: 6122 | N49: =AVERAGE(H49:M49) -> 5555.8333 | O49: =$N49 -> 5555.8333 | P49: =$N49 -> 5555.8333 | Q49: =$N49 -> 5555.8333 | R49: =$N49 -> 5555.8333 | S49: =$N49 -> 5555.8333 | T49: =$N49 -> 5555.8333 | U49: =$N49 -> 5555.8333 | V49: =$N49 -> 5555.8333 | W49: =$N49 -> 5555.8333
A50: =23.86*1000000/1000 -> 23860 | C50: IMPORTAÇÃO | D50: 7449 | E50: 9391 | F50: 9968 | G50: 8805 | H50: 9611 | I50: 9898 | J50: 8675 | K50: 6857 | L50: 9445 | M50: 5735 | N50: =AVERAGE(H50:M50) -> 8370.1667 | O50: =$N50 -> 8370.1667 | P50: =$N50 -> 8370.1667 | Q50: =$N50 -> 8370.1667 | R50: =$N50 -> 8370.1667 | S50: =$N50 -> 8370.1667 | T50: =$N50 -> 8370.1667 | U50: =$N50 -> 8370.1667 | V50: =$N50 -> 8370.1667 | W50: =$N50 -> 8370.1667
A51: BTU/1000 t | B51: manter média (2017-22) | C51: EXPORTAÇÃO | D51: 0 | E51: 0 | F51: 0 | G51: 0 | H51: 0 | I51: 0 | J51: 0 | K51: 0 | L51: 0 | M51: 0 | N51: 0 | O51: 0 | P51: 0 | Q51: 0 | R51: 0 | S51: 0 | T51: 0 | U51: 0 | V51: 0 | W51: 0
...

Sheet BFPIaE-production-f
A1: Fuel (BTU) | B1: 2019 | C1: 2020 | D1: 2021 | E1: 2022 | F1: 2023 | G1: 2024 | H1: 2025 | I1: 2026 | J1: 2027 | K1: 2028 | L1: 2029 | M1: 2030 | N1: 2031 | O1: 2032 | P1: 2033 | Q1: 2034 | R1: 2035 | S1: 2036 | T1: 2037 | U1: 2038 | V1: 2039 | W1: 2040 | X1: 2041 | Y1: 2042 | Z1: 2043 | AA1: 2044 | AB1: 2045 | AC1: 2046 | AD1: 2047 | AE1: 2048 | AF1: 2049 | AG1: 2050
A2: electricity (not used in this variable) | B2: 0 | C2: 0 | D2: 0 | E2: 0 | F2: 0 | G2: 0 | H2: 0 | I2: 0 | J2: 0 | K2: 0 | L2: 0 | M2: 0 | N2: 0 | O2: 0 | P2: =AVERAGE(B2:O2) -> 0 | Q2: =AVERAGE(C2:P2) -> 0 | R2: =AVERAGE(D2:Q2) -> 0 | S2: =AVERAGE(E2:R2) -> 0 | T2: =AVERAGE(F2:S2) -> 0 | U2: =AVERAGE(G2:T2) -> 0 | V2: =AVERAGE(H2:U2) -> 0 | W2: =AVERAGE(I2:V2) -> 0 | ... AG2: =AVERAGE(S2:AF2) -> 0
A3: hard coal | B3: =BEN!$A$5*BEN!J4 -> 0 | C3: =BEN!$A$5*BEN!K4 -> 0 | D3: =BEN!$A$5*BEN!L4 -> 0 | E3: =BEN!$A$5*BEN!M4 -> 0 | F3: =BEN!$A$5*BEN!N4 -> 0 | G3: =BEN!$A$5*BEN!O4 -> 0 | H3: =BEN!$A$5*BEN!P4 -> 0 | I3: =BEN!$A$5*BEN!Q4 -> 0 | ... O3: =BEN!$A$5*BEN!W4 -> 0 | P3: =AVERAGE(B3:O3) -> 0 | Q3: =AVERAGE(C3:P3) -> 0 | R3: =AVERAGE(D3:Q3) -> 0 | S3: =AVERAGE(E3:R3) -> 0 | T3: =AVERAGE(F3:S3) -> 0 | U3: =AVERAGE(G3:T3) -> 0 | V3: =AVERAGE(H3:U3) -> 0 | W3: =AVERAGE(I3:V3) -> 0 | ... AG3: =AVERAGE(S3:AF3) -> 0
A4: natural gas | B4: =BEN!$A$9*BEN!J8 -> 1061239 | C4: =BEN!$A$9*BEN!K8 -> 982478.4 | D4: =BEN!$A$9*BEN!L8 -> 999932.6 | E4: =BEN!$A$9*BEN!M8 -> 957971.6 | F4: =BEN!$A$9*BEN!N8 -> 1035432 | G4: =BEN!$A$9*BEN!O8 -> 1078575 | H4: =BEN!$A$9*BEN!P8 -> 1092956 | I4: =BEN!$A$9*BEN!Q8 -> 1121718 | ... O4: =BEN!$A$9*BEN!W8 -> 1927054 | P4: =AVERAGE(B4:O4) -> 1319207.7 | Q4: =AVERAGE(C4:P4) -> 1337634 | R4: =AVERAGE(D4:Q4) -> 1363002.3 | S4: =AVERAGE(E4:R4) -> 1388935.8 | T4: =AVERAGE(F4:S4) -> 1419719 | U4: =AVERAGE(G4:T4) -> 1447168.1 | V4: =AVERAGE(H4:U4) -> 1473496.1 | W4: =AVERAGE(I4:V4) -> 1500677.6 | ... AG4: =AVERAGE(S4:AF4) -> 1482439
A5: nuclear | B5: =BEN!$A$15*BEN!J14 -> 0 | C5: =BEN!$A$15*BEN!K14 -> 2801103.7 | D5: =BEN!$A$15*BEN!L14 -> 4663906.7 | E5: =BEN!$A$15*BEN!M14 -> 7023457.2 | F5: =BEN!$A$15*BEN!N14 -> 7023457.2 | G5: =BEN!$A$15*BEN!O14 -> 7023457.2 | H5: =BEN!$A$15*BEN!P14 -> 7023457.2 | I5: =BEN!$A$15*BEN!Q14 -> 7023457.2 | ... O5: =BEN!$A$15*BEN!W14 -> 7023457.2 | P5: =AVERAGE(B5:O5) -> 6051645.7 | Q5: =AVERAGE(C5:P5) -> 6483906.1 | R5: =AVERAGE(D5:Q5) -> 6746963.4 | S5: =AVERAGE(E5:R5) -> 6895753.1 | T5: =AVERAGE(F5:S5) -> 6886631.4 | U5: =AVERAGE(G5:T5) -> 6876858.2 | V5: =AVERAGE(H5:U5) -> 6866386.8 | W5: =AVERAGE(I5:V5) -> 6855167.5 | ... AG5: =AVERAGE(S5:AF5) -> 6828686.8
A6: hydro (is not a fuel) | B6: 0 | C6: 0 | D6: 0 | E6: 0 | F6: 0 | G6: 0 | H6: 0 | I6: 0 | J6: 0 | K6: 0 | L6: 0 | M6: 0 | N6: 0 | O6: 0 | P6: =AVERAGE(B6:O6) -> 0 | Q6: =AVERAGE(C6:P6) -> 0 | R6: =AVERAGE(D6:Q6) -> 0 | S6: =AVERAGE(E6:R6) -> 0 | T6: =AVERAGE(F6:S6) -> 0 | U6: =AVERAGE(G6:T6) -> 0 | V6: =AVERAGE(H6:U6) -> 0 | W6: =AVERAGE(I6:V6) -> 0 | ... AG6: =AVERAGE(S6:AF6) -> 0
A7: wind (is not a fuel) | B7: 0 | C7: 0 | D7: 0 | E7: 0 | F7: 0 | G7: 0 | H7: 0 | I7: 0 | J7: 0 | K7: 0 | L7: 0 | M7: 0 | N7: 0 | O7: 0 | P7: =AVERAGE(B7:O7) -> 0 | Q7: =AVERAGE(C7:P7) -> 0 | R7: =AVERAGE(D7:Q7) -> 0 | S7: =AVERAGE(E7:R7) -> 0 | T7: =AVERAGE(F7:S7) -> 0 | U7: =AVERAGE(G7:T7) -> 0 | V7: =AVERAGE(H7:U7) -> 0 | W7: =AVERAGE(I7:V7) -> 0 | ... AG7: =AVERAGE(S7:AF7) -> 0
A8: solar (is not a fuel) | B8: 0 | C8: 0 | D8: 0 | E8: 0 | F8: 0 | G8: 0 | H8: 0 | I8: 0 | J8: 0 | K8: 0 | L8: 0 | M8: 0 | N8: 0 | O8: 0 | P8: =AVERAGE(B8:O8) -> 0 | Q8: =AVERAGE(C8:P8) -> 0 | R8: =AVERAGE(D8:Q8) -> 0 | S8: =AVERAGE(E8:R8) -> 0 | T8: =AVERAGE(F8:S8) -> 0 | U8: =AVERAGE(G8:T8) -> 0 | V8: =AVERAGE(H8:U8) -> 0 | W8: =AVERAGE(I8:V8) -> 0 | ... AG8: =AVERAGE(S8:AF8) -> 0
A9: biomass | B9: =BEN!$A$20*BEN!J19 -> 2148057600 | C9: =BEN!$A$20*BEN!K19 -> 2313221300 | D9: =BEN!$A$20*BEN!L19 -> 2155755550 | E9: =BEN!$A$20*BEN!M19 -> 2128149400 | F9: =BEN!$A$20*BEN!N19 -> 1.4120321e+09 | G9: =BEN!$A$20*BEN!O19 -> 1.4969664e+09 | H9: =BEN!$A$20*BEN!P19 -> 1.5819006e+09 | I9: =BEN!$A$20*BEN!Q19 -> 1.6668349e+09 | ... O9: =BEN!$A$20*BEN!W19 -> 2176440474 | P9: =AVERAGE(B9:O9) -> 1.9062533e+09 | Q9: =AVERAGE(C9:P9) -> 1.8889816e+09 | R9: =AVERAGE(D9:Q9) -> 1.8586788e+09 | S9: =AVERAGE(E9:R9) -> 1.837459e+09 | T9: =AVERAGE(F9:S9) -> 1.8166954e+09 | U9: =AVERAGE(G9:T9) -> 1.8455999e+09 | V9: =AVERAGE(H9:U9) -> 1.8705023e+09 | W9: =AVERAGE(I9:V9) -> 1.8911167e+09 | ... AG9: =AVERAGE(S9:AF9) -> 1.8868778e+09
A10: petroleum gasoline | B10: =BEN!$A$28*BEN!J27 -> 775969620 | C10: =BEN!$A$28*BEN!K27 -> 719502132 | D10: =BEN!$A$28*BEN!L27 -> 858623600 | E10: =BEN!$A$28*BEN!M27 -> 876162744 | F10: =BEN!$A$28*BEN!N27 -> 8.5129103e+08 | G10: =BEN!$A$28*BEN!O27 -> 8.2641931e+08 | H10: =BEN!$A$28*BEN!P27 -> 8.0154759e+08 | I10: =BEN!$A$28*BEN!Q27 -> 8.109687e+08 | ... O10: =BEN!$A$28*BEN!W27 -> 8.1172239e+08 | P10: =AVERAGE(B10:O10) -> 8.1747913e+08 | Q10: =AVERAGE(C10:P10) -> 8.2044409e+08 | R10: =AVERAGE(D10:Q10) -> 8.2765423e+08 | S10: =AVERAGE(E10:R10) -> 8.2544213e+08 | T10: =AVERAGE(F10:S10) -> 8.2181923e+08 | U10: =AVERAGE(G10:T10) -> 8.197141e+08 | V10: =AVERAGE(H10:U10) -> 8.1923516e+08 | W10: =AVERAGE(I10:V10) -> 8.2049856e+08 | ... AG10: =AVERAGE(S10:AF10) -> 8.2106791e+08
A11: petroleum diesel | B11: =BEN!$A$32*BEN!J31 -> 1.3688931e+09 | C11: =BEN!$A$32*BEN!K31 -> 1.3981696e+09 | D11: =BEN!$A$32*BEN!L31 -> 1.4420506e+09 | E11: =BEN!$A$32*BEN!M31 -> 1509924857 | F11: =BEN!$A$32*BEN!N31 -> 1.5267336e+09 | G11: =BEN!$A$32*BEN!O31 -> 1.5181357e+09 | H11: =BEN!$A$32*BEN!P31 -> 1.5095379e+09 | I11: =BEN!$A$32*BEN!Q31 -> 1.5603062e+09 | ... O11: =BEN!$A$32*BEN!W31 -> 1.7293973e+09 | P11: =AVERAGE(B11:O11) -> 1.5659233e+09 | Q11: =AVERAGE(C11:P11) -> 1.5799969e+09 | R11: =AVERAGE(D11:Q11) -> 1.5929845e+09 | S11: =AVERAGE(E11:R11) -> 1.6037655e+09 | T11: =AVERAGE(F11:S11) -> 1.6104684e+09 | U11: =AVERAGE(G11:T11) -> 1.6164495e+09 | V11: =AVERAGE(H11:U11) -> 1.6234719e+09 | W11: =AVERAGE(I11:V11) -> 1.6316101e+09 | ... AG11: =AVERAGE(S11:AF11) -> 1.6244756e+09
A12: biofuel gasoline | B12: =BEN!$A$36*BEN!J35 -> 7.5768563e+08 | C12: =BEN!$A$36*BEN!K35 -> 7.0257691e+08 | D12: =BEN!$A$36*BEN!L35 -> 6.4436469e+08 | E12: =BEN!$A$36*BEN!M35 -> 7.0011997e+08 | F12: =BEN!$A$36*BEN!N35 -> 7.1281719e+08 | G12: =BEN!$A$36*BEN!O35 -> 7.533521e+08 | H12: =BEN!$A$36*BEN!P35 -> 7.7094734e+08 | I12: =BEN!$A$36*BEN!Q35 -> 7.9985624e+08 | ... O12: =BEN!$A$36*BEN!W35 -> 1.0161169e+09 | P12: =AVERAGE(B12:O12) -> 8.1422125e+08 | Q12: =AVERAGE(C12:P12) -> 8.1825951e+08 | R12: =AVERAGE(D12:Q12) -> 8.2652256e+08 | S12: =AVERAGE(E12:R12) -> 8.3953383e+08 | T12: =AVERAGE(F12:S12) -> 8.4949197e+08 | U12: =AVERAGE(G12:T12) -> 8.5925445e+08 | V12: =AVERAGE(H12:U12) -> 8.668189e+08 | W12: =AVERAGE(I12:V12) -> 8.7366687e+08 | ... AG12: =AVERAGE(S12:AF12) -> 8.6731254e+08
A13: biofuel diesel | B13: =BEN!$A$40*BEN!J39 -> 1.7329414e+08 | C13: =BEN!$A$40*BEN!K39 -> 1.881546e+08 | D13: =BEN!$A$40*BEN!L39 -> 1.9792507e+08 | E13: =BEN!$A$40*BEN!M39 -> 1.9792507e+08 | F13: =BEN!$A$40*BEN!N39 -> 2.1460661e+08 | G13: =BEN!$A$40*BEN!O39 -> 2.5543399e+08 | H13: =BEN!$A$40*BEN!P39 -> 2.7910029e+08 | I13: =BEN!$A$40*BEN!Q39 -> 3.034894e+08 | ... O13: =BEN!$A$40*BEN!W39 -> 4.2272989e+08 | P13: =AVERAGE(B13:O13) -> 2.9431897e+08 | Q13: =AVERAGE(C13:P13) -> 3.0296361e+08 | R13: =AVERAGE(D13:Q13) -> 3.1116425e+08 | S13: =AVERAGE(E13:R13) -> 3.1925276e+08 | T13: =AVERAGE(F13:S13) -> 3.2791902e+08 | U13: =AVERAGE(G13:T13) -> 3.3601277e+08 | V13: =AVERAGE(H13:U13) -> 3.417684e+08 | W13: =AVERAGE(I13:V13) -> 3.4624469e+08 | ... AG13: =AVERAGE(S13:AF13) -> 3.399938e+08
A14: jet fuel or kerosene | B14: =BEN!$B$44*BEN!J43 -> 1.9789654e+08 | C14: =BEN!$B$44*BEN!K43 -> 1.0880936e+08 | D14: =BEN!$B$44*BEN!L43 -> 1.3460298e+08 | E14: =BEN!$B$44*BEN!M43 -> 1.5999977e+08 | F14: =BEN!$B$44*BEN!N43 -> 1.7126736e+08 | G14: =BEN!$B$44*BEN!O43 -> 1.8253494e+08 | H14: =BEN!$B$44*BEN!P43 -> 1.9380253e+08 | I14: =BEN!$B$44*BEN!Q43 -> 2.0882599e+08 | ... O14: =BEN!$B$44*BEN!W43 -> 2.2309827e+08 | P14: =AVERAGE(B14:O14) -> 1.9090479e+08 | Q14: =AVERAGE(C14:P14) -> 1.9040538e+08 | R14: =AVERAGE(D14:Q14) -> 1.9623367e+08 | S14: =AVERAGE(E14:R14) -> 2.0063586e+08 | T14: =AVERAGE(F14:S14) -> 2.0353844e+08 | U14: =AVERAGE(G14:T14) -> 2.0584352e+08 | V14: =AVERAGE(H14:U14) -> 2.0750842e+08 | W14: =AVERAGE(I14:V14) -> 2.0848741e+08 | ... AG14: =AVERAGE(S14:AF14) -> 2.0559719e+08
A15: heat (not used in this variable) | B15: 0 | C15: 0 | D15: 0 | E15: 0 | F15: 0 | G15: 0 | H15: 0 | I15: 0 | J15: 0 | K15: 0 | L15: 0 | M15: 0 | N15: 0 | O15: 0 | P15: =AVERAGE(B15:O15) -> 0 | Q15: =AVERAGE(C15:P15) -> 0 | R15: =AVERAGE(D15:Q15) -> 0 | S15: =AVERAGE(E15:R15) -> 0 | T15: =AVERAGE(F15:S15) -> 0 | U15: =AVERAGE(G15:T15) -> 0 | V15: =AVERAGE(H15:U15) -> 0 | W15: =AVERAGE(I15:V15) -> 0 | ... AG15: =AVERAGE(S15:AF15) -> 0
A16: geothermal (is not a fuel) | B16: 0 | C16: 0 | D16: 0 | E16: 0 | F16: 0 | G16: 0 | H16: 0 | I16: 0 | J16: 0 | K16: 0 | L16: 0 | M16: 0 | N16: 0 | O16: 0 | P16: =AVERAGE(B16:O16) -> 0 | Q16: =AVERAGE(C16:P16) -> 0 | R16: =AVERAGE(D16:Q16) -> 0 | S16: =AVERAGE(E16:R16) -> 0 | T16: =AVERAGE(F16:S16) -> 0 | U16: =AVERAGE(G16:T16) -> 0 | V16: =AVERAGE(H16:U16) -> 0 | W16: =AVERAGE(I16:V16) -> 0 | ... AG16: =AVERAGE(S16:AF16) -> 0
A17: lignite | B17: =BEN!$A$50*BEN!J49 -> 129082600 | C17: =BEN!$A$50*BEN!K49 -> 130776660 | D17: =BEN!$A$50*BEN!L49 -> 159026900 | E17: =BEN!$A$50*BEN!M49 -> 146070920 | F17: =BEN!$A$50*BEN!N49 -> 1.3256218e+08 | G17: =BEN!$A$50*BEN!O49 -> 1.3256218e+08 | H17: =BEN!$A$50*BEN!P49 -> 1.3256218e+08 | I17: =BEN!$A$50*BEN!Q49 -> 1.3256218e+08 | ... O17: =BEN!$A$50*BEN!W49 -> 1.3256218e+08 | P17: =AVERAGE(B17:O17) -> 1.3504135e+08 | Q17: =AVERAGE(C17:P17) -> 1.3546698e+08 | R17: =AVERAGE(D17:Q17) -> 1.35802e+08 | S17: =AVERAGE(E17:R17) -> 1.3414308e+08 | T17: =AVERAGE(F17:S17) -> 1.3329109e+08 | U17: =AVERAGE(G17:T17) -> 1.3334315e+08 | V17: =AVERAGE(H17:U17) -> 1.3339894e+08 | W17: =AVERAGE(I17:V17) -> 1.334587e+08 | ... AG17: =AVERAGE(S17:AF17) -> 1.3369246e+08
A18: crude oil | B18: =BEN!$A$54*BEN!J53 -> 5719962008 | C18: =BEN!$A$54*BEN!K53 -> 6050220626 | D18: =BEN!$A$54*BEN!L53 -> 5961113312 | E18: =BEN!$A$54*BEN!M53 -> 6199403858 | F18: =BEN!$A$54*BEN!N53 -> 6.8193442e+09 | G18: =BEN!$A$54*BEN!O53 -> 7.8525782e+09 | H18: =BEN!$A$54*BEN!P53 -> 8.4725186e+09 | I18: =BEN!$A$54*BEN!Q53 -> 9.2991058e+09 | ... O18: =BEN!$A$54*BEN!W53 -> 1.0125693e+10 | P18: =AVERAGE(B18:O18) -> 8.5434404e+09 | Q18: =AVERAGE(C18:P18) -> 8.7451175e+09 | R18: =AVERAGE(D18:Q18) -> 8.9376101e+09 | S18: =AVERAGE(E18:R18) -> 9.150217e+09 | T18: =AVERAGE(F18:S18) -> 9.3609894e+09 | U18: =AVERAGE(G18:T18) -> 9.5425355e+09 | V18: =AVERAGE(H18:U18) -> 9.6632467e+09 | W18: =AVERAGE(I18:V18) -> 9.7482987e+09 | ... AG18: =AVERAGE(S18:AF18) -> 9.5534985e+09
A19: heavy fuel oil | B19: =BEN!$A$58*BEN!J57 -> 464686572 | C19: =BEN!$A$58*BEN!K57 -> 665243109 | D19: =BEN!$A$58*BEN!L57 -> 653925963 | E19: =BEN!$A$58*BEN!M57 -> 700447788 | F19: =BEN!$A$58*BEN!N57 -> 6.9169409e+08 | G19: =BEN!$A$58*BEN!O57 -> 6.9908695e+08 | H19: =BEN!$A$58*BEN!P57 -> 7.064798e+08 | I19: =BEN!$A$58*BEN!Q57 -> 7.1387266e+08 | ... O19: =BEN!$A$58*BEN!W57 -> 6.1337602e+08 | P19: =AVERAGE(B19:O19) -> 6.6211136e+08 | Q19: =AVERAGE(C19:P19) -> 6.7621313e+08 | R19: =AVERAGE(D19:Q19) -> 6.7699671e+08 | S19: =AVERAGE(E19:R19) -> 6.7864462e+08 | T19: =AVERAGE(F19:S19) -> 6.7708725e+08 | U19: =AVERAGE(G19:T19) -> 6.760439e+08 | V19: =AVERAGE(H19:U19) -> 6.7439797e+08 | W19: =AVERAGE(I19:V19) -> 6.7210641e+08 | ... AG19: =AVERAGE(S19:AF19) -> 6.7060315e+08
A20: LPG propane or butane | B20: =BEN!$A$62*BEN!J61 -> 249379420 | C20: =BEN!$A$62*BEN!K61 -> 253574540 | D20: =BEN!$A$62*BEN!L61 -> 245823800 | E20: =BEN!$A$62*BEN!M61 -> 256439500 | F20: =BEN!$A$62*BEN!N61 -> 283835680 | G20: =BEN!$A$62*BEN!O61 -> 3.0904477e+08 | H20: =BEN!$A$62*BEN!P61 -> 3.3425386e+08 | I20: =BEN!$A$62*BEN!Q61 -> 3.401671e+08 | ... O20: =BEN!$A$62*BEN!W61 -> 400544430 | P20: =AVERAGE(B20:O20) -> 3.2142458e+08 | Q20: =AVERAGE(C20:P20) -> 3.2657066e+08 | R20: =AVERAGE(D20:Q20) -> 3.3178467e+08 | S20: =AVERAGE(E20:R20) -> 3.3792473e+08 | T20: =AVERAGE(F20:S20) -> 3.437451e+08 | U20: =AVERAGE(G20:T20) -> 3.4802435e+08 | V20: =AVERAGE(H20:U20) -> 3.508086e+08 | W20: =AVERAGE(I20:V20) -> 3.5199108e+08 | ... AG20: =AVERAGE(S20:AF20) -> 3.4873686e+08
A21: municipal solid waste | B21: =BEN!J65 -> 0 | C21: =BEN!K65 -> 0 | D21: =BEN!L65 -> 0 | E21: =BEN!M65 -> 0 | F21: =BEN!N65 -> 0 | G21: =BEN!O65 -> 0 | H21: =BEN!P65 -> 0 | I21: =BEN!Q65 -> 0 | ... O21: =BEN!W65 -> 0 | P21: =AVERAGE(B21:O21) -> 0 | Q21: =AVERAGE(C21:P21) -> 0 | R21: =AVERAGE(D21:Q21) -> 0 | S21: =AVERAGE(E21:R21) -> 0 | T21: =AVERAGE(F21:S21) -> 0 | U21: =AVERAGE(G21:T21) -> 0 | V21: =AVERAGE(H21:U21) -> 0 | W21: =AVERAGE(I21:V21) -> 0 | ... AG21: =AVERAGE(S21:AF21) -> 0
A22: hydrogen | B22: =BEN!J66 -> 0 | C22: =BEN!K66 -> 0 | D22: =BEN!L66 -> 0 | E22: =BEN!M66 -> 0 | F22: =BEN!N66 -> 0 | G22: =BEN!O66 -> 0 | H22: =BEN!P66 -> 0 | I22: =BEN!Q66 -> 0 | ... O22: =BEN!W66 -> 0 | P22: =AVERAGE(B22:O22) -> 0 | Q22: =AVERAGE(C22:P22) -> 0 | R22: =AVERAGE(D22:Q22) -> 0 | S22: =AVERAGE(E22:R22) -> 0 | T22: =AVERAGE(F22:S22) -> 0 | U22: =AVERAGE(G22:T22) -> 0 | V22: =AVERAGE(H22:U22) -> 0 | W22: =AVERAGE(I22:V22) -> 0 | ... AG22: =AVERAGE(S22:AF22) -> 0

Sheet BFPIaE-imports-f
A1: Fuel (BTU) | B1: 2019 | C1: 2020 | D1: 2021 | E1: 2022 | F1: 2023 | G1: 2024 | H1: 2025 | I1: 2026 | J1: 2027 | K1: 2028 | L1: 2029 | M1: 2030 | N1: 2031 | O1: 2032 | P1: 2033 | Q1: 2034 | R1: 2035 | S1: 2036 | T1: 2037 | U1: 2038 | V1: 2039 | W1: 2040 | X1: 2041 | Y1: 2042 | Z1: 2043 | AA1: 2044 | AB1: 2045 | AC1: 2046 | AD1: 2047 | AE1: 2048 | AF1: 2049 | AG1: 2050
A2: electricity (not used in this variable) | B2: 0 | C2: 0 | D2: 0 | E2: 0 | F2: 0 | G2: 0 | H2: 0 | I2: 0 | J2: 0 | K2: 0 | L2: 0 | M2: 0 | N2: 0 | O2: 0 | P2: =AVERAGE(B2:N2) -> 0 | Q2: =AVERAGE(C2:O2) -> 0 | R2: =AVERAGE(D2:P2) -> 0 | S2: =AVERAGE(E2:Q2) -> 0 | T2: =AVERAGE(F2:R2) -> 0 | U2: =AVERAGE(G2:S2) -> 0 | V2: =AVERAGE(H2:T2) -> 0 | W2: =AVERAGE(I2:U2) -> 0 | ... AG2: =AVERAGE(S2:AE2) -> 0
A3: hard coal | B3: =BEN!$A$5*BEN!J5 -> 299104080 | C3: =BEN!$A$5*BEN!K5 -> 270468330 | D3: =BEN!$A$5*BEN!L5 -> 313289790 | E3: =BEN!$A$5*BEN!M5 -> 293905590 | F3: =BEN!$A$5*BEN!N5 -> 309277848 | G3: =BEN!$A$5*BEN!O5 -> 309277848 | H3: =BEN!$A$5*BEN!P5 -> 309277848 | I3: =BEN!$A$5*BEN!Q5 -> 309277848 | ... O3: =BEN!$A$5*BEN!W5 -> 309277848 | P3: =AVERAGE(B3:N3) -> 3.0463603e+08 | Q3: =AVERAGE(C3:O3) -> 305418630 | R3: =AVERAGE(D3:P3) -> 3.0804691e+08 | S3: =AVERAGE(E3:Q3) -> 3.0744144e+08 | T3: =AVERAGE(F3:R3) -> 3.0852924e+08 | U3: =AVERAGE(G3:S3) -> 3.0838797e+08 | V3: =AVERAGE(H3:T3) -> 3.0833039e+08 | W3: =AVERAGE(I3:U3) -> 3.0826194e+08 | ... AG3: =AVERAGE(S3:AE3) -> 3.0802219e+08
A4: natural gas | B4: =BEN!$A$9*BEN!J9 -> 386317 | C4: =BEN!$A$9*BEN!K9 -> 378673.4 | D4: =BEN!$A$9*BEN!L9 -> 664126.4 | E4: =BEN!$A$9*BEN!M9 -> 345735 | F4: =BEN!$A$9*BEN!N9 -> 891622 | G4: =BEN!$A$9*BEN!O9 -> 1078575 | H4: =BEN!$A$9*BEN!P9 -> 1049813 | I4: =BEN!$A$9*BEN!Q9 -> 1035432 | ... O4: =BEN!$A$9*BEN!W9 -> 690288 | P4: =AVERAGE(B4:N4) -> 758228.75 | Q4: =AVERAGE(C4:O4) -> 781611.14 | R4: =AVERAGE(D4:P4) -> 810807.7 | S4: =AVERAGE(E4:Q4) -> 819844.99 | T4: =AVERAGE(F4:R4) -> 855619.82 | U4: =AVERAGE(G4:S4) -> 850098.51 | V4: =AVERAGE(H4:T4) -> 832948.11 | W4: =AVERAGE(I4:U4) -> 817585.45 | ... AG4: =AVERAGE(S4:AE4) -> 812175.01
A5: nuclear | B5: =BEN!$A$15*BEN!J15 -> 41823377 | C5: =BEN!$A$15*BEN!K15 -> 63942437 | D5: =BEN!$A$15*BEN!L15 -> 64273602 | E5: =BEN!$A$15*BEN!M15 -> 42996253 | F5: =BEN!$A$15*BEN!N15 -> 42996253 | G5: =BEN!$A$15*BEN!O15 -> 42996253 | H5: =BEN!$A$15*BEN!P15 -> 42996253 | I5: =BEN!$A$15*BEN!Q15 -> 42996253 | ... O5: =BEN!$A$15*BEN!W15 -> 42996253 | P5: =AVERAGE(B5:N5) -> 46153996 | Q5: =AVERAGE(C5:O5) -> 46244217 | R5: =AVERAGE(D5:P5) -> 44875875 | S5: =AVERAGE(E5:Q5) -> 43488999 | T5: =AVERAGE(F5:R5) -> 43633586 | U5: =AVERAGE(G5:S5) -> 43671489 | V5: =AVERAGE(H5:T5) -> 43720515 | W5: =AVERAGE(I5:U5) -> 43772456 | ... AG5: =AVERAGE(S5:AE5) -> 43892624
A6: hydro (is not a fuel) | B6: 0 | C6: 0 | D6: 0 | E6: 0 | F6: 0 | G6: 0 | H6: 0 | I6: 0 | J6: 0 | K6: 0 | L6: 0 | M6: 0 | N6: 0 | O6: 0 | P6: =AVERAGE(B6:N6) -> 0 | Q6: =AVERAGE(C6:O6) -> 0 | R6: =AVERAGE(D6:P6) -> 0 | S6: =AVERAGE(E6:Q6) -> 0 | T6: =AVERAGE(F6:R6) -> 0 | U6: =AVERAGE(G6:S6) -> 0 | V6: =AVERAGE(H6:T6) -> 0 | W6: =AVERAGE(I6:U6) -> 0 | ... AG6: =AVERAGE(S6:AE6) -> 0
A7: wind (is not a fuel) | B7: 0 | C7: 0 | D7: 0 | E7: 0 | F7: 0 | G7: 0 | H7: 0 | I7: 0 | J7: 0 | K7: 0 | L7: 0 | M7: 0 | N7: 0 | O7: 0 | P7: =AVERAGE(B7:N7) -> 0 | Q7: =AVERAGE(C7:O7) -> 0 | R7: =AVERAGE(D7:P7) -> 0 | S7: =AVERAGE(E7:Q7) -> 0 | T7: =AVERAGE(F7:R7) -> 0 | U7: =AVERAGE(G7:S7) -> 0 | V7: =AVERAGE(H7:T7) -> 0 | W7: =AVERAGE(I7:U7) -> 0 | ... AG7: =AVERAGE(S7:AE7) -> 0
A8: solar (is not a fuel) | B8: 0 | C8: 0 | D8: 0 | E8: 0 | F8: 0 | G8: 0 | H8: 0 | I8: 0 | J8: 0 | K8: 0 | L8: 0 | M8: 0 | N8: 0 | O8: 0 | P8: =AVERAGE(B8:N8) -> 0 | Q8: =AVERAGE(C8:O8) -> 0 | R8: =AVERAGE(D8:P8) -> 0 | S8: =AVERAGE(E8:Q8) -> 0 | T8: =AVERAGE(F8:R8) -> 0 | U8: =AVERAGE(G8:S8) -> 0 | V8: =AVERAGE(H8:T8) -> 0 | W8: =AVERAGE(I8:U8) -> 0 | ... AG8: =AVERAGE(S8:AE8) -> 0
A9: biomass | B9: =BEN!$A$20*BEN!J20 -> 0 | C9: =BEN!$A$20*BEN!K20 -> 0 | D9: =BEN!$A$20*BEN!L20 -> 0 | E9: =BEN!$A$20*BEN!M20 -> 0 | F9: =BEN!$A$20*BEN!N20 -> 0 | G9: =BEN!$A$20*BEN!O20 -> 0 | H9: =BEN!$A$20*BEN!P20 -> 0 | I9: =BEN!$A$20*BEN!Q20 -> 0 | ... O9: =BEN!$A$20*BEN!W20 -> 0 | P9: =AVERAGE(B9:N9) -> 0 | Q9: =AVERAGE(C9:O9) -> 0 | R9: =AVERAGE(D9:P9) -> 0 | S9: =AVERAGE(E9:Q9) -> 0 | T9: =AVERAGE(F9:R9) -> 0 | U9: =AVERAGE(G9:S9) -> 0 | V9: =AVERAGE(H9:T9) -> 0 | W9: =AVERAGE(I9:U9) -> 0 | ... AG9: =AVERAGE(S9:AE9) -> 0
A10: petroleum gasoline | B10: =BEN!$A$28*BEN!J28 -> 149357728 | C10: =BEN!$A$28*BEN!K28 -> 151007752 | D10: =BEN!$A$28*BEN!L28 -> 84181780 | E10: =BEN!$A$28*BEN!M28 -> 126685176 | F10: =BEN!$A$28*BEN!N28 -> 63512265 | G10: =BEN!$A$28*BEN!O28 -> 31004339 | H10: =BEN!$A$28*BEN!P28 -> 0 | I10: =BEN!$A$28*BEN!Q28 -> 0 | ... O10: =BEN!$A$28*BEN!W28 -> 73304369 | P10: =AVERAGE(B10:N10) -> 47994171 | Q10: =AVERAGE(C10:O10) -> 42143912 | R10: =AVERAGE(D10:P10) -> 34219791 | S10: =AVERAGE(E10:Q10) -> 30986109 | T10: =AVERAGE(F10:R10) -> 23873387 | U10: =AVERAGE(G10:S10) -> 21371375 | V10: =AVERAGE(H10:T10) -> 20822840 | W10: =AVERAGE(I10:U10) -> 22466792 | ... AG10: =AVERAGE(S10:AE10) -> 26828873
A11: petroleum diesel | B11: =BEN!$A$32*BEN!J32 -> 4.3773351e+08 | C11: =BEN!$A$32*BEN!K32 -> 4.0364494e+08 | D11: =BEN!$A$32*BEN!L32 -> 4.8582093e+08 | E11: =BEN!$A$32*BEN!M32 -> 4.8407107e+08 | F11: =BEN!$A$32*BEN!N32 -> 4.9419882e+08 | G11: =BEN!$A$32*BEN!O32 -> 5.4093373e+08 | H11: =BEN!$A$32*BEN!P32 -> 5.8766863e+08 | I11: =BEN!$A$32*BEN!Q32 -> 5.7910399e+08 | ... O11: =BEN!$A$32*BEN!W32 -> 6.5395167e+08 | P11: =AVERAGE(B11:N11) -> 5.3612148e+08 | Q11: =AVERAGE(C11:O11) -> 5.5275365e+08 | R11: =AVERAGE(D11:P11) -> 5.6294415e+08 | S11: =AVERAGE(E11:Q11) -> 5.6809282e+08 | T11: =AVERAGE(F11:R11) -> 5.7415998e+08 | U11: =AVERAGE(G11:S11) -> 5.7984414e+08 | V11: =AVERAGE(H11:T11) -> 5.824e+08 | W11: =AVERAGE(I11:U11) -> 5.8179812e+08 | ... AG11: =AVERAGE(S11:AE11) -> 5.7934993e+08
A12: biofuel gasoline | B12: =BEN!$A$36*BEN!J36 -> 30970368 | C12: =BEN!$A$36*BEN!K36 -> 20646912 | D12: =BEN!$A$36*BEN!L36 -> 9310507.2 | E12: =BEN!$A$36*BEN!M36 -> 2133657.9 | F12: =BEN!$A$36*BEN!N36 -> 0 | G12: =BEN!$A$36*BEN!O36 -> 0 | H12: =BEN!$A$36*BEN!P36 -> 0 | I12: =BEN!$A$36*BEN!Q36 -> 0 | ... O12: =BEN!$A$36*BEN!W36 -> 0 | P12: =AVERAGE(B12:N12) -> 4850880.4 | Q12: =AVERAGE(C12:O12) -> 2468544.4 | R12: =AVERAGE(D12:P12) -> 1253465 | S12: =AVERAGE(E12:Q12) -> 727160.2 | T12: =AVERAGE(F12:R12) -> 659453.06 | U12: =AVERAGE(G12:S12) -> 715388.46 | V12: =AVERAGE(H12:T12) -> 766115.62 | W12: =AVERAGE(I12:U12) -> 821145.5 | ... AG12: =AVERAGE(S12:AE12) -> 954104.61
A13: biofuel diesel | B13: =BEN!$A$40*BEN!J40 -> 0 | C13: =BEN!$A$40*BEN!K40 -> 0 | D13: =BEN!$A$40*BEN!L40 -> 0 | E13: =BEN!$A$40*BEN!M40 -> 0 | F13: =BEN!$A$40*BEN!N40 -> 0 | G13: =BEN!$A$40*BEN!O40 -> 0 | H13: =BEN!$A$40*BEN!P40 -> 0 | I13: =BEN!$A$40*BEN!Q40 -> 0 | ... O13: =BEN!$A$40*BEN!W40 -> 0 | P13: =AVERAGE(B13:N13) -> 0 | Q13: =AVERAGE(C13:O13) -> 0 | R13: =AVERAGE(D13:P13) -> 0 | S13: =AVERAGE(E13:Q13) -> 0 | T13: =AVERAGE(F13:R13) -> 0 | U13: =AVERAGE(G13:S13) -> 0 | V13: =AVERAGE(H13:T13) -> 0 | W13: =AVERAGE(I13:U13) -> 0 | ... AG13: =AVERAGE(S13:AE13) -> 0
A14: jet fuel or kerosene | B14: =BEN!$B$44*BEN!J44 -> 31349161 | C14: =BEN!$B$44*BEN!K44 -> 12579347 | D14: =BEN!$B$44*BEN!L44 -> 9880938 | E14: =BEN!$B$44*BEN!M44 -> 33372967 | F14: =BEN!$B$44*BEN!N44 -> 6056527.8 | G14: =BEN!$B$44*BEN!O44 -> 12113056 | H14: =BEN!$B$44*BEN!P44 -> 18169583 | I14: =BEN!$B$44*BEN!Q44 -> 34257627 | ... O14: =BEN!$B$44*BEN!W44 -> 26901369 | P14: =AVERAGE(B14:N14) -> 17780883 | Q14: =AVERAGE(C14:O14) -> 17438745 | R14: =AVERAGE(D14:P14) -> 17838864 | S14: =AVERAGE(E14:Q14) -> 18420233 | T14: =AVERAGE(F14:R14) -> 17225302 | U14: =AVERAGE(G14:S14) -> 18176357 | V14: =AVERAGE(H14:T14) -> 18569606 | W14: =AVERAGE(I14:U14) -> 18570127 | ... AG14: =AVERAGE(S14:AE14) -> 17932062
A15: heat (not used in this variable) | B15: 0 | C15: 0 | D15: 0 | E15: 0 | F15: 0 | G15: 0 | H15: 0 | I15: 0 | J15: 0 | K15: 0 | L15: 0 | M15: 0 | N15: 0 | O15: 0 | P15: =AVERAGE(B15:N15) -> 0 | Q15: =AVERAGE(C15:O15) -> 0 | R15: =AVERAGE(D15:P15) -> 0 | S15: =AVERAGE(E15:Q15) -> 0 | T15: =AVERAGE(F15:R15) -> 0 | U15: =AVERAGE(G15:S15) -> 0 | V15: =AVERAGE(H15:T15) -> 0 | W15: =AVERAGE(I15:U15) -> 0 | ... AG15: =AVERAGE(S15:AE15) -> 0
A16: geothermal (is not a fuel) | B16: 0 | C16: 0 | D16: 0 | E16: 0 | F16: 0 | G16: 0 | H16: 0 | I16: 0 | J16: 0 | K16: 0 | L16: 0 | M16: 0 | N16: 0 | O16: 0 | P16: =AVERAGE(B16:N16) -> 0 | Q16: =AVERAGE(C16:O16) -> 0 | R16: =AVERAGE(D16:P16) -> 0 | S16: =AVERAGE(E16:Q16) -> 0 | T16: =AVERAGE(F16:R16) -> 0 | U16: =AVERAGE(G16:S16) -> 0 | V16: =AVERAGE(H16:T16) -> 0 | W16: =AVERAGE(I16:U16) -> 0 | ... AG16: =AVERAGE(S16:AE16) -> 0
A17: lignite | B17: =BEN!$A$50*BEN!J50 -> 206985500 | C17: =BEN!$A$50*BEN!K50 -> 163608020 | D17: =BEN!$A$50*BEN!L50 -> 225357700 | E17: =BEN!$A$50*BEN!M50 -> 136837100 | F17: =BEN!$A$50*BEN!N50 -> 1.9971218e+08 | G17: =BEN!$A$50*BEN!O50 -> 1.9971218e+08 | H17: =BEN!$A$50*BEN!P50 -> 1.9971218e+08 | I17: =BEN!$A$50*BEN!Q50 -> 1.9971218e+08 | ... O17: =BEN!$A$50*BEN!W50 -> 1.9971218e+08 | P17: =AVERAGE(B17:N17) -> 1.9463061e+08 | Q17: =AVERAGE(C17:O17) -> 1.9407112e+08 | R17: =AVERAGE(D17:P17) -> 1.9645748e+08 | S17: =AVERAGE(E17:Q17) -> 1.9405082e+08 | T17: =AVERAGE(F17:R17) -> 1.98637e+08 | U17: =AVERAGE(G17:S17) -> 1.9820151e+08 | V17: =AVERAGE(H17:T17) -> 1.981188e+08 | W17: =AVERAGE(I17:U17) -> 1.980026e+08 | ... AG17: =AVERAGE(S17:AE17) -> 1.9739855e+08
A18: crude oil | B18: =BEN!$A$54*BEN!J54 -> 352191096 | C18: =BEN!$A$54*BEN!K54 -> 344244546 | D18: =BEN!$A$54*BEN!L54 -> 287276612 | E18: =BEN!$A$54*BEN!M54 -> 504341040 | F18: =BEN!$A$54*BEN!N54 -> 4.5970909e+08 | G18: =BEN!$A$54*BEN!O54 -> 4.1507714e+08 | H18: =BEN!$A$54*BEN!P54 -> 3.7044519e+08 | I18: =BEN!$A$54*BEN!Q54 -> 3.6449426e+08 | ... O18: =BEN!$A$54*BEN!W54 -> 3.7044519e+08 | P18: =AVERAGE(B18:N18) -> 3.7642085e+08 | Q18: =AVERAGE(C18:O18) -> 3.7782502e+08 | R18: =AVERAGE(D18:P18) -> 3.8030012e+08 | S18: =AVERAGE(E18:Q18) -> 3.8726538e+08 | T18: =AVERAGE(F18:R18) -> 3.7772377e+08 | U18: =AVERAGE(G18:S18) -> 3.7215118e+08 | V18: =AVERAGE(H18:T18) -> 3.6927784e+08 | W18: =AVERAGE(I18:U18) -> 3.6940907e+08 | ... AG18: =AVERAGE(S18:AE18) -> 3.7370849e+08
A19: heavy fuel oil | B19: =BEN!$A$58*BEN!J58 -> 2126712 | C19: =BEN!$A$58*BEN!K58 -> 1481103 | D19: =BEN!$A$58*BEN!L58 -> 23621694 | E19: =BEN!$A$58*BEN!M58 -> 8013147 | F19: =BEN!$A$58*BEN!N58 -> 0 | G19: =BEN!$A$58*BEN!O58 -> 0 | H19: =BEN!$A$58*BEN!P58 -> 0 | I19: =BEN!$A$58*BEN!Q58 -> 0 | ... O19: =BEN!$A$58*BEN!W58 -> 0 | P19: =AVERAGE(B19:N19) -> 2710973.5 | Q19: =AVERAGE(C19:O19) -> 2547380.3 | R19: =AVERAGE(D19:P19) -> 2641985.7 | S19: =AVERAGE(E19:Q19) -> 1020884.7 | T19: =AVERAGE(F19:R19) -> 607718.43 | U19: =AVERAGE(G19:S19) -> 686248.02 | V19: =AVERAGE(H19:T19) -> 732995.59 | W19: =AVERAGE(I19:U19) -> 785783.9 | ... AG19: =AVERAGE(S19:AE19) -> 947762.25
