Workbook

Sheet About
A1: BDCSoCaESoPbIC BAU Domestic Content Share of Consumption and Export Share of Production by ISIC Code
A3: Source: | B3: Most Industries
B4: OECD
B5: 2018
B6: Input-Output Tables 2018 Edition (ISIC Rev. 4)
B7: https://stats.oecd.org/Index.aspx?DataSetCode=IOTSI4_2018
B8: Variables: TTL and ICESHR
B10: ISIC Code Splits
B11: see variable io-model/DLIM
B12: ISIC codes are assigned to each SCN code in io-model/DLIM.
B13: This variables uses both the 128x27 IBGE "Recursos " and "Usos" tables (from the source specified in DLIM)
B14: National Account System (SCN) version 2010
B15: https://ftp.ibge.gov.br/Contas_Nacionais/Matriz_de_Insumo_Produto/2015/Matriz_de_Insumo_Produto_2015_Nivel_67.xls
A17: Notes
A18: This variable is used to determine the share of a policy-driven increase in the domestic need
A19: for a type of economic output that is satisfied by increased domestic production rather
A20: than by increased imports.
A22: This variable contains the share of the domestic consumption of goods/services
A23: within each ISIC code that was produced domestically rather than imported.
A24: The calculations appear on the "Calculations" tab and are straightforward to follow
A25: by looking at the formulas in Excel.
A27: Note on ISIC 84 in variable ICESHR
A28: Many non-European countries in the OECD database, in variable ICESHR, omit a value for
A29: ISIC code 84 (Public administration and defence; compulsory social security).
A30: Though this value may be low, it is unlikely to be zero, due to imported content in
... A52: We convert 2015 USD to 2012 USD with the following conversion factor:
A53: 0.96868157 | B53: 2015 USD / 2012 USD

Sheet OECD TTL
A1: =DotStatQuery(B1) -> #NAME? | B1: Sorry, the query is too large to fit into the Excel cell. You will not be able to update your table with the .Stat Populator.
A2: Dataset: Input-Output Tables (IOTs) 2018 ed.
A3: Variable | C3: TTL: Total
A4: Country | C4: BRA: Brazil
A5: Time | C5: 2015
A6: Unit | C6: US Dollar, Millions
A7: To: (sector in column) | C7: D01T03: Agriculture, forestry and fishing | D7: D05T06: Mining and extraction of energy producing products | E7: D07T08: Mining and quarrying of non-energy producing products | F7: D09: Mining support service activities | G7: D10T12: Food products, beverages and tobacco | H7: D13T15: Textiles, wearing apparel, leather and related products | I7: D16: Wood and products of wood and cork | J7: D17T18: Paper products and printing | K7: D19: Coke and refined petroleum products | L7: D20T21: Chemicals and pharmaceutical products | M7: D22: Rubber and plastic products | N7: D23: Other non-metallic mineral products | O7: D24: Basic metals | P7: D25: Fabricated metal products | Q7: D26: Computer, electronic and optical products | R7: D27: Electrical equipment | S7: D28: Machinery and equipment, nec | T7: D29: Motor vehicles, trailers and semi-trailers | U7: D30: Other transport equipment | V7: D31T33: Other manufacturing; repair and installation of machinery and equipment | W7: D35T39: Electricity, gas, water supply, sewerage, waste and remediation services | X7: D41T43: Construction | Y7: D45T47: Wholesale and retail trade; repair of motor vehicles | Z7: D49T53: Transportation and storage | AA7: D55T56: Accomodation and food services | AB7: D58T60: Publishing, audiovisual and broadcasting activities | AC7: D61: Telecommunications | AD7: D62T63: IT and other information services | AE7: D64T66: Financial and insurance activities | AF7: D68: Real estate activities | AG7: D69T82: Other business sector services | AH7: D84: Public admin. and defence; compulsory social security | AI7: D85: Education | AJ7: D86T88: Human health and social work | AK7: D90T96: Arts, entertainment, recreation and other service activities | AL7: D97T98: Private households with employed persons | AM7: HFCE: Final consumption expenditure of households | AN7: NPISH: Final consumption expenditure of non-profit institutions serving households | AO7: GGFC: Final consumption expenditure of general government | AP7: GFCF: Gross Fixed Capital Formation | AQ7: INVNT: Changes in inventories | AR7: CONS_ABR: Direct purchases abroad by residents (imports) | AS7: CONS_NONRES: Direct purchases by non-residents (exports) | AT7: EXPO: Exports (cross border) | AU7: IMPO: Imports (cross border)
A8: From: (sector in row)
A9: TTL_01T03: Agriculture, forestry and fishing | C9: 6071.2 | D9: 22.9 | E9: 12.6 | F9: 5.4 | G9: 54628.4 | H9: 1070.9 | I9: 950.5 | J9: 1220.4 | K9: 3732.1 | L9: 116.1 | M9: 376.9 | N9: 55 | O9: 271.2 | P9: 7.4 | Q9: 1.9 | R9: 1.6 | S9: 2.6 | T9: 17 | U9: 4.9 | V9: 15.4 | W9: 16.5 | X9: 420 | Y9: 820.1 | Z9: 24.6 | AA9: 1503.9 | AB9: 3.6 | AC9: 19.5 | AD9: 5.6 | AE9: 25.7 | AF9: 52 | AG9: 88.9 | AH9: 360.6 | AI9: 254.5 | AJ9: 170.5 | AK9: 156 | AL9: 0 | AM9: 35490.9 | AN9: 0 | AO9: 2021.7 | AP9: 5117.2 | AQ9: -280.5 | AR9: 150.2 | AS9: 17.4 | AT9: 34291.8 | AU9: -3343.4
A10: TTL_05T06: Mining and extraction of energy producing products | C10: 35.2 | D10: 3165.2 | E10: 72.9 | F10: 283.8 | G10: 439.3 | H10: 57.8 | I10: 17.3 | J10: 268.7 | K10: 32198.4 | L10: 855.8 | M10: 35.9 | N10: 233.3 | O10: 1547.6 | P10: 152.2 | Q10: 1.2 | R10: 10.2 | S10: 11.8 | T10: 112.3 | U10: 13.9 | V10: 3.6 | W10: 4544.1 | X10: 241 | Y10: 260.3 | Z10: 138.4 | AA10: 6.9 | AB10: 2.1 | AC10: 20 | AD10: 4.4 | AE10: 45.9 | AF10: 82.2 | AG10: 80.7 | AH10: 75 | AI10: 12.5 | AJ10: 199.1 | AK10: 150.6 | AL10: 0 | AM10: 161.6 | AN10: 0 | AO10: 32.7 | AP10: 4254.8 | AQ10: -228.8 | AR10: 6.4 | AS10: 0.2 | AT10: 11513.1 | AU10: -13509.9
A11: TTL_07T08: Mining and quarrying of non-energy producing products | C11: 148.4 | D11: 134.8 | E11: 774.1 | F11: 24.4 | G11: 141.5 | H11: 4.1 | I11: 0.7 | J11: 18.5 | K11: 66.9 | L11: 1065.1 | M11: 12.7 | N11: 1577.5 | O11: 6004.1 | P11: 79.9 | Q11: 5.5 | R11: 196.1 | S11: 33.4 | T11: 118.3 | U11: 22 | V11: 84.1 | W11: 34.6 | X11: 1914.2 | Y11: 60.7 | Z11: 17.1 | AA11: 3 | AB11: 0.3 | AC11: 0.7 | AD11: 0.5 | AE11: 6.2 | AF11: 30.5 | AG11: 12.9 | AH11: 80.6 | AI11: 6 | AJ11: 7.9 | AK11: 23.6 | AL11: 0 | AM11: 86.6 | AN11: 0 | AO11: 3.6 | AP11: 68.9 | AQ11: -49.2 | AR11: 1.1 | AS11: 0 | AT11: 15903.2 | AU11: -2324.1
A12: TTL_09: Mining support service activities | C12: 390.2 | D12: 1981.2 | E12: 412.9 | F12: 281.3 | G12: 96.6 | H12: 0 | I12: 2.6 | J12: 22.8 | K12: 67.6 | L12: 28.6 | M12: 29.1 | N12: 15 | O12: 6.5 | P12: 0.7 | Q12: 0 | R12: 0.1 | S12: 13.2 | T12: 0.5 | U12: 0.1 | V12: 6.9 | W12: 166.7 | X12: 439.9 | Y12: 0.8 | Z12: 14.5 | AA12: 0.1 | AB12: 0 | AC12: 0 | AD12: 0.1 | AE12: 0.2 | AF12: 0 | AG12: 9.4 | AH12: 53.2 | AI12: 17.9 | AJ12: 0.5 | AK12: 0.5 | AL12: 0 | AM12: 0.4 | AN12: 0 | AO12: 781.8 | AP12: 0.7 | AQ12: 0.5 | AR12: 0.2 | AS12: 0 | AT12: 62.1 | AU12: -73.5
A13: TTL_10T12: Food products, beverages and tobacco | C13: 4743.3 | D13: 149.8 | E13: 51.6 | F13: 7.4 | G13: 27878.5 | H13: 668.7 | I13: 34 | J13: 335.2 | K13: 1174.7 | L13: 3015 | M13: 451.2 | N13: 114.2 | O13: 97.4 | P13: 98.3 | Q13: 40.5 | R13: 87.7 | S13: 59.5 | T13: 93.1 | U13: 33.3 | V13: 122.2 | W13: 85.3 | X13: 290.9 | Y13: 1161.8 | Z13: 160.4 | AA13: 14989 | AB13: 28 | AC13: 60.4 | AD13: 33.9 | AE13: 96.7 | AF13: 34.8 | AG13: 228.4 | AH13: 991.2 | AI13: 994.4 | AJ13: 936.3 | AK13: 468.5 | AL13: 0 | AM13: 110403.4 | AN13: 0.3 | AO13: 1487.2 | AP13: 372.6 | AQ13: 109.8 | AR13: 583.8 | AS13: 53.8 | AT13: 30575.3 | AU13: -7327.9
A14: TTL_13T15: Textiles, wearing apparel, leather and related products | C14: 228.6 | D14: 38.4 | E14: 10.7 | F14: 6.9 | G14: 164 | H14: 10509.7 | I14: 3.1 | J14: 108.6 | K14: 30.3 | L14: 167.6 | M14: 151.2 | N14: 16.5 | O14: 11.2 | P14: 55.8 | Q14: 7.8 | R14: 12.7 | S14: 15.3 | T14: 374.8 | U14: 65.9 | V14: 389.3 | W14: 130.2 | X14: 216.5 | Y14: 650.2 | Z14: 75.8 | AA14: 112.6 | AB14: 23.9 | AC14: 9.3 | AD14: 5.3 | AE14: 82.5 | AF14: 7.7 | AG14: 100.3 | AH14: 238 | AI14: 75.7 | AJ14: 323.4 | AK14: 261.6 | AL14: 0 | AM14: 33181.7 | AN14: 0 | AO14: 176.4 | AP14: 151 | AQ14: 12.1 | AR14: 213.7 | AS14: 31.1 | AT14: 3595.2 | AU14: -7272.9
A15: TTL_16: Wood and of products of wood and cork (except furniture) | C15: 227.7 | D15: 2.6 | E15: 12.4 | F15: 6.4 | G15: 139.9 | H15: 10.3 | I15: 921.6 | J15: 114.9 | K15: 1.8 | L15: 24.1 | M15: 6.6 | N15: 12.4 | O15: 10.9 | P15: 66.3 | Q15: 2.4 | R15: 2.8 | S15: 79.4 | T15: 68.5 | U15: 48 | V15: 1515.3 | W15: 114.7 | X15: 1317.5 | Y15: 246.9 | Z15: 34.8 | AA15: 5.6 | AB15: 21.3 | AC15: 3.5 | AD15: 2 | AE15: 22.8 | AF15: 233.6 | AG15: 70.9 | AH15: 80.3 | AI15: 13 | AJ15: 28.2 | AK15: 112.8 | AL15: 0 | AM15: 629.3 | AN15: 0 | AO15: 24.3 | AP15: 66.1 | AQ15: 7.1 | AR15: 18.7 | AS15: 2.1 | AT15: 1946.9 | AU15: -231.7
A16: TTL_17T18: Paper products and printing | C16: 188.1 | D16: 20.7 | E16: 66.3 | F16: 5.3 | G16: 2522 | H16: 454.3 | I16: 219.3 | J16: 4083.1 | K16: 58.6 | L16: 898.6 | M16: 553.3 | N16: 536.1 | O16: 28.2 | P16: 389.4 | Q16: 372.5 | R16: 121.6 | S16: 80.4 | T16: 324.2 | U16: 32.7 | V16: 302.4 | W16: 180.4 | X16: 153.2 | Y16: 1780.9 | Z16: 253.2 | AA16: 293.1 | AB16: 882.7 | AC16: 278.2 | AD16: 274.3 | AE16: 850.9 | AF16: 81.5 | AG16: 1398.7 | AH16: 1180.6 | AI16: 452.2 | AJ16: 532.1 | AK16: 634.6 | AL16: 0 | AM16: 3926.1 | AN16: 0.1 | AO16: 89.5 | AP16: 232.6 | AQ16: -2.9 | AR16: 80.9 | AS16: 5.5 | AT16: 6840.4 | AU16: -1455.7
A17: TTL_19: Coke and refined petroleum products | C17: 5688.7 | D17: 827.5 | E17: 1510.3 | F17: 143.9 | G17: 2877.5 | H17: 364.4 | I17: 109.2 | J17: 672 | K17: 33940.1 | L17: 8081.3 | M17: 1029 | N17: 1292.1 | O17: 1540.9 | P17: 215.2 | Q17: 69.3 | R17: 320.1 | S17: 147.6 | T17: 502.1 | U17: 114.9 | V17: 269.7 | W17: 1787.7 | X17: 2515.2 | Y17: 2028.1 | Z17: 21335 | AA17: 463.2 | AB17: 29.2 | AC17: 36.4 | AD17: 38.3 | AE17: 419.7 | AF17: 148.7 | AG17: 742.5 | AH17: 1617.5 | AI17: 182.7 | AJ17: 614.9 | AK17: 473.1 | AL17: 0 | AM17: 24668 | AN17: 0 | AO17: 38.7 | AP17: 25.1 | AQ17: 44.1 | AR17: 186.4 | AS17: 15.6 | AT17: 4745.1 | AU17: -8905.2
A18: TTL_20T21: Chemicals and pharmaceutical products | C18: 19057.5 | D18: 1385.4 | E18: 418.3 | F18: 50.4 | G18: 2524.5 | H18: 2288.7 | I18: 422.4 | J18: 2499 | K18: 6057.7 | L18: 29472.8 | M18: 6115.7 | N18: 1452.5 | O18: 1014 | P18: 997.2 | Q18: 207.7 | R18: 1029.4 | S18: 215.2 | T18: 849.5 | U18: 207.3 | V18: 1179.2 | W18: 280.2 | X18: 2741.7 | Y18: 1212.3 | Z18: 740.2 | AA18: 124.3 | AB18: 99.4 | AC18: 82.1 | AD18: 31.6 | AE18: 181.1 | AF18: 180 | AG18: 565.1 | AH18: 553.1 | AI18: 329.5 | AJ18: 1797.3 | AK18: 558.7 | AL18: 0 | AM18: 33283.1 | AN18: 0.3 | AO18: 10168.3 | AP18: 1088.4 | AQ18: 27.5 | AR18: 144.2 | AS18: 10.6 | AT18: 8173.9 | AU18: -30495.7
A19: TTL_22: Rubber and plastics products | C19: 316.9 | D19: 46.8 | E19: 216.1 | F19: 31 | G19: 4089.3 | H19: 357.3 | I19: 63.5 | J19: 465.7 | K19: 59.6 | L19: 1359.2 | M19: 4231.4 | N19: 624.2 | O19: 178.3 | P19: 244.5 | Q19: 372.3 | R19: 598.8 | S19: 629 | T19: 3840 | U19: 259.5 | V19: 1055.7 | W19: 166.9 | X19: 3479.3 | Y19: 1502.1 | Z19: 2097.7 | AA19: 110.2 | AB19: 7.2 | AC19: 11.5 | AD19: 7.9 | AE19: 115 | AF19: 81.1 | AG19: 395.5 | AH19: 315.8 | AI19: 77.7 | AJ19: 335.8 | AK19: 204.9 | AL19: 0 | AM19: 4315.3 | AN19: 0 | AO19: 70.9 | AP19: 440 | AQ19: 5.2 | AR19: 6 | AS19: 1 | AT19: 2440.1 | AU19: -4614.6
A20: TTL_23: Other non-metallic mineral products | C20: 1582.3 | D20: 34.6 | E20: 110.2 | F20: 23.8 | G20: 1128.5 | H20: 32.6 | I20: 2.2 | J20: 72.6 | K20: 46.4 | L20: 469 | M20: 145.9 | N20: 2812.8 | O20: 138.4 | P20: 65 | Q20: 8.1 | R20: 103.6 | S20: 110.9 | T20: 753.8 | U20: 66.1 | V20: 230.1 | W20: 527.2 | X20: 15760.3 | Y20: 387.1 | Z20: 80.5 | AA20: 187.1 | AB20: 2.8 | AC20: 7.7 | AD20: 4.2 | AE20: 52.6 | AF20: 156.9 | AG20: 90.7 | AH20: 202.5 | AI20: 58.2 | AJ20: 153.2 | AK20: 110.2 | AL20: 0 | AM20: 1092.2 | AN20: 0 | AO20: 49.3 | AP20: 139.3 | AQ20: 16.5 | AR20: 2.6 | AS20: 0.5 | AT20: 2037.5 | AU20: -1954.8
... A49: OUTPUT: Output at basic prices | C49: 145972.1 | D49: 47609.5 | E49: 26401.3 | F49: 4831.8 | G49: 196073.8 | H49: 44770 | I49: 8044.8 | J49: 30199.9 | K49: 112965.6 | L49: 109321.4 | M49: 30611.7 | N49: 27101.2 | O49: 48034.8 | P49: 27615.6 | Q49: 25782 | R49: 21784.7 | S49: 36501.9 | T49: 65641.3 | U49: 15435.8 | V49: 40199.3 | W49: 97912.3 | X49: 191319.8 | Y49: 333062 | Z49: 152925.9 | AA49: 74861.6 | AB49: 19331.4 | AC49: 48726.2 | AD49: 37984.2 | AE49: 175880.3 | AF49: 168922.7 | AG49: 195796.7 | AH49: 217738.1 | AI49: 127026.8 | AJ49: 122794.9 | AK49: 54530.1 | AL49: 18634.7 | AM49: 0 | AN49: 0 | AO49: 0 | AP49: 0 | AQ49: 0 | AR49: 0 | AS49: 0 | AT49: 0 | AU49: 0
A50: Data extracted on 15 May 2024 14:54 UTC (GMT) from OECD.Stat

Sheet OECD ICESHR
A1: =DotStatQuery(B1) -> #NAME? | B1: Sorry, the query is too large to fit into the Excel cell. You will not be able to update your table with the .Stat Populator.
A2: Dataset: Input-Output Tables (IOTs) 2018 ed.
A3: Variable | C3: ICESHR: Imports content of exports, as % of exports
A4: Country | C4: BRA: Brazil
A5: Time | C5: 2015
A6: Unit | C6: Percentage
A7: To: (sector in column) | C7: ICESHR: Imports content of exports shares
A8: From: (sector in row)
A9: TTL_01T03: Agriculture, forestry and fishing | C9: 9.67
A10: TTL_05T06: Mining and extraction of energy producing products | C10: 16.58
A11: TTL_07T08: Mining and quarrying of non-energy producing products | C11: 12.46
A12: TTL_09: Mining support service activities | C12: 12.36
A13: TTL_10T12: Food products, beverages and tobacco | C13: 11.14
A14: TTL_13T15: Textiles, wearing apparel, leather and related products | C14: 12.15
A15: TTL_16: Wood and of products of wood and cork (except furniture) | C15: 9.96
A16: TTL_17T18: Paper products and printing | C16: 13.38
A17: TTL_19: Coke and refined petroleum products | C17: 24.54
A18: TTL_20T21: Chemicals and pharmaceutical products | C18: 18.38
A19: TTL_22: Rubber and plastics products | C19: 17.59
A20: TTL_23: Other non-metallic mineral products | C20: 12.46
... A44: TOTAL: Total | C44: 12.56
A45: Data extracted on 15 May 2024 16:48 UTC (GMT) from OECD.Stat

Sheet SCNUse128
A1: Tabela 02 - Usos de bens e serviços - 2015 | D1: SCNUse128
A3: Código do produto | B3: Matching ISIC Code | C3: Consumo intermediário das atividades (valores correntes em 1 000 000 R$) | BV3: Demanda final (valores correntes em 1 000 000 R$)
C4: Descrição do produto | D4: 0191 Agricultura, inclusive o apoio à agricultura e a pós-colheita | E4: 0192 Pecuária, inclusive o apoio à pecuária | F4: 0280 Produção florestal; pesca e aquicultura | G4: 0580 Extração de carvão mineral e de minerais não metálicos | H4: 0680 Extração de petróleo e gás, inclusive as atividades de apoio | I4: 0791 Extração de minério de ferro, inclusive beneficiamentos e a aglomeração | J4: 0792 Extração de minerais metálicos não ferrosos, inclusive beneficiamentos | K4: 1091 Abate e produtos de carne, inclusive os produtos do laticínio e da pesca | L4: 1092 Fabricação e refino de açúcar | M4: 1093 Outros produtos alimentares | N4: 1100 Fabricação de bebidas | O4: 1200 Fabricação de produtos do fumo | P4: 1300 Fabricação de produtos têxteis | Q4: 1400 Confecção de artefatos do vestuário e acessórios | R4: 1500 Fabricação de calçados e de artefatos de couro | S4: 1600 Fabricação de produtos da madeira | T4: 1700 Fabricação de celulose, papel e produtos de papel | U4: 1800 Impressão e reprodução de gravações | V4: 1991 Refino de petróleo e coquerias | W4: 1992 Fabricação de biocombustíveis | X4: 2091 Fabricação de químicos orgânicos e inorgânicos, resinas e elastômeros | Y4: 2092 Fabricação de defensivos, desinfestantes, tintas e químicos diversos | Z4: 2093 Fabricação de produtos de limpeza, cosméticos/perfumaria e higiene pessoal | AA4: 2100 Fabricação de produtos farmoquímicos e farmacêuticos | AB4: 2200 Fabricação de produtos de borracha e de material plástico | AC4: 2310 Cimento / Artefatos de cimento, gesso e semelhantes | AD4: 2320 Vidros, cerâmicos e outros prod. de minerais não-metálicos | AE4: 2491 Produção de ferro gusa/ferroligas, siderurgia e tubos de aço sem costura | AF4: 2492 Metalurgia de metais não ferosos e a fundição de metais | AG4: 2500 Fabricação de produtos de metal, exceto máquinas e equipamentos | AH4: 2600 Fabricação de equipamentos de informática, produtos eletrônicos e ópticos | AI4: 2700 Fabricação de máquinas e equipamentos elétricos | AJ4: 2800 Fabricação de máquinas e equipamentos mecânicos | AK4: 2991 Fabricação de automóveis, caminhões e ônibus, exceto peças | AL4: 2992 Fabricação de peças e acessórios para veículos automotores | AM4: 3000 Fabricação de outros equipamentos de transporte, exceto veículos automotores | AN4: 3180 Fabricação de móveis e de produtos de indústrias diversas | AO4: 3300 Manutenção, reparação e instalação de máquinas e equipamentos | AP4: 3510 Transmissão de energia elétrica | AQ4: 3520 Produção de gás; processamento de gás natural; distribuição de combustíveis gasosos por redes urbanas | AR4: 3680 Água, esgoto e gestão de resíduos | AS4: 4180 Construção | AT4: 4580 Comércio por atacado e varejo | AU4: 4900 Transporte terrestre | AV4: 5000 Transporte aquaviário | AW4: 5100 Transporte aéreo | AX4: 5280 Armazenamento, atividades auxiliares dos transportes e correio | AY4: 5500 Alojamento | AZ4: 5600 Alimentação | BA4: 5800 Edição e edição integrada à impressão | BB4: 5980 Atividades de televisão, rádio, cinema e gravação/edição de som e imagem | BC4: 6100 Telecomunicações | BD4: 6280 Desenvolvimento de sistemas e outros serviços de informação | BE4: 6480 Intermediação financeira, seguros e previdência complementar | BF4: 6800 Atividades imobiliárias | BG4: 6980 Atividades jurídicas, contábeis, consultoria e sedes de empresas | BH4: 7180 Serviços de arquitetura, engenharia, testes/análises técnicas e P & D | BI4: 7380 Outras atividades profissionais, científicas e técnicas | BJ4: 7700 Aluguéis não imobiliários e gestão de ativos de propriedade intelectual | BK4: 7880 Outras atividades administrativas e serviços complementares | BL4: 8000 Atividades de vigilância, segurança e investigação | BM4: 8400 Administração pública, defesa e seguridade social | BN4: 8591 Educação pública | BO4: 8592 Educação privada | BP4: 8691 Saúde pública | BQ4: 8692 Saúde privada | BR4: 9080 Atividades artísticas, criativas e de espetáculos | BS4: 9480 Organizações associativas e outros serviços pessoais | BT4: 9700 Serviços domésticos | BU4: Total do produto | BV4: Exportação de bens e serviços (1) | BW4: Consumo do governo | BX4: Consumo das ISFLSF | BY4: Consumo das famílias | BZ4: Formação bruta de capital fixo | CA4: Variação de estoque | CB4: Demanda final | CC4: Demanda total | CE4: 2300 Fabricação de produtos de minerais não metálicos | CF4: 3500 Energia elétrica, gás natural e outras utilidades
D5: =VALUE(LEFT(D$4,4)) -> 191 | E5: =VALUE(LEFT(E$4,4)) -> 192 | F5: =VALUE(LEFT(F$4,4)) -> 280 | G5: =VALUE(LEFT(G$4,4)) -> 580 | H5: =VALUE(LEFT(H$4,4)) -> 680 | I5: =VALUE(LEFT(I$4,4)) -> 791 | J5: =VALUE(LEFT(J$4,4)) -> 792 | K5: =VALUE(LEFT(K$4,4)) -> 1091 | ... BT5: =VALUE(LEFT(BT$4,4)) -> 9700
A6: Matching ISIC Code | D6: =IFERROR(INDEX(SCNtoISIC!$F:$F,MATCH(D$5,SCNtoISIC!$C:$C,0)),0) -> ISIC 01T03 | E6: =IFERROR(INDEX(SCNtoISIC!$F:$F,MATCH(E$5,SCNtoISIC!$C:$C,0)),0) -> ISIC 01T03 | F6: =IFERROR(INDEX(SCNtoISIC!$F:$F,MATCH(F$5,SCNtoISIC!$C:$C,0)),0) -> ISIC 01T03 | G6: =IFERROR(INDEX(SCNtoISIC!$F:$F,MATCH(G$5,SCNtoISIC!$C:$C,0)),0) -> ISIC 05 | H6: =IFERROR(INDEX(SCNtoISIC!$F:$F,MATCH(H$5,SCNtoISIC!$C:$C,0)),0) -> ISIC 06 | I6: =IFERROR(INDEX(SCNtoISIC!$F:$F,MATCH(I$5,SCNtoISIC!$C:$C,0)),0) -> ISIC 07T08 | J6: =IFERROR(INDEX(SCNtoISIC!$F:$F,MATCH(J$5,SCNtoISIC!$C:$C,0)),0) -> ISIC 09 | K6: =IFERROR(INDEX(SCNtoISIC!$F:$F,MATCH(K$5,SCNtoISIC!$C:$C,0)),0) -> ISIC 10T12 | ... BT6: =IFERROR(INDEX(SCNtoISIC!$F:$F,MATCH(BT$5,SCNtoISIC!$C:$C,0)),0) -> ISIC 97T98 | CG6: SCN67
A7: 1911 | B7: =IFERROR(INDEX(SCNtoISIC!$M:$M,MATCH($A7,SCNtoISIC!$J:$J,0)),0) -> ISIC 01T03 | C7: Arroz, trigo e outros cereais | D7: 305 | E7: 302 | F7: 0 | G7: 0 | H7: 0 | I7: 0 | J7: 0 | K7: 46 | L7: 0 | M7: 15554 | N7: 384 | O7: 0 | P7: 0 | Q7: 0 | R7: 0 | S7: 0 | T7: 0 | U7: 0 | V7: 0 | W7: 0 | X7: 0 | Y7: 0 | Z7: 0 | AA7: 0 | AB7: 0 | AC7: =0.6*CE7 -> 0 | AD7: =(1-0.6)*CE7 -> 0 | AE7: 0 | AF7: 0 | AG7: 0 | AH7: 0 | AI7: 0 | AJ7: 0 | AK7: 0 | AL7: 0 | AM7: 0 | AN7: 0 | AO7: 0 | AP7: =2/3*CF7 -> 0 | AQ7: =1/3*CF7 -> 0 | AR7: 0 | AS7: 0 | AT7: 628 | AU7: 0 | AV7: 0 | AW7: 0 | AX7: 0 | AY7: 1 | AZ7: 0 | BA7: 0 | BB7: 0 | BC7: 0 | BD7: 0 | BE7: 0 | BF7: 0 | BG7: 0 | BH7: 0 | BI7: 0 | BJ7: 0 | BK7: 0 | BL7: 0 | BM7: 189 | BN7: 0 | BO7: 0 | BP7: 0 | BQ7: 0 | BR7: 0 | BS7: 0 | BT7: 0 | BU7: 17409 | BV7: 1280 | BW7: 0 | BX7: 0 | BY7: 593 | BZ7: 0 | CA7: 192 | CB7: 2065 | CC7: 19474 | CE7: 0 | CF7: 0 | CG7: 191
A8: 1912 | B8: =IFERROR(INDEX(SCNtoISIC!$M:$M,MATCH($A8,SCNtoISIC!$J:$J,0)),0) -> ISIC 01T03 | C8: Milho em grão | D8: 877 | E8: 3394 | F8: 14 | G8: 0 | H8: 0 | I8: 0 | J8: 0 | K8: 567 | L8: 0 | M8: 9554 | N8: 0 | O8: 0 | P8: 0 | Q8: 0 | R8: 0 | S8: 0 | T8: 0 | U8: 0 | V8: 0 | W8: 0 | X8: 0 | Y8: 0 | Z8: 0 | AA8: 0 | AB8: 0 | AC8: =0.6*CE8 -> 0 | AD8: =(1-0.6)*CE8 -> 0 | AE8: 0 | AF8: 0 | AG8: 0 | AH8: 0 | AI8: 0 | AJ8: 0 | AK8: 0 | AL8: 0 | AM8: 0 | AN8: 0 | AO8: 0 | AP8: =2/3*CF8 -> 0 | AQ8: =1/3*CF8 -> 0 | AR8: 0 | AS8: 0 | AT8: 440 | AU8: 0 | AV8: 0 | AW8: 0 | AX8: 0 | AY8: 0 | AZ8: 153 | BA8: 0 | BB8: 0 | BC8: 0 | BD8: 0 | BE8: 0 | BF8: 0 | BG8: 0 | BH8: 0 | BI8: 0 | BJ8: 0 | BK8: 0 | BL8: 0 | BM8: 193 | BN8: 1 | BO8: 0 | BP8: 0 | BQ8: 2 | BR8: 0 | BS8: 0 | BT8: 0 | BU8: 15195 | BV8: 17925 | BW8: 0 | BX8: 0 | BY8: 4404 | BZ8: 0 | CA8: 389 | CB8: 22718 | CC8: 37913 | CE8: 0 | CF8: 0 | CG8: 191
A9: 1913 | B9: =IFERROR(INDEX(SCNtoISIC!$M:$M,MATCH($A9,SCNtoISIC!$J:$J,0)),0) -> ISIC 01T03 | C9: Algodão herbáceo, outras fibras da lavoura temporária | D9: 318 | E9: 27 | F9: 0 | G9: 0 | H9: 0 | I9: 0 | J9: 0 | K9: 0 | L9: 0 | M9: 569 | N9: 0 | O9: 0 | P9: 3430 | Q9: 0 | R9: 0 | S9: 0 | T9: 0 | U9: 0 | V9: 0 | W9: 59 | X9: 0 | Y9: 0 | Z9: 0 | AA9: 0 | AB9: 0 | AC9: =0.6*CE9 -> 0 | AD9: =(1-0.6)*CE9 -> 0 | AE9: 0 | AF9: 0 | AG9: 0 | AH9: 0 | AI9: 0 | AJ9: 0 | AK9: 0 | AL9: 0 | AM9: 0 | AN9: 0 | AO9: 0 | AP9: =2/3*CF9 -> 0 | AQ9: =1/3*CF9 -> 0 | AR9: 0 | AS9: 0 | AT9: 183 | AU9: 0 | AV9: 0 | AW9: 0 | AX9: 0 | AY9: 0 | AZ9: 0 | BA9: 0 | BB9: 0 | BC9: 0 | BD9: 0 | BE9: 0 | BF9: 0 | BG9: 0 | BH9: 0 | BI9: 0 | BJ9: 0 | BK9: 0 | BL9: 0 | BM9: 0 | BN9: 0 | BO9: 0 | BP9: 0 | BQ9: 0 | BR9: 0 | BS9: 0 | BT9: 0 | BU9: 4586 | BV9: 4679 | BW9: 0 | BX9: 0 | BY9: 6 | BZ9: 0 | CA9: 740 | CB9: 5425 | CC9: 10011 | CE9: 0 | CF9: 0 | CG9: 191
A10: 1914 | B10: =IFERROR(INDEX(SCNtoISIC!$M:$M,MATCH($A10,SCNtoISIC!$J:$J,0)),0) -> ISIC 01T03 | C10: Cana-de-açúcar | D10: 668 | E10: 162 | F10: 4 | G10: 0 | H10: 0 | I10: 0 | J10: 0 | K10: 0 | L10: 27287 | M10: 0 | N10: 1680 | O10: 0 | P10: 0 | Q10: 0 | R10: 0 | S10: 0 | T10: 0 | U10: 0 | V10: 0 | W10: 17784 | X10: 0 | Y10: 0 | Z10: 0 | AA10: 0 | AB10: 0 | AC10: =0.6*CE10 -> 0 | AD10: =(1-0.6)*CE10 -> 0 | AE10: 0 | AF10: 0 | AG10: 0 | AH10: 0 | AI10: 0 | AJ10: 0 | AK10: 0 | AL10: 0 | AM10: 0 | AN10: 0 | AO10: 0 | AP10: =2/3*CF10 -> 0 | AQ10: =1/3*CF10 -> 0 | AR10: 0 | AS10: 0 | AT10: 0 | AU10: 0 | AV10: 0 | AW10: 0 | AX10: 0 | AY10: 0 | AZ10: 940 | BA10: 0 | BB10: 0 | BC10: 0 | BD10: 0 | BE10: 0 | BF10: 0 | BG10: 0 | BH10: 0 | BI10: 0 | BJ10: 0 | BK10: 0 | BL10: 0 | BM10: 0 | BN10: 0 | BO10: 0 | BP10: 0 | BQ10: 0 | BR10: 0 | BS10: 0 | BT10: 0 | BU10: 48525 | BV10: 0 | BW10: 0 | BX10: 0 | BY10: 1316 | BZ10: 0 | CA10: 0 | CB10: 1316 | CC10: 49841 | CE10: 0 | CF10: 0 | CG10: 191
A11: 1915 | B11: =IFERROR(INDEX(SCNtoISIC!$M:$M,MATCH($A11,SCNtoISIC!$J:$J,0)),0) -> ISIC 01T03 | C11: Soja em grão | D11: 2238 | E11: 188 | F11: 0 | G11: 0 | H11: 0 | I11: 0 | J11: 0 | K11: 505 | L11: 0 | M11: 31899 | N11: 0 | O11: 0 | P11: 0 | Q11: 0 | R11: 0 | S11: 0 | T11: 0 | U11: 0 | V11: 0 | W11: 1573 | X11: 0 | Y11: 0 | Z11: 0 | AA11: 0 | AB11: 0 | AC11: =0.6*CE11 -> 0 | AD11: =(1-0.6)*CE11 -> 0 | AE11: 0 | AF11: 0 | AG11: 0 | AH11: 0 | AI11: 0 | AJ11: 0 | AK11: 0 | AL11: 0 | AM11: 0 | AN11: 0 | AO11: 0 | AP11: =2/3*CF11 -> 0 | AQ11: =1/3*CF11 -> 0 | AR11: 0 | AS11: 0 | AT11: 9836 | AU11: 0 | AV11: 0 | AW11: 0 | AX11: 0 | AY11: 0 | AZ11: 0 | BA11: 0 | BB11: 0 | BC11: 0 | BD11: 0 | BE11: 0 | BF11: 0 | BG11: 0 | BH11: 0 | BI11: 0 | BJ11: 0 | BK11: 0 | BL11: 0 | BM11: 0 | BN11: 0 | BO11: 0 | BP11: 0 | BQ11: 0 | BR11: 0 | BS11: 0 | BT11: 0 | BU11: 46239 | BV11: 70046 | BW11: 0 | BX11: 0 | BY11: 86 | BZ11: 0 | CA11: 522 | CB11: 70654 | CC11: 116893 | CE11: 0 | CF11: 0 | CG11: 191
A12: 1916 | B12: =IFERROR(INDEX(SCNtoISIC!$M:$M,MATCH($A12,SCNtoISIC!$J:$J,0)),0) -> ISIC 01T03 | C12: Outros produtos e serviços da lavoura temporária | D12: 4041 | E12: 1005 | F12: 71 | G12: 0 | H12: 0 | I12: 0 | J12: 0 | K12: 37 | L12: 0 | M12: 4424 | N12: 0 | O12: 6180 | P12: 0 | Q12: 0 | R12: 0 | S12: 0 | T12: 0 | U12: 0 | V12: 0 | W12: 389 | X12: 0 | Y12: 0 | Z12: 0 | AA12: 0 | AB12: 0 | AC12: =0.6*CE12 -> 0 | AD12: =(1-0.6)*CE12 -> 0 | AE12: 0 | AF12: 0 | AG12: 0 | AH12: 0 | AI12: 0 | AJ12: 0 | AK12: 0 | AL12: 0 | AM12: 0 | AN12: 0 | AO12: 0 | AP12: =2/3*CF12 -> 0 | AQ12: =1/3*CF12 -> 0 | AR12: 39 | AS12: 7 | AT12: 554 | AU12: 0 | AV12: 0 | AW12: 0 | AX12: 0 | AY12: 262 | AZ12: 2369 | BA12: 0 | BB12: 0 | BC12: 0 | BD12: 0 | BE12: 0 | BF12: 0 | BG12: 5 | BH12: 0 | BI12: 0 | BJ12: 0 | BK12: 153 | BL12: 0 | BM12: 491 | BN12: 414 | BO12: 63 | BP12: 195 | BQ12: 236 | BR12: 1 | BS12: 319 | BT12: 0 | BU12: 21255 | BV12: 1463 | BW12: 65 | BX12: 0 | BY12: 55672 | BZ12: 0 | CA12: 115 | CB12: 57315 | CC12: 78570 | CE12: 0 | CF12: 0 | CG12: 191
A13: 1917 | B13: =IFERROR(INDEX(SCNtoISIC!$M:$M,MATCH($A13,SCNtoISIC!$J:$J,0)),0) -> ISIC 01T03 | C13: Laranja | D13: 11 | E13: 9 | F13: 4 | G13: 0 | H13: 0 | I13: 0 | J13: 0 | K13: 0 | L13: 0 | M13: 6615 | N13: 0 | O13: 0 | P13: 0 | Q13: 0 | R13: 0 | S13: 0 | T13: 0 | U13: 0 | V13: 0 | W13: 0 | X13: 0 | Y13: 0 | Z13: 0 | AA13: 0 | AB13: 0 | AC13: =0.6*CE13 -> 0 | AD13: =(1-0.6)*CE13 -> 0 | AE13: 0 | AF13: 0 | AG13: 0 | AH13: 0 | AI13: 0 | AJ13: 0 | AK13: 0 | AL13: 0 | AM13: 0 | AN13: 0 | AO13: 0 | AP13: =2/3*CF13 -> 0 | AQ13: =1/3*CF13 -> 0 | AR13: 0 | AS13: 0 | AT13: 0 | AU13: 0 | AV13: 0 | AW13: 0 | AX13: 0 | AY13: 93 | AZ13: 327 | BA13: 0 | BB13: 0 | BC13: 0 | BD13: 0 | BE13: 0 | BF13: 0 | BG13: 0 | BH13: 0 | BI13: 0 | BJ13: 0 | BK13: 0 | BL13: 0 | BM13: 8 | BN13: 7 | BO13: 0 | BP13: 3 | BQ13: 0 | BR13: 0 | BS13: 6 | BT13: 0 | BU13: 7083 | BV13: 31 | BW13: 0 | BX13: 0 | BY13: 2283 | BZ13: 163 | CA13: 0 | CB13: 2477 | CC13: 9560 | CE13: 0 | CF13: 0 | CG13: 191
A14: 1918 | B14: =IFERROR(INDEX(SCNtoISIC!$M:$M,MATCH($A14,SCNtoISIC!$J:$J,0)),0) -> ISIC 01T03 | C14: Café em grão | D14: 27 | E14: 110 | F14: 1 | G14: 0 | H14: 0 | I14: 0 | J14: 0 | K14: 0 | L14: 0 | M14: 5024 | N14: 0 | O14: 0 | P14: 0 | Q14: 0 | R14: 0 | S14: 0 | T14: 0 | U14: 0 | V14: 0 | W14: 0 | X14: 0 | Y14: 0 | Z14: 0 | AA14: 0 | AB14: 0 | AC14: =0.6*CE14 -> 0 | AD14: =(1-0.6)*CE14 -> 0 | AE14: 0 | AF14: 0 | AG14: 0 | AH14: 0 | AI14: 0 | AJ14: 0 | AK14: 0 | AL14: 0 | AM14: 0 | AN14: 0 | AO14: 0 | AP14: =2/3*CF14 -> 0 | AQ14: =1/3*CF14 -> 0 | AR14: 0 | AS14: 0 | AT14: 0 | AU14: 0 | AV14: 0 | AW14: 0 | AX14: 0 | AY14: 0 | AZ14: 0 | BA14: 0 | BB14: 0 | BC14: 0 | BD14: 0 | BE14: 0 | BF14: 0 | BG14: 0 | BH14: 3 | BI14: 0 | BJ14: 0 | BK14: 0 | BL14: 0 | BM14: 13 | BN14: 0 | BO14: 0 | BP14: 0 | BQ14: 0 | BR14: 0 | BS14: 8 | BT14: 0 | BU14: 5186 | BV14: 18452 | BW14: 0 | BX14: 0 | BY14: 376 | BZ14: 113 | CA14: -6241 | CB14: 12700 | CC14: 17886 | CE14: 0 | CF14: 0 | CG14: 191
A15: 1919 | B15: =IFERROR(INDEX(SCNtoISIC!$M:$M,MATCH($A15,SCNtoISIC!$J:$J,0)),0) -> ISIC 01T03 | C15: Outros produtos da lavoura permanente | D15: 77 | E15: 19 | F15: 1 | G15: 0 | H15: 0 | I15: 0 | J15: 0 | K15: 1 | L15: 0 | M15: 2761 | N15: 21 | O15: 0 | P15: 0 | Q15: 0 | R15: 0 | S15: 0 | T15: 0 | U15: 0 | V15: 0 | W15: 0 | X15: 0 | Y15: 0 | Z15: 0 | AA15: 0 | AB15: 0 | AC15: =0.6*CE15 -> 0 | AD15: =(1-0.6)*CE15 -> 0 | AE15: 0 | AF15: 0 | AG15: 0 | AH15: 0 | AI15: 0 | AJ15: 0 | AK15: 0 | AL15: 0 | AM15: 0 | AN15: 0 | AO15: 0 | AP15: =2/3*CF15 -> 0 | AQ15: =1/3*CF15 -> 0 | AR15: 0 | AS15: 0 | AT15: 122 | AU15: 0 | AV15: 0 | AW15: 0 | AX15: 0 | AY15: 24 | AZ15: 566 | BA15: 0 | BB15: 0 | BC15: 0 | BD15: 0 | BE15: 0 | BF15: 0 | BG15: 0 | BH15: 2 | BI15: 0 | BJ15: 0 | BK15: 0 | BL15: 0 | BM15: 119 | BN15: 98 | BO15: 3 | BP15: 38 | BQ15: 24 | BR15: 0 | BS15: 4 | BT15: 0 | BU15: 3880 | BV15: 2324 | BW15: 10 | BX15: 0 | BY15: 26423 | BZ15: 130 | CA15: 0 | CB15: 28887 | CC15: 32767 | CE15: 0 | CF15: 0 | CG15: 191
A16: 1921 | B16: =IFERROR(INDEX(SCNtoISIC!$M:$M,MATCH($A16,SCNtoISIC!$J:$J,0)),0) -> ISIC 01T03 | C16: Bovinos e outros animais vivos, produtos animal, caça e serviços | D16: 435 | E16: 1981 | F16: 11 | G16: 0 | H16: 0 | I16: 0 | J16: 0 | K16: 59132 | L16: 0 | M16: 40 | N16: 0 | O16: 0 | P16: 0 | Q16: 0 | R16: 0 | S16: 0 | T16: 0 | U16: 0 | V16: 0 | W16: 0 | X16: 0 | Y16: 0 | Z16: 0 | AA16: 0 | AB16: 0 | AC16: =0.6*CE16 -> 0 | AD16: =(1-0.6)*CE16 -> 0 | AE16: 0 | AF16: 0 | AG16: 0 | AH16: 0 | AI16: 0 | AJ16: 0 | AK16: 0 | AL16: 0 | AM16: 0 | AN16: 0 | AO16: 0 | AP16: =2/3*CF16 -> 0 | AQ16: =1/3*CF16 -> 0 | AR16: 0 | AS16: 0 | AT16: 0 | AU16: 0 | AV16: 0 | AW16: 0 | AX16: 0 | AY16: 0 | AZ16: 0 | BA16: 0 | BB16: 0 | BC16: 0 | BD16: 0 | BE16: 0 | BF16: 0 | BG16: 0 | BH16: 0 | BI16: 7 | BJ16: 0 | BK16: 0 | BL16: 0 | BM16: 98 | BN16: 61 | BO16: 5 | BP16: 0 | BQ16: 119 | BR16: 0 | BS16: 0 | BT16: 0 | BU16: 61889 | BV16: 1237 | BW16: 1 | BX16: 0 | BY16: 1025 | BZ16: 13552 | CA16: 876 | CB16: 16691 | CC16: 78580 | CE16: 0 | CF16: 0 | CG16: 192
A17: 1922 | B17: =IFERROR(INDEX(SCNtoISIC!$M:$M,MATCH($A17,SCNtoISIC!$J:$J,0)),0) -> ISIC 01T03 | C17: Leite de vaca e de outros animais | D17: 64 | E17: 1351 | F17: 40 | G17: 0 | H17: 0 | I17: 0 | J17: 0 | K17: 17148 | L17: 0 | M17: 0 | N17: 0 | O17: 0 | P17: 0 | Q17: 0 | R17: 0 | S17: 0 | T17: 0 | U17: 0 | V17: 0 | W17: 0 | X17: 0 | Y17: 0 | Z17: 0 | AA17: 0 | AB17: 0 | AC17: =0.6*CE17 -> 0 | AD17: =(1-0.6)*CE17 -> 0 | AE17: 0 | AF17: 0 | AG17: 0 | AH17: 0 | AI17: 0 | AJ17: 0 | AK17: 0 | AL17: 0 | AM17: 0 | AN17: 0 | AO17: 0 | AP17: =2/3*CF17 -> 0 | AQ17: =1/3*CF17 -> 0 | AR17: 0 | AS17: 0 | AT17: 0 | AU17: 0 | AV17: 0 | AW17: 0 | AX17: 0 | AY17: 0 | AZ17: 72 | BA17: 0 | BB17: 0 | BC17: 0 | BD17: 0 | BE17: 0 | BF17: 0 | BG17: 0 | BH17: 0 | BI17: 0 | BJ17: 0 | BK17: 0 | BL17: 0 | BM17: 0 | BN17: 0 | BO17: 0 | BP17: 0 | BQ17: 0 | BR17: 0 | BS17: 11 | BT17: 0 | BU17: 18686 | BV17: 0 | BW17: 0 | BX17: 0 | BY17: 12371 | BZ17: 0 | CA17: 0 | CB17: 12371 | CC17: 31057 | CE17: 0 | CF17: 0 | CG17: 192
A18: 1923 | B18: =IFERROR(INDEX(SCNtoISIC!$M:$M,MATCH($A18,SCNtoISIC!$J:$J,0)),0) -> ISIC 01T03 | C18: Suínos | D18: 45 | E18: 225 | F18: 2 | G18: 0 | H18: 0 | I18: 0 | J18: 0 | K18: 8761 | L18: 0 | M18: 0 | N18: 0 | O18: 0 | P18: 0 | Q18: 0 | R18: 0 | S18: 0 | T18: 0 | U18: 0 | V18: 0 | W18: 0 | X18: 0 | Y18: 0 | Z18: 0 | AA18: 0 | AB18: 0 | AC18: =0.6*CE18 -> 0 | AD18: =(1-0.6)*CE18 -> 0 | AE18: 0 | AF18: 0 | AG18: 0 | AH18: 0 | AI18: 0 | AJ18: 0 | AK18: 0 | AL18: 0 | AM18: 0 | AN18: 0 | AO18: 0 | AP18: =2/3*CF18 -> 0 | AQ18: =1/3*CF18 -> 0 | AR18: 0 | AS18: 0 | AT18: 0 | AU18: 0 | AV18: 0 | AW18: 0 | AX18: 0 | AY18: 0 | AZ18: 0 | BA18: 0 | BB18: 0 | BC18: 0 | BD18: 0 | BE18: 0 | BF18: 0 | BG18: 0 | BH18: 0 | BI18: 0 | BJ18: 0 | BK18: 0 | BL18: 0 | BM18: 0 | BN18: 0 | BO18: 0 | BP18: 0 | BQ18: 0 | BR18: 0 | BS18: 0 | BT18: 0 | BU18: 9033 | BV18: 8 | BW18: 0 | BX18: 0 | BY18: 261 | BZ18: 41 | CA18: 0 | CB18: 310 | CC18: 9343 | CE18: 0 | CF18: 0 | CG18: 192
... A93: 33001 | B93: =IFERROR(INDEX(SCNtoISIC!$M:$M,MATCH($A93,SCNtoISIC!$J:$J,0)),0) -> ISIC 31T33 | C93: Manutenção, reparação e instalação de máquinas e equipamentos | D93: 87 | E93: 36 | F93: 118 | G93: 957 | H93: 3903 | I93: 1431 | J93: 1063 | K93: 1333 | L93: 640 | M93: 700 | N93: 494 | O93: 15 | P93: 199 | Q93: 338 | R93: 215 | S93: 663 | T93: 3267 | U93: 1553 | V93: 673 | W93: 900 | X93: 1265 | Y93: 661 | Z93: 171 | AA93: 800 | AB93: 611 | AC93: =0.6*CE93 -> 2061.6 | AD93: =(1-0.6)*CE93 -> 1374.4 | AE93: 10197 | AF93: 2371 | AG93: 919 | AH93: 81 | AI93: 566 | AJ93: 1645 | AK93: 201 | AL93: 682 | AM93: 816 | AN93: 912 | AO93: 1093 | AP93: =2/3*CF93 -> 1238.6667 | AQ93: =1/3*CF93 -> 619.33333 | AR93: 1281 | AS93: 2840 | AT93: 6321 | AU93: 1223 | AV93: 1635 | AW93: 796 | AX93: 3766 | AY93: 8 | AZ93: 281 | BA93: 781 | BB93: 190 | BC93: 634 | BD93: 1109 | BE93: 418 | BF93: 117 | BG93: 1136 | BH93: 257 | BI93: 165 | BJ93: 1226 | BK93: 1067 | BL93: 266 | BM93: 1438 | BN93: 156 | BO93: 0 | BP93: 1320 | BQ93: 519 | BR93: 692 | BS93: 616 | BT93: 0 | BU93: 77128 | BV93: 2388 | BW93: 0 | BX93: 0 | BY93: 504 | BZ93: 12099 | CA93: 0 | CB93: 14991 | CC93: 92119 | CE93: 3436 | CF93: 1858 | CG93: 3510
A94: 35101 | B94: =IFERROR(INDEX(SCNtoISIC!$M:$M,MATCH($A94,SCNtoISIC!$J:$J,0)),0) -> ISIC 351 | C94: Transmissão de energia elétrica | D94: =2/3*D$146 -> 4978.6667 | E94: =2/3*E$146 -> 3338 | F94: =2/3*F$146 -> 274 | G94: =2/3*G$146 -> 464.66667 | H94: =2/3*H$146 -> 206 | I94: =2/3*I$146 -> 770.66667 | J94: =2/3*J$146 -> 319.33333 | K94: =2/3*K$146 -> 1095.3333 | ... AB94: =2/3*AB$146 -> 1484.6667 | AC94: =0.6*CE94 -> 1846 | AD94: =(1-0.6)*CE94 -> 1230.6667 | AE94: =2/3*AE$146 -> 2403.3333 | AF94: =2/3*AF$146 -> 1866.6667 | AG94: =2/3*AG$146 -> 878 | AH94: =2/3*AH$146 -> 112.66667 | AI94: =2/3*AI$146 -> 438.66667 | AJ94: =2/3*AJ$146 -> 467.33333 | AK94: =2/3*AK$146 -> 337.33333 | AL94: =2/3*AL$146 -> 792.66667 | ... AO94: =2/3*AO$146 -> 173.33333 | AP94: =2/3*CF94 -> 42050.667 | AQ94: =1/3*CF94 -> 21025.333 | AR94: =2/3*AR$146 -> 2305.3333 | AS94: =2/3*AS$146 -> 426.66667 | AT94: =2/3*AT$146 -> 14080 | AU94: =2/3*AU$146 -> 936.66667 | AV94: =2/3*AV$146 -> 40.666667 | AW94: =2/3*AW$146 -> 27.333333 | AX94: =2/3*AX$146 -> 779.33333 | AY94: =2/3*AY$146 -> 909.33333 | ... CC94: =2/3*CC$146 -> 206927.33 | CE94: =2/3*CE$146 -> 3076.6667 | CF94: =2/3*CF$146 -> 63076 | CG94: 3520
A95: 35201 | B95: =IFERROR(INDEX(SCNtoISIC!$M:$M,MATCH($A95,SCNtoISIC!$J:$J,0)),0) -> ISIC 352T353 | C95: Produção de gás; processamento de gás natural; distribuição de combustíveis gasosos por redes urbanas | D95: =1/3*D$146 -> 2489.3333 | E95: =1/3*E$146 -> 1669 | F95: =1/3*F$146 -> 137 | G95: =1/3*G$146 -> 232.33333 | H95: =1/3*H$146 -> 103 | I95: =1/3*I$146 -> 385.33333 | J95: =1/3*J$146 -> 159.66667 | K95: =1/3*K$146 -> 547.66667 | ... AB95: =1/3*AB$146 -> 742.33333 | AC95: =0.6*CE95 -> 923 | AD95: =(1-0.6)*CE95 -> 615.33333 | AE95: =1/3*AE$146 -> 1201.6667 | AF95: =1/3*AF$146 -> 933.33333 | AG95: =1/3*AG$146 -> 439 | AH95: =1/3*AH$146 -> 56.333333 | AI95: =1/3*AI$146 -> 219.33333 | AJ95: =1/3*AJ$146 -> 233.66667 | AK95: =1/3*AK$146 -> 168.66667 | AL95: =1/3*AL$146 -> 396.33333 | ... AO95: =1/3*AO$146 -> 86.666667 | AP95: =2/3*CF95 -> 21025.333 | AQ95: =1/3*CF95 -> 10512.667 | AR95: =1/3*AR$146 -> 1152.6667 | AS95: =1/3*AS$146 -> 213.33333 | AT95: =1/3*AT$146 -> 7040 | AU95: =1/3*AU$146 -> 468.33333 | AV95: =1/3*AV$146 -> 20.333333 | AW95: =1/3*AW$146 -> 13.666667 | AX95: =1/3*AX$146 -> 389.66667 | AY95: =1/3*AY$146 -> 454.66667 | ... CC95: =1/3*CC$146 -> 103463.67 | CE95: =1/3*CE$146 -> 1538.3333 | CF95: =1/3*CF$146 -> 31538 | CG95: 3680
A96: 36801 | B96: =IFERROR(INDEX(SCNtoISIC!$M:$M,MATCH($A96,SCNtoISIC!$J:$J,0)),0) -> ISIC 36T39 | C96: Água, esgoto, reciclagem e gestão de resíduos | D96: 3 | E96: 1 | F96: 1 | G96: 30 | H96: 46 | I96: 184 | J96: 69 | K96: 146 | L96: 54 | M96: 294 | N96: 536 | O96: 1 | P96: 60 | Q96: 28 | R96: 22 | S96: 213 | T96: 344 | U96: 8 | V96: 426 | W96: 28 | X96: 623 | Y96: 429 | Z96: 126 | AA96: 76 | AB96: 521 | AC96: =0.6*CE96 -> 460.8 | AD96: =(1-0.6)*CE96 -> 307.2 | AE96: 4867 | AF96: 2369 | AG96: 169 | AH96: 20 | AI96: 61 | AJ96: 101 | AK96: 89 | AL96: 258 | AM96: 133 | AN96: 78 | AO96: 27 | AP96: =2/3*CF96 -> 54 | AQ96: =1/3*CF96 -> 27 | AR96: 958 | AS96: 279 | AT96: 4160 | AU96: 264 | AV96: 9 | AW96: 6 | AX96: 704 | AY96: 330 | AZ96: 1109 | BA96: 32 | BB96: 51 | BC96: 43 | BD96: 94 | BE96: 519 | BF96: 368 | BG96: 493 | BH96: 65 | BI96: 28 | BJ96: 43 | BK96: 4115 | BL96: 29 | BM96: 10446 | BN96: 1335 | BO96: 214 | BP96: 1721 | BQ96: 1874 | BR96: 94 | BS96: 1689 | BT96: 0 | BU96: 44362 | BV96: 4 | BW96: 0 | BX96: 0 | BY96: 25835 | BZ96: 0 | CA96: 439 | CB96: 26278 | CC96: 70640 | CE96: 768 | CF96: 81 | CG96: 4180
A97: 41801 | B97: =IFERROR(INDEX(SCNtoISIC!$M:$M,MATCH($A97,SCNtoISIC!$J:$J,0)),0) -> ISIC 41T43 | C97: Edificações | D97: 21 | E97: 41 | F97: 3 | G97: 1 | H97: 435 | I97: 215 | J97: 38 | K97: 0 | L97: 0 | M97: 6 | N97: 0 | O97: 0 | P97: 0 | Q97: 0 | R97: 0 | S97: 0 | T97: 10 | U97: 0 | V97: 0 | W97: 27 | X97: 71 | Y97: 0 | Z97: 0 | AA97: 0 | AB97: 0 | AC97: =0.6*CE97 -> 2.4 | AD97: =(1-0.6)*CE97 -> 1.6 | AE97: 18 | AF97: 12 | AG97: 33 | AH97: 72 | AI97: 3 | AJ97: 51 | AK97: 228 | AL97: 13 | AM97: 228 | AN97: 13 | AO97: 0 | AP97: =2/3*CF97 -> 0 | AQ97: =1/3*CF97 -> 0 | AR97: 0 | AS97: 31663 | AT97: 1077 | AU97: 18 | AV97: 5 | AW97: 2 | AX97: 298 | AY97: 236 | AZ97: 0 | BA97: 10 | BB97: 225 | BC97: 2 | BD97: 832 | BE97: 350 | BF97: 540 | BG97: 55 | BH97: 149 | BI97: 0 | BJ97: 178 | BK97: 1952 | BL97: 0 | BM97: 3566 | BN97: 1027 | BO97: 365 | BP97: 1723 | BQ97: 0 | BR97: 9 | BS97: 272 | BT97: 0 | BU97: 46097 | BV97: 236 | BW97: 0 | BX97: 0 | BY97: 0 | BZ97: 340306 | CA97: 0 | CB97: 340542 | CC97: 386639 | CE97: 4 | CF97: 0 | CG97: 4180
A98: 41802 | B98: =IFERROR(INDEX(SCNtoISIC!$M:$M,MATCH($A98,SCNtoISIC!$J:$J,0)),0) -> ISIC 41T43 | C98: Obras de infraestrutura | D98: 0 | E98: 0 | F98: 0 | G98: 0 | H98: 1251 | I98: 956 | J98: 154 | K98: 0 | L98: 0 | M98: 0 | N98: 0 | O98: 0 | P98: 0 | Q98: 0 | R98: 0 | S98: 0 | T98: 0 | U98: 0 | V98: 0 | W98: 0 | X98: 0 | Y98: 0 | Z98: 0 | AA98: 0 | AB98: 0 | AC98: =0.6*CE98 -> 0 | AD98: =(1-0.6)*CE98 -> 0 | AE98: 79 | AF98: 40 | AG98: 0 | AH98: 0 | AI98: 0 | AJ98: 0 | AK98: 0 | AL98: 0 | AM98: 0 | AN98: 0 | AO98: 0 | AP98: =2/3*CF98 -> 0 | AQ98: =1/3*CF98 -> 0 | AR98: 4426 | AS98: 8021 | AT98: 0 | AU98: 248 | AV98: 0 | AW98: 0 | AX98: 334 | AY98: 0 | AZ98: 0 | BA98: 0 | BB98: 0 | BC98: 957 | BD98: 0 | BE98: 0 | BF98: 0 | BG98: 0 | BH98: 0 | BI98: 0 | BJ98: 0 | BK98: 0 | BL98: 0 | BM98: 7973 | BN98: 2 | BO98: 0 | BP98: 0 | BQ98: 0 | BR98: 0 | BS98: 97 | BT98: 0 | BU98: 24538 | BV98: 0 | BW98: 0 | BX98: 0 | BY98: 0 | BZ98: 119076 | CA98: 0 | CB98: 119076 | CC98: 143614 | CE98: 0 | CF98: 0 | CG98: 4180
A99: 41803 | B99: =IFERROR(INDEX(SCNtoISIC!$M:$M,MATCH($A99,SCNtoISIC!$J:$J,0)),0) -> ISIC 41T43 | C99: Serviços especializados para construção | D99: 70 | E99: 152 | F99: 8 | G99: 3 | H99: 316 | I99: 11 | J99: 150 | K99: 0 | L99: 4 | M99: 1 | N99: 0 | O99: 0 | P99: 23 | Q99: 0 | R99: 0 | S99: 0 | T99: 11 | U99: 18 | V99: 22 | W99: 0 | X99: 0 | Y99: 2 | Z99: 0 | AA99: 0 | AB99: 0 | AC99: =0.6*CE99 -> 13.8 | AD99: =(1-0.6)*CE99 -> 9.2 | AE99: 18 | AF99: 1548 | AG99: 21 | AH99: 0 | AI99: 9 | AJ99: 27 | AK99: 0 | AL99: 9 | AM99: 0 | AN99: 3 | AO99: 0 | AP99: =2/3*CF99 -> 0 | AQ99: =1/3*CF99 -> 0 | AR99: 0 | AS99: 26096 | AT99: 57 | AU99: 9 | AV99: 0 | AW99: 0 | AX99: 764 | AY99: 42 | AZ99: 392 | BA99: 0 | BB99: 0 | BC99: 4087 | BD99: 0 | BE99: 1442 | BF99: 1151 | BG99: 214 | BH99: 650 | BI99: 3 | BJ99: 2 | BK99: 810 | BL99: 9 | BM99: 1874 | BN99: 258 | BO99: 0 | BP99: 1955 | BQ99: 0 | BR99: 104 | BS99: 11 | BT99: 0 | BU99: 42379 | BV99: 4462 | BW99: 0 | BX99: 0 | BY99: 0 | BZ99: 103136 | CA99: 0 | CB99: 107598 | CC99: 149977 | CE99: 23 | CF99: 0 | CG99: 4580
A100: 45801 | B100: =IFERROR(INDEX(SCNtoISIC!$M:$M,MATCH($A100,SCNtoISIC!$J:$J,0)),0) -> 0 | C100: Comércio por atacado e varejo | D100: 184 | E100: 43 | F100: 21 | G100: 100 | H100: 123 | I100: 717 | J100: 139 | K100: 6005 | L100: 275 | M100: 3826 | N100: 205 | O100: 166 | P100: 540 | Q100: 689 | R100: 880 | S100: 242 | T100: 1645 | U100: 63 | V100: 470 | W100: 418 | X100: 713 | Y100: 1077 | Z100: 77 | AA100: 1303 | AB100: 1609 | AC100: =0.6*CE100 -> 830.4 | AD100: =(1-0.6)*CE100 -> 553.6 | AE100: 1322 | AF100: 433 | AG100: 1218 | AH100: 1239 | AI100: 1040 | AJ100: 4552 | AK100: 346 | AL100: 28 | AM100: 175 | AN100: 670 | AO100: 82 | AP100: =2/3*CF100 -> 254.66667 | AQ100: =1/3*CF100 -> 127.33333 | AR100: 630 | AS100: 565 | AT100: 10138 | AU100: 6130 | AV100: 0 | AW100: 0 | AX100: 429 | AY100: 0 | AZ100: 98 | BA100: 455 | BB100: 571 | BC100: 3226 | BD100: 316 | BE100: 149 | BF100: 29 | BG100: 391 | BH100: 141 | BI100: 179 | BJ100: 862 | BK100: 350 | BL100: 196 | BM100: 1555 | BN100: 278 | BO100: 11 | BP100: 1042 | BQ100: 632 | BR100: 69 | BS100: 47 | BT100: 0 | BU100: 62890 | BV100: 5547 | BW100: 0 | BX100: 0 | BY100: 42731 | BZ100: 0 | CA100: 0 | CB100: 48278 | CC100: 111168 | CE100: 1384 | CF100: 382 | CG100: 4580
A101: 49001 | B101: =IFERROR(INDEX(SCNtoISIC!$M:$M,MATCH($A101,SCNtoISIC!$J:$J,0)),0) -> ISIC 45T47 | C101: Transporte terrestre de carga | D101: 4198 | E101: 669 | F101: 402 | G101: 753 | H101: 4660 | I101: 1826 | J101: 662 | K101: 8350 | L101: 1527 | M101: 11243 | N101: 2348 | O101: 120 | P101: 785 | Q101: 512 | R101: 771 | S101: 416 | T101: 2389 | U101: 274 | V101: 3317 | W101: 857 | X101: 4092 | Y101: 1605 | Z101: 1191 | AA101: 2338 | AB101: 2093 | AC101: =0.6*CE101 -> 1360.8 | AD101: =(1-0.6)*CE101 -> 907.2 | AE101: 3967 | AF101: 483 | AG101: 1847 | AH101: 1079 | AI101: 1117 | AJ101: 1385 | AK101: 3184 | AL101: 1043 | AM101: 554 | AN101: 1192 | AO101: 50 | AP101: =2/3*CF101 -> 2474 | AQ101: =1/3*CF101 -> 1237 | AR101: 248 | AS101: 1759 | AT101: 35632 | AU101: 32030 | AV101: 110 | AW101: 69 | AX101: 4432 | AY101: 20 | AZ101: 710 | BA101: 394 | BB101: 117 | BC101: 206 | BD101: 148 | BE101: 467 | BF101: 11 | BG101: 531 | BH101: 307 | BI101: 48 | BJ101: 339 | BK101: 119 | BL101: 62 | BM101: 1379 | BN101: 96 | BO101: 2 | BP101: 325 | BQ101: 0 | BR101: 69 | BS101: 104 | BT101: 0 | BU101: 159012 | BV101: 1202 | BW101: 0 | BX101: 0 | BY101: 1602 | BZ101: 0 | CA101: 0 | CB101: 2804 | CC101: 161816 | CE101: 2268 | CF101: 3711 | CG101: 4900
A102: 49002 | B102: =IFERROR(INDEX(SCNtoISIC!$M:$M,MATCH($A102,SCNtoISIC!$J:$J,0)),0) -> ISIC 49T53 | C102: Transporte terrestre de passageiros | D102: 5 | E102: 3 | F102: 21 | G102: 14 | H102: 406 | I102: 308 | J102: 126 | K102: 75 | L102: 35 | M102: 121 | N102: 14 | O102: 0 | P102: 2 | Q102: 129 | R102: 6 | S102: 544 | T102: 1 | U102: 0 | V102: 0 | W102: 60 | X102: 177 | Y102: 140 | Z102: 16 | AA102: 118 | AB102: 198 | AC102: =0.6*CE102 -> 179.4 | AD102: =(1-0.6)*CE102 -> 119.6 | AE102: 74 | AF102: 13 | AG102: 325 | AH102: 3 | AI102: 55 | AJ102: 484 | AK102: 0 | AL102: 244 | AM102: 2 | AN102: 9 | AO102: 75 | AP102: =2/3*CF102 -> 0 | AQ102: =1/3*CF102 -> 0 | AR102: 7 | AS102: 78 | AT102: 48 | AU102: 153 | AV102: 0 | AW102: 0 | AX102: 39 | AY102: 20 | AZ102: 56 | BA102: 0 | BB102: 99 | BC102: 16 | BD102: 184 | BE102: 370 | BF102: 24 | BG102: 8 | BH102: 817 | BI102: 39 | BJ102: 24 | BK102: 233 | BL102: 31 | BM102: 2183 | BN102: 2001 | BO102: 1149 | BP102: 892 | BQ102: 0 | BR102: 13 | BS102: 2253 | BT102: 0 | BU102: 14839 | BV102: 567 | BW102: 0 | BX102: 0 | BY102: 88885 | BZ102: 0 | CA102: 0 | CB102: 89452 | CC102: 104291 | CE102: 299 | CF102: 0 | CG102: 4900
A103: 50001 | B103: =IFERROR(INDEX(SCNtoISIC!$M:$M,MATCH($A103,SCNtoISIC!$J:$J,0)),0) -> ISIC 49T53 | C103: Transporte aquaviário | D103: 0 | E103: 0 | F103: 0 | G103: 0 | H103: 8164 | I103: 0 | J103: 18 | K103: 2064 | L103: 124 | M103: 612 | N103: 2 | O103: 1 | P103: 14 | Q103: 23 | R103: 10 | S103: 215 | T103: 1991 | U103: 30 | V103: 90 | W103: 16 | X103: 1105 | Y103: 18 | Z103: 67 | AA103: 3 | AB103: 66 | AC103: =0.6*CE103 -> 112.2 | AD103: =(1-0.6)*CE103 -> 74.8 | AE103: 518 | AF103: 19 | AG103: 50 | AH103: 74 | AI103: 71 | AJ103: 391 | AK103: 322 | AL103: 108 | AM103: 265 | AN103: 1 | AO103: 9 | AP103: =2/3*CF103 -> 0 | AQ103: =1/3*CF103 -> 0 | AR103: 0 | AS103: 6 | AT103: 1787 | AU103: 1119 | AV103: 1731 | AW103: 0 | AX103: 89 | AY103: 0 | AZ103: 25 | BA103: 0 | BB103: 3 | BC103: 0 | BD103: 24 | BE103: 0 | BF103: 0 | BG103: 1 | BH103: 3 | BI103: 0 | BJ103: 0 | BK103: 384 | BL103: 1 | BM103: 0 | BN103: 0 | BO103: 0 | BP103: 0 | BQ103: 0 | BR103: 1 | BS103: 0 | BT103: 0 | BU103: 21822 | BV103: 6619 | BW103: 0 | BX103: 0 | BY103: 1910 | BZ103: 0 | CA103: 0 | CB103: 8529 | CC103: 30351 | CE103: 187 | CF103: 0 | CG103: 5000
A104: 51001 | B104: =IFERROR(INDEX(SCNtoISIC!$M:$M,MATCH($A104,SCNtoISIC!$J:$J,0)),0) -> ISIC 49T53 | C104: Transporte aéreo | D104: 1 | E104: 0 | F104: 4 | G104: 4 | H104: 1991 | I104: 10 | J104: 28 | K104: 282 | L104: 6 | M104: 236 | N104: 50 | O104: 25 | P104: 31 | Q104: 33 | R104: 42 | S104: 41 | T104: 99 | U104: 17 | V104: 42 | W104: 4 | X104: 239 | Y104: 273 | Z104: 11 | AA104: 135 | AB104: 42 | AC104: =0.6*CE104 -> 80.4 | AD104: =(1-0.6)*CE104 -> 53.6 | AE104: 84 | AF104: 13 | AG104: 52 | AH104: 242 | AI104: 164 | AJ104: 212 | AK104: 213 | AL104: 57 | AM104: 57 | AN104: 35 | AO104: 63 | AP104: =2/3*CF104 -> 401.33333 | AQ104: =1/3*CF104 -> 200.66667 | AR104: 44 | AS104: 1437 | AT104: 3415 | AU104: 205 | AV104: 83 | AW104: 11 | AX104: 642 | AY104: 72 | AZ104: 53 | BA104: 20 | BB104: 162 | BC104: 207 | BD104: 676 | BE104: 2898 | BF104: 62 | BG104: 944 | BH104: 340 | BI104: 555 | BJ104: 91 | BK104: 323 | BL104: 25 | BM104: 1247 | BN104: 352 | BO104: 2076 | BP104: 462 | BQ104: 0 | BR104: 92 | BS104: 8775 | BT104: 0 | BU104: 30843 | BV104: 5991 | BW104: 0 | BX104: 0 | BY104: 10407 | BZ104: 0 | CA104: 0 | CB104: 16398 | CC104: 47241 | CE104: 134 | CF104: 602 | CG104: 5100
A105: 52801 | B105: =IFERROR(INDEX(SCNtoISIC!$M:$M,MATCH($A105,SCNtoISIC!$J:$J,0)),0) -> ISIC 49T53 | C105: Armazenamento e serviços auxiliares aos transportes | D105: 897 | E105: 53 | F105: 223 | G105: 26 | H105: 4005 | I105: 2590 | J105: 610 | K105: 3005 | L105: 1785 | M105: 3712 | N105: 2275 | O105: 28 | P105: 111 | Q105: 7 | R105: 77 | S105: 215 | T105: 1085 | U105: 157 | V105: 783 | W105: 865 | X105: 1000 | Y105: 434 | Z105: 422 | AA105: 601 | AB105: 192 | AC105: =0.6*CE105 -> 159 | AD105: =(1-0.6)*CE105 -> 106 | AE105: 2762 | AF105: 138 | AG105: 940 | AH105: 645 | AI105: 930 | AJ105: 315 | AK105: 3800 | AL105: 516 | AM105: 516 | AN105: 240 | AO105: 232 | AP105: =2/3*CF105 -> 60 | AQ105: =1/3*CF105 -> 30 | AR105: 9 | AS105: 323 | AT105: 12083 | AU105: 7842 | AV105: 2914 | AW105: 4651 | AX105: 3579 | AY105: 2 | AZ105: 33 | BA105: 20 | BB105: 42 | BC105: 120 | BD105: 17 | BE105: 215 | BF105: 1 | BG105: 66 | BH105: 92 | BI105: 194 | BJ105: 29 | BK105: 142 | BL105: 34 | BM105: 1668 | BN105: 121 | BO105: 0 | BP105: 181 | BQ105: 0 | BR105: 2 | BS105: 1071 | BT105: 0 | BU105: 71998 | BV105: 9008 | BW105: 0 | BX105: 0 | BY105: 24848 | BZ105: 0 | CA105: 0 | CB105: 33856 | CC105: 105854 | CE105: 265 | CF105: 90 | CG105: 5280
A106: 52802 | B106: =IFERROR(INDEX(SCNtoISIC!$M:$M,MATCH($A106,SCNtoISIC!$J:$J,0)),0) -> ISIC 49T53 | C106: Correio e outros serviços de entrega | D106: 1 | E106: 0 | F106: 1 | G106: 3 | H106: 31 | I106: 0 | J106: 7 | K106: 90 | L106: 60 | M106: 164 | N106: 26 | O106: 6 | P106: 73 | Q106: 110 | R106: 104 | S106: 21 | T106: 160 | U106: 49 | V106: 37 | W106: 21 | X106: 44 | Y106: 376 | Z106: 16 | AA106: 115 | AB106: 72 | AC106: =0.6*CE106 -> 68.4 | AD106: =(1-0.6)*CE106 -> 45.6 | AE106: 22 | AF106: 12 | AG106: 95 | AH106: 180 | AI106: 85 | AJ106: 66 | AK106: 152 | AL106: 113 | AM106: 151 | AN106: 145 | AO106: 21 | AP106: =2/3*CF106 -> 411.33333 | AQ106: =1/3*CF106 -> 205.66667 | AR106: 14 | AS106: 379 | AT106: 4547 | AU106: 152 | AV106: 9 | AW106: 9 | AX106: 1624 | AY106: 57 | AZ106: 198 | BA106: 60 | BB106: 41 | BC106: 509 | BD106: 127 | BE106: 4784 | BF106: 205 | BG106: 522 | BH106: 154 | BI106: 69 | BJ106: 186 | BK106: 540 | BL106: 37 | BM106: 1906 | BN106: 195 | BO106: 427 | BP106: 298 | BQ106: 267 | BR106: 55 | BS106: 454 | BT106: 0 | BU106: 21185 | BV106: 96 | BW106: 0 | BX106: 0 | BY106: 2269 | BZ106: 0 | CA106: 0 | CB106: 2365 | CC106: 23550 | CE106: 114 | CF106: 617 | CG106: 5280
A107: 55001 | B107: =IFERROR(INDEX(SCNtoISIC!$M:$M,MATCH($A107,SCNtoISIC!$J:$J,0)),0) -> ISIC 55T56 | C107: Serviços de alojamento em hotéis e similares | D107: 4 | E107: 1 | F107: 4 | G107: 12 | H107: 352 | I107: 81 | J107: 25 | K107: 387 | L107: 37 | M107: 377 | N107: 74 | O107: 36 | P107: 36 | Q107: 33 | R107: 40 | S107: 11 | T107: 110 | U107: 13 | V107: 41 | W107: 19 | X107: 166 | Y107: 187 | Z107: 49 | AA107: 276 | AB107: 130 | AC107: =0.6*CE107 -> 69 | AD107: =(1-0.6)*CE107 -> 46 | AE107: 228 | AF107: 59 | AG107: 223 | AH107: 206 | AI107: 172 | AJ107: 416 | AK107: 146 | AL107: 103 | AM107: 108 | AN107: 155 | AO107: 99 | AP107: =2/3*CF107 -> 214.66667 | AQ107: =1/3*CF107 -> 107.33333 | AR107: 18 | AS107: 1713 | AT107: 4307 | AU107: 252 | AV107: 7 | AW107: 105 | AX107: 266 | AY107: 0 | AZ107: 39 | BA107: 115 | BB107: 194 | BC107: 144 | BD107: 635 | BE107: 1526 | BF107: 72 | BG107: 419 | BH107: 403 | BI107: 186 | BJ107: 193 | BK107: 189 | BL107: 59 | BM107: 2947 | BN107: 346 | BO107: 458 | BP107: 470 | BQ107: 0 | BR107: 188 | BS107: 8830 | BT107: 0 | BU107: 28934 | BV107: 6574 | BW107: 0 | BX107: 0 | BY107: 11281 | BZ107: 0 | CA107: 0 | CB107: 17855 | CC107: 46789 | CE107: 115 | CF107: 322 | CG107: 5500
... A134: 97001 | B134: =IFERROR(INDEX(SCNtoISIC!$M:$M,MATCH($A134,SCNtoISIC!$J:$J,0)),0) -> ISIC 97T98 | C134: Serviços domésticos | D134: 0 | E134: 0 | F134: 0 | G134: 0 | H134: 0 | I134: 0 | J134: 0 | K134: 0 | L134: 0 | M134: 0 | N134: 0 | O134: 0 | P134: 0 | Q134: 0 | R134: 0 | S134: 0 | T134: 0 | U134: 0 | V134: 0 | W134: 0 | X134: 0 | Y134: 0 | Z134: 0 | AA134: 0 | AB134: 0 | AC134: =0.6*CE134 -> 0 | AD134: =(1-0.6)*CE134 -> 0 | AE134: 0 | AF134: 0 | AG134: 0 | AH134: 0 | AI134: 0 | AJ134: 0 | AK134: 0 | AL134: 0 | AM134: 0 | AN134: 0 | AO134: 0 | AP134: =2/3*CF134 -> 0 | AQ134: =1/3*CF134 -> 0 | AR134: 0 | AS134: 0 | AT134: 0 | AU134: 0 | AV134: 0 | AW134: 0 | AX134: 0 | AY134: 0 | AZ134: 0 | BA134: 0 | BB134: 0 | BC134: 0 | BD134: 0 | BE134: 0 | BF134: 0 | BG134: 0 | BH134: 0 | BI134: 0 | BJ134: 0 | BK134: 0 | BL134: 0 | BM134: 0 | BN134: 0 | BO134: 0 | BP134: 0 | BQ134: 0 | BR134: 0 | BS134: 0 | BT134: 0 | BU134: 0 | BV134: 0 | BW134: 0 | BX134: 0 | BY134: 61996 | BZ134: 0 | CA134: 0 | CB134: 61996 | CC134: 61996 | CE134: 0 | CF134: 0 | CG134: 9700
D135: =SUM(D7:D134) -> 146174 | E135: =SUM(E7:E134) -> 65569 | F135: =SUM(F7:F134) -> 8020 | G135: =SUM(G7:G134) -> 10878 | H135: =SUM(H7:H134) -> 98428 | I135: =SUM(I7:I134) -> 28837 | J135: =SUM(J7:J134) -> 11661 | K135: =SUM(K7:K134) -> 214821 | ... BU135: =SUM(BU7:BU134) -> 5071268
A136: Total | D136: 146174 | E136: 65569 | F136: 8020 | G136: 10878 | H136: 98428 | I136: 28837 | J136: 11661 | K136: 214821 | L136: 40678 | M136: 204687 | N136: 53521 | O136: 10826 | P136: 33055 | Q136: 36373 | R136: 26696 | S136: 16748 | T136: 57550 | U136: 11077 | V136: 336922 | W136: 34161 | X136: 120094 | Y136: 59389 | Z136: 32078 | AA136: 34825 | AB136: 75094 | AC136: =0.6*CE136 -> 37091.4 | AD136: =(1-0.6)*CE136 -> 24727.6 | AE136: 79845 | AF136: 44607 | AG136: 56967 | AH136: 71494 | AI136: 54961 | AJ136: 82995 | AK136: 124036 | AL136: 52081 | AM136: 38950 | AN136: 39022 | AO136: 40275 | AP136: =2/3*CF136 -> 116866 | AQ136: =1/3*CF136 -> 58433 | AR136: 25127 | AS136: 336290 | AT136: 415048 | AU136: 187084 | AV136: 11322 | AW136: 30456 | AX136: 50054 | AY136: 10865 | AZ136: 113919 | BA136: 11729 | BB136: 24162 | BC136: 95736 | BD136: 42835 | BE136: 209334 | BF136: 47045 | BG136: 62343 | BH136: 25978 | BI136: 60911 | BJ136: 16122 | BK136: 61584 | BL136: 7012 | BM136: 210478 | BN136: 51733 | BO136: 34132 | BP136: 60011 | BQ136: 89394 | BR136: 15492 | BS136: 74559 | BT136: 0 | BU136: 5071268 | BV136: 773468 | BW136: 1185776 | BX136: 87323 | BY136: 3747870 | BZ136: 1069397 | CA136: -25433 | CB136: 6838401 | CC136: 11909669 | CE136: 61819 | CF136: 175299
BV137: =SUM(D136:BT136) -> 5071268
C138: Remunerações | D138: 26121 | E138: 21490 | F138: 2199 | G138: 4040 | H138: 22138 | I138: 4349 | J138: 2264 | K138: 25736 | L138: 8420 | M138: 28893 | N138: 8407 | O138: 1379 | P138: 9992 | Q138: 17703 | R138: 9781 | S138: 5910 | T138: 11483 | U138: 5677 | V138: 6968 | W138: 6275 | X138: 11285 | Y138: 9342 | Z138: 5589 | AA138: 11215 | AB138: 20552 | AC138: 20003 | AE138: 12073 | AF138: 22659 | AG138: 10116 | AH138: 14442 | AI138: 28171 | AJ138: 20227 | AK138: 17896 | AL138: 9718 | AM138: 16132 | AN138: 11883 | AO138: 16133 | AP138: 16809 | AR138: 126609 | AS138: 44837 | AT138: 299831 | AU138: 78373 | AV138: 5048 | AW138: 7103 | AX138: 40882 | AY138: 9604 | AZ138: 47868 | BA138: 6996 | BB138: 10394 | BC138: 17317 | BD138: 46704 | BE138: 143243 | BF138: 6713 | BG138: 52463 | BH138: 21956 | BI138: 11200 | BJ138: 10547 | BK138: 99876 | BL138: 28312 | BM138: 438035 | BN138: 246146 | BO138: 68720 | BP138: 113676 | BQ138: 67773 | BR138: 10977 | BS138: 39513 | BT138: 61996 | BU138: 2666182 | BV138: 2666182
C139: Outros impostos sobre a produção | D139: 1255 | E139: 564 | F139: 123 | G139: 177 | H139: 1210 | I139: 354 | J139: 138 | K139: 1875 | L139: 604 | M139: 2126 | N139: 717 | O139: 101 | P139: 419 | Q139: 583 | R139: 409 | S139: 264 | T139: 645 | U139: 234 | V139: 1007 | W139: 372 | X139: 969 | Y139: 570 | Z139: 339 | AA139: 514 | AB139: 945 | AC139: 855 | AE139: 766 | AF139: 926 | AG139: 768 | AH139: 671 | AI139: 1215 | AJ139: 1160 | AK139: 775 | AL139: 474 | AM139: 643 | AN139: 387 | AO139: 2114 | AP139: 656 | AR139: 4023 | AS139: 1271 | AT139: 10006 | AU139: 2944 | AV139: 370 | AW139: 574 | AX139: 1611 | AY139: 323 | AZ139: 1374 | BA139: 237 | BB139: 1273 | BC139: 4701 | BD139: 1570 | BE139: 7277 | BF139: 358 | BG139: 2003 | BH139: 712 | BI139: 383 | BJ139: 454 | BK139: 2724 | BL139: 872 | BM139: 136 | BN139: 4 | BO139: 2064 | BP139: 1 | BQ139: 2209 | BR139: 250 | BS139: 1048 | BT139: 0 | BU139: 78696 | BV139: 78696
C140: Total industry output (basic value) | D140: =SUM(D136,D138,D139) -> 173550 | E140: =SUM(E136,E138,E139) -> 87623 | F140: =SUM(F136,F138,F139) -> 10342 | G140: =SUM(G136,G138,G139) -> 15095 | H140: =SUM(H136,H138,H139) -> 121776 | I140: =SUM(I136,I138,I139) -> 33540 | J140: =SUM(J136,J138,J139) -> 14063 | K140: =SUM(K136,K138,K139) -> 242432 | ... BU140: =SUM(BU136,BU138,BU139) -> 7816146
C141: Outros subsídios à produção | D141: -10763 | E141: -168 | F141: -42 | G141: -91 | H141: 0 | I141: -36 | J141: 0 | K141: -121 | L141: -169 | M141: -157 | N141: -47 | O141: 0 | P141: -31 | Q141: 0 | R141: 0 | S141: -46 | T141: -118 | U141: 0 | V141: -223 | W141: -198 | X141: -45 | Y141: 0 | Z141: 0 | AA141: -31 | AB141: -178 | AC141: -147 | AE141: -80 | AF141: -98 | AG141: 0 | AH141: -110 | AI141: -289 | AJ141: -326 | AK141: -266 | AL141: -74 | AM141: -42 | AN141: 0 | AO141: -807 | AP141: -46 | AR141: -540 | AS141: -42 | AT141: -1375 | AU141: -2421 | AV141: 0 | AW141: -37 | AX141: -72 | AY141: 0 | AZ141: 0 | BA141: 0 | BB141: 0 | BC141: -95 | BD141: 0 | BE141: 0 | BF141: 0 | BG141: 0 | BH141: -642 | BI141: 0 | BJ141: -230 | BK141: -72 | BL141: 0 | BM141: 0 | BN141: 0 | BO141: 0 | BP141: 0 | BQ141: -36 | BR141: 0 | BS141: 0 | BT141: 0 | BU141: -20311 | BV141: -20311
...

Sheet SCNSup128
A1: Tabela 01 - Recursos de bens e serviços - 2015
A3: Código do produto nível 67 | B3: Matching ISIC Code | C3: Produção das atividades (valores correntes em 1 000 000 R$)
C4: Descrição do produto nível 67 | D4: Agricultura, inclusive o apoio à agricultura e a pós-colheita | E4: Pecuária, inclusive o apoio à pecuária | F4: Produção florestal; pesca e aquicultura | G4: Extração de carvão mineral e de minerais não metálicos | H4: Extração de petróleo e gás, inclusive as atividades de apoio | I4: Extração de minério de ferro, inclusive beneficiamentos e a aglomeração | J4: Extração de minerais metálicos não ferrosos, inclusive beneficiamentos | K4: Abate e produtos de carne, inclusive os produtos do laticínio e da pesca | L4: Fabricação e refino de açúcar | M4: Outros produtos alimentares | N4: Fabricação de bebidas | O4: Fabricação de produtos do fumo | P4: Fabricação de produtos têxteis | Q4: Confecção de artefatos do vestuário e acessórios | R4: Fabricação de calçados e de artefatos de couro | S4: Fabricação de produtos da madeira | T4: Fabricação de celulose, papel e produtos de papel | U4: Impressão e reprodução de gravações | V4: Refino de petróleo e coquerias | W4: Fabricação de biocombustíveis | X4: Fabricação de químicos orgânicos e inorgânicos, resinas e elastômeros | Y4: Fabricação de defensivos, desinfestantes, tintas e químicos diversos | Z4: Fabricação de produtos de limpeza, cosméticos/perfumaria e higiene pessoal | AA4: Fabricação de produtos farmoquímicos e farmacêuticos | AB4: Fabricação de produtos de borracha e de material plástico | AC4: Cimento / Artefatos de cimento, gesso e semelhantes | AD4: Vidros, cerâmicos e outros prod. de minerais não-metálicos | AE4: Produção de ferro gusa/ferroligas, siderurgia e tubos de aço sem costura | AF4: Metalurgia de metais não ferosos e a fundição de metais | AG4: Fabricação de produtos de metal, exceto máquinas e equipamentos | AH4: Fabricação de equipamentos de informática, produtos eletrônicos e ópticos | AI4: Fabricação de máquinas e equipamentos elétricos | AJ4: Fabricação de máquinas e equipamentos mecânicos | AK4: Fabricação de automóveis, caminhões e ônibus, exceto peças | AL4: Fabricação de peças e acessórios para veículos automotores | AM4: Fabricação de outros equipamentos de transporte, exceto veículos automotores | AN4: Fabricação de móveis e de produtos de indústrias diversas | AO4: Manutenção, reparação e instalação de máquinas e equipamentos | AP4: Transmissão de energia elétrica | AQ4: Produção de gás; processamento de gás natural; distribuição de combustíveis gasosos por redes urbanas | AR4: Água, esgoto e gestão de resíduos | AS4: Construção | AT4: Comércio por atacado e varejo | AU4: Transporte terrestre | AV4: Transporte aquaviário | AW4: Transporte aéreo | AX4: Armazenamento, atividades auxiliares dos transportes e correio | AY4: Alojamento | AZ4: Alimentação | BA4: Edição e edição integrada à impressão | BB4: Atividades de televisão, rádio, cinema e gravação/edição de som e imagem | BC4: Telecomunicações | BD4: Desenvolvimento de sistemas e outros serviços de informação | BE4: Intermediação financeira, seguros e previdência complementar | BF4: Atividades imobiliárias | BG4: Atividades jurídicas, contábeis, consultoria e sedes de empresas | BH4: Serviços de arquitetura, engenharia, testes/análises técnicas e P & D | BI4: Outras atividades profissionais, científicas e técnicas | BJ4: Aluguéis não imobiliários e gestão de ativos de propriedade intelectual | BK4: Outras atividades administrativas e serviços complementares | BL4: Atividades de vigilância, segurança e investigação | BM4: Administração pública, defesa e seguridade social | BN4: Educação pública | BO4: Educação privada | BP4: Saúde pública | BQ4: Saúde privada | BR4: Atividades artísticas, criativas e de espetáculos | BS4: Organizações associativas e outros serviços pessoais | BT4: Serviços domésticos | BU4: Total do produto | BV4: Importação de bens e serviços (valores correntes em 1 000 000 R$) (1) | BX4: Fabricação de produtos de minerais não metálicos | BY4: Energia elétrica, gás natural e outras utilidades
