Workbook
Name dollars_2020_2012: [1]About!$A$104
Name dollars_2021_2012: [1]About!$A$103
Name lignite_multiplier: '[1]Hard Coal and Lig Multipliers'!$N$15
Name nonlignite_multiplier: '[1]Hard Coal and Lig Multipliers'!$N$16
Name nonlignite_multiplier: '[1]Hard Coal and Lig Multipliers'!$N$16
Name nonlignite_multiplier: '[1]Hard Coal and Lig Multipliers'!$N$16
Name nonlignite_multiplier: '[2]Hard Coal and Lig Multipliers'!$N$15

Sheet About
A1: IMFPbFT International Market Fuel Price by Fuel Type
A3: Source: | B3: see fuels/BFPaT and EPS outputs referenced in BAU Fuel Use by Sector tab
A4: Natural Gas Price Source:
B5: AEO Table 60 | C5: https://www.eia.gov/outlooks/aeo/data/browser/#/?id=76-AEO2021&region=0-0&cases=highogs&start=2019&end=2050&f=A&sourcekey=0
B6: AEO Table 13 | C6: https://www.eia.gov/outlooks/aeo/data/browser/#/?id=13-AEO2021&cases=ref2021&sourcekey=0
B7: EIA Natural Gas Prices | C7: https://www.eia.gov/dnav/ng/ng_pri_sum_dcu_nus_m.htm
B8: Henry Hub Prices | C8: https://www.eia.gov/dnav/ng/hist/rngwhhdA.htm
A9: Notes
A10: The prices in this variable should include export taxes, if any. In other words, they should be
A11: the prices paid on the global market. For more details on export taxes, see variable fuels/ETRbF.
A13: Electricity exports are handled separately (in the power sector), not in this variable.
A15: Nuclear here refers to nuclear fuel, i.e. uranium oxide, not electricity from nuclear plants.
A17: We estimate this value based on the prices seen within the United States.
A18: For fuels that vary by sector, we take a weighted average based on the first year consumption in the model.
A20: Natural gas prices
A21: Estimated by creating an average multiplier for pipeline and lng gas compared to henry hub prices.
A22: Use futures prices forecast of henry hub prices multiplied by pipeline and lng multiplier to get forecasted natural gas export prices for 2022-2025.
A23: Linearly interpolated between 2025 and 2030.
A24: Use AEO forecast of henry hub prices multiplied by pipeline and lng multiplier to get forecasted natural gas export prices for 2030-2050.
A25: Created weighted total natural gas export price based on forecasted export volumes of pipeline and lng (AEO 60).
A27: mmbtu per thousand cubic feet | B27: 1.037
A28: 2020 to 2012 $ | B28: 0.887
A29: 2021 to 2012 $ | B29: =0.847 -> 0.847

Sheet AEO21 Table13
A1: Table 13. Natural Gas Supply, Disposition, and Prices
A2: https://www.eia.gov/outlooks/aeo/data/browser/#/?id=13-AEO2021&cases=ref2021&sourcekey=0
A3: Fri Mar 19 2021 13:32:00 GMT-0700 (Pacific Daylight Time)
A4: Source: U.S. Energy Information Administration
B5: full name | C5: api key | D5: units | E5: 2019 | F5: 2020 | G5: 2021 | H5: 2022 | I5: 2023 | J5: 2024 | K5: 2025 | L5: 2026 | M5: 2027 | N5: 2028 | O5: 2029 | P5: 2030 | Q5: 2031 | R5: 2032 | S5: 2033 | T5: 2034 | U5: 2035 | V5: 2036 | W5: 2037 | X5: 2038 | Y5: 2039 | Z5: 2040 | AA5: 2041 | AB5: 2042 | AC5: 2043 | AD5: 2044 | AE5: 2045 | AF5: 2046 | AG5: 2047 | AH5: 2048 | AI5: 2049 | AJ5: 2050 | AK5: Growth (2020-2050)
A6: Production | C6: 13-AEO2021.2.
A7: Dry Gas Production | B7: Natural Gas: Production: Dry Gas Production: Reference case | C7: 13-AEO2021.3.ref2021-d113020a | D7: Tcf | F7: 33.890736 | G7: 32.309692 | H7: 32.780651 | I7: 34.02206 | J7: 34.964745 | K7: 36.261745 | L7: 36.88525 | M7: 37.021378 | N7: 37.19635 | O7: 37.54443 | P7: 37.881168 | Q7: 38.134373 | R7: 38.298534 | S7: 38.468994 | T7: 38.611877 | U7: 38.613323 | V7: 38.774208 | W7: 38.983143 | X7: 39.289341 | Y7: 39.585915 | Z7: 39.916763 | AA7: 40.111534 | AB7: 40.487705 | AC7: 40.920616 | AD7: 41.286839 | AE7: 41.538971 | AF7: 41.804253 | AG7: 42.065693 | AH7: 42.392258 | AI7: 42.658817 | AJ7: 42.992821 | AK7: 0.008
A8: Supplemental Natural Gas | B8: Natural Gas: Production: Supplemental Natural Gas: Reference case | C8: 13-AEO2021.4.ref2021-d113020a | D8: Tcf | F8: 0.06535 | G8: 0.06094 | H8: 0.061172 | I8: 0.061404 | J8: 0.061636 | K8: 0.061867 | L8: 0.062099 | M8: 0.062099 | N8: 0.062099 | O8: 0.062099 | P8: 0.062099 | Q8: 0.062099 | R8: 0.062099 | S8: 0.062099 | T8: 0.062099 | U8: 0.062099 | V8: 0.062099 | W8: 0.062099 | X8: 0.062099 | Y8: 0.062099 | Z8: 0.062099 | AA8: 0.062099 | AB8: 0.062099 | AC8: 0.062099 | AD8: 0.062099 | AE8: 0.062099 | AF8: 0.062099 | AG8: 0.062099 | AH8: 0.062099 | AI8: 0.062099 | AJ8: 0.062099 | AK8: -0.002
A9: Net Imports | B9: Natural Gas: Net Imports: Reference case | C9: 13-AEO2021.6.ref2021-d113020a | D9: Tcf | F9: -2.670551 | G9: -3.649866 | H9: -3.840418 | I9: -4.24364 | J9: -4.846223 | K9: -5.320686 | L9: -5.550917 | M9: -5.669797 | N9: -5.930669 | O9: -6.238175 | P9: -6.688156 | Q9: -6.812176 | R9: -6.892396 | S9: -7.006797 | T9: -7.029311 | U9: -7.027888 | V9: -7.064267 | W9: -7.053469 | X9: -7.046336 | Y9: -7.060203 | Z9: -7.092656 | AA9: -7.083726 | AB9: -7.127188 | AC9: -7.165261 | AD9: -7.237316 | AE9: -7.247638 | AF9: -7.295463 | AG9: -7.328695 | AH9: -7.393071 | AI9: -7.388108 | AJ9: -7.403225 | AK9: 0.035
A10: Pipeline | B10: Natural Gas: Net Imports: Pipeline: Reference case | C10: 13-AEO2021.7.ref2021-d113020a | D10: Tcf | F10: -0.421029 | G10: -0.546257 | H10: -0.791407 | I10: -1.155499 | J10: -1.383807 | K10: -1.301577 | L10: -1.202922 | M10: -1.321801 | N10: -1.470551 | O10: -1.590179 | P10: -1.84016 | Q10: -1.864181 | R10: -1.932277 | S10: -2.058801 | T10: -2.081315 | U10: -2.079893 | V10: -2.104148 | W10: -2.105474 | X10: -2.09834 | Y10: -2.112207 | Z10: -2.132536 | AA10: -2.13573 | AB10: -2.179192 | AC10: -2.217265 | AD10: -2.277197 | AE10: -2.299642 | AF10: -2.347467 | AG10: -2.380699 | AH10: -2.432952 | AI10: -2.440112 | AJ10: -2.455229 | AK10: 0.061
A11: Liquefied Natural Gas | B11: Natural Gas: Net Imports: Liquefied Natural Gas: Reference case | C11: 13-AEO2021.8.ref2021-d113020a | D11: Tcf | F11: -2.249521 | G11: -3.10361 | H11: -3.049012 | I11: -3.08814 | J11: -3.462417 | K11: -4.019109 | L11: -4.347996 | M11: -4.347996 | N11: -4.460119 | O11: -4.647996 | P11: -4.847996 | Q11: -4.947996 | R11: -4.960119 | S11: -4.947996 | T11: -4.947996 | U11: -4.947996 | V11: -4.960119 | W11: -4.947996 | X11: -4.947996 | Y11: -4.947996 | Z11: -4.960119 | AA11: -4.947996 | AB11: -4.947996 | AC11: -4.947996 | AD11: -4.960119 | AE11: -4.947996 | AF11: -4.947996 | AG11: -4.947996 | AH11: -4.960119 | AI11: -4.947996 | AJ11: -4.947996 | AK11: 0.027
A12: Total Supply | B12: Natural Gas: Total Supply: Reference case | C12: 13-AEO2021.10.ref2021-d113020a | D12: Tcf | F12: 31.285534 | G12: 28.720766 | H12: 29.001406 | I12: 29.839825 | J12: 30.180155 | K12: 31.002926 | L12: 31.396433 | M12: 31.413681 | N12: 31.32778 | O12: 31.368355 | P12: 31.255112 | Q12: 31.384296 | R12: 31.468239 | S12: 31.524296 | T12: 31.644665 | U12: 31.647533 | V12: 31.772041 | W12: 31.991774 | X12: 32.305103 | Y12: 32.587811 | Z12: 32.886208 | AA12: 33.089909 | AB12: 33.422615 | AC12: 33.817455 | AD12: 34.111622 | AE12: 34.353432 | AF12: 34.570889 | AG12: 34.799099 | AH12: 35.061287 | AI12: 35.332809 | AJ12: 35.651695 | AK12: 0.004
A13: Consumption by Sector | B13: Natural Gas: Use by Sector: Total: Reference case | C13: 13-AEO2021.12.ref2021-d113020a | D13: Tcf | F13: 30.759628 | G13: 28.969814 | H13: 29.133207 | I13: 29.864119 | J13: 30.095409 | K13: 30.814251 | L13: 31.112349 | M13: 31.129002 | N13: 31.027622 | O13: 31.079346 | P13: 30.969501 | Q13: 31.118366 | R13: 31.182737 | S13: 31.255699 | T13: 31.386862 | U13: 31.384893 | V13: 31.516623 | W13: 31.740519 | X13: 32.048031 | Y13: 32.346977 | Z13: 32.653408 | AA13: 32.848423 | AB13: 33.185112 | AC13: 33.58342 | AD13: 33.875362 | AE13: 34.116329 | AF13: 34.339634 | AG13: 34.553959 | AH13: 34.812855 | AI13: 35.075024 | AJ13: 35.391342 | AK13: 0.005
A14: Residential | B14: Natural Gas: Use by Sector: Residential: Reference case | C14: 13-AEO2021.13.ref2021-d113020a | D14: Tcf | F14: 4.78282 | G14: 4.659657 | H14: 4.791546 | I14: 4.784126 | J14: 4.785736 | K14: 4.781549 | L14: 4.770129 | M14: 4.757244 | N14: 4.746172 | O14: 4.735456 | P14: 4.719688 | Q14: 4.708289 | R14: 4.699761 | S14: 4.691553 | T14: 4.683408 | U14: 4.677774 | V14: 4.673339 | W14: 4.668981 | X14: 4.664959 | Y14: 4.661228 | Z14: 4.659263 | AA14: 4.657234 | AB14: 4.655647 | AC14: 4.654244 | AD14: 4.653849 | AE14: 4.652879 | AF14: 4.652227 | AG14: 4.650692 | AH14: 4.64872 | AI14: 4.645582 | AJ14: 4.642358 | AK14: -0.001
A15: Commercial | B15: Natural Gas: Use by Sector: Commercial: Reference case | C15: 13-AEO2021.14.ref2021-d113020a | D15: Tcf | F15: 3.18868 | G15: 3.293635 | H15: 3.266141 | I15: 3.372137 | J15: 3.435285 | K15: 3.491935 | L15: 3.498285 | M15: 3.500263 | N15: 3.501419 | O15: 3.50007 | P15: 3.491981 | Q15: 3.493029 | R15: 3.498033 | S15: 3.502732 | T15: 3.506851 | U15: 3.513099 | V15: 3.520664 | W15: 3.527468 | X15: 3.533231 | Y15: 3.53841 | Z15: 3.544436 | AA15: 3.551436 | AB15: 3.558698 | AC15: 3.56541 | AD15: 3.572658 | AE15: 3.578047 | AF15: 3.583146 | AG15: 3.586689 | AH15: 3.58899 | AI15: 3.589589 | AJ15: 3.58919 | AK15: 0.004
A16: Industrial | B16: Natural Gas: Use by Sector: Industrial: Reference case | C16: 13-AEO2021.15.ref2021-d113020a | D16: Tcf | F16: 10.307474 | G16: 10.324542 | H16: 10.423319 | I16: 10.710521 | J16: 11.029292 | K16: 11.326619 | L16: 11.520507 | M16: 11.549958 | N16: 11.634205 | O16: 11.729107 | P16: 11.80891 | Q16: 11.905672 | R16: 11.966723 | S16: 12.03717 | T16: 12.138468 | U16: 12.221153 | V16: 12.301403 | W16: 12.389917 | X16: 12.489612 | Y16: 12.605134 | Z16: 12.706349 | AA16: 12.799595 | AB16: 12.950118 | AC16: 13.115742 | AD16: 13.225972 | AE16: 13.295372 | AF16: 13.43231 | AG16: 13.543573 | AH16: 13.651255 | AI16: 13.769857 | AJ16: 13.904431 | AK16: 0.01
A17: Other Industrial | B17: Natural Gas: Use by Sector: Industrial: Other: Reference case | C17: 13-AEO2021.16.ref2021-d113020a | D17: Tcf | F17: 8.161885 | G17: 8.103975 | H17: 8.140368 | I17: 8.363998 | J17: 8.611549 | K17: 8.774698 | L17: 8.886193 | M17: 8.900866 | N17: 8.950128 | O17: 8.999684 | P17: 9.019031 | Q17: 9.0755 | R17: 9.115315 | S17: 9.152719 | T17: 9.230459 | U17: 9.311929 | V17: 9.389535 | W17: 9.471344 | X17: 9.563922 | Y17: 9.661481 | Z17: 9.740618 | AA17: 9.821562 | AB17: 9.945354 | AC17: 10.071958 | AD17: 10.160589 | AE17: 10.23168 | AF17: 10.348585 | AG17: 10.451379 | AH17: 10.546 | AI17: 10.665246 | AJ17: 10.796975 | AK17: 0.009
A18: Lease and Plant Fuel | B18: Natural Gas: Use by Sector: Industrial: Lease and Plant Fuel: Reference case | C18: 13-AEO2021.17.ref2021-d113020a | D18: Tcf | F18: 1.798462 | G18: 1.743226 | H18: 1.813852 | I18: 1.871607 | J18: 1.88674 | K18: 1.937467 | L18: 1.970579 | M18: 1.985358 | N18: 2.003525 | O18: 2.020688 | P18: 2.051146 | Q18: 2.076438 | R18: 2.095855 | S18: 2.130717 | T18: 2.154274 | U18: 2.15549 | V18: 2.156316 | W18: 2.164839 | X18: 2.171955 | Y18: 2.189918 | Z18: 2.21018 | AA18: 2.224298 | AB18: 2.25103 | AC18: 2.290049 | AD18: 2.30983 | AE18: 2.309958 | AF18: 2.329991 | AG18: 2.338459 | AH18: 2.349702 | AI18: 2.350877 | AJ18: 2.353721 | AK18: 0.009
A19: Fuel Used to Liquefy Gas for Export | B19: Natural Gas: Use by Sector: Industrial: Liquefaction for Export: Reference case | C19: 13-AEO2021.18.ref2021-d113020a | D19: Tcf | F19: 0.347127 | G19: 0.477341 | H19: 0.469098 | I19: 0.474914 | J19: 0.531003 | K19: 0.614454 | L19: 0.663734 | M19: 0.663734 | N19: 0.680553 | O19: 0.708734 | P19: 0.738734 | Q19: 0.753734 | R19: 0.755553 | S19: 0.753734 | T19: 0.753734 | U19: 0.753734 | V19: 0.755553 | W19: 0.753734 | X19: 0.753734 | Y19: 0.753734 | Z19: 0.755553 | AA19: 0.753734 | AB19: 0.753734 | AC19: 0.753734 | AD19: 0.755553 | AE19: 0.753734 | AF19: 0.753734 | AG19: 0.753734 | AH19: 0.755553 | AI19: 0.753734 | AJ19: 0.753734 | AK19: 0.026
A20: Natural Gas-to-Liquids Heat and Power | B20: Natural Gas: Use by Sector: Industrial: GTL Heat and Power: Reference case | C20: 13-AEO2021.19.ref2021-d113020a | D20: Tcf | F20: 0 | G20: 0 | H20: 0 | I20: 0 | J20: 0 | K20: 0 | L20: 0 | M20: 0 | N20: 0 | O20: 0 | P20: 0 | Q20: 0 | R20: 0 | S20: 0 | T20: 0 | U20: 0 | V20: 0 | W20: 0 | X20: 0 | Y20: 0 | Z20: 0 | AA20: 0 | AB20: 0 | AC20: 0 | AD20: 0 | AE20: 0 | AF20: 0 | AG20: 0 | AH20: 0 | AI20: 0 | AJ20: 0 | AK20: - -
A21: Natural Gas to Liquids Production | B21: Natural Gas: Use by Sector: Industrial: GTL Liquids: Reference case | C21: 13-AEO2021.20.ref2021-d113020a | D21: Tcf | F21: 0 | G21: 0 | H21: 0 | I21: 0 | J21: 0 | K21: 0 | L21: 0 | M21: 0 | N21: 0 | O21: 0 | P21: 0 | Q21: 0 | R21: 0 | S21: 0 | T21: 0 | U21: 0 | V21: 0 | W21: 0 | X21: 0 | Y21: 0 | Z21: 0 | AA21: 0 | AB21: 0 | AC21: 0 | AD21: 0 | AE21: 0 | AF21: 0 | AG21: 0 | AH21: 0 | AI21: 0 | AJ21: 0 | AK21: - -
A22: Transportation | B22: Natural Gas: Use by Sector: Transportation: Reference case | C22: 13-AEO2021.21.ref2021-d113020a | D22: Tcf | F22: 0.765735 | G22: 0.843826 | H22: 0.824717 | I22: 0.79586 | J22: 0.767088 | K22: 0.765038 | L22: 0.730884 | M22: 0.734135 | N22: 0.742233 | O22: 0.750429 | P22: 0.747803 | Q22: 0.763764 | R22: 0.779739 | S22: 0.792384 | T22: 0.805472 | U22: 0.821334 | V22: 0.834601 | W22: 0.848805 | X22: 0.866594 | Y22: 0.881065 | Z22: 0.909393 | AA22: 0.92513 | AB22: 0.949754 | AC22: 0.97281 | AD22: 0.996973 | AE22: 1.013085 | AF22: 1.039627 | AG22: 1.060481 | AH22: 1.080297 | AI22: 1.102157 | AJ22: 1.126101 | AK22: 0.013
A23: Motor Vehicles | B23: Trains | C23: and Ships | D23: Natural Gas: Use by Sector: Transportation: Vehicles: Reference case | E23: 13-AEO2021.22.ref2021-d113020a | F23: Tcf | H23: 0.084656 | I23: 0.109117 | J23: 0.095128 | K23: 0.103537 | L23: 0.111005 | M23: 0.123857 | N23: 0.129723 | O23: 0.138251 | P23: 0.147405 | Q23: 0.156129 | R23: 0.158139 | S23: 0.172918 | T23: 0.183914 | U23: 0.194109 | V23: 0.205109 | W23: 0.216278 | X23: 0.226467 | Y23: 0.236582 | Z23: 0.249709 | AA23: 0.260067 | AB23: 0.281876 | AC23: 0.293851 | AD23: 0.313053 | AE23: 0.328496 | AF23: 0.345042 | AG23: 0.356012 | AH23: 0.374896 | AI23: 0.391496 | AJ23: 0.405643 | AK23: 0.420723 | AL23: 0.437008 | AM23: 0.056
A24: Pipeline and Distribution Fuel | B24: Natural Gas: Use by Sector: Transportation: Pipeline Fuel: Reference case | C24: 13-AEO2021.23.ref2021-d113020a | D24: Tcf | F24: 0.681079 | G24: 0.734709 | H24: 0.729589 | I24: 0.692323 | J24: 0.656083 | K24: 0.64118 | L24: 0.601161 | M24: 0.595884 | N24: 0.594828 | O24: 0.594301 | P24: 0.589664 | Q24: 0.590846 | R24: 0.595825 | S24: 0.598276 | T24: 0.600363 | U24: 0.605056 | V24: 0.608135 | W24: 0.612223 | X24: 0.616885 | Y24: 0.620998 | Z24: 0.627518 | AA24: 0.631279 | AB24: 0.636701 | AC24: 0.644314 | AD24: 0.651931 | AE24: 0.657074 | AF24: 0.664731 | AG24: 0.668984 | AH24: 0.674654 | AI24: 0.681434 | AJ24: 0.689093 | AK24: 0
A25: Electric Power | B25: Natural Gas: Use by Sector: Electric Power: Reference case | C25: 13-AEO2021.24.ref2021-d113020a | D25: Tcf | F25: 11.71492 | G25: 9.848155 | H25: 9.827483 | I25: 10.201474 | J25: 10.078012 | K25: 10.449108 | L25: 10.592544 | M25: 10.587401 | N25: 10.40359 | O25: 10.364284 | P25: 10.201119 | Q25: 10.247613 | R25: 10.238481 | S25: 10.231859 | T25: 10.252663 | U25: 10.151533 | V25: 10.186614 | W25: 10.305348 | X25: 10.493639 | Y25: 10.661141 | Z25: 10.833966 | AA25: 10.915029 | AB25: 11.070894 | AC25: 11.275215 | AD25: 11.425906 | AE25: 11.576945 | AF25: 11.632323 | AG25: 11.712527 | AH25: 11.843592 | AI25: 11.967836 | AJ25: 12.12926 | AK25: 0.001
A26: Discrepancy | B26: Natural Gas: Discrepancy: Reference case | C26: 13-AEO2021.26.ref2021-d113020a | D26: Tcf | F26: 0.525906 | G26: -0.249048 | H26: -0.131802 | I26: -0.024294 | J26: 0.084745 | K26: 0.188675 | L26: 0.284084 | M26: 0.284679 | N26: 0.300158 | O26: 0.289009 | P26: 0.28561 | Q26: 0.26593 | R26: 0.285501 | S26: 0.268597 | T26: 0.257803 | U26: 0.26264 | V26: 0.255419 | W26: 0.251255 | X26: 0.257072 | Y26: 0.240833 | Z26: 0.2328 | AA26: 0.241486 | AB26: 0.237503 | AC26: 0.234035 | AD26: 0.236259 | AE26: 0.237103 | AF26: 0.231255 | AG26: 0.24514 | AH26: 0.248432 | AI26: 0.257786 | AJ26: 0.260353 | AK26: - -
A27: Natural Gas Prices | C27: 13-AEO2021.28.
A28: Natural Gas Spot Price at Henry Hub | C28: 13-AEO2021.30.
A29: (2020 dollars per million Btu) | B29: Natural Gas: Henry Hub Spot Price: Reference case | C29: 13-AEO2021.31.ref2021-d113020a | D29: 2020 $/MMBtu | F29: 2.066472 | G29: 3.10073 | H29: 3.225684 | I29: 2.992324 | J29: 2.801792 | K29: 2.880324 | L29: 2.984331 | M29: 3.042141 | N29: 3.17551 | O29: 3.290631 | P29: 3.343955 | Q29: 3.358484 | R29: 3.423043 | S29: 3.48721 | T29: 3.51704 | U29: 3.532698 | V29: 3.537317 | W29: 3.52832 | X29: 3.54974 | Y29: 3.550356 | Z29: 3.549253 | AA29: 3.549023 | AB29: 3.528726 | AC29: 3.505651 | AD29: 3.501869 | AE29: 3.507699 | AF29: 3.521007 | AG29: 3.547183 | AH29: 3.59621 | AI29: 3.654005 | AJ29: 3.693939 | AK29: 0.02
A30: Delivered Prices | C30: 13-AEO2021.33.
A31: (2020 dollars per thousand cubic feet) | C31: 13-AEO2021.34.
A32: Residential | B32: Natural Gas: Delivered Prices: Residential: Reference case | C32: 13-AEO2021.35.ref2021-d113020a | D32: 2020 $/Mcf | F32: 10.537243 | G32: 10.814795 | H32: 10.740482 | I32: 10.613196 | J32: 10.451303 | K32: 10.547084 | L32: 10.694221 | M32: 10.79739 | N32: 10.914479 | O32: 11.0551 | P32: 11.419861 | Q32: 11.468187 | R32: 11.564026 | S32: 11.677169 | T32: 11.745335 | U32: 11.781732 | V32: 11.798117 | W32: 11.826159 | X32: 11.858226 | Y32: 11.879637 | Z32: 11.886778 | AA32: 11.91252 | AB32: 11.921178 | AC32: 11.935447 | AD32: 11.940625 | AE32: 11.975809 | AF32: 11.995084 | AG32: 12.039871 | AH32: 12.087629 | AI32: 12.154815 | AJ32: 12.216571 | AK32: 0.005
A33: Commercial | B33: Natural Gas: Delivered Prices: Commercial: Reference case | C33: 13-AEO2021.36.ref2021-d113020a | D33: 2020 $/Mcf | F33: 7.509337 | G33: 7.950109 | H33: 8.195803 | I33: 8.02144 | J33: 7.832705 | K33: 7.89473 | L33: 8.004504 | M33: 8.068838 | N33: 8.151382 | O33: 8.259359 | P33: 8.515853 | Q33: 8.52672 | R33: 8.583048 | S33: 8.67097 | T33: 8.719043 | U33: 8.738714 | V33: 8.740422 | W33: 8.753948 | X33: 8.771951 | Y33: 8.782027 | Z33: 8.779941 | AA33: 8.796523 | AB33: 8.795634 | AC33: 8.80281 | AD33: 8.799577 | AE33: 8.826352 | AF33: 8.838455 | AG33: 8.874834 | AH33: 8.914612 | AI33: 8.971898 | AJ33: 9.024093 | AK33: 0.006
A34: Industrial | B34: Natural Gas: Delivered Prices: Industrial: Reference case | C34: 13-AEO2021.37.ref2021-d113020a | D34: 2020 $/Mcf | F34: 3.180391 | G34: 4.162838 | H34: 4.314582 | I34: 4.083631 | J34: 3.864322 | K34: 3.927631 | L34: 4.02624 | M34: 4.089579 | N34: 4.214507 | O34: 4.329679 | P34: 4.361543 | Q34: 4.370373 | R34: 4.424331 | S34: 4.498998 | T34: 4.53306 | U34: 4.544279 | V34: 4.544791 | W34: 4.533345 | X34: 4.552034 | Y34: 4.544717 | Z34: 4.535112 | AA34: 4.531607 | AB34: 4.51222 | AC34: 4.494655 | AD34: 4.485391 | AE34: 4.492876 | AF34: 4.495961 | AG34: 4.518952 | AH34: 4.560307 | AI34: 4.615804 | AJ34: 4.655444 | AK34: 0.013
A35: Transportation | B35: Natural Gas: Delivered Prices: Transportation: Reference case | C35: 13-AEO2021.38.ref2021-d113020a | D35: 2020 $/Mcf | F35: 13.520962 | G35: 14.078305 | H35: 14.653452 | I35: 14.196401 | J35: 13.728652 | K35: 13.486947 | L35: 13.341523 | M35: 13.131707 | N35: 12.934259 | O35: 12.743641 | P35: 13.253026 | Q35: 12.973546 | R35: 12.892562 | S35: 12.76227 | T35: 12.617708 | U35: 12.479836 | V35: 12.351564 | W35: 12.229142 | X35: 12.174371 | Y35: 12.077763 | Z35: 12.032022 | AA35: 11.955648 | AB35: 11.89168 | AC35: 11.826577 | AD35: 11.777018 | AE35: 11.745801 | AF35: 11.726257 | AG35: 11.724689 | AH35: 11.734485 | AI35: 11.769066 | AJ35: 11.790224 | AK35: -0.005
A36: Electric Power | B36: Natural Gas: Delivered Prices: Electric Power: Reference case | C36: 13-AEO2021.39.ref2021-d113020a | D36: 2020 $/Mcf | F36: 2.530745 | G36: 3.61926 | H36: 3.726939 | I36: 3.487904 | J36: 3.256875 | K36: 3.348767 | L36: 3.439697 | M36: 3.485474 | N36: 3.600854 | O36: 3.708318 | P36: 3.732601 | Q36: 3.730784 | R36: 3.78701 | S36: 3.856758 | T36: 3.891376 | U36: 3.891621 | V36: 3.89395 | W36: 3.873144 | X36: 3.903093 | Y36: 3.901399 | Z36: 3.900083 | AA36: 3.889824 | AB36: 3.875112 | AC36: 3.858833 | AD36: 3.858512 | AE36: 3.866042 | AF36: 3.870427 | AG36: 3.890644 | AH36: 3.940309 | AI36: 3.991955 | AJ36: 4.034189 | AK36: 0.016
A37: Average | B37: Natural Gas: Delivered Prices: Average: Reference case | C37: 13-AEO2021.40.ref2021-d113020a | D37: 2020 $/Mcf | F37: 4.693558 | G37: 5.66904 | H37: 5.794549 | I37: 5.555105 | J37: 5.348705 | K37: 5.398383 | L37: 5.486406 | M37: 5.548413 | N37: 5.672808 | O37: 5.787228 | P37: 5.912332 | Q37: 5.917324 | R37: 5.978648 | S37: 6.057963 | T37: 6.093779 | U37: 6.110519 | V37: 6.108442 | W37: 6.090482 | X37: 6.0977 | Y37: 6.08242 | Z37: 6.06673 | AA37: 6.059522 | AB37: 6.034441 | AC37: 6.006975 | AD37: 5.992235 | AE37: 5.994117 | AF37: 5.99522 | AG37: 6.014273 | AH37: 6.048097 | AI37: 6.091946 | AJ37: 6.122423 | AK37: 0.009
A38: Natural Gas Spot Price at Henry Hub | C38: 13-AEO2021.59.
A39: (nominal dollars per million Btu) | B39: Natural Gas: Henry Hub Spot Price: Reference case | C39: 13-AEO2021.60.ref2021-d113020a | D39: nom $/MMBtu | F39: 2.066472 | G39: 3.133435 | H39: 3.297882 | I39: 3.100855 | J39: 2.952188 | K39: 3.098166 | L39: 3.286463 | M39: 3.435213 | N39: 3.680265 | O39: 3.914186 | P39: 4.080595 | Q39: 4.201032 | R39: 4.385629 | S39: 4.572134 | T39: 4.714931 | U39: 4.840396 | V39: 4.951261 | W39: 5.042459 | X39: 5.179508 | Y39: 5.287582 | Z39: 5.397773 | AA39: 5.513302 | AB39: 5.602274 | AC39: 5.69328 | AD39: 5.822867 | AE39: 5.976249 | AF39: 6.154725 | AG39: 6.367115 | AH39: 6.63338 | AI39: 6.931768 | AJ39: 7.213103 | AK39: 0.043
A40: Delivered Prices | C40: 13-AEO2021.66.
...

Sheet AEO22 Table13
A1: Table 13. Natural Gas Supply, Disposition, and Prices
A2: https://www.eia.gov/outlooks/aeo/data/browser/#/?id=13-AEO2022&region=0-0&cases=ref2022&start=2020&end=2050&f=A&sourcekey=0
A3: Fri Jun 03 2022 14:36:16 GMT-0700 (Pacific Daylight Time)
A4: Source: U.S. Energy Information Administration
B5: full name | C5: api key | D5: units | E5: 2020 | F5: 2021 | G5: 2022 | H5: 2023 | I5: 2024 | J5: 2025 | K5: 2026 | L5: 2027 | M5: 2028 | N5: 2029 | O5: 2030 | P5: 2031 | Q5: 2032 | R5: 2033 | S5: 2034 | T5: 2035 | U5: 2036 | V5: 2037 | W5: 2038 | X5: 2039 | Y5: 2040 | Z5: 2041 | AA5: 2042 | AB5: 2043 | AC5: 2044 | AD5: 2045 | AE5: 2046 | AF5: 2047 | AG5: 2048 | AH5: 2049 | AI5: 2050 | AJ5: Growth (2021-2050)
A6: Production | C6: 13-AEO2022.2.
A7: Dry Gas Production | B7: Natural Gas: Production: Dry Gas Production: Low economic growth | C7: 13-AEO2022.3.lowmacro-d011222a | D7: Tcf | F7: 34.409626 | G7: 35.322708 | H7: 35.604687 | I7: 35.806705 | J7: 35.905468 | K7: 35.882885 | L7: 35.810017 | M7: 36.400112 | N7: 36.655968 | O7: 36.721214 | P7: 36.966469 | Q7: 37.231819 | R7: 37.474743 | S7: 37.30827 | T7: 37.172085 | U7: 37.122219 | V7: 37.233501 | W7: 37.447079 | X7: 37.700321 | Y7: 37.972595 | Z7: 38.092804 | AA7: 38.278564 | AB7: 38.60881 | AC7: 38.921223 | AD7: 39.147614 | AE7: 39.39146 | AF7: 39.666965 | AG7: 39.861118 | AH7: 40.032658 | AI7: 40.400124 | AJ7: 0.006
A8: Supplemental Natural Gas | B8: Natural Gas: Production: Supplemental Natural Gas: Low economic growth | C8: 13-AEO2022.4.lowmacro-d011222a | D8: Tcf | F8: 0.05953 | G8: 0.06312 | H8: 0.062993 | I8: 0.062865 | J8: 0.062738 | K8: 0.062611 | L8: 0.062483 | M8: 0.062483 | N8: 0.062483 | O8: 0.062483 | P8: 0.062483 | Q8: 0.062483 | R8: 0.062483 | S8: 0.062483 | T8: 0.062483 | U8: 0.062483 | V8: 0.062483 | W8: 0.062483 | X8: 0.062483 | Y8: 0.062483 | Z8: 0.062483 | AA8: 0.062483 | AB8: 0.062483 | AC8: 0.062483 | AD8: 0.062483 | AE8: 0.062483 | AF8: 0.062483 | AG8: 0.062483 | AH8: 0.062483 | AI8: 0.062483 | AJ8: 0.002
A9: Net Imports | B9: Natural Gas: Net Imports: Low economic growth | C9: 13-AEO2022.6.lowmacro-d011222a | D9: Tcf | F9: -4.018888 | G9: -5.032922 | H9: -5.319394 | I9: -5.505922 | J9: -5.795665 | K9: -5.835703 | L9: -6.007035 | M9: -6.346346 | N9: -6.726242 | O9: -7.007736 | P9: -7.372563 | Q9: -7.634319 | R9: -7.706789 | S9: -7.787818 | T9: -7.890796 | U9: -7.918286 | V9: -7.883421 | W9: -7.908661 | X9: -7.962761 | Y9: -8.031993 | Z9: -8.043514 | AA9: -8.068309 | AB9: -8.137873 | AC9: -8.294017 | AD9: -8.36681 | AE9: -8.370378 | AF9: -8.386253 | AG9: -8.38794 | AH9: -8.39177 | AI9: -8.429087 | AJ9: 0.026
A10: Pipeline | B10: Natural Gas: Net Imports: Pipeline: Low economic growth | C10: 13-AEO2022.7.lowmacro-d011222a | D10: Tcf | F10: -0.476819 | G10: -0.916066 | H10: -0.959442 | I10: -1.099447 | J10: -1.217244 | K10: -1.243205 | L10: -1.312514 | M10: -1.43905 | N10: -1.631721 | O10: -1.713215 | P10: -1.878042 | Q10: -1.927022 | R10: -1.912268 | S10: -1.993297 | T10: -2.096275 | U10: -2.11099 | V10: -2.088901 | W10: -2.11414 | X10: -2.16824 | Y10: -2.224696 | Z10: -2.248994 | AA10: -2.273788 | AB10: -2.343352 | AC10: -2.486721 | AD10: -2.572289 | AE10: -2.575856 | AF10: -2.591733 | AG10: -2.580644 | AH10: -2.59725 | AI10: -2.634566 | AJ10: 0.061
A11: Liquefied Natural Gas | B11: Natural Gas: Net Imports: Liquefied Natural Gas: Low economic growth | C11: 13-AEO2022.8.lowmacro-d011222a | D11: Tcf | F11: -3.542069 | G11: -4.116855 | H11: -4.359952 | I11: -4.406474 | J11: -4.578421 | K11: -4.592499 | L11: -4.694521 | M11: -4.907297 | N11: -5.094521 | O11: -5.294521 | P11: -5.494521 | Q11: -5.707297 | R11: -5.794521 | S11: -5.794521 | T11: -5.794521 | U11: -5.807297 | V11: -5.794521 | W11: -5.794521 | X11: -5.794521 | Y11: -5.807297 | Z11: -5.794521 | AA11: -5.794521 | AB11: -5.794521 | AC11: -5.807297 | AD11: -5.794521 | AE11: -5.794521 | AF11: -5.794521 | AG11: -5.807297 | AH11: -5.794521 | AI11: -5.794521 | AJ11: 0.017
A12: Total Supply | B12: Natural Gas: Total Supply: Low economic growth | C12: 13-AEO2022.10.lowmacro-d011222a | D12: Tcf | F12: 30.450266 | G12: 30.352909 | H12: 30.348286 | I12: 30.363649 | J12: 30.172539 | K12: 30.109793 | L12: 29.865467 | M12: 30.116251 | N12: 29.99221 | O12: 29.775963 | P12: 29.656391 | Q12: 29.659985 | R12: 29.830439 | S12: 29.582935 | T12: 29.343773 | U12: 29.266418 | V12: 29.412565 | W12: 29.600903 | X12: 29.800045 | Y12: 30.003086 | Z12: 30.111774 | AA12: 30.272739 | AB12: 30.533422 | AC12: 30.68969 | AD12: 30.843288 | AE12: 31.083569 | AF12: 31.343197 | AG12: 31.535664 | AH12: 31.703373 | AI12: 32.033524 | AJ12: 0.002
A13: Consumption by Sector | B13: Natural Gas: Use by Sector: Total: Low economic growth | C13: 13-AEO2022.12.lowmacro-d011222a | D13: Tcf | F13: 30.242594 | G13: 30.085173 | H13: 30.064831 | I13: 30.056604 | J13: 29.859272 | K13: 29.777143 | L13: 29.518978 | M13: 29.768036 | N13: 29.655115 | O13: 29.44602 | P13: 29.328667 | Q13: 29.327215 | R13: 29.514547 | S13: 29.269196 | T13: 29.029827 | U13: 28.959255 | V13: 29.105549 | W13: 29.295654 | X13: 29.500248 | Y13: 29.703928 | Z13: 29.806578 | AA13: 29.968973 | AB13: 30.229542 | AC13: 30.386457 | AD13: 30.550423 | AE13: 30.797487 | AF13: 31.028425 | AG13: 31.22183 | AH13: 31.388659 | AI13: 31.717159 | AJ13: 0.002
A14: Residential | B14: Natural Gas: Use by Sector: Residential: Low economic growth | C14: 13-AEO2022.13.lowmacro-d011222a | D14: Tcf | F14: 4.819419 | G14: 4.87988 | H14: 4.803436 | I14: 4.816045 | J14: 4.830301 | K14: 4.835493 | L14: 4.835128 | M14: 4.826184 | N14: 4.811259 | O14: 4.796466 | P14: 4.782578 | Q14: 4.765706 | R14: 4.748952 | S14: 4.735481 | T14: 4.726693 | U14: 4.720163 | V14: 4.712776 | W14: 4.704755 | X14: 4.69628 | Y14: 4.689078 | Z14: 4.680464 | AA14: 4.673137 | AB14: 4.667832 | AC14: 4.663457 | AD14: 4.659014 | AE14: 4.653883 | AF14: 4.647811 | AG14: 4.64085 | AH14: 4.632444 | AI14: 4.623201 | AJ14: -0.001
A15: Commercial | B15: Natural Gas: Use by Sector: Commercial: Low economic growth | C15: 13-AEO2022.14.lowmacro-d011222a | D15: Tcf | F15: 3.350484 | G15: 3.482587 | H15: 3.428924 | I15: 3.434704 | J15: 3.444488 | K15: 3.443654 | L15: 3.458211 | M15: 3.461361 | N15: 3.456904 | O15: 3.452962 | P15: 3.453952 | Q15: 3.451528 | R15: 3.448314 | S15: 3.448515 | T15: 3.454259 | U15: 3.462657 | V15: 3.468118 | W15: 3.470585 | X15: 3.471409 | Y15: 3.472769 | Z15: 3.472588 | AA15: 3.475296 | AB15: 3.481176 | AC15: 3.487429 | AD15: 3.493799 | AE15: 3.499022 | AF15: 3.502862 | AG15: 3.505532 | AH15: 3.505991 | AI15: 3.505614 | AJ15: 0.002
A16: Industrial | B16: Natural Gas: Use by Sector: Industrial: Low economic growth | C16: 13-AEO2022.15.lowmacro-d011222a | D16: Tcf | F16: 10.38806 | G16: 10.575246 | H16: 10.486811 | I16: 10.540606 | J16: 10.645499 | K16: 10.709901 | L16: 10.719416 | M16: 10.767504 | N16: 10.779654 | O16: 10.815272 | P16: 10.848524 | Q16: 10.876146 | R16: 10.905524 | S16: 10.913145 | T16: 10.922623 | U16: 10.966375 | V16: 10.982613 | W16: 11.020459 | X16: 11.064152 | Y16: 11.106756 | Z16: 11.119011 | AA16: 11.164563 | AB16: 11.248596 | AC16: 11.29722 | AD16: 11.350711 | AE16: 11.430659 | AF16: 11.498 | AG16: 11.531771 | AH16: 11.566927 | AI16: 11.694829 | AJ16: 0.004
A17: Other Industrial | B17: Natural Gas: Use by Sector: Industrial: Other: Low economic growth | C17: 13-AEO2022.16.lowmacro-d011222a | D17: Tcf | F17: 8.25777 | G17: 8.328052 | H17: 8.209694 | I17: 8.235285 | J17: 8.295445 | K17: 8.354473 | L17: 8.355721 | M17: 8.349208 | N17: 8.332207 | O17: 8.328288 | P17: 8.329494 | Q17: 8.313449 | R17: 8.315689 | S17: 8.332453 | T17: 8.340832 | U17: 8.390054 | V17: 8.412317 | W17: 8.446038 | X17: 8.472146 | Y17: 8.496502 | Z17: 8.513413 | AA17: 8.551575 | AB17: 8.608138 | AC17: 8.642073 | AD17: 8.672221 | AE17: 8.737638 | AF17: 8.794087 | AG17: 8.814433 | AH17: 8.846367 | AI17: 8.932115 | AJ17: 0.003
A18: Lease and Plant Fuel | B18: Natural Gas: Use by Sector: Industrial: Lease and Plant Fuel: Low economic growth | C18: 13-AEO2022.17.lowmacro-d011222a | D18: Tcf | F18: 1.840362 | G18: 1.90736 | H18: 1.917754 | I18: 1.942354 | J18: 1.973323 | K18: 1.97772 | L18: 1.977887 | M18: 2.015253 | N18: 2.029239 | O18: 2.052577 | P18: 2.068422 | Q18: 2.094856 | R18: 2.114927 | S18: 2.105785 | T18: 2.106883 | U18: 2.100379 | V18: 2.095387 | W18: 2.099513 | X18: 2.117098 | Y18: 2.134312 | Z18: 2.130689 | AA18: 2.138081 | AB18: 2.16555 | AC18: 2.179204 | AD18: 2.203582 | AE18: 2.218113 | AF18: 2.229005 | AG18: 2.241395 | AH18: 2.245652 | AI18: 2.287807 | AJ18: 0.008
A19: Fuel Used to Liquefy Gas for Export | B19: Natural Gas: Use by Sector: Industrial: Liquefaction for Export: Low economic growth | C19: 13-AEO2022.18.lowmacro-d011222a | D19: Tcf | F19: 0.289928 | G19: 0.339835 | H19: 0.359363 | I19: 0.362967 | J19: 0.376731 | K19: 0.377708 | L19: 0.385808 | M19: 0.403042 | N19: 0.418208 | O19: 0.434408 | P19: 0.450608 | Q19: 0.467842 | R19: 0.474908 | S19: 0.474908 | T19: 0.474908 | U19: 0.475942 | V19: 0.474908 | W19: 0.474908 | X19: 0.474908 | Y19: 0.475942 | Z19: 0.474908 | AA19: 0.474908 | AB19: 0.474908 | AC19: 0.475942 | AD19: 0.474908 | AE19: 0.474908 | AF19: 0.474908 | AG19: 0.475942 | AH19: 0.474908 | AI19: 0.474908 | AJ19: 0.017
A20: Natural Gas-to-Liquids Heat and Power | B20: Natural Gas: Use by Sector: Industrial: GTL Heat and Power: Low economic growth | C20: 13-AEO2022.19.lowmacro-d011222a | D20: Tcf | F20: 0 | G20: 0 | H20: 0 | I20: 0 | J20: 0 | K20: 0 | L20: 0 | M20: 0 | N20: 0 | O20: 0 | P20: 0 | Q20: 0 | R20: 0 | S20: 0 | T20: 0 | U20: 0 | V20: 0 | W20: 0 | X20: 0 | Y20: 0 | Z20: 0 | AA20: 0 | AB20: 0 | AC20: 0 | AD20: 0 | AE20: 0 | AF20: 0 | AG20: 0 | AH20: 0 | AI20: 0 | AJ20: - -
A21: Natural Gas to Liquids Production | B21: Natural Gas: Use by Sector: Industrial: GTL Liquids: Low economic growth | C21: 13-AEO2022.20.lowmacro-d011222a | D21: Tcf | F21: 0 | G21: 0 | H21: 0 | I21: 0 | J21: 0 | K21: 0 | L21: 0 | M21: 0 | N21: 0 | O21: 0 | P21: 0 | Q21: 0 | R21: 0 | S21: 0 | T21: 0 | U21: 0 | V21: 0 | W21: 0 | X21: 0 | Y21: 0 | Z21: 0 | AA21: 0 | AB21: 0 | AC21: 0 | AD21: 0 | AE21: 0 | AF21: 0 | AG21: 0 | AH21: 0 | AI21: 0 | AJ21: - -
A22: Transportation | B22: Natural Gas: Use by Sector: Transportation: Low economic growth | C22: 13-AEO2022.21.lowmacro-d011222a | D22: Tcf | F22: 0.82787 | G22: 0.770456 | H22: 0.769016 | I22: 0.759091 | J22: 0.754646 | K22: 0.751995 | L22: 0.746852 | M22: 0.759835 | N22: 0.761848 | O22: 0.761588 | P22: 0.766947 | Q22: 0.773339 | R22: 0.783053 | S22: 0.781493 | T22: 0.786302 | U22: 0.794828 | V22: 0.808952 | W22: 0.8245 | X22: 0.837743 | Y22: 0.857536 | Z22: 0.870359 | AA22: 0.884783 | AB22: 0.901461 | AC22: 0.921563 | AD22: 0.930299 | AE22: 0.946389 | AF22: 0.964842 | AG22: 0.981295 | AH22: 0.998166 | AI22: 1.012687 | AJ22: 0.007
A23: Motor Vehicles | B23: Trains | C23: and Ships | D23: Natural Gas: Use by Sector: Transportation: Vehicles: Low economic growth | E23: 13-AEO2022.22.lowmacro-d011222a | F23: Tcf | H23: 0.10664 | I23: 0.096182 | J23: 0.113294 | K23: 0.119665 | L23: 0.126026 | M23: 0.135944 | N23: 0.146969 | O23: 0.154949 | P23: 0.162695 | Q23: 0.171487 | R23: 0.180423 | S23: 0.184107 | T23: 0.191779 | U23: 0.199366 | V23: 0.206543 | W23: 0.214237 | X23: 0.222566 | Y23: 0.231628 | Z23: 0.239112 | AA23: 0.253512 | AB23: 0.263027 | AC23: 0.272002 | AD23: 0.284502 | AE23: 0.297652 | AF23: 0.308227 | AG23: 0.321112 | AH23: 0.331511 | AI23: 0.340022 | AJ23: 0.349799 | AK23: 0.405344 | AL23: 0.047
A24: Pipeline and Distribution Fuel | B24: Natural Gas: Use by Sector: Transportation: Pipeline Fuel: Low economic growth | C24: 13-AEO2022.23.lowmacro-d011222a | D24: Tcf | F24: 0.72123 | G24: 0.674274 | H24: 0.655722 | I24: 0.639426 | J24: 0.62862 | K24: 0.616051 | L24: 0.599883 | M24: 0.604886 | N24: 0.599153 | O24: 0.590101 | P24: 0.586524 | Q24: 0.589232 | R24: 0.591273 | S24: 0.582127 | T24: 0.57976 | U24: 0.580591 | V24: 0.586386 | W24: 0.592872 | X24: 0.598631 | Y24: 0.604024 | Z24: 0.607332 | AA24: 0.61278 | AB24: 0.616958 | AC24: 0.623911 | AD24: 0.622073 | AE24: 0.625277 | AF24: 0.633331 | AG24: 0.641273 | AH24: 0.648367 | AI24: 0.653551 | AJ24: -0.003
A25: Electric Power | B25: Natural Gas: Use by Sector: Electric Power: Low economic growth | C25: 13-AEO2022.24.lowmacro-d011222a | D25: Tcf | F25: 10.85676 | G25: 10.377003 | H25: 10.576644 | I25: 10.506159 | J25: 10.184333 | K25: 10.036098 | L25: 9.759375 | M25: 9.953151 | N25: 9.845448 | O25: 9.61973 | P25: 9.476666 | Q25: 9.460497 | R25: 9.628703 | S25: 9.390562 | T25: 9.139952 | U25: 9.015231 | V25: 9.13309 | W25: 9.275352 | X25: 9.430664 | Y25: 9.577788 | Z25: 9.664156 | AA25: 9.771195 | AB25: 9.930477 | AC25: 10.016788 | AD25: 10.116599 | AE25: 10.267536 | AF25: 10.414912 | AG25: 10.56238 | AH25: 10.685132 | AI25: 10.88083 | AJ25: 0
A26: Discrepancy | B26: Natural Gas: Discrepancy: Low economic growth | C26: 13-AEO2022.26.lowmacro-d011222a | D26: Tcf | F26: 0.207672 | G26: 0.267736 | H26: 0.283455 | I26: 0.307045 | J26: 0.313267 | K26: 0.332649 | L26: 0.346489 | M26: 0.348215 | N26: 0.337095 | O26: 0.329943 | P26: 0.327724 | Q26: 0.332769 | R26: 0.315891 | S26: 0.31374 | T26: 0.313946 | U26: 0.307163 | V26: 0.307016 | W26: 0.305248 | X26: 0.299797 | Y26: 0.299158 | Z26: 0.305197 | AA26: 0.303766 | AB26: 0.303881 | AC26: 0.303232 | AD26: 0.292866 | AE26: 0.286081 | AF26: 0.314772 | AG26: 0.313833 | AH26: 0.314714 | AI26: 0.316364 | AJ26: - -
A27: Natural Gas Prices | C27: 13-AEO2022.28.
A28: Natural Gas Spot Price at Henry Hub | C28: 13-AEO2022.30.
A29: (2021 dollars per million Btu) | B29: Natural Gas: Henry Hub Spot Price: Low economic growth | C29: 13-AEO2022.31.lowmacro-d011222a | D29: 2021 $/MMBtu | F29: 4.115437 | G29: 3.837557 | H29: 3.471147 | I29: 3.126585 | J29: 2.953741 | K29: 2.906966 | L29: 2.954549 | M29: 3.136157 | N29: 3.292231 | O29: 3.388971 | P29: 3.454448 | Q29: 3.491858 | R29: 3.59329 | S29: 3.594153 | T29: 3.524364 | U29: 3.485305 | V29: 3.48693 | W29: 3.51827 | X29: 3.545613 | Y29: 3.577658 | Z29: 3.63465 | AA29: 3.652029 | AB29: 3.589562 | AC29: 3.561126 | AD29: 3.469676 | AE29: 3.425366 | AF29: 3.400315 | AG29: 3.392432 | AH29: 3.403568 | AI29: 3.409512 | AJ29: -0.006
A30: Delivered Prices | C30: 13-AEO2022.33.
A31: (2021 dollars per thousand cubic feet) | C31: 13-AEO2022.34.
A32: Residential | B32: Natural Gas: Delivered Prices: Residential: Low economic growth | C32: 13-AEO2022.35.lowmacro-d011222a | D32: 2021 $/Mcf | F32: 12.171644 | G32: 12.625865 | H32: 11.979866 | I32: 11.480213 | J32: 11.157559 | K32: 10.968821 | L32: 10.837678 | M32: 10.981541 | N32: 11.152151 | O32: 11.246775 | P32: 11.342472 | Q32: 11.68836 | R32: 11.833169 | S32: 11.888336 | T32: 11.88853 | U32: 11.856069 | V32: 11.895705 | W32: 11.930015 | X32: 11.970271 | Y32: 12.000363 | Z32: 12.084126 | AA32: 12.079756 | AB32: 12.043774 | AC32: 12.028834 | AD32: 11.998742 | AE32: 11.996384 | AF32: 12.001075 | AG32: 12.006783 | AH32: 12.045881 | AI32: 12.069625 | AJ32: 0
A33: Commercial | B33: Natural Gas: Delivered Prices: Commercial: Low economic growth | C33: 13-AEO2022.36.lowmacro-d011222a | D33: 2021 $/Mcf | F33: 8.771839 | G33: 9.162567 | H33: 8.828384 | I33: 8.499667 | J33: 8.33059 | K33: 8.281426 | L33: 8.273354 | M33: 8.399084 | N33: 8.544633 | O33: 8.616765 | P33: 8.690123 | Q33: 8.905362 | R33: 9.008744 | S33: 9.037756 | T33: 9.009416 | U33: 8.96355 | V33: 8.989129 | W33: 9.011681 | X33: 9.040559 | Y33: 9.060416 | Z33: 9.132076 | AA33: 9.116379 | AB33: 9.069324 | AC33: 9.045333 | AD33: 9.007052 | AE33: 8.995634 | AF33: 8.99243 | AG33: 8.990973 | AH33: 9.022299 | AI33: 9.039542 | AJ33: 0.001
A34: Industrial | B34: Natural Gas: Delivered Prices: Industrial: Low economic growth | C34: 13-AEO2022.37.lowmacro-d011222a | D34: 2021 $/Mcf | F34: 5.269056 | G34: 5.03236 | H34: 4.688 | I34: 4.317468 | J34: 4.135796 | K34: 4.079431 | L34: 4.111363 | M34: 4.275023 | N34: 4.428134 | O34: 4.517744 | P34: 4.577354 | Q34: 4.57688 | R34: 4.677366 | S34: 4.682547 | T34: 4.609011 | U34: 4.556269 | V34: 4.554906 | W34: 4.577663 | X34: 4.599112 | Y34: 4.622378 | Z34: 4.678865 | AA34: 4.686431 | AB34: 4.620964 | AC34: 4.584721 | AD34: 4.508954 | AE34: 4.477705 | AF34: 4.458506 | AG34: 4.452824 | AH34: 4.463304 | AI34: 4.471565 | AJ34: -0.006
A35: Transportation | B35: Natural Gas: Delivered Prices: Transportation: Low economic growth | C35: 13-AEO2022.38.lowmacro-d011222a | D35: 2021 $/Mcf | F35: 15.22551 | G35: 15.189867 | H35: 14.413707 | I35: 13.82573 | J35: 13.402384 | K35: 13.030856 | L35: 12.741631 | M35: 12.603173 | N35: 12.474068 | O35: 12.308931 | P35: 12.141323 | Q35: 12.813327 | R35: 12.722208 | S35: 12.575328 | T35: 12.46647 | U35: 12.278451 | V35: 12.158415 | W35: 12.07103 | X35: 11.987044 | Y35: 11.964777 | Z35: 11.952209 | AA35: 11.886301 | AB35: 11.783961 | AC35: 11.709952 | AD35: 11.603604 | AE35: 11.546721 | AF35: 11.496274 | AG35: 11.448224 | AH35: 11.422692 | AI35: 11.379571 | AJ35: -0.01
A36: Electric Power | B36: Natural Gas: Delivered Prices: Electric Power: Low economic growth | C36: 13-AEO2022.39.lowmacro-d011222a | D36: 2021 $/Mcf | F36: 5.332857 | G36: 4.178648 | H36: 3.885905 | I36: 3.547021 | J36: 3.377793 | K36: 3.342421 | L36: 3.381722 | M36: 3.556563 | N36: 3.688859 | O36: 3.763834 | P36: 3.807873 | Q36: 3.82572 | R36: 3.921008 | S36: 3.904177 | T36: 3.798467 | U36: 3.750271 | V36: 3.744769 | W36: 3.767939 | X36: 3.793509 | Y36: 3.829679 | Z36: 3.882215 | AA36: 3.881239 | AB36: 3.803053 | AC36: 3.765003 | AD36: 3.692361 | AE36: 3.66632 | AF36: 3.650438 | AG36: 3.654424 | AH36: 3.66035 | AI36: 3.687017 | AJ36: -0.013
A37: Average | B37: Natural Gas: Delivered Prices: Average: Low economic growth | C37: 13-AEO2022.40.lowmacro-d011222a | D37: 2021 $/Mcf | F37: 6.975946 | G37: 6.635291 | H37: 6.229839 | I37: 5.862714 | J37: 5.690771 | K37: 5.630795 | L37: 5.656798 | M37: 5.799069 | N37: 5.953547 | O37: 6.053108 | P37: 6.125708 | Q37: 6.227705 | R37: 6.316007 | S37: 6.343978 | T37: 6.301665 | U37: 6.264091 | V37: 6.259395 | W37: 6.268137 | X37: 6.278011 | Y37: 6.292707 | Z37: 6.344999 | AA37: 6.332001 | AB37: 6.253158 | AC37: 6.213667 | AD37: 6.142462 | AE37: 6.105012 | AF37: 6.077645 | AG37: 6.06405 | AH37: 6.067497 | AI37: 6.06418 | AJ37: -0.005
A38: Natural Gas Spot Price at Henry Hub | C38: 13-AEO2022.59.
A39: (nominal dollars per million Btu) | B39: Natural Gas: Henry Hub Spot Price: Low economic growth | C39: 13-AEO2022.60.lowmacro-d011222a | D39: nom $/MMBtu | F39: 4.115437 | G39: 3.961129 | H39: 3.67353 | I39: 3.407579 | J39: 3.321223 | K39: 3.380046 | L39: 3.55681 | M39: 3.909547 | N39: 4.247153 | O39: 4.519075 | P39: 4.759894 | Q39: 4.967306 | R39: 5.278396 | S39: 5.456114 | T39: 5.532805 | U39: 5.659725 | V39: 5.858712 | W39: 6.116162 | X39: 6.373682 | Y39: 6.653007 | Z39: 6.991181 | AA39: 7.266311 | AB39: 7.385303 | AC39: 7.573573 | AD39: 7.62625 | AE39: 7.781052 | AF39: 7.982764 | AG39: 8.228611 | AH39: 8.525277 | AI39: 8.814068 | AJ39: 0.027
A40: Delivered Prices | C40: 13-AEO2022.66.
...

Sheet AEO21 Table60
A1: Table 60. Natural Gas Imports and Exports
A2: https://www.eia.gov/outlooks/aeo/data/browser/#/?id=76-AEO2021&region=0-0&cases=highogs&start=2019&end=2050&f=A&sourcekey=0
A3: Fri Mar 19 2021 13:31:12 GMT-0700 (Pacific Daylight Time)
A4: Source: U.S. Energy Information Administration
B5: full name | C5: api key | D5: units | E5: 2019 | F5: 2020 | G5: 2021 | H5: 2022 | I5: 2023 | J5: 2024 | K5: 2025 | L5: 2026 | M5: 2027 | N5: 2028 | O5: 2029 | P5: 2030 | Q5: 2031 | R5: 2032 | S5: 2033 | T5: 2034 | U5: 2035 | V5: 2036 | W5: 2037 | X5: 2038 | Y5: 2039 | Z5: 2040 | AA5: 2041 | AB5: 2042 | AC5: 2043 | AD5: 2044 | AE5: 2045 | AF5: 2046 | AG5: 2047 | AH5: 2048 | AI5: 2049 | AJ5: 2050 | AK5: Growth (2020-2050)
A6: Volumes (trillion cubic feet) | C6: 76-AEO2021.2.
A7: Imports | B7: Natural Gas: Volumes: Imports: High oil and gas supply | C7: 76-AEO2021.3.highogs-d120120a | D7: Tcf | F7: 2.591845 | G7: 2.658888 | H7: 2.581335 | I7: 2.23374 | J7: 2.022558 | K7: 2.154527 | L7: 2.254248 | M7: 2.17263 | N7: 2.059658 | O7: 1.933034 | P7: 1.705166 | Q7: 1.695373 | R7: 1.588383 | S7: 1.443764 | T7: 1.408442 | U7: 1.381659 | V7: 1.372678 | W7: 1.378547 | X7: 1.372888 | Y7: 1.353339 | Z7: 1.349054 | AA7: 1.339908 | AB7: 1.309852 | AC7: 1.259662 | AD7: 1.237417 | AE7: 1.190565 | AF7: 1.152394 | AG7: 1.128619 | AH7: 1.06587 | AI7: 1.032826 | AJ7: 1.02677 | AK7: -0.03
A8: Pipeline Imports from Canada | B8: Natural Gas: Volumes: Imports: Pipeline Imports from Canada: High oil and gas supply | C8: 76-AEO2021.4.highogs-d120120a | D8: Tcf | F8: 2.527186 | G8: 2.580227 | H8: 2.503026 | I8: 2.155784 | J8: 1.944892 | K8: 2.076816 | L8: 2.17677 | M8: 2.095063 | N8: 1.982531 | O8: 1.855707 | P8: 1.628266 | Q8: 1.618474 | R8: 1.511483 | S8: 1.366865 | T8: 1.331543 | U8: 1.30476 | V8: 1.295779 | W8: 1.301647 | X8: 1.295988 | Y8: 1.27644 | Z8: 1.272155 | AA8: 1.263009 | AB8: 1.232953 | AC8: 1.182763 | AD8: 1.160517 | AE8: 1.113665 | AF8: 1.075495 | AG8: 1.05172 | AH8: 0.988971 | AI8: 0.955927 | AJ8: 0.94987 | AK8: -0.032
A9: Pipeline Imports from Mexico | B9: Natural Gas: Volumes: Imports: Pipeline Imports from Mexico: High oil and gas supply | C9: 76-AEO2021.5.highogs-d120120a | D9: Tcf | F9: 0 | G9: 0 | H9: 0 | I9: 0 | J9: 6.2e-05 | K9: 0.000459 | L9: 0.000579 | M9: 0.000668 | N9: 0.000228 | O9: 0.000427 | P9: 0 | Q9: 0 | R9: 0 | S9: 0 | T9: 0 | U9: 0 | V9: 0 | W9: 0 | X9: 0 | Y9: 0 | Z9: 0 | AA9: 0 | AB9: 0 | AC9: 0 | AD9: 0 | AE9: 0 | AF9: 0 | AG9: 0 | AH9: 0 | AI9: 0 | AJ9: 0 | AK9: - -
A10: Liquefied Natural Gas Imports | B10: Natural Gas: Volumes: Imports: Liquefied Natural Gas Imports: High oil and gas supply | C10: 76-AEO2021.6.highogs-d120120a | D10: Tcf | F10: 0.064659 | G10: 0.078661 | H10: 0.078309 | I10: 0.077956 | J10: 0.077604 | K10: 0.077252 | L10: 0.076899 | M10: 0.076899 | N10: 0.076899 | O10: 0.076899 | P10: 0.076899 | Q10: 0.076899 | R10: 0.076899 | S10: 0.076899 | T10: 0.076899 | U10: 0.076899 | V10: 0.076899 | W10: 0.076899 | X10: 0.076899 | Y10: 0.076899 | Z10: 0.076899 | AA10: 0.076899 | AB10: 0.076899 | AC10: 0.076899 | AD10: 0.076899 | AE10: 0.076899 | AF10: 0.076899 | AG10: 0.076899 | AH10: 0.076899 | AI10: 0.076899 | AJ10: 0.076899 | AK10: 0.006
A11: Exports | B11: Natural Gas: Volumes: Exports: High oil and gas supply | C11: 76-AEO2021.7.highogs-d120120a | D11: Tcf | F11: 5.260553 | G11: 6.296653 | H11: 6.521109 | I11: 6.762466 | J11: 7.25752 | K11: 7.86409 | L11: 8.32939 | M11: 8.588181 | N11: 8.927889 | O11: 9.361116 | P11: 9.833778 | Q11: 10.080954 | R11: 10.344864 | S11: 10.563437 | T11: 10.789639 | U11: 11.01073 | V11: 11.253021 | W11: 11.458885 | X11: 11.687817 | Y11: 11.909035 | Z11: 12.158211 | AA11: 12.256628 | AB11: 12.283306 | AC11: 12.311003 | AD11: 12.357313 | AE11: 12.357868 | AF11: 12.383665 | AG11: 12.409163 | AH11: 12.465016 | AI11: 12.467362 | AJ11: 12.477144 | AK11: 0.029
A12: Pipeline Exports to Canada | B12: Natural Gas: Volumes: Exports: Pipeline Exports to Canada: High oil and gas supply | C12: 76-AEO2021.8.highogs-d120120a | D12: Tcf | F12: 0.881853 | G12: 0.938842 | H12: 0.907451 | I12: 0.966469 | J12: 0.989208 | K12: 0.980991 | L12: 0.973344 | M12: 0.983885 | N12: 1.021513 | O12: 1.03111 | P12: 1.068119 | Q12: 1.081704 | R12: 1.100447 | S12: 1.111323 | T12: 1.111028 | U12: 1.12156 | V12: 1.134434 | W12: 1.144015 | X12: 1.1574 | Y12: 1.163259 | Z12: 1.176172 | AA12: 1.177003 | AB12: 1.186794 | AC12: 1.196353 | AD12: 1.208235 | AE12: 1.208432 | AF12: 1.216575 | AG12: 1.226854 | AH12: 1.245973 | AI12: 1.248916 | AJ12: 1.263373 | AK12: 0.012
A13: Pipeline Exports to Mexico | B13: Natural Gas: Volumes: Exports: Pipeline Exports to Mexico: High oil and gas supply | C13: 76-AEO2021.9.highogs-d120120a | D13: Tcf | F13: 2.06452 | G13: 2.190212 | H13: 2.486337 | I13: 2.6299 | J13: 2.728291 | K13: 2.786738 | L13: 2.83115 | M13: 2.879399 | N13: 2.969358 | O13: 3.005112 | P13: 3.040764 | Q13: 3.074354 | R13: 3.107399 | S13: 3.127219 | T13: 3.153715 | U13: 3.164275 | V13: 3.181569 | W13: 3.189975 | X13: 3.205522 | Y13: 3.220881 | Z13: 3.24502 | AA13: 3.25473 | AB13: 3.271617 | AC13: 3.289755 | AD13: 3.31206 | AE13: 3.324541 | AF13: 3.342195 | AG13: 3.357413 | AH13: 3.382025 | AI13: 3.393551 | AJ13: 3.388876 | AK13: 0.017
A14: Liquefied Natural Gas Exports | B14: Natural Gas: Volumes: Exports: Liquefied Natural Gas Exports: High oil and gas supply | C14: 76-AEO2021.10.highogs-d120120a | D14: Tcf | F14: 2.31418 | G14: 3.167598 | H14: 3.12732 | I14: 3.166097 | J14: 3.540021 | K14: 4.096361 | L14: 4.524895 | M14: 4.724895 | N14: 4.937018 | O14: 5.324895 | P14: 5.724895 | Q14: 5.924895 | R14: 6.137018 | S14: 6.324895 | T14: 6.524895 | U14: 6.724895 | V14: 6.937018 | W14: 7.124896 | X14: 7.324895 | Y14: 7.524895 | Z14: 7.737019 | AA14: 7.824895 | AB14: 7.824895 | AC14: 7.824895 | AD14: 7.837018 | AE14: 7.824895 | AF14: 7.824895 | AG14: 7.824895 | AH14: 7.837018 | AI14: 7.824895 | AJ14: 7.824895 | AK14: 0.041
A15: Net Imports | B15: Natural Gas: Volumes: Net Imports: High oil and gas supply | C15: 76-AEO2021.11.highogs-d120120a | D15: Tcf | F15: -2.668709 | G15: -3.637765 | H15: -3.939773 | I15: -4.528727 | J15: -5.234962 | K15: -5.709562 | L15: -6.075141 | M15: -6.41555 | N15: -6.868231 | O15: -7.428083 | P15: -8.128613 | Q15: -8.38558 | R15: -8.756481 | S15: -9.119673 | T15: -9.381196 | U15: -9.62907 | V15: -9.880342 | W15: -10.080339 | X15: -10.31493 | Y15: -10.555696 | Z15: -10.809156 | AA15: -10.916719 | AB15: -10.973454 | AC15: -11.051341 | AD15: -11.119896 | AE15: -11.167303 | AF15: -11.231272 | AG15: -11.280543 | AH15: -11.399146 | AI15: -11.434536 | AJ15: -11.450375 | AK15: 0.05
A16: Canada | B16: Natural Gas: Volumes: Net Imports: Canada: High oil and gas supply | C16: 76-AEO2021.12.highogs-d120120a | D16: Tcf | F16: 1.645333 | G16: 1.641385 | H16: 1.595575 | I16: 1.189314 | J16: 0.955684 | K16: 1.095825 | L16: 1.203426 | M16: 1.111177 | N16: 0.961019 | O16: 0.824597 | P16: 0.560147 | Q16: 0.53677 | R16: 0.411037 | S16: 0.255542 | T16: 0.220514 | U16: 0.1832 | V16: 0.161345 | W16: 0.157632 | X16: 0.138588 | Y16: 0.113181 | Z16: 0.095983 | AA16: 0.086006 | AB16: 0.046158 | AC16: -0.013591 | AD16: -0.047718 | AE16: -0.094766 | AF16: -0.141081 | AG16: -0.175134 | AH16: -0.257002 | AI16: -0.29299 | AJ16: -0.313502 | AK16: - -
A17: Mexico | B17: Natural Gas: Volumes: Net Imports: Mexico: High oil and gas supply | C17: 76-AEO2021.13.highogs-d120120a | D17: Tcf | F17: -2.06452 | G17: -2.190212 | H17: -2.486337 | I17: -2.6299 | J17: -2.728229 | K17: -2.786279 | L17: -2.830571 | M17: -2.878732 | N17: -2.969131 | O17: -3.004684 | P17: -3.040764 | Q17: -3.074354 | R17: -3.107399 | S17: -3.127219 | T17: -3.153715 | U17: -3.164275 | V17: -3.181569 | W17: -3.189975 | X17: -3.205522 | Y17: -3.220881 | Z17: -3.24502 | AA17: -3.25473 | AB17: -3.271617 | AC17: -3.289755 | AD17: -3.31206 | AE17: -3.324541 | AF17: -3.342195 | AG17: -3.357413 | AH17: -3.382025 | AI17: -3.393551 | AJ17: -3.388876 | AK17: 0.017
A18: Liquefied Natural Gas | B18: Natural Gas: Volumes: Net Imports: Liquefied Natural Gas: High oil and gas supply | C18: 76-AEO2021.14.highogs-d120120a | D18: Tcf | F18: -2.249521 | G18: -3.088938 | H18: -3.049012 | I18: -3.08814 | J18: -3.462417 | K18: -4.019109 | L18: -4.447996 | M18: -4.647996 | N18: -4.860119 | O18: -5.247996 | P18: -5.647996 | Q18: -5.847996 | R18: -6.060119 | S18: -6.247996 | T18: -6.447996 | U18: -6.647996 | V18: -6.860119 | W18: -7.047996 | X18: -7.247996 | Y18: -7.447996 | Z18: -7.660119 | AA18: -7.747996 | AB18: -7.747996 | AC18: -7.747996 | AD18: -7.760119 | AE18: -7.747996 | AF18: -7.747996 | AG18: -7.747996 | AH18: -7.760119 | AI18: -7.747996 | AJ18: -7.747996 | AK18: 0.042
B21: Transposed
C22: Pipeline Exports to Canada | D22: Pipeline Exports to Mexico | E22: Liquefied Natural Gas Exports
B23: {=TRANSPOSE(F5:AK5)} -> 2020 | C23: {=TRANSPOSE(F12:AK12)} -> 0.881853 | D23: {=TRANSPOSE(F13:AK13)} -> 2.06452 | E23: {=TRANSPOSE(F14:AK14)} -> 2.31418
B24: 2021 | C24: 0.938842 | D24: 2.190212 | E24: 3.167598
B25: 2022 | C25: 0.907451 | D25: 2.486337 | E25: 3.12732
B26: 2023 | C26: 0.966469 | D26: 2.6299 | E26: 3.166097
B27: 2024 | C27: 0.989208 | D27: 2.728291 | E27: 3.540021
B28: 2025 | C28: 0.980991 | D28: 2.786738 | E28: 4.096361
B29: 2026 | C29: 0.973344 | D29: 2.83115 | E29: 4.524895
B30: 2027 | C30: 0.983885 | D30: 2.879399 | E30: 4.724895
B31: 2028 | C31: 1.021513 | D31: 2.969358 | E31: 4.937018
B32: 2029 | C32: 1.03111 | D32: 3.005112 | E32: 5.324895
B33: 2030 | C33: 1.068119 | D33: 3.040764 | E33: 5.724895
B34: 2031 | C34: 1.081704 | D34: 3.074354 | E34: 5.924895
B35: 2032 | C35: 1.100447 | D35: 3.107399 | E35: 6.137018
... B53: 2050 | C53: 1.263373 | D53: 3.388876 | E53: 7.824895
B54: Growth (2020-2050) | C54: 0.012 | D54: 0.017 | E54: 0.041

Sheet AEO22 Table60
A1: Table 60. Natural Gas Imports and Exports
A2: https://www.eia.gov/outlooks/aeo/data/browser/#/?id=76-AEO2022&region=0-0&cases=ref2022&start=2020&end=2050&f=A&linechart=&ctype=linechart&sourcekey=0
A3: Fri Jun 03 2022 14:37:41 GMT-0700 (Pacific Daylight Time)
A4: Source: U.S. Energy Information Administration
B5: full name | C5: api key | D5: units | E5: 2020 | F5: 2021 | G5: 2022 | H5: 2023 | I5: 2024 | J5: 2025 | K5: 2026 | L5: 2027 | M5: 2028 | N5: 2029 | O5: 2030 | P5: 2031 | Q5: 2032 | R5: 2033 | S5: 2034 | T5: 2035 | U5: 2036 | V5: 2037 | W5: 2038 | X5: 2039 | Y5: 2040 | Z5: 2041 | AA5: 2042 | AB5: 2043 | AC5: 2044 | AD5: 2045 | AE5: 2046 | AF5: 2047 | AG5: 2048 | AH5: 2049 | AI5: 2050 | AJ5: Growth (2021-2050)
A6: Volumes (trillion cubic feet) | C6: 76-AEO2022.2.
A7: Imports | B7: Natural Gas: Volumes: Imports: Low economic growth | C7: 76-AEO2022.3.lowmacro-d011222a | D7: Tcf | F7: 2.730044 | G7: 2.478948 | H7: 2.399872 | I7: 2.299369 | J7: 2.227211 | K7: 2.201699 | L7: 2.167048 | M7: 2.117685 | N7: 1.987127 | O7: 1.935035 | P7: 1.844631 | Q7: 1.832976 | R7: 1.877825 | S7: 1.8405 | T7: 1.799475 | U7: 1.794174 | V7: 1.827648 | W7: 1.824522 | X7: 1.795108 | Y7: 1.761056 | Z7: 1.736678 | AA7: 1.728937 | AB7: 1.669057 | AC7: 1.548609 | AD7: 1.472641 | AE7: 1.452845 | AF7: 1.425173 | AG7: 1.428671 | AH7: 1.39673 | AI7: 1.353371 | AJ7: -0.024
A8: Pipeline Imports from Canada | B8: Natural Gas: Volumes: Imports: Pipeline Imports from Canada: Low economic growth | C8: 76-AEO2022.4.lowmacro-d011222a | D8: Tcf | F8: 2.692753 | G8: 2.400303 | H8: 2.323249 | I8: 2.224767 | J8: 2.154631 | K8: 2.13114 | L8: 2.098511 | M8: 2.049148 | N8: 1.91859 | O8: 1.866498 | P8: 1.776095 | Q8: 1.76444 | R8: 1.809288 | S8: 1.771963 | T8: 1.730938 | U8: 1.725637 | V8: 1.759111 | W8: 1.755986 | X8: 1.726571 | Y8: 1.69252 | Z8: 1.668141 | AA8: 1.6604 | AB8: 1.60052 | AC8: 1.480073 | AD8: 1.404104 | AE8: 1.384308 | AF8: 1.356636 | AG8: 1.360134 | AH8: 1.328193 | AI8: 1.284834 | AJ8: -0.025
A9: Pipeline Imports from Mexico | B9: Natural Gas: Volumes: Imports: Pipeline Imports from Mexico: Low economic growth | C9: 76-AEO2022.5.lowmacro-d011222a | D9: Tcf | F9: 0 | G9: 0 | H9: 0 | I9: 0 | J9: 0 | K9: 0 | L9: 0 | M9: 0 | N9: 0 | O9: 0 | P9: 0 | Q9: 0 | R9: 0 | S9: 0 | T9: 0 | U9: 0 | V9: 0 | W9: 0 | X9: 0 | Y9: 0 | Z9: 0 | AA9: 0 | AB9: 0 | AC9: 0 | AD9: 0 | AE9: 0 | AF9: 0 | AG9: 0 | AH9: 0 | AI9: 0 | AJ9: - -
A10: Liquefied Natural Gas Imports | B10: Natural Gas: Volumes: Imports: Liquefied Natural Gas Imports: Low economic growth | C10: 76-AEO2022.6.lowmacro-d011222a | D10: Tcf | F10: 0.037291 | G10: 0.078645 | H10: 0.076623 | I10: 0.074602 | J10: 0.07258 | K10: 0.070558 | L10: 0.068537 | M10: 0.068537 | N10: 0.068537 | O10: 0.068537 | P10: 0.068537 | Q10: 0.068537 | R10: 0.068537 | S10: 0.068537 | T10: 0.068537 | U10: 0.068537 | V10: 0.068537 | W10: 0.068537 | X10: 0.068537 | Y10: 0.068537 | Z10: 0.068537 | AA10: 0.068537 | AB10: 0.068537 | AC10: 0.068537 | AD10: 0.068537 | AE10: 0.068537 | AF10: 0.068537 | AG10: 0.068537 | AH10: 0.068537 | AI10: 0.068537 | AJ10: 0.021
A11: Exports | B11: Natural Gas: Volumes: Exports: Low economic growth | C11: 76-AEO2022.7.lowmacro-d011222a | D11: Tcf | F11: 6.748932 | G11: 7.511869 | H11: 7.719266 | I11: 7.80529 | J11: 8.022876 | K11: 8.037402 | L11: 8.174084 | M11: 8.464031 | N11: 8.713368 | O11: 8.942771 | P11: 9.217195 | Q11: 9.467295 | R11: 9.584615 | S11: 9.628318 | T11: 9.690271 | U11: 9.712461 | V11: 9.711069 | W11: 9.733184 | X11: 9.75787 | Y11: 9.793049 | Z11: 9.780193 | AA11: 9.797247 | AB11: 9.80693 | AC11: 9.842627 | AD11: 9.839452 | AE11: 9.823222 | AF11: 9.811426 | AG11: 9.816612 | AH11: 9.788502 | AI11: 9.782457 | AJ11: 0.013
A12: Pipeline Exports to Canada | B12: Natural Gas: Volumes: Exports: Pipeline Exports to Canada: Low economic growth | C12: 76-AEO2022.8.lowmacro-d011222a | D12: Tcf | F12: 0.950934 | G12: 0.994317 | H12: 0.966944 | I12: 0.984799 | J12: 0.99467 | K12: 0.984524 | L12: 0.989653 | M12: 0.998102 | N12: 1.021865 | O12: 1.021977 | P12: 1.059877 | Q12: 1.06349 | R12: 1.063998 | S12: 1.071854 | T12: 1.096582 | U12: 1.10407 | V12: 1.110207 | W12: 1.121564 | X12: 1.137337 | Y12: 1.150079 | Z12: 1.158589 | AA12: 1.182333 | AB12: 1.198976 | AC12: 1.231174 | AD12: 1.24635 | AE12: 1.254089 | AF12: 1.263327 | AG12: 1.274598 | AH12: 1.27874 | AI12: 1.289769 | AJ12: 0.011
A13: Pipeline Exports to Mexico | B13: Natural Gas: Volumes: Exports: Pipeline Exports to Mexico: Low economic growth | C13: 76-AEO2022.9.lowmacro-d011222a | D13: Tcf | F13: 2.218637 | G13: 2.322052 | H13: 2.315747 | I13: 2.339416 | J13: 2.377205 | K13: 2.389821 | L13: 2.421372 | M13: 2.490095 | N13: 2.528445 | O13: 2.557736 | P13: 2.59426 | Q13: 2.627972 | R13: 2.657558 | S13: 2.693406 | T13: 2.730632 | U13: 2.732557 | V13: 2.737805 | W13: 2.748562 | X13: 2.757474 | Y13: 2.767137 | Z13: 2.758546 | AA13: 2.751855 | AB13: 2.744895 | AC13: 2.735619 | AD13: 2.730044 | AE13: 2.706074 | AF13: 2.685041 | AG13: 2.666181 | AH13: 2.646703 | AI13: 2.62963 | AJ13: 0.006
A14: Liquefied Natural Gas Exports | B14: Natural Gas: Volumes: Exports: Liquefied Natural Gas Exports: Low economic growth | C14: 76-AEO2022.10.lowmacro-d011222a | D14: Tcf | F14: 3.57936 | G14: 4.1955 | H14: 4.436575 | I14: 4.481076 | J14: 4.651001 | K14: 4.663058 | L14: 4.763058 | M14: 4.975833 | N14: 5.163058 | O14: 5.363058 | P14: 5.563058 | Q14: 5.775833 | R14: 5.863058 | S14: 5.863058 | T14: 5.863058 | U14: 5.875834 | V14: 5.863058 | W14: 5.863058 | X14: 5.863058 | Y14: 5.875834 | Z14: 5.863058 | AA14: 5.863058 | AB14: 5.863058 | AC14: 5.875834 | AD14: 5.863058 | AE14: 5.863058 | AF14: 5.863058 | AG14: 5.875834 | AH14: 5.863058 | AI14: 5.863058 | AJ14: 0.017
A15: Net Imports | B15: Natural Gas: Volumes: Net Imports: Low economic growth | C15: 76-AEO2022.11.lowmacro-d011222a | D15: Tcf | F15: -4.018888 | G15: -5.032922 | H15: -5.319394 | I15: -5.505921 | J15: -5.795666 | K15: -5.835704 | L15: -6.007035 | M15: -6.346347 | N15: -6.726242 | O15: -7.007736 | P15: -7.372563 | Q15: -7.634318 | R15: -7.706789 | S15: -7.787818 | T15: -7.890796 | U15: -7.918287 | V15: -7.883422 | W15: -7.908662 | X15: -7.962761 | Y15: -8.031993 | Z15: -8.043514 | AA15: -8.06831 | AB15: -8.137873 | AC15: -8.294018 | AD15: -8.366811 | AE15: -8.370377 | AF15: -8.386254 | AG15: -8.387941 | AH15: -8.391771 | AI15: -8.429087 | AJ15: 0.026
A16: Canada | B16: Natural Gas: Volumes: Net Imports: Canada: Low economic growth | C16: 76-AEO2022.12.lowmacro-d011222a | D16: Tcf | F16: 1.741819 | G16: 1.405986 | H16: 1.356305 | I16: 1.239969 | J16: 1.159961 | K16: 1.146616 | L16: 1.108858 | M16: 1.051045 | N16: 0.896725 | O16: 0.844522 | P16: 0.716218 | Q16: 0.70095 | R16: 0.74529 | S16: 0.700109 | T16: 0.634357 | U16: 0.621567 | V16: 0.648904 | W16: 0.634422 | X16: 0.589234 | Y16: 0.54244 | Z16: 0.509553 | AA16: 0.478067 | AB16: 0.401543 | AC16: 0.248898 | AD16: 0.157755 | AE16: 0.130219 | AF16: 0.093309 | AG16: 0.085537 | AH16: 0.049454 | AI16: -0.004935 | AJ16: - -
A17: Mexico | B17: Natural Gas: Volumes: Net Imports: Mexico: Low economic growth | C17: 76-AEO2022.13.lowmacro-d011222a | D17: Tcf | F17: -2.218637 | G17: -2.322052 | H17: -2.315747 | I17: -2.339416 | J17: -2.377205 | K17: -2.389821 | L17: -2.421372 | M17: -2.490095 | N17: -2.528445 | O17: -2.557736 | P17: -2.59426 | Q17: -2.627972 | R17: -2.657558 | S17: -2.693406 | T17: -2.730632 | U17: -2.732557 | V17: -2.737805 | W17: -2.748562 | X17: -2.757474 | Y17: -2.767137 | Z17: -2.758546 | AA17: -2.751855 | AB17: -2.744895 | AC17: -2.735619 | AD17: -2.730044 | AE17: -2.706074 | AF17: -2.685041 | AG17: -2.666181 | AH17: -2.646703 | AI17: -2.62963 | AJ17: 0.006
A18: Liquefied Natural Gas | B18: Natural Gas: Volumes: Net Imports: Liquefied Natural Gas: Low economic growth | C18: 76-AEO2022.14.lowmacro-d011222a | D18: Tcf | F18: -3.542069 | G18: -4.116856 | H18: -4.359952 | I18: -4.406474 | J18: -4.578421 | K18: -4.592499 | L18: -4.694521 | M18: -4.907297 | N18: -5.094521 | O18: -5.294521 | P18: -5.494521 | Q18: -5.707296 | R18: -5.794521 | S18: -5.794521 | T18: -5.794521 | U18: -5.807297 | V18: -5.794521 | W18: -5.794521 | X18: -5.794521 | Y18: -5.807297 | Z18: -5.794521 | AA18: -5.794521 | AB18: -5.794521 | AC18: -5.807297 | AD18: -5.794521 | AE18: -5.794521 | AF18: -5.794521 | AG18: -5.807297 | AH18: -5.794521 | AI18: -5.794521 | AJ18: 0.017
B21: Transposed
C22: Pipeline Exports to Canada | D22: Pipeline Exports to Mexico | E22: Liquefied Natural Gas Exports
B23: 2021 | C23: 0.950934 | D23: 2.218661 | E23: 3.57936
B24: 2022 | C24: 0.993488 | D24: 2.321824 | E24: 4.1955
B25: 2023 | C25: 0.962994 | D25: 2.313414 | E25: 4.436575
B26: 2024 | C26: 0.979468 | D26: 2.334801 | E26: 4.481076
B27: 2025 | C27: 0.994414 | D27: 2.372 | E27: 4.651001
B28: 2026 | C28: 0.984083 | D28: 2.381717 | E28: 4.663058
B29: 2027 | C29: 0.982755 | D29: 2.409727 | E29: 4.763058
B30: 2028 | C30: 0.994677 | D30: 2.477914 | E30: 4.975833
B31: 2029 | C31: 1.026718 | D31: 2.513206 | E31: 5.163058
B32: 2030 | C32: 1.024433 | D32: 2.539065 | E32: 5.363058
B33: 2031 | C33: 1.059514 | D33: 2.574106 | E33: 5.563058
B34: 2032 | C34: 1.065948 | D34: 2.607545 | E34: 5.775833
... B52: 2050 | C52: 1.307339 | D52: 2.577559 | E52: 5.863058
B53: Growth (2021-2050) | C53: 0.011 | D53: 0.005 | E53: 0.017

Sheet Historical Monthly Gas Cons
A1: Back to Contents | B1: Data 1: Natural Gas Delivered to Consumers in the U.S. (MMcf)
A2: Sourcekey | B2: N3060US2
